package com.NovaCraft.world.ancient_city.prisoner;

import net.minecraft.world.gen.feature.*;
import net.minecraft.block.*;
import net.minecraft.world.*;
import java.util.*;
import com.NovaCraftBlocks.NovaCraftBlocks;
import net.minecraft.init.*;
import net.minecraft.nbt.NBTTagCompound;
import net.minecraft.nbt.NBTTagList;
import net.minecraft.tileentity.TileEntityMobSpawner;

public class AncientCitySmallHangingStructure1Gen extends WorldGenerator
{
	public AncientCitySmallHangingStructure1Gen() {
	}
	
	 public boolean generate(final World world, final Random random, final int i, final int j, final int k) {
		 
			world.setBlock(i + 2, j + 1, k + 2, NovaCraftBlocks.nullstone_brick_wall, 0, 2);
			world.setBlock(i + 2, j + 2, k + 2, NovaCraftBlocks.nullstone_brick_wall, 0, 2);
			world.setBlock(i + 1, j + 3, k, NovaCraftBlocks.nullstone_tiles, 0, 2);
			world.setBlock(i + 2, j + 3, k, NovaCraftBlocks.nullstone_tiles, 0, 2);
			world.setBlock(i + 3, j + 3, k, NovaCraftBlocks.nullstone_tiles, 0, 2);
			world.setBlock(i, j + 3, k + 1, NovaCraftBlocks.nullstone_tiles, 0, 2);
			world.setBlock(i + 1, j + 3, k + 1, NovaCraftBlocks.nullstone_tiles, 0, 2);
			world.setBlock(i + 2, j + 3, k + 1, NovaCraftBlocks.nullstone_tiles, 0, 2);
			world.setBlock(i + 3, j + 3, k + 1, NovaCraftBlocks.nullstone_tiles, 0, 2);
			world.setBlock(i + 4, j + 3, k + 1, NovaCraftBlocks.nullstone_tiles, 0, 2);
			world.setBlock(i, j + 3, k + 2, NovaCraftBlocks.nullstone_tiles, 0, 2);
			world.setBlock(i + 1, j + 3, k + 2, NovaCraftBlocks.nullstone_tiles, 0, 2);
			world.setBlock(i + 2, j + 3, k + 2, NovaCraftBlocks.nullstone_tiles, 0, 2);
			world.setBlock(i + 3, j + 3, k + 2, NovaCraftBlocks.nullstone_tiles, 0, 2);
			world.setBlock(i + 4, j + 3, k + 2, NovaCraftBlocks.nullstone_tiles, 0, 2);
			world.setBlock(i, j + 3, k + 3, NovaCraftBlocks.nullstone_tiles, 0, 2);
			world.setBlock(i + 1, j + 3, k + 3, NovaCraftBlocks.nullstone_tiles, 0, 2);
			world.setBlock(i + 2, j + 3, k + 3, NovaCraftBlocks.nullstone_tiles, 0, 2);
			world.setBlock(i + 3, j + 3, k + 3, NovaCraftBlocks.nullstone_tiles, 0, 2);
			world.setBlock(i + 4, j + 3, k + 3, NovaCraftBlocks.nullstone_tiles, 0, 2);
			world.setBlock(i + 1, j + 3, k + 4, NovaCraftBlocks.nullstone_tiles, 0, 2);
			world.setBlock(i + 2, j + 3, k + 4, NovaCraftBlocks.nullstone_tiles, 0, 2);
			world.setBlock(i + 3, j + 3, k + 4, NovaCraftBlocks.nullstone_tiles, 0, 2);
			world.setBlock(i, j + 4, k, NovaCraftBlocks.nullstone_tiled_wall, 0, 2);
			world.setBlock(i + 1, j + 4, k, NovaCraftBlocks.nullstone_bricks, 0, 2);
			world.setBlock(i + 2, j + 4, k, NovaCraftBlocks.nullstone_tiled_wall, 0, 2);
			world.setBlock(i + 3, j + 4, k, NovaCraftBlocks.nullstone_bricks, 0, 2);
			world.setBlock(i + 4, j + 4, k, NovaCraftBlocks.nullstone_tiled_wall, 0, 2);
			world.setBlock(i, j + 4, k + 1, NovaCraftBlocks.nullstone_bricks, 0, 2);
			world.setBlock(i + 4, j + 4, k + 1, NovaCraftBlocks.nullstone_bricks, 0, 2);
			world.setBlock(i, j + 4, k + 2, NovaCraftBlocks.nullstone_tiled_wall, 0, 2);
			world.setBlock(i + 4, j + 4, k + 2, NovaCraftBlocks.nullstone_tiled_wall, 0, 2);
			world.setBlock(i, j + 4, k + 3, NovaCraftBlocks.nullstone_bricks, 0, 2);
			world.setBlock(i + 4, j + 4, k + 3, NovaCraftBlocks.nullstone_bricks, 0, 2);
			world.setBlock(i, j + 4, k + 4, NovaCraftBlocks.nullstone_tiled_wall, 0, 2);
			world.setBlock(i + 1, j + 4, k + 4, NovaCraftBlocks.nullstone_bricks, 0, 2);
			world.setBlock(i + 2, j + 4, k + 4, NovaCraftBlocks.nullstone_tiled_wall, 0, 2);
			world.setBlock(i + 3, j + 4, k + 4, NovaCraftBlocks.nullstone_bricks, 0, 2);
			world.setBlock(i + 4, j + 4, k + 4, NovaCraftBlocks.nullstone_tiled_wall, 0, 2);
			world.setBlock(i, j + 5, k, NovaCraftBlocks.nullstone_tiled_wall, 0, 2);
			world.setBlock(i + 1, j + 5, k, NovaCraftBlocks.nullstone_tiled_wall, 0, 2);
			world.setBlock(i + 3, j + 5, k, NovaCraftBlocks.nullstone_tiled_wall, 0, 2);
			world.setBlock(i + 4, j + 5, k, NovaCraftBlocks.nullstone_tiled_wall, 0, 2);
			world.setBlock(i, j + 5, k + 1, NovaCraftBlocks.nullstone_tiled_wall, 0, 2);
			world.setBlock(i + 4, j + 5, k + 1, NovaCraftBlocks.nullstone_tiled_wall, 0, 2);
			world.setBlock(i, j + 5, k + 2, NovaCraftBlocks.dim_vanite_torch, 5, 2);
			world.setBlock(i + 4, j + 5, k + 2, NovaCraftBlocks.dim_vanite_torch, 5, 2);
			world.setBlock(i, j + 5, k + 3, NovaCraftBlocks.nullstone_tiled_wall, 0, 2);
			world.setBlock(i + 4, j + 5, k + 3, NovaCraftBlocks.nullstone_tiled_wall, 0, 2);
			world.setBlock(i, j + 5, k + 4, NovaCraftBlocks.nullstone_tiled_wall, 0, 2);
			world.setBlock(i + 1, j + 5, k + 4, NovaCraftBlocks.nullstone_tiled_wall, 0, 2);
			world.setBlock(i + 2, j + 5, k + 4, NovaCraftBlocks.dim_vanite_torch, 5, 2);
			world.setBlock(i + 3, j + 5, k + 4, NovaCraftBlocks.nullstone_tiled_wall, 0, 2);
			world.setBlock(i + 4, j + 5, k + 4, NovaCraftBlocks.nullstone_tiled_wall, 0, 2);
			world.setBlock(i, j + 6, k, NovaCraftBlocks.nullstone_tiled_wall, 0, 2);
			world.setBlock(i + 1, j + 6, k, NovaCraftBlocks.nullstone_tiles, 0, 2);
			world.setBlock(i + 2, j + 6, k, NovaCraftBlocks.nullstone_tiles, 0, 2);
			world.setBlock(i + 3, j + 6, k, NovaCraftBlocks.nullstone_tiles, 0, 2);
			world.setBlock(i + 4, j + 6, k, NovaCraftBlocks.nullstone_tiled_wall, 0, 2);
			world.setBlock(i, j + 6, k + 1, NovaCraftBlocks.nullstone_tiles, 0, 2);
			world.setBlock(i + 4, j + 6, k + 1, NovaCraftBlocks.nullstone_tiles, 0, 2);
			world.setBlock(i, j + 6, k + 2, NovaCraftBlocks.nullstone_tiles, 0, 2);
			world.setBlock(i + 4, j + 6, k + 2, NovaCraftBlocks.nullstone_tiles, 0, 2);
			world.setBlock(i, j + 6, k + 3, NovaCraftBlocks.nullstone_tiles, 0, 2);
			world.setBlock(i + 4, j + 6, k + 3, NovaCraftBlocks.nullstone_tiles, 0, 2);
			world.setBlock(i, j + 6, k + 4, NovaCraftBlocks.nullstone_tiled_wall, 0, 2);
			world.setBlock(i + 1, j + 6, k + 4, NovaCraftBlocks.nullstone_tiles, 0, 2);
			world.setBlock(i + 2, j + 6, k + 4, NovaCraftBlocks.nullstone_tiles, 0, 2);
			world.setBlock(i + 3, j + 6, k + 4, NovaCraftBlocks.nullstone_tiles, 0, 2);
			world.setBlock(i + 4, j + 6, k + 4, NovaCraftBlocks.nullstone_tiled_wall, 0, 2);
			world.setBlock(i + 1, j + 7, k + 1, NovaCraftBlocks.nullstone_tiles, 0, 2);
			world.setBlock(i + 2, j + 7, k + 1, NovaCraftBlocks.nullstone_tiles, 0, 2);
			world.setBlock(i + 3, j + 7, k + 1, NovaCraftBlocks.nullstone_tiles, 0, 2);
			world.setBlock(i + 1, j + 7, k + 2, NovaCraftBlocks.nullstone_tiles, 0, 2);
			world.setBlock(i + 2, j + 7, k + 2, Blocks.glowstone, 0, 2);
			world.setBlock(i + 3, j + 7, k + 2, NovaCraftBlocks.nullstone_tiles, 0, 2);
			world.setBlock(i + 1, j + 7, k + 3, NovaCraftBlocks.nullstone_tiles, 0, 2);
			world.setBlock(i + 2, j + 7, k + 3, NovaCraftBlocks.nullstone_tiles, 0, 2);
			world.setBlock(i + 3, j + 7, k + 3, NovaCraftBlocks.nullstone_tiles, 0, 2);
			world.setBlock(i + 2, j + 8, k + 1, NovaCraftBlocks.nullstone_tiled_wall, 0, 2);
			world.setBlock(i + 1, j + 8, k + 2, NovaCraftBlocks.nullstone_tiled_wall, 0, 2);
			world.setBlock(i + 3, j + 8, k + 2, NovaCraftBlocks.nullstone_tiled_wall, 0, 2);
			world.setBlock(i + 2, j + 8, k + 3, NovaCraftBlocks.nullstone_tiled_wall, 0, 2);
			world.setBlock(i + 2, j + 9, k + 1, NovaCraftBlocks.nullstone_tiled_wall, 0, 2);
			world.setBlock(i + 1, j + 9, k + 2, NovaCraftBlocks.nullstone_tiled_wall, 0, 2);
			world.setBlock(i + 2, j + 9, k + 2, NovaCraftBlocks.nullstone_tiled_wall, 0, 2);
			world.setBlock(i + 3, j + 9, k + 2, NovaCraftBlocks.nullstone_tiled_wall, 0, 2);
			world.setBlock(i + 2, j + 9, k + 3, NovaCraftBlocks.nullstone_tiled_wall, 0, 2);
			world.setBlock(i + 2, j + 10, k + 2, NovaCraftBlocks.nullstone_tiled_wall, 0, 2);
			world.setBlock(i + 2, j + 11, k + 2, NovaCraftBlocks.nullstone_tiled_wall, 0, 2);
			world.setBlock(i + 2, j + 12, k + 2, NovaCraftBlocks.nullstone_tiled_wall, 0, 2);
			world.setBlock(i + 2, j + 13, k + 2, NovaCraftBlocks.nullstone_tiled_wall, 0, 2);
			
			world.setBlock(i + 2, j + 14, k + 2, NovaCraftBlocks.nullstone_tiled_wall, 0, 2);
			if ((world.getBlock(i + 2, j + 15, k + 2) == Blocks.air || world.getBlock(i + 2, j + 15, k + 2) == Blocks.gravel) && world.getBlock(i + 2, j + 14, k + 2) == NovaCraftBlocks.nullstone_tiled_wall) {
	            world.setBlock(i + 2, j + 15, k + 2, NovaCraftBlocks.nullstone_tiled_wall, 0, 2);	            
	        } if ((world.getBlock(i + 2, j + 16, k + 2) == Blocks.air || world.getBlock(i + 2, j + 16, k + 2) == Blocks.gravel) && world.getBlock(i + 2, j + 15, k + 2) == NovaCraftBlocks.nullstone_tiled_wall) {
	            world.setBlock(i + 2, j + 16, k + 2, NovaCraftBlocks.nullstone_tiled_wall, 0, 2);	            
	        } if ((world.getBlock(i + 2, j + 17, k + 2) == Blocks.air || world.getBlock(i + 2, j + 17, k + 2) == Blocks.gravel) && world.getBlock(i + 2, j + 16, k + 2) == NovaCraftBlocks.nullstone_tiled_wall) {
	            world.setBlock(i + 2, j + 17, k + 2, NovaCraftBlocks.nullstone_tiled_wall, 0, 2);	            
	        } if ((world.getBlock(i + 2, j + 18, k + 2) == Blocks.air || world.getBlock(i + 2, j + 18, k + 2) == Blocks.gravel) && world.getBlock(i + 2, j + 17, k + 2) == NovaCraftBlocks.nullstone_tiled_wall) {
	            world.setBlock(i + 2, j + 18, k + 2, NovaCraftBlocks.nullstone_tiled_wall, 0, 2);	            
	        }
			
			
			world.setBlock(i + 2, j + 4, k + 2, NovaCraftBlocks.cracked_nullstone_deactivator, 0, 2);
			
			world.setBlock(i + 2, j, k + 2, Blocks.mob_spawner, 0, 2);
			TileEntityMobSpawner tileentitymobspawner2 = (TileEntityMobSpawner)world.getTileEntity(i + 2, j, k + 2);
			
			if (tileentitymobspawner2 != null)
			{
    		tileentitymobspawner2.func_145881_a().setEntityName("nova_craft.sculk_incinerator");

	        NBTTagCompound spawnerNBT2 = new NBTTagCompound();
	        tileentitymobspawner2.writeToNBT(spawnerNBT2);

	        NBTTagCompound spawnData2 = new NBTTagCompound();
	        spawnData2.setString("id", "nova_craft.sculk_incinerator");

	        NBTTagList effects2 = new NBTTagList();

	        NBTTagCompound resistanceEffect2 = new NBTTagCompound();
	        resistanceEffect2.setByte("Id", (byte) 11);
	        resistanceEffect2.setByte("Amplifier", (byte) 1);
	        resistanceEffect2.setInteger("Duration", Integer.MAX_VALUE);
	        resistanceEffect2.setByte("Ambient", (byte) 1);
	        resistanceEffect2.setByte("ShowParticles", (byte) 0);

	        effects2.appendTag(resistanceEffect2);
	        spawnData2.setTag("ActiveEffects", effects2);
	        
	        spawnerNBT2.setTag("SpawnData", spawnData2);

	        tileentitymobspawner2.readFromNBT(spawnerNBT2);
			}
		 
		 return true;
	 }

}
