package com.NovaCraft.world.ancient_city.prisoner;

import net.minecraft.world.gen.feature.*;
import net.minecraft.block.*;
import net.minecraft.world.*;
import java.util.*;
import com.NovaCraftBlocks.NovaCraftBlocks;
import net.minecraft.init.*;
import net.minecraft.nbt.NBTTagCompound;
import net.minecraft.nbt.NBTTagList;
import net.minecraft.tileentity.TileEntityMobSpawner;

public class AncientCityMediumHangingStructureGen extends WorldGenerator
{
	public AncientCityMediumHangingStructureGen() {

	}
	
	 public boolean generate(final World world, final Random random, final int i, final int j, final int k) {
		 
			world.setBlock(i + 3, j + 1, k + 2, NovaCraftBlocks.nullstone_brick_wall, 0, 2);
			world.setBlock(i + 3, j + 2, k + 2, NovaCraftBlocks.nullstone_brick_wall, 0, 2);
			world.setBlock(i + 7, j + 2, k + 4, NovaCraftBlocks.nullstone_brick_wall, 0, 2);
			world.setBlock(i + 3, j + 3, k + 2, NovaCraftBlocks.nullstone_brick_wall, 0, 2);
			world.setBlock(i + 1, j + 3, k + 4, NovaCraftBlocks.nullstone_brick_wall, 0, 2);
			world.setBlock(i + 7, j + 3, k + 4, NovaCraftBlocks.nullstone_brick_wall, 0, 2);
			world.setBlock(i + 3, j + 3, k + 6, NovaCraftBlocks.nullstone_brick_wall, 0, 2);
			world.setBlock(i + 4, j + 4, k + 1, NovaCraftBlocks.nullstone_bricks, 0, 2);
			world.setBlock(i + 3, j + 4, k + 2, NovaCraftBlocks.nullstone_bricks, 0, 2);
			world.setBlock(i + 5, j + 4, k + 2, NovaCraftBlocks.nullstone_bricks, 0, 2);
			world.setBlock(i + 2, j + 4, k + 3, NovaCraftBlocks.nullstone_bricks, 0, 2);
			world.setBlock(i + 6, j + 4, k + 3, NovaCraftBlocks.nullstone_bricks, 0, 2);
			world.setBlock(i + 1, j + 4, k + 4, NovaCraftBlocks.nullstone_bricks, 0, 2);
			world.setBlock(i + 7, j + 4, k + 4, NovaCraftBlocks.nullstone_bricks, 0, 2);
			world.setBlock(i + 2, j + 4, k + 5, NovaCraftBlocks.nullstone_bricks, 0, 2);
			world.setBlock(i + 6, j + 4, k + 5, NovaCraftBlocks.nullstone_bricks, 0, 2);
			world.setBlock(i + 3, j + 4, k + 6, NovaCraftBlocks.nullstone_bricks, 0, 2);
			world.setBlock(i + 5, j + 4, k + 6, NovaCraftBlocks.nullstone_bricks, 0, 2);
			world.setBlock(i + 4, j + 4, k + 7, NovaCraftBlocks.nullstone_bricks, 0, 2);
			world.setBlock(i + 4, j + 5, k, NovaCraftBlocks.nullstone_bricks, 0, 2);
			world.setBlock(i + 3, j + 5, k + 1, NovaCraftBlocks.nullstone_bricks, 0, 2);
			world.setBlock(i + 4, j + 5, k + 1, NovaCraftBlocks.nullstone_tiles, 0, 2);
			world.setBlock(i + 5, j + 5, k + 1, NovaCraftBlocks.nullstone_bricks, 0, 2);
			world.setBlock(i + 2, j + 5, k + 2, NovaCraftBlocks.nullstone_bricks, 0, 2);
			world.setBlock(i + 3, j + 5, k + 2, NovaCraftBlocks.nullstone_tiles, 0, 2);
			world.setBlock(i + 4, j + 5, k + 2, NovaCraftBlocks.nullstone_tiles, 0, 2);
			world.setBlock(i + 5, j + 5, k + 2, NovaCraftBlocks.nullstone_tiles, 0, 2);
			world.setBlock(i + 6, j + 5, k + 2, NovaCraftBlocks.nullstone_bricks, 0, 2);
			world.setBlock(i + 1, j + 5, k + 3, NovaCraftBlocks.nullstone_bricks, 0, 2);
			world.setBlock(i + 2, j + 5, k + 3, NovaCraftBlocks.nullstone_tiles, 0, 2);
			world.setBlock(i + 3, j + 5, k + 3, NovaCraftBlocks.nullstone_tiles, 0, 2);
			world.setBlock(i + 4, j + 5, k + 3, NovaCraftBlocks.nullstone_tiles, 0, 2);
			world.setBlock(i + 5, j + 5, k + 3, NovaCraftBlocks.nullstone_tiles, 0, 2);
			world.setBlock(i + 6, j + 5, k + 3, NovaCraftBlocks.nullstone_tiles, 0, 2);
			world.setBlock(i + 7, j + 5, k + 3, NovaCraftBlocks.nullstone_bricks, 0, 2);
			world.setBlock(i, j + 5, k + 4, NovaCraftBlocks.nullstone_bricks, 0, 2);
			world.setBlock(i + 1, j + 5, k + 4, NovaCraftBlocks.nullstone_tiles, 0, 2);
			world.setBlock(i + 2, j + 5, k + 4, NovaCraftBlocks.nullstone_tiles, 0, 2);
			world.setBlock(i + 3, j + 5, k + 4, NovaCraftBlocks.nullstone_tiles, 0, 2);
			world.setBlock(i + 4, j + 5, k + 4, NovaCraftBlocks.nullstone_tiles, 0, 2);
			world.setBlock(i + 5, j + 5, k + 4, NovaCraftBlocks.nullstone_tiles, 0, 2);
			world.setBlock(i + 6, j + 5, k + 4, NovaCraftBlocks.nullstone_tiles, 0, 2);
			world.setBlock(i + 7, j + 5, k + 4, NovaCraftBlocks.nullstone_tiles, 0, 2);
			world.setBlock(i + 8, j + 5, k + 4, NovaCraftBlocks.nullstone_bricks, 0, 2);
			world.setBlock(i + 1, j + 5, k + 5, NovaCraftBlocks.nullstone_bricks, 0, 2);
			world.setBlock(i + 2, j + 5, k + 5, NovaCraftBlocks.nullstone_tiles, 0, 2);
			world.setBlock(i + 3, j + 5, k + 5, NovaCraftBlocks.nullstone_tiles, 0, 2);
			world.setBlock(i + 4, j + 5, k + 5, NovaCraftBlocks.nullstone_tiles, 0, 2);
			world.setBlock(i + 5, j + 5, k + 5, NovaCraftBlocks.nullstone_tiles, 0, 2);
			world.setBlock(i + 6, j + 5, k + 5, NovaCraftBlocks.nullstone_tiles, 0, 2);
			world.setBlock(i + 7, j + 5, k + 5, NovaCraftBlocks.nullstone_bricks, 0, 2);
			world.setBlock(i + 2, j + 5, k + 6, NovaCraftBlocks.nullstone_bricks, 0, 2);
			world.setBlock(i + 3, j + 5, k + 6, NovaCraftBlocks.nullstone_tiles, 0, 2);
			world.setBlock(i + 4, j + 5, k + 6, NovaCraftBlocks.nullstone_tiles, 0, 2);
			world.setBlock(i + 5, j + 5, k + 6, NovaCraftBlocks.nullstone_tiles, 0, 2);
			world.setBlock(i + 6, j + 5, k + 6, NovaCraftBlocks.nullstone_bricks, 0, 2);
			world.setBlock(i + 3, j + 5, k + 7, NovaCraftBlocks.nullstone_bricks, 0, 2);
			world.setBlock(i + 4, j + 5, k + 7, NovaCraftBlocks.nullstone_tiles, 0, 2);
			world.setBlock(i + 5, j + 5, k + 7, NovaCraftBlocks.nullstone_bricks, 0, 2);
			world.setBlock(i + 4, j + 5, k + 8, NovaCraftBlocks.nullstone_bricks, 0, 2);
			world.setBlock(i + 4, j + 6, k, NovaCraftBlocks.nullstone_tiled_wall, 0, 2);
			world.setBlock(i + 2, j + 6, k + 2, NovaCraftBlocks.nullstone_tiled_wall, 0, 2);
			world.setBlock(i + 6, j + 6, k + 2, NovaCraftBlocks.nullstone_tiled_wall, 0, 2);
			world.setBlock(i + 3, j + 6, k + 3, NovaCraftBlocks.nullstone_brick_stairs, 2, 2);
			world.setBlock(i + 4, j + 6, k + 3, NovaCraftBlocks.nullstone_brick_stairs, 2, 2);
			world.setBlock(i + 5, j + 6, k + 3, NovaCraftBlocks.nullstone_brick_stairs, 1, 2);
			world.setBlock(i, j + 6, k + 4, NovaCraftBlocks.nullstone_tiled_wall, 0, 2);
			world.setBlock(i + 3, j + 6, k + 4, NovaCraftBlocks.nullstone_brick_stairs, 0, 2);
			world.setBlock(i + 4, j + 6, k + 4, NovaCraftBlocks.nullstone_tiles, 0, 2);
			world.setBlock(i + 5, j + 6, k + 4, NovaCraftBlocks.nullstone_brick_stairs, 1, 2);
			world.setBlock(i + 8, j + 6, k + 4, NovaCraftBlocks.nullstone_tiled_wall, 0, 2);
			world.setBlock(i + 3, j + 6, k + 5, NovaCraftBlocks.nullstone_brick_stairs, 0, 2);
			world.setBlock(i + 4, j + 6, k + 5, NovaCraftBlocks.nullstone_brick_stairs, 3, 2);
			world.setBlock(i + 5, j + 6, k + 5, NovaCraftBlocks.nullstone_brick_stairs, 3, 2);
			world.setBlock(i + 2, j + 6, k + 6, NovaCraftBlocks.nullstone_tiled_wall, 0, 2);
			world.setBlock(i + 6, j + 6, k + 6, NovaCraftBlocks.nullstone_tiled_wall, 0, 2);
			world.setBlock(i + 4, j + 6, k + 8, NovaCraftBlocks.nullstone_tiled_wall, 0, 2);
			world.setBlock(i + 4, j + 7, k, NovaCraftBlocks.nullstone_tiled_wall, 0, 2);
			world.setBlock(i + 4, j + 7, k + 1, NovaCraftBlocks.nullstone_tiled_wall, 0, 2);
			world.setBlock(i + 2, j + 7, k + 2, NovaCraftBlocks.dim_vanite_torch, 5, 2);
			world.setBlock(i + 6, j + 7, k + 2, NovaCraftBlocks.dim_vanite_torch, 5, 2);
			world.setBlock(i, j + 7, k + 4, NovaCraftBlocks.nullstone_tiled_wall, 0, 2);
			world.setBlock(i + 1, j + 7, k + 4, NovaCraftBlocks.nullstone_tiled_wall, 0, 2);
			world.setBlock(i + 7, j + 7, k + 4, NovaCraftBlocks.nullstone_tiled_wall, 0, 2);
			world.setBlock(i + 8, j + 7, k + 4, NovaCraftBlocks.nullstone_tiled_wall, 0, 2);
			world.setBlock(i + 2, j + 7, k + 6, NovaCraftBlocks.dim_vanite_torch, 5, 2);
			world.setBlock(i + 6, j + 7, k + 6, NovaCraftBlocks.dim_vanite_torch, 5, 2);
			world.setBlock(i + 4, j + 7, k + 7, NovaCraftBlocks.nullstone_tiled_wall, 0, 2);
			world.setBlock(i + 4, j + 7, k + 8, NovaCraftBlocks.nullstone_tiled_wall, 0, 2);
			world.setBlock(i + 4, j + 8, k, NovaCraftBlocks.dim_vanite_torch, 5, 2);
			world.setBlock(i + 4, j + 8, k + 1, NovaCraftBlocks.nullstone_tiled_wall, 0, 2);
			world.setBlock(i + 4, j + 8, k + 2, NovaCraftBlocks.nullstone_tiled_wall, 0, 2);
			world.setBlock(i, j + 8, k + 4, NovaCraftBlocks.dim_vanite_torch, 5, 2);
			world.setBlock(i + 1, j + 8, k + 4, NovaCraftBlocks.nullstone_tiled_wall, 0, 2);
			world.setBlock(i + 2, j + 8, k + 4, NovaCraftBlocks.nullstone_tiled_wall, 0, 2);
			world.setBlock(i + 6, j + 8, k + 4, NovaCraftBlocks.nullstone_tiled_wall, 0, 2);
			world.setBlock(i + 7, j + 8, k + 4, NovaCraftBlocks.nullstone_tiled_wall, 0, 2);
			world.setBlock(i + 8, j + 8, k + 4, NovaCraftBlocks.dim_vanite_torch, 5, 2);
			world.setBlock(i + 4, j + 8, k + 6, NovaCraftBlocks.nullstone_tiled_wall, 0, 2);
			world.setBlock(i + 4, j + 8, k + 7, NovaCraftBlocks.nullstone_tiled_wall, 0, 2);
			world.setBlock(i + 4, j + 8, k + 8, NovaCraftBlocks.dim_vanite_torch, 5, 2);
			world.setBlock(i + 4, j + 9, k + 2, NovaCraftBlocks.nullstone_tiled_wall, 0, 2);
			world.setBlock(i + 4, j + 9, k + 3, NovaCraftBlocks.nullstone_tiled_wall, 0, 2);
			world.setBlock(i + 2, j + 9, k + 4, NovaCraftBlocks.nullstone_tiled_wall, 0, 2);
			world.setBlock(i + 3, j + 9, k + 4, NovaCraftBlocks.nullstone_tiled_wall, 0, 2);
			world.setBlock(i + 5, j + 9, k + 4, NovaCraftBlocks.nullstone_tiled_wall, 0, 2);
			world.setBlock(i + 6, j + 9, k + 4, NovaCraftBlocks.nullstone_tiled_wall, 0, 2);
			world.setBlock(i + 4, j + 9, k + 5, NovaCraftBlocks.nullstone_tiled_wall, 0, 2);
			world.setBlock(i + 4, j + 9, k + 6, NovaCraftBlocks.nullstone_tiled_wall, 0, 2);
			world.setBlock(i + 4, j + 10, k + 3, NovaCraftBlocks.nullstone_tiled_wall, 0, 2);
			world.setBlock(i + 3, j + 10, k + 4, NovaCraftBlocks.nullstone_tiled_wall, 0, 2);
			world.setBlock(i + 4, j + 10, k + 4, NovaCraftBlocks.nullstone_tiled_wall, 0, 2);
			world.setBlock(i + 5, j + 10, k + 4, NovaCraftBlocks.nullstone_tiled_wall, 0, 2);
			world.setBlock(i + 4, j + 10, k + 5, NovaCraftBlocks.nullstone_tiled_wall, 0, 2);
			world.setBlock(i + 4, j + 11, k + 4, NovaCraftBlocks.nullstone_tiled_wall, 0, 2);
			world.setBlock(i + 4, j + 12, k + 4, NovaCraftBlocks.nullstone_tiled_wall, 0, 2);
						
			world.setBlock(i + 4, j + 13, k + 4, NovaCraftBlocks.nullstone_tiled_wall, 0, 2);
			if ((world.getBlock(i + 4, j + 14, k + 4) == Blocks.air || world.getBlock(i + 4, j + 14, k + 4) == Blocks.gravel) && world.getBlock(i + 4, j + 13, k + 4) == NovaCraftBlocks.nullstone_tiled_wall) {
	            world.setBlock(i + 4, j + 14, k + 4, NovaCraftBlocks.nullstone_tiled_wall, 0, 2);	            
	        } if ((world.getBlock(i + 4, j + 15, k + 4) == Blocks.air || world.getBlock(i + 4, j + 15, k + 4) == Blocks.gravel) && world.getBlock(i + 4, j + 14, k + 4) == NovaCraftBlocks.nullstone_tiled_wall) {
	            world.setBlock(i + 4, j + 15, k + 4, NovaCraftBlocks.nullstone_tiled_wall, 0, 2);	            
	        } if ((world.getBlock(i + 4, j + 16, k + 4) == Blocks.air || world.getBlock(i + 4, j + 16, k + 4) == Blocks.gravel) && world.getBlock(i + 4, j + 15, k + 4) == NovaCraftBlocks.nullstone_tiled_wall) {
	            world.setBlock(i + 4, j + 16, k + 4, NovaCraftBlocks.nullstone_tiled_wall, 0, 2);	            
	        } if ((world.getBlock(i + 4, j + 17, k + 4) == Blocks.air || world.getBlock(i + 4, j + 17, k + 4) == Blocks.gravel) && world.getBlock(i + 4, j + 16, k + 4) == NovaCraftBlocks.nullstone_tiled_wall) {
	            world.setBlock(i + 4, j + 17, k + 4, NovaCraftBlocks.nullstone_tiled_wall, 0, 2);	            
	        } if ((world.getBlock(i + 4, j + 18, k + 4) == Blocks.air || world.getBlock(i + 4, j + 18, k + 4) == Blocks.gravel) && world.getBlock(i + 4, j + 17, k + 4) == NovaCraftBlocks.nullstone_tiled_wall) {
	            world.setBlock(i + 4, j + 18, k + 4, NovaCraftBlocks.nullstone_tiled_wall, 0, 2);	            
	        } if ((world.getBlock(i + 4, j + 19, k + 4) == Blocks.air || world.getBlock(i + 4, j + 19, k + 4) == Blocks.gravel) && world.getBlock(i + 4, j + 18, k + 4) == NovaCraftBlocks.nullstone_tiled_wall) {
	            world.setBlock(i + 4, j + 19, k + 4, NovaCraftBlocks.nullstone_tiled_wall, 0, 2);	            
	        }
			
			world.setBlock(i + 4, j + 7, k + 4, NovaCraftBlocks.cracked_nullstone_deactivator, 0, 2);
			
			world.setBlock(i + 3, j, k + 2, Blocks.mob_spawner, 0, 2);
			TileEntityMobSpawner tileentitymobspawner = (TileEntityMobSpawner)world.getTileEntity(i + 3, j, k + 2);
			
			if (tileentitymobspawner != null)
			{
    		tileentitymobspawner.func_145881_a().setEntityName("nova_craft.sculk_incinerator");

	        NBTTagCompound spawnerNBT = new NBTTagCompound();
	        tileentitymobspawner.writeToNBT(spawnerNBT);

	        NBTTagCompound spawnData = new NBTTagCompound();
	        spawnData.setString("id", "nova_craft.sculk_incinerator");

	        NBTTagList effects = new NBTTagList();
	        
	        NBTTagCompound resistanceEffect = new NBTTagCompound();
	        resistanceEffect.setByte("Id", (byte) 11);
	        resistanceEffect.setByte("Amplifier", (byte) 1);
	        resistanceEffect.setInteger("Duration", Integer.MAX_VALUE);
	        resistanceEffect.setByte("Ambient", (byte) 1);
	        resistanceEffect.setByte("ShowParticles", (byte) 0);

	        effects.appendTag(resistanceEffect);
	        spawnData.setTag("ActiveEffects", effects);
	        
	        spawnerNBT.setTag("SpawnData", spawnData);

	        tileentitymobspawner.readFromNBT(spawnerNBT);
			}
		 
		 return true;
	 }

}
