package com.NovaCraft.world.ancient_city;

import net.minecraft.world.gen.feature.*;
import net.minecraft.block.*;
import net.minecraft.world.*;
import java.util.*;
import com.NovaCraftBlocks.NovaCraftBlocks;
import net.minecraft.init.*;

public class AncientCityColumnTopGen extends WorldGenerator
{
	public AncientCityColumnTopGen() {

	}
    
    public boolean generate(final World world, final Random random, final int i, final int j, final int k) {
    	
		world.setBlock(i + 3, j, k, Blocks.stone, 0, 2);
		world.setBlock(i + 4, j, k, Blocks.stone, 0, 2);
		world.setBlock(i + 5, j, k, Blocks.stone, 0, 2);
		world.setBlock(i + 6, j, k, Blocks.stone, 0, 2);
		world.setBlock(i + 7, j, k, Blocks.stone, 0, 2);
		world.setBlock(i + 8, j, k, Blocks.stone, 0, 2);
		world.setBlock(i + 9, j, k, Blocks.stone, 0, 2);
		world.setBlock(i + 10, j, k, Blocks.stone, 0, 2);
		world.setBlock(i + 11, j, k, Blocks.stone, 0, 2);
		world.setBlock(i + 12, j, k, Blocks.stone, 0, 2);
		world.setBlock(i + 13, j, k, Blocks.stone, 0, 2);
		world.setBlock(i + 14, j, k, Blocks.stone, 0, 2);
		world.setBlock(i + 15, j, k, Blocks.stone, 0, 2);
		world.setBlock(i + 16, j, k, Blocks.stone, 0, 2);
		world.setBlock(i + 17, j, k, Blocks.stone, 0, 2);
		world.setBlock(i + 2, j, k + 1, Blocks.stone, 0, 2);
		world.setBlock(i + 3, j, k + 1, Blocks.stone, 0, 2);
		world.setBlock(i + 4, j, k + 1, Blocks.stone, 0, 2);
		world.setBlock(i + 5, j, k + 1, Blocks.stone, 0, 2);
		world.setBlock(i + 6, j, k + 1, Blocks.stone, 0, 2);
		world.setBlock(i + 7, j, k + 1, Blocks.stone, 0, 2);
		world.setBlock(i + 8, j, k + 1, Blocks.stone, 0, 2);
		world.setBlock(i + 9, j, k + 1, Blocks.stone, 0, 2);
		world.setBlock(i + 10, j, k + 1, Blocks.stone, 0, 2);
		world.setBlock(i + 11, j, k + 1, Blocks.stone, 0, 2);
		world.setBlock(i + 12, j, k + 1, Blocks.stone, 0, 2);
		world.setBlock(i + 13, j, k + 1, Blocks.stone, 0, 2);
		world.setBlock(i + 14, j, k + 1, Blocks.stone, 0, 2);
		world.setBlock(i + 15, j, k + 1, Blocks.stone, 0, 2);
		world.setBlock(i + 16, j, k + 1, Blocks.stone, 0, 2);
		world.setBlock(i + 17, j, k + 1, Blocks.stone, 0, 2);
		world.setBlock(i + 18, j, k + 1, Blocks.stone, 0, 2);
		world.setBlock(i + 1, j, k + 2, Blocks.stone, 0, 2);
		world.setBlock(i + 2, j, k + 2, Blocks.stone, 0, 2);
		world.setBlock(i + 3, j, k + 2, Blocks.stone, 0, 2);
		world.setBlock(i + 4, j, k + 2, Blocks.stone, 0, 2);
		world.setBlock(i + 5, j, k + 2, Blocks.stone, 0, 2);
		world.setBlock(i + 6, j, k + 2, Blocks.stone, 0, 2);
		world.setBlock(i + 7, j, k + 2, Blocks.stone, 0, 2);
		world.setBlock(i + 8, j, k + 2, Blocks.stone, 0, 2);
		world.setBlock(i + 9, j, k + 2, Blocks.stone, 0, 2);
		world.setBlock(i + 10, j, k + 2, Blocks.stone, 0, 2);
		world.setBlock(i + 11, j, k + 2, Blocks.stone, 0, 2);
		world.setBlock(i + 12, j, k + 2, Blocks.stone, 0, 2);
		world.setBlock(i + 13, j, k + 2, Blocks.stone, 0, 2);
		world.setBlock(i + 14, j, k + 2, Blocks.stone, 0, 2);
		world.setBlock(i + 15, j, k + 2, Blocks.stone, 0, 2);
		world.setBlock(i + 16, j, k + 2, Blocks.stone, 0, 2);
		world.setBlock(i + 17, j, k + 2, Blocks.stone, 0, 2);
		world.setBlock(i + 18, j, k + 2, Blocks.stone, 0, 2);
		world.setBlock(i, j, k + 3, Blocks.stone, 0, 2);
		world.setBlock(i + 1, j, k + 3, Blocks.stone, 0, 2);
		world.setBlock(i + 2, j, k + 3, Blocks.stone, 0, 2);
		world.setBlock(i + 3, j, k + 3, Blocks.stone, 0, 2);
		world.setBlock(i + 4, j, k + 3, Blocks.stone, 0, 2);
		world.setBlock(i + 5, j, k + 3, Blocks.stone, 0, 2);
		world.setBlock(i + 6, j, k + 3, Blocks.stone, 0, 2);
		world.setBlock(i + 7, j, k + 3, Blocks.stone, 0, 2);
		world.setBlock(i + 8, j, k + 3, Blocks.stone, 0, 2);
		world.setBlock(i + 9, j, k + 3, Blocks.stone, 0, 2);
		world.setBlock(i + 10, j, k + 3, Blocks.stone, 0, 2);
		world.setBlock(i + 11, j, k + 3, Blocks.stone, 0, 2);
		world.setBlock(i + 12, j, k + 3, Blocks.stone, 0, 2);
		world.setBlock(i + 13, j, k + 3, Blocks.stone, 0, 2);
		world.setBlock(i + 14, j, k + 3, Blocks.stone, 0, 2);
		world.setBlock(i + 15, j, k + 3, Blocks.stone, 0, 2);
		world.setBlock(i + 16, j, k + 3, Blocks.stone, 0, 2);
		world.setBlock(i + 17, j, k + 3, Blocks.stone, 0, 2);
		world.setBlock(i + 18, j, k + 3, Blocks.stone, 0, 2);
		world.setBlock(i, j, k + 4, Blocks.stone, 0, 2);
		world.setBlock(i + 1, j, k + 4, Blocks.stone, 0, 2);
		world.setBlock(i + 2, j, k + 4, Blocks.stone, 0, 2);
		world.setBlock(i + 3, j, k + 4, Blocks.stone, 0, 2);
		world.setBlock(i + 4, j, k + 4, Blocks.stone, 0, 2);
		world.setBlock(i + 5, j, k + 4, Blocks.stone, 0, 2);
		world.setBlock(i + 6, j, k + 4, Blocks.stone, 0, 2);
		world.setBlock(i + 7, j, k + 4, Blocks.stone, 0, 2);
		world.setBlock(i + 8, j, k + 4, Blocks.stone, 0, 2);
		world.setBlock(i + 9, j, k + 4, Blocks.stone, 0, 2);
		world.setBlock(i + 10, j, k + 4, Blocks.stone, 0, 2);
		world.setBlock(i + 11, j, k + 4, Blocks.stone, 0, 2);
		world.setBlock(i + 12, j, k + 4, Blocks.stone, 0, 2);
		world.setBlock(i + 13, j, k + 4, Blocks.stone, 0, 2);
		world.setBlock(i + 14, j, k + 4, Blocks.stone, 0, 2);
		world.setBlock(i + 15, j, k + 4, Blocks.stone, 0, 2);
		world.setBlock(i + 16, j, k + 4, Blocks.stone, 0, 2);
		world.setBlock(i + 17, j, k + 4, Blocks.stone, 0, 2);
		world.setBlock(i + 18, j, k + 4, Blocks.stone, 0, 2);
		world.setBlock(i, j, k + 5, Blocks.stone, 0, 2);
		world.setBlock(i + 1, j, k + 5, Blocks.stone, 0, 2);
		world.setBlock(i + 2, j, k + 5, Blocks.stone, 0, 2);
		world.setBlock(i + 3, j, k + 5, Blocks.stone, 0, 2);
		world.setBlock(i + 4, j, k + 5, Blocks.stone, 0, 2);
		world.setBlock(i + 5, j, k + 5, Blocks.stone, 0, 2);
		world.setBlock(i + 6, j, k + 5, Blocks.stone, 0, 2);
		world.setBlock(i + 7, j, k + 5, Blocks.stone, 0, 2);
		world.setBlock(i + 8, j, k + 5, Blocks.stone, 0, 2);
		world.setBlock(i + 9, j, k + 5, Blocks.stone, 0, 2);
		world.setBlock(i + 10, j, k + 5, Blocks.stone, 0, 2);
		world.setBlock(i + 11, j, k + 5, Blocks.stone, 0, 2);
		world.setBlock(i + 12, j, k + 5, Blocks.stone, 0, 2);
		world.setBlock(i + 13, j, k + 5, Blocks.stone, 0, 2);
		world.setBlock(i + 14, j, k + 5, Blocks.stone, 0, 2);
		world.setBlock(i + 15, j, k + 5, Blocks.stone, 0, 2);
		world.setBlock(i + 16, j, k + 5, Blocks.stone, 0, 2);
		world.setBlock(i + 17, j, k + 5, Blocks.stone, 0, 2);
		world.setBlock(i + 18, j, k + 5, Blocks.stone, 0, 2);
		world.setBlock(i, j, k + 6, Blocks.stone, 0, 2);
		world.setBlock(i + 1, j, k + 6, Blocks.stone, 0, 2);
		world.setBlock(i + 2, j, k + 6, Blocks.stone, 0, 2);
		world.setBlock(i + 3, j, k + 6, Blocks.stone, 0, 2);
		world.setBlock(i + 4, j, k + 6, Blocks.stone, 0, 2);
		world.setBlock(i + 5, j, k + 6, Blocks.stone, 0, 2);
		world.setBlock(i + 6, j, k + 6, Blocks.stone, 0, 2);
		world.setBlock(i + 7, j, k + 6, Blocks.stone, 0, 2);
		world.setBlock(i + 8, j, k + 6, Blocks.stone, 0, 2);
		world.setBlock(i + 9, j, k + 6, Blocks.stone, 0, 2);
		world.setBlock(i + 10, j, k + 6, Blocks.stone, 0, 2);
		world.setBlock(i + 11, j, k + 6, Blocks.stone, 0, 2);
		world.setBlock(i + 12, j, k + 6, Blocks.stone, 0, 2);
		world.setBlock(i + 13, j, k + 6, Blocks.stone, 0, 2);
		world.setBlock(i + 14, j, k + 6, Blocks.stone, 0, 2);
		world.setBlock(i + 15, j, k + 6, Blocks.stone, 0, 2);
		world.setBlock(i + 16, j, k + 6, Blocks.stone, 0, 2);
		world.setBlock(i + 17, j, k + 6, Blocks.stone, 0, 2);
		world.setBlock(i + 18, j, k + 6, Blocks.stone, 0, 2);
		world.setBlock(i, j, k + 7, Blocks.stone, 0, 2);
		world.setBlock(i + 1, j, k + 7, Blocks.stone, 0, 2);
		world.setBlock(i + 2, j, k + 7, Blocks.stone, 0, 2);
		world.setBlock(i + 3, j, k + 7, Blocks.stone, 0, 2);
		world.setBlock(i + 4, j, k + 7, Blocks.stone, 0, 2);
		world.setBlock(i + 5, j, k + 7, Blocks.stone, 0, 2);
		world.setBlock(i + 6, j, k + 7, Blocks.stone, 0, 2);
		world.setBlock(i + 7, j, k + 7, Blocks.stone, 0, 2);
		world.setBlock(i + 8, j, k + 7, Blocks.stone, 0, 2);
		world.setBlock(i + 9, j, k + 7, Blocks.stone, 0, 2);
		world.setBlock(i + 10, j, k + 7, Blocks.stone, 0, 2);
		world.setBlock(i + 11, j, k + 7, Blocks.stone, 0, 2);
		world.setBlock(i + 12, j, k + 7, Blocks.stone, 0, 2);
		world.setBlock(i + 13, j, k + 7, Blocks.stone, 0, 2);
		world.setBlock(i + 14, j, k + 7, Blocks.stone, 0, 2);
		world.setBlock(i + 15, j, k + 7, Blocks.stone, 0, 2);
		world.setBlock(i + 16, j, k + 7, Blocks.stone, 0, 2);
		world.setBlock(i + 17, j, k + 7, Blocks.stone, 0, 2);
		world.setBlock(i + 18, j, k + 7, Blocks.stone, 0, 2);
		world.setBlock(i, j, k + 8, Blocks.stone, 0, 2);
		world.setBlock(i + 1, j, k + 8, Blocks.stone, 0, 2);
		world.setBlock(i + 2, j, k + 8, Blocks.stone, 0, 2);
		world.setBlock(i + 3, j, k + 8, Blocks.stone, 0, 2);
		world.setBlock(i + 4, j, k + 8, Blocks.stone, 0, 2);
		world.setBlock(i + 5, j, k + 8, Blocks.stone, 0, 2);
		world.setBlock(i + 6, j, k + 8, Blocks.stone, 0, 2);
		world.setBlock(i + 7, j, k + 8, Blocks.stone, 0, 2);
		world.setBlock(i + 8, j, k + 8, Blocks.stone, 0, 2);
		world.setBlock(i + 9, j, k + 8, Blocks.stone, 0, 2);
		world.setBlock(i + 10, j, k + 8, Blocks.stone, 0, 2);
		world.setBlock(i + 11, j, k + 8, Blocks.stone, 0, 2);
		world.setBlock(i + 12, j, k + 8, Blocks.stone, 0, 2);
		world.setBlock(i + 13, j, k + 8, Blocks.stone, 0, 2);
		world.setBlock(i + 14, j, k + 8, Blocks.stone, 0, 2);
		world.setBlock(i + 15, j, k + 8, Blocks.stone, 0, 2);
		world.setBlock(i + 16, j, k + 8, Blocks.stone, 0, 2);
		world.setBlock(i + 17, j, k + 8, Blocks.stone, 0, 2);
		world.setBlock(i + 18, j, k + 8, Blocks.stone, 0, 2);
		world.setBlock(i + 19, j, k + 8, Blocks.stone, 0, 2);
		world.setBlock(i, j, k + 9, Blocks.stone, 0, 2);
		world.setBlock(i + 1, j, k + 9, Blocks.stone, 0, 2);
		world.setBlock(i + 2, j, k + 9, Blocks.stone, 0, 2);
		world.setBlock(i + 3, j, k + 9, Blocks.stone, 0, 2);
		world.setBlock(i + 4, j, k + 9, Blocks.stone, 0, 2);
		world.setBlock(i + 5, j, k + 9, Blocks.stone, 0, 2);
		world.setBlock(i + 6, j, k + 9, Blocks.stone, 0, 2);
		world.setBlock(i + 7, j, k + 9, Blocks.stone, 0, 2);
		world.setBlock(i + 8, j, k + 9, Blocks.stone, 0, 2);
		world.setBlock(i + 9, j, k + 9, Blocks.stone, 0, 2);
		world.setBlock(i + 10, j, k + 9, Blocks.stone, 0, 2);
		world.setBlock(i + 11, j, k + 9, Blocks.stone, 0, 2);
		world.setBlock(i + 12, j, k + 9, Blocks.stone, 0, 2);
		world.setBlock(i + 13, j, k + 9, Blocks.stone, 0, 2);
		world.setBlock(i + 14, j, k + 9, Blocks.stone, 0, 2);
		world.setBlock(i + 15, j, k + 9, Blocks.stone, 0, 2);
		world.setBlock(i + 16, j, k + 9, Blocks.stone, 0, 2);
		world.setBlock(i + 17, j, k + 9, Blocks.stone, 0, 2);
		world.setBlock(i + 18, j, k + 9, Blocks.stone, 0, 2);
		world.setBlock(i + 19, j, k + 9, Blocks.stone, 0, 2);
		world.setBlock(i + 20, j, k + 9, Blocks.stone, 0, 2);
		world.setBlock(i, j, k + 10, Blocks.stone, 0, 2);
		world.setBlock(i + 1, j, k + 10, Blocks.stone, 0, 2);
		world.setBlock(i + 2, j, k + 10, Blocks.stone, 0, 2);
		world.setBlock(i + 3, j, k + 10, Blocks.stone, 0, 2);
		world.setBlock(i + 4, j, k + 10, Blocks.stone, 0, 2);
		world.setBlock(i + 5, j, k + 10, Blocks.stone, 0, 2);
		world.setBlock(i + 6, j, k + 10, Blocks.stone, 0, 2);
		world.setBlock(i + 7, j, k + 10, Blocks.stone, 0, 2);
		world.setBlock(i + 8, j, k + 10, Blocks.stone, 0, 2);
		world.setBlock(i + 9, j, k + 10, Blocks.stone, 0, 2);
		world.setBlock(i + 10, j, k + 10, Blocks.stone, 0, 2);
		world.setBlock(i + 11, j, k + 10, Blocks.stone, 0, 2);
		world.setBlock(i + 12, j, k + 10, Blocks.stone, 0, 2);
		world.setBlock(i + 13, j, k + 10, Blocks.stone, 0, 2);
		world.setBlock(i + 14, j, k + 10, Blocks.stone, 0, 2);
		world.setBlock(i + 15, j, k + 10, Blocks.stone, 0, 2);
		world.setBlock(i + 16, j, k + 10, Blocks.stone, 0, 2);
		world.setBlock(i + 17, j, k + 10, Blocks.stone, 0, 2);
		world.setBlock(i + 18, j, k + 10, Blocks.stone, 0, 2);
		world.setBlock(i + 19, j, k + 10, Blocks.stone, 0, 2);
		world.setBlock(i + 20, j, k + 10, Blocks.stone, 0, 2);
		world.setBlock(i + 21, j, k + 10, Blocks.stone, 0, 2);
		world.setBlock(i, j, k + 11, Blocks.stone, 0, 2);
		world.setBlock(i + 1, j, k + 11, Blocks.stone, 0, 2);
		world.setBlock(i + 2, j, k + 11, Blocks.stone, 0, 2);
		world.setBlock(i + 3, j, k + 11, Blocks.stone, 0, 2);
		world.setBlock(i + 4, j, k + 11, Blocks.stone, 0, 2);
		world.setBlock(i + 5, j, k + 11, Blocks.stone, 0, 2);
		world.setBlock(i + 6, j, k + 11, Blocks.stone, 0, 2);
		world.setBlock(i + 7, j, k + 11, Blocks.stone, 0, 2);
		world.setBlock(i + 8, j, k + 11, Blocks.stone, 0, 2);
		world.setBlock(i + 9, j, k + 11, Blocks.stone, 0, 2);
		world.setBlock(i + 10, j, k + 11, Blocks.stone, 0, 2);
		world.setBlock(i + 11, j, k + 11, Blocks.stone, 0, 2);
		world.setBlock(i + 12, j, k + 11, Blocks.stone, 0, 2);
		world.setBlock(i + 13, j, k + 11, Blocks.stone, 0, 2);
		world.setBlock(i + 14, j, k + 11, Blocks.stone, 0, 2);
		world.setBlock(i + 15, j, k + 11, Blocks.stone, 0, 2);
		world.setBlock(i + 16, j, k + 11, Blocks.stone, 0, 2);
		world.setBlock(i + 17, j, k + 11, Blocks.stone, 0, 2);
		world.setBlock(i + 18, j, k + 11, Blocks.stone, 0, 2);
		world.setBlock(i + 19, j, k + 11, Blocks.stone, 0, 2);
		world.setBlock(i + 20, j, k + 11, Blocks.stone, 0, 2);
		world.setBlock(i + 21, j, k + 11, Blocks.stone, 0, 2);
		world.setBlock(i, j, k + 12, Blocks.stone, 0, 2);
		world.setBlock(i + 1, j, k + 12, Blocks.stone, 0, 2);
		world.setBlock(i + 2, j, k + 12, Blocks.stone, 0, 2);
		world.setBlock(i + 3, j, k + 12, Blocks.stone, 0, 2);
		world.setBlock(i + 4, j, k + 12, Blocks.stone, 0, 2);
		world.setBlock(i + 5, j, k + 12, Blocks.stone, 0, 2);
		world.setBlock(i + 6, j, k + 12, Blocks.stone, 0, 2);
		world.setBlock(i + 7, j, k + 12, Blocks.stone, 0, 2);
		world.setBlock(i + 8, j, k + 12, Blocks.stone, 0, 2);
		world.setBlock(i + 9, j, k + 12, Blocks.stone, 0, 2);
		world.setBlock(i + 10, j, k + 12, Blocks.stone, 0, 2);
		world.setBlock(i + 11, j, k + 12, Blocks.stone, 0, 2);
		world.setBlock(i + 12, j, k + 12, Blocks.stone, 0, 2);
		world.setBlock(i + 13, j, k + 12, Blocks.stone, 0, 2);
		world.setBlock(i + 14, j, k + 12, Blocks.stone, 0, 2);
		world.setBlock(i + 15, j, k + 12, Blocks.stone, 0, 2);
		world.setBlock(i + 16, j, k + 12, Blocks.stone, 0, 2);
		world.setBlock(i + 17, j, k + 12, Blocks.stone, 0, 2);
		world.setBlock(i + 18, j, k + 12, Blocks.stone, 0, 2);
		world.setBlock(i + 19, j, k + 12, Blocks.stone, 0, 2);
		world.setBlock(i + 20, j, k + 12, Blocks.stone, 0, 2);
		world.setBlock(i + 21, j, k + 12, Blocks.stone, 0, 2);
		world.setBlock(i, j, k + 13, Blocks.stone, 0, 2);
		world.setBlock(i + 1, j, k + 13, Blocks.stone, 0, 2);
		world.setBlock(i + 2, j, k + 13, Blocks.stone, 0, 2);
		world.setBlock(i + 3, j, k + 13, Blocks.stone, 0, 2);
		world.setBlock(i + 4, j, k + 13, Blocks.stone, 0, 2);
		world.setBlock(i + 5, j, k + 13, Blocks.stone, 0, 2);
		world.setBlock(i + 6, j, k + 13, Blocks.stone, 0, 2);
		world.setBlock(i + 7, j, k + 13, Blocks.stone, 0, 2);
		world.setBlock(i + 8, j, k + 13, Blocks.stone, 0, 2);
		world.setBlock(i + 9, j, k + 13, Blocks.stone, 0, 2);
		world.setBlock(i + 10, j, k + 13, Blocks.stone, 0, 2);
		world.setBlock(i + 11, j, k + 13, Blocks.stone, 0, 2);
		world.setBlock(i + 12, j, k + 13, Blocks.stone, 0, 2);
		world.setBlock(i + 13, j, k + 13, Blocks.stone, 0, 2);
		world.setBlock(i + 14, j, k + 13, Blocks.stone, 0, 2);
		world.setBlock(i + 15, j, k + 13, Blocks.stone, 0, 2);
		world.setBlock(i + 16, j, k + 13, Blocks.stone, 0, 2);
		world.setBlock(i + 17, j, k + 13, Blocks.stone, 0, 2);
		world.setBlock(i + 18, j, k + 13, Blocks.stone, 0, 2);
		world.setBlock(i + 19, j, k + 13, Blocks.stone, 0, 2);
		world.setBlock(i + 20, j, k + 13, Blocks.stone, 0, 2);
		world.setBlock(i + 21, j, k + 13, Blocks.stone, 0, 2);
		world.setBlock(i, j, k + 14, Blocks.stone, 0, 2);
		world.setBlock(i + 1, j, k + 14, Blocks.stone, 0, 2);
		world.setBlock(i + 2, j, k + 14, Blocks.stone, 0, 2);
		world.setBlock(i + 3, j, k + 14, Blocks.stone, 0, 2);
		world.setBlock(i + 4, j, k + 14, Blocks.stone, 0, 2);
		world.setBlock(i + 5, j, k + 14, Blocks.stone, 0, 2);
		world.setBlock(i + 6, j, k + 14, Blocks.stone, 0, 2);
		world.setBlock(i + 7, j, k + 14, Blocks.stone, 0, 2);
		world.setBlock(i + 8, j, k + 14, Blocks.stone, 0, 2);
		world.setBlock(i + 9, j, k + 14, Blocks.stone, 0, 2);
		world.setBlock(i + 10, j, k + 14, Blocks.stone, 0, 2);
		world.setBlock(i + 11, j, k + 14, Blocks.stone, 0, 2);
		world.setBlock(i + 12, j, k + 14, Blocks.stone, 0, 2);
		world.setBlock(i + 13, j, k + 14, Blocks.stone, 0, 2);
		world.setBlock(i + 14, j, k + 14, Blocks.stone, 0, 2);
		world.setBlock(i + 15, j, k + 14, Blocks.stone, 0, 2);
		world.setBlock(i + 16, j, k + 14, Blocks.stone, 0, 2);
		world.setBlock(i + 17, j, k + 14, Blocks.stone, 0, 2);
		world.setBlock(i + 18, j, k + 14, Blocks.stone, 0, 2);
		world.setBlock(i + 19, j, k + 14, Blocks.stone, 0, 2);
		world.setBlock(i + 20, j, k + 14, Blocks.stone, 0, 2);
		world.setBlock(i + 21, j, k + 14, Blocks.stone, 0, 2);
		world.setBlock(i, j, k + 15, Blocks.stone, 0, 2);
		world.setBlock(i + 1, j, k + 15, Blocks.stone, 0, 2);
		world.setBlock(i + 2, j, k + 15, Blocks.stone, 0, 2);
		world.setBlock(i + 3, j, k + 15, Blocks.stone, 0, 2);
		world.setBlock(i + 4, j, k + 15, Blocks.stone, 0, 2);
		world.setBlock(i + 5, j, k + 15, Blocks.stone, 0, 2);
		world.setBlock(i + 6, j, k + 15, Blocks.stone, 0, 2);
		world.setBlock(i + 7, j, k + 15, Blocks.stone, 0, 2);
		world.setBlock(i + 8, j, k + 15, Blocks.stone, 0, 2);
		world.setBlock(i + 9, j, k + 15, Blocks.stone, 0, 2);
		world.setBlock(i + 10, j, k + 15, Blocks.stone, 0, 2);
		world.setBlock(i + 11, j, k + 15, Blocks.stone, 0, 2);
		world.setBlock(i + 12, j, k + 15, Blocks.stone, 0, 2);
		world.setBlock(i + 13, j, k + 15, Blocks.stone, 0, 2);
		world.setBlock(i + 14, j, k + 15, Blocks.stone, 0, 2);
		world.setBlock(i + 15, j, k + 15, Blocks.stone, 0, 2);
		world.setBlock(i + 16, j, k + 15, Blocks.stone, 0, 2);
		world.setBlock(i + 17, j, k + 15, Blocks.stone, 0, 2);
		world.setBlock(i + 18, j, k + 15, Blocks.stone, 0, 2);
		world.setBlock(i + 19, j, k + 15, Blocks.stone, 0, 2);
		world.setBlock(i + 20, j, k + 15, Blocks.stone, 0, 2);
		world.setBlock(i + 21, j, k + 15, Blocks.stone, 0, 2);
		world.setBlock(i + 22, j, k + 15, NovaCraftBlocks.sculk_block, 0, 2);
		world.setBlock(i, j, k + 16, Blocks.stone, 0, 2);
		world.setBlock(i + 1, j, k + 16, Blocks.stone, 0, 2);
		world.setBlock(i + 2, j, k + 16, Blocks.stone, 0, 2);
		world.setBlock(i + 3, j, k + 16, Blocks.stone, 0, 2);
		world.setBlock(i + 4, j, k + 16, Blocks.stone, 0, 2);
		world.setBlock(i + 5, j, k + 16, Blocks.stone, 0, 2);
		world.setBlock(i + 6, j, k + 16, Blocks.stone, 0, 2);
		world.setBlock(i + 7, j, k + 16, Blocks.stone, 0, 2);
		world.setBlock(i + 8, j, k + 16, Blocks.stone, 0, 2);
		world.setBlock(i + 9, j, k + 16, Blocks.stone, 0, 2);
		world.setBlock(i + 10, j, k + 16, Blocks.stone, 0, 2);
		world.setBlock(i + 11, j, k + 16, Blocks.stone, 0, 2);
		world.setBlock(i + 12, j, k + 16, Blocks.stone, 0, 2);
		world.setBlock(i + 13, j, k + 16, Blocks.stone, 0, 2);
		world.setBlock(i + 14, j, k + 16, Blocks.stone, 0, 2);
		world.setBlock(i + 15, j, k + 16, Blocks.stone, 0, 2);
		world.setBlock(i + 16, j, k + 16, Blocks.stone, 0, 2);
		world.setBlock(i + 17, j, k + 16, Blocks.stone, 0, 2);
		world.setBlock(i + 18, j, k + 16, Blocks.stone, 0, 2);
		world.setBlock(i + 19, j, k + 16, Blocks.stone, 0, 2);
		world.setBlock(i + 20, j, k + 16, Blocks.stone, 0, 2);
		world.setBlock(i + 21, j, k + 16, Blocks.stone, 0, 2);
		world.setBlock(i + 22, j, k + 16, NovaCraftBlocks.sculk_block, 0, 2);
		world.setBlock(i, j, k + 17, Blocks.stone, 0, 2);
		world.setBlock(i + 1, j, k + 17, Blocks.stone, 0, 2);
		world.setBlock(i + 2, j, k + 17, Blocks.stone, 0, 2);
		world.setBlock(i + 3, j, k + 17, Blocks.stone, 0, 2);
		world.setBlock(i + 4, j, k + 17, Blocks.stone, 0, 2);
		world.setBlock(i + 5, j, k + 17, Blocks.stone, 0, 2);
		world.setBlock(i + 6, j, k + 17, Blocks.stone, 0, 2);
		world.setBlock(i + 7, j, k + 17, Blocks.stone, 0, 2);
		world.setBlock(i + 8, j, k + 17, Blocks.stone, 0, 2);
		world.setBlock(i + 9, j, k + 17, Blocks.stone, 0, 2);
		world.setBlock(i + 10, j, k + 17, Blocks.stone, 0, 2);
		world.setBlock(i + 11, j, k + 17, Blocks.stone, 0, 2);
		world.setBlock(i + 12, j, k + 17, Blocks.stone, 0, 2);
		world.setBlock(i + 13, j, k + 17, Blocks.stone, 0, 2);
		world.setBlock(i + 14, j, k + 17, Blocks.stone, 0, 2);
		world.setBlock(i + 15, j, k + 17, Blocks.stone, 0, 2);
		world.setBlock(i + 16, j, k + 17, Blocks.stone, 0, 2);
		world.setBlock(i + 17, j, k + 17, Blocks.stone, 0, 2);
		world.setBlock(i + 18, j, k + 17, Blocks.stone, 0, 2);
		world.setBlock(i + 19, j, k + 17, Blocks.stone, 0, 2);
		world.setBlock(i + 20, j, k + 17, Blocks.stone, 0, 2);
		world.setBlock(i + 21, j, k + 17, Blocks.stone, 0, 2);
		world.setBlock(i + 22, j, k + 17, NovaCraftBlocks.sculk_block, 0, 2);
		world.setBlock(i + 1, j, k + 18, Blocks.stone, 0, 2);
		world.setBlock(i + 2, j, k + 18, Blocks.stone, 0, 2);
		world.setBlock(i + 3, j, k + 18, Blocks.stone, 0, 2);
		world.setBlock(i + 4, j, k + 18, Blocks.stone, 0, 2);
		world.setBlock(i + 5, j, k + 18, Blocks.stone, 0, 2);
		world.setBlock(i + 6, j, k + 18, Blocks.stone, 0, 2);
		world.setBlock(i + 7, j, k + 18, Blocks.stone, 0, 2);
		world.setBlock(i + 8, j, k + 18, Blocks.stone, 0, 2);
		world.setBlock(i + 9, j, k + 18, Blocks.stone, 0, 2);
		world.setBlock(i + 10, j, k + 18, Blocks.stone, 0, 2);
		world.setBlock(i + 11, j, k + 18, Blocks.stone, 0, 2);
		world.setBlock(i + 12, j, k + 18, Blocks.stone, 0, 2);
		world.setBlock(i + 13, j, k + 18, Blocks.stone, 0, 2);
		world.setBlock(i + 14, j, k + 18, Blocks.stone, 0, 2);
		world.setBlock(i + 15, j, k + 18, Blocks.stone, 0, 2);
		world.setBlock(i + 16, j, k + 18, Blocks.stone, 0, 2);
		world.setBlock(i + 17, j, k + 18, Blocks.stone, 0, 2);
		world.setBlock(i + 18, j, k + 18, Blocks.stone, 0, 2);
		world.setBlock(i + 19, j, k + 18, Blocks.stone, 0, 2);
		world.setBlock(i + 20, j, k + 18, Blocks.stone, 0, 2);
		world.setBlock(i + 21, j, k + 18, NovaCraftBlocks.sculk_block, 0, 2);
		world.setBlock(i + 2, j, k + 19, Blocks.stone, 0, 2);
		world.setBlock(i + 3, j, k + 19, NovaCraftBlocks.sculk_block, 0, 2);
		world.setBlock(i + 4, j, k + 19, NovaCraftBlocks.sculk_block, 0, 2);
		world.setBlock(i + 5, j, k + 19, NovaCraftBlocks.sculk_block, 0, 2);
		world.setBlock(i + 6, j, k + 19, NovaCraftBlocks.sculk_block, 0, 2);
		world.setBlock(i + 7, j, k + 19, NovaCraftBlocks.sculk_block, 0, 2);
		world.setBlock(i + 8, j, k + 19, NovaCraftBlocks.sculk_block, 0, 2);
		world.setBlock(i + 9, j, k + 19, NovaCraftBlocks.sculk_block, 0, 2);
		world.setBlock(i + 10, j, k + 19, NovaCraftBlocks.sculk_block, 0, 2);
		world.setBlock(i + 11, j, k + 19, NovaCraftBlocks.sculk_block, 0, 2);
		world.setBlock(i + 12, j, k + 19, NovaCraftBlocks.sculk_block, 0, 2);
		world.setBlock(i + 13, j, k + 19, NovaCraftBlocks.sculk_block, 0, 2);
		world.setBlock(i + 14, j, k + 19, NovaCraftBlocks.sculk_block, 0, 2);
		world.setBlock(i + 15, j, k + 19, NovaCraftBlocks.sculk_block, 0, 2);
		world.setBlock(i + 16, j, k + 19, NovaCraftBlocks.sculk_block, 0, 2);
		world.setBlock(i + 17, j, k + 19, NovaCraftBlocks.sculk_block, 0, 2);
		world.setBlock(i + 18, j, k + 19, NovaCraftBlocks.sculk_block, 0, 2);
		world.setBlock(i + 19, j, k + 19, NovaCraftBlocks.sculk_block, 0, 2);
		world.setBlock(i + 20, j, k + 19, NovaCraftBlocks.sculk_block, 0, 2);
		world.setBlock(i + 3, j + 1, k, Blocks.stone, 0, 2);
		world.setBlock(i + 4, j + 1, k, Blocks.stone, 0, 2);
		world.setBlock(i + 5, j + 1, k, Blocks.stone, 0, 2);
		world.setBlock(i + 6, j + 1, k, Blocks.stone, 0, 2);
		world.setBlock(i + 7, j + 1, k, Blocks.stone, 0, 2);
		world.setBlock(i + 8, j + 1, k, Blocks.stone, 0, 2);
		world.setBlock(i + 9, j + 1, k, Blocks.stone, 0, 2);
		world.setBlock(i + 10, j + 1, k, Blocks.stone, 0, 2);
		world.setBlock(i + 11, j + 1, k, Blocks.stone, 0, 2);
		world.setBlock(i + 12, j + 1, k, Blocks.stone, 0, 2);
		world.setBlock(i + 13, j + 1, k, Blocks.stone, 0, 2);
		world.setBlock(i + 14, j + 1, k, Blocks.stone, 0, 2);
		world.setBlock(i + 15, j + 1, k, Blocks.stone, 0, 2);
		world.setBlock(i + 16, j + 1, k, Blocks.stone, 0, 2);
		world.setBlock(i + 17, j + 1, k, Blocks.stone, 0, 2);
		world.setBlock(i + 2, j + 1, k + 1, Blocks.stone, 0, 2);
		world.setBlock(i + 3, j + 1, k + 1, Blocks.stone, 0, 2);
		world.setBlock(i + 4, j + 1, k + 1, Blocks.stone, 0, 2);
		world.setBlock(i + 5, j + 1, k + 1, Blocks.stone, 0, 2);
		world.setBlock(i + 6, j + 1, k + 1, Blocks.stone, 0, 2);
		world.setBlock(i + 7, j + 1, k + 1, Blocks.stone, 0, 2);
		world.setBlock(i + 8, j + 1, k + 1, Blocks.stone, 0, 2);
		world.setBlock(i + 9, j + 1, k + 1, Blocks.stone, 0, 2);
		world.setBlock(i + 10, j + 1, k + 1, Blocks.stone, 0, 2);
		world.setBlock(i + 11, j + 1, k + 1, Blocks.stone, 0, 2);
		world.setBlock(i + 12, j + 1, k + 1, Blocks.stone, 0, 2);
		world.setBlock(i + 13, j + 1, k + 1, Blocks.stone, 0, 2);
		world.setBlock(i + 14, j + 1, k + 1, Blocks.stone, 0, 2);
		world.setBlock(i + 15, j + 1, k + 1, Blocks.stone, 0, 2);
		world.setBlock(i + 16, j + 1, k + 1, Blocks.stone, 0, 2);
		world.setBlock(i + 17, j + 1, k + 1, Blocks.stone, 0, 2);
		world.setBlock(i + 18, j + 1, k + 1, Blocks.stone, 0, 2);
		world.setBlock(i + 1, j + 1, k + 2, Blocks.stone, 0, 2);
		world.setBlock(i + 2, j + 1, k + 2, Blocks.stone, 0, 2);
		world.setBlock(i + 3, j + 1, k + 2, Blocks.stone, 0, 2);
		world.setBlock(i + 4, j + 1, k + 2, Blocks.stone, 0, 2);
		world.setBlock(i + 5, j + 1, k + 2, Blocks.stone, 0, 2);
		world.setBlock(i + 6, j + 1, k + 2, Blocks.stone, 0, 2);
		world.setBlock(i + 7, j + 1, k + 2, Blocks.stone, 0, 2);
		world.setBlock(i + 8, j + 1, k + 2, Blocks.stone, 0, 2);
		world.setBlock(i + 9, j + 1, k + 2, Blocks.stone, 0, 2);
		world.setBlock(i + 10, j + 1, k + 2, Blocks.stone, 0, 2);
		world.setBlock(i + 11, j + 1, k + 2, Blocks.stone, 0, 2);
		world.setBlock(i + 12, j + 1, k + 2, Blocks.stone, 0, 2);
		world.setBlock(i + 13, j + 1, k + 2, Blocks.stone, 0, 2);
		world.setBlock(i + 14, j + 1, k + 2, Blocks.stone, 0, 2);
		world.setBlock(i + 15, j + 1, k + 2, Blocks.stone, 0, 2);
		world.setBlock(i + 16, j + 1, k + 2, Blocks.stone, 0, 2);
		world.setBlock(i + 17, j + 1, k + 2, Blocks.stone, 0, 2);
		world.setBlock(i + 18, j + 1, k + 2, Blocks.stone, 0, 2);
		world.setBlock(i, j + 1, k + 3, Blocks.stone, 0, 2);
		world.setBlock(i + 1, j + 1, k + 3, Blocks.stone, 0, 2);
		world.setBlock(i + 2, j + 1, k + 3, Blocks.stone, 0, 2);
		world.setBlock(i + 3, j + 1, k + 3, Blocks.stone, 0, 2);
		world.setBlock(i + 4, j + 1, k + 3, Blocks.stone, 0, 2);
		world.setBlock(i + 5, j + 1, k + 3, Blocks.stone, 0, 2);
		world.setBlock(i + 6, j + 1, k + 3, Blocks.stone, 0, 2);
		world.setBlock(i + 7, j + 1, k + 3, Blocks.stone, 0, 2);
		world.setBlock(i + 8, j + 1, k + 3, Blocks.stone, 0, 2);
		world.setBlock(i + 9, j + 1, k + 3, Blocks.stone, 0, 2);
		world.setBlock(i + 10, j + 1, k + 3, Blocks.stone, 0, 2);
		world.setBlock(i + 11, j + 1, k + 3, Blocks.stone, 0, 2);
		world.setBlock(i + 12, j + 1, k + 3, Blocks.stone, 0, 2);
		world.setBlock(i + 13, j + 1, k + 3, Blocks.stone, 0, 2);
		world.setBlock(i + 14, j + 1, k + 3, Blocks.stone, 0, 2);
		world.setBlock(i + 15, j + 1, k + 3, Blocks.stone, 0, 2);
		world.setBlock(i + 16, j + 1, k + 3, Blocks.stone, 0, 2);
		world.setBlock(i + 17, j + 1, k + 3, Blocks.stone, 0, 2);
		world.setBlock(i + 18, j + 1, k + 3, Blocks.stone, 0, 2);
		world.setBlock(i, j + 1, k + 4, Blocks.stone, 0, 2);
		world.setBlock(i + 1, j + 1, k + 4, Blocks.stone, 0, 2);
		world.setBlock(i + 2, j + 1, k + 4, Blocks.stone, 0, 2);
		world.setBlock(i + 3, j + 1, k + 4, Blocks.stone, 0, 2);
		world.setBlock(i + 4, j + 1, k + 4, Blocks.stone, 0, 2);
		world.setBlock(i + 5, j + 1, k + 4, Blocks.stone, 0, 2);
		world.setBlock(i + 6, j + 1, k + 4, Blocks.stone, 0, 2);
		world.setBlock(i + 7, j + 1, k + 4, Blocks.stone, 0, 2);
		world.setBlock(i + 8, j + 1, k + 4, Blocks.stone, 0, 2);
		world.setBlock(i + 9, j + 1, k + 4, Blocks.stone, 0, 2);
		world.setBlock(i + 10, j + 1, k + 4, Blocks.stone, 0, 2);
		world.setBlock(i + 11, j + 1, k + 4, Blocks.stone, 0, 2);
		world.setBlock(i + 12, j + 1, k + 4, Blocks.stone, 0, 2);
		world.setBlock(i + 13, j + 1, k + 4, Blocks.stone, 0, 2);
		world.setBlock(i + 14, j + 1, k + 4, Blocks.stone, 0, 2);
		world.setBlock(i + 15, j + 1, k + 4, Blocks.stone, 0, 2);
		world.setBlock(i + 16, j + 1, k + 4, Blocks.stone, 0, 2);
		world.setBlock(i + 17, j + 1, k + 4, Blocks.stone, 0, 2);
		world.setBlock(i + 18, j + 1, k + 4, Blocks.stone, 0, 2);
		world.setBlock(i, j + 1, k + 5, Blocks.stone, 0, 2);
		world.setBlock(i + 1, j + 1, k + 5, Blocks.stone, 0, 2);
		world.setBlock(i + 2, j + 1, k + 5, Blocks.stone, 0, 2);
		world.setBlock(i + 3, j + 1, k + 5, Blocks.stone, 0, 2);
		world.setBlock(i + 4, j + 1, k + 5, Blocks.stone, 0, 2);
		world.setBlock(i + 5, j + 1, k + 5, Blocks.stone, 0, 2);
		world.setBlock(i + 6, j + 1, k + 5, Blocks.stone, 0, 2);
		world.setBlock(i + 7, j + 1, k + 5, Blocks.stone, 0, 2);
		world.setBlock(i + 8, j + 1, k + 5, Blocks.stone, 0, 2);
		world.setBlock(i + 9, j + 1, k + 5, Blocks.stone, 0, 2);
		world.setBlock(i + 10, j + 1, k + 5, Blocks.stone, 0, 2);
		world.setBlock(i + 11, j + 1, k + 5, Blocks.stone, 0, 2);
		world.setBlock(i + 12, j + 1, k + 5, Blocks.stone, 0, 2);
		world.setBlock(i + 13, j + 1, k + 5, Blocks.stone, 0, 2);
		world.setBlock(i + 14, j + 1, k + 5, Blocks.stone, 0, 2);
		world.setBlock(i + 15, j + 1, k + 5, Blocks.stone, 0, 2);
		world.setBlock(i + 16, j + 1, k + 5, Blocks.stone, 0, 2);
		world.setBlock(i + 17, j + 1, k + 5, Blocks.stone, 0, 2);
		world.setBlock(i + 18, j + 1, k + 5, Blocks.stone, 0, 2);
		world.setBlock(i, j + 1, k + 6, Blocks.stone, 0, 2);
		world.setBlock(i + 1, j + 1, k + 6, Blocks.stone, 0, 2);
		world.setBlock(i + 2, j + 1, k + 6, Blocks.stone, 0, 2);
		world.setBlock(i + 3, j + 1, k + 6, Blocks.stone, 0, 2);
		world.setBlock(i + 4, j + 1, k + 6, Blocks.stone, 0, 2);
		world.setBlock(i + 5, j + 1, k + 6, Blocks.stone, 0, 2);
		world.setBlock(i + 6, j + 1, k + 6, Blocks.stone, 0, 2);
		world.setBlock(i + 7, j + 1, k + 6, Blocks.stone, 0, 2);
		world.setBlock(i + 8, j + 1, k + 6, Blocks.stone, 0, 2);
		world.setBlock(i + 9, j + 1, k + 6, Blocks.stone, 0, 2);
		world.setBlock(i + 10, j + 1, k + 6, Blocks.stone, 0, 2);
		world.setBlock(i + 11, j + 1, k + 6, Blocks.stone, 0, 2);
		world.setBlock(i + 12, j + 1, k + 6, Blocks.stone, 0, 2);
		world.setBlock(i + 13, j + 1, k + 6, Blocks.stone, 0, 2);
		world.setBlock(i + 14, j + 1, k + 6, Blocks.stone, 0, 2);
		world.setBlock(i + 15, j + 1, k + 6, Blocks.stone, 0, 2);
		world.setBlock(i + 16, j + 1, k + 6, Blocks.stone, 0, 2);
		world.setBlock(i + 17, j + 1, k + 6, Blocks.stone, 0, 2);
		world.setBlock(i + 18, j + 1, k + 6, Blocks.stone, 0, 2);
		world.setBlock(i, j + 1, k + 7, Blocks.stone, 0, 2);
		world.setBlock(i + 1, j + 1, k + 7, Blocks.stone, 0, 2);
		world.setBlock(i + 2, j + 1, k + 7, Blocks.stone, 0, 2);
		world.setBlock(i + 3, j + 1, k + 7, Blocks.stone, 0, 2);
		world.setBlock(i + 4, j + 1, k + 7, Blocks.stone, 0, 2);
		world.setBlock(i + 5, j + 1, k + 7, Blocks.stone, 0, 2);
		world.setBlock(i + 6, j + 1, k + 7, Blocks.stone, 0, 2);
		world.setBlock(i + 7, j + 1, k + 7, Blocks.stone, 0, 2);
		world.setBlock(i + 8, j + 1, k + 7, Blocks.stone, 0, 2);
		world.setBlock(i + 9, j + 1, k + 7, Blocks.stone, 0, 2);
		world.setBlock(i + 10, j + 1, k + 7, Blocks.stone, 0, 2);
		world.setBlock(i + 11, j + 1, k + 7, Blocks.stone, 0, 2);
		world.setBlock(i + 12, j + 1, k + 7, Blocks.stone, 0, 2);
		world.setBlock(i + 13, j + 1, k + 7, Blocks.stone, 0, 2);
		world.setBlock(i + 14, j + 1, k + 7, Blocks.stone, 0, 2);
		world.setBlock(i + 15, j + 1, k + 7, Blocks.stone, 0, 2);
		world.setBlock(i + 16, j + 1, k + 7, Blocks.stone, 0, 2);
		world.setBlock(i + 17, j + 1, k + 7, Blocks.stone, 0, 2);
		world.setBlock(i + 18, j + 1, k + 7, Blocks.stone, 0, 2);
		world.setBlock(i, j + 1, k + 8, Blocks.stone, 0, 2);
		world.setBlock(i + 1, j + 1, k + 8, Blocks.stone, 0, 2);
		world.setBlock(i + 2, j + 1, k + 8, Blocks.stone, 0, 2);
		world.setBlock(i + 3, j + 1, k + 8, Blocks.stone, 0, 2);
		world.setBlock(i + 4, j + 1, k + 8, Blocks.stone, 0, 2);
		world.setBlock(i + 5, j + 1, k + 8, Blocks.stone, 0, 2);
		world.setBlock(i + 6, j + 1, k + 8, Blocks.stone, 0, 2);
		world.setBlock(i + 7, j + 1, k + 8, Blocks.stone, 0, 2);
		world.setBlock(i + 8, j + 1, k + 8, Blocks.stone, 0, 2);
		world.setBlock(i + 9, j + 1, k + 8, Blocks.stone, 0, 2);
		world.setBlock(i + 10, j + 1, k + 8, Blocks.stone, 0, 2);
		world.setBlock(i + 11, j + 1, k + 8, Blocks.stone, 0, 2);
		world.setBlock(i + 12, j + 1, k + 8, Blocks.stone, 0, 2);
		world.setBlock(i + 13, j + 1, k + 8, Blocks.stone, 0, 2);
		world.setBlock(i + 14, j + 1, k + 8, Blocks.stone, 0, 2);
		world.setBlock(i + 15, j + 1, k + 8, Blocks.stone, 0, 2);
		world.setBlock(i + 16, j + 1, k + 8, Blocks.stone, 0, 2);
		world.setBlock(i + 17, j + 1, k + 8, Blocks.stone, 0, 2);
		world.setBlock(i + 18, j + 1, k + 8, Blocks.stone, 0, 2);
		world.setBlock(i + 19, j + 1, k + 8, Blocks.stone, 0, 2);
		world.setBlock(i, j + 1, k + 9, Blocks.stone, 0, 2);
		world.setBlock(i + 1, j + 1, k + 9, Blocks.stone, 0, 2);
		world.setBlock(i + 2, j + 1, k + 9, Blocks.stone, 0, 2);
		world.setBlock(i + 3, j + 1, k + 9, Blocks.stone, 0, 2);
		world.setBlock(i + 4, j + 1, k + 9, Blocks.stone, 0, 2);
		world.setBlock(i + 5, j + 1, k + 9, Blocks.stone, 0, 2);
		world.setBlock(i + 6, j + 1, k + 9, Blocks.stone, 0, 2);
		world.setBlock(i + 7, j + 1, k + 9, Blocks.stone, 0, 2);
		world.setBlock(i + 8, j + 1, k + 9, Blocks.stone, 0, 2);
		world.setBlock(i + 9, j + 1, k + 9, Blocks.stone, 0, 2);
		world.setBlock(i + 10, j + 1, k + 9, Blocks.stone, 0, 2);
		world.setBlock(i + 11, j + 1, k + 9, Blocks.stone, 0, 2);
		world.setBlock(i + 12, j + 1, k + 9, Blocks.stone, 0, 2);
		world.setBlock(i + 13, j + 1, k + 9, Blocks.stone, 0, 2);
		world.setBlock(i + 14, j + 1, k + 9, Blocks.stone, 0, 2);
		world.setBlock(i + 15, j + 1, k + 9, Blocks.stone, 0, 2);
		world.setBlock(i + 16, j + 1, k + 9, Blocks.stone, 0, 2);
		world.setBlock(i + 17, j + 1, k + 9, Blocks.stone, 0, 2);
		world.setBlock(i + 18, j + 1, k + 9, Blocks.stone, 0, 2);
		world.setBlock(i + 19, j + 1, k + 9, Blocks.stone, 0, 2);
		world.setBlock(i + 20, j + 1, k + 9, Blocks.stone, 0, 2);
		world.setBlock(i, j + 1, k + 10, Blocks.stone, 0, 2);
		world.setBlock(i + 1, j + 1, k + 10, Blocks.stone, 0, 2);
		world.setBlock(i + 2, j + 1, k + 10, Blocks.stone, 0, 2);
		world.setBlock(i + 3, j + 1, k + 10, Blocks.stone, 0, 2);
		world.setBlock(i + 4, j + 1, k + 10, Blocks.stone, 0, 2);
		world.setBlock(i + 5, j + 1, k + 10, Blocks.stone, 0, 2);
		world.setBlock(i + 6, j + 1, k + 10, Blocks.stone, 0, 2);
		world.setBlock(i + 7, j + 1, k + 10, Blocks.stone, 0, 2);
		world.setBlock(i + 8, j + 1, k + 10, Blocks.stone, 0, 2);
		world.setBlock(i + 9, j + 1, k + 10, Blocks.stone, 0, 2);
		world.setBlock(i + 10, j + 1, k + 10, Blocks.stone, 0, 2);
		world.setBlock(i + 11, j + 1, k + 10, Blocks.stone, 0, 2);
		world.setBlock(i + 12, j + 1, k + 10, Blocks.stone, 0, 2);
		world.setBlock(i + 13, j + 1, k + 10, Blocks.stone, 0, 2);
		world.setBlock(i + 14, j + 1, k + 10, Blocks.stone, 0, 2);
		world.setBlock(i + 15, j + 1, k + 10, Blocks.stone, 0, 2);
		world.setBlock(i + 16, j + 1, k + 10, Blocks.stone, 0, 2);
		world.setBlock(i + 17, j + 1, k + 10, Blocks.stone, 0, 2);
		world.setBlock(i + 18, j + 1, k + 10, Blocks.stone, 0, 2);
		world.setBlock(i + 19, j + 1, k + 10, Blocks.stone, 0, 2);
		world.setBlock(i + 20, j + 1, k + 10, Blocks.stone, 0, 2);
		world.setBlock(i + 21, j + 1, k + 10, Blocks.stone, 0, 2);
		world.setBlock(i, j + 1, k + 11, Blocks.stone, 0, 2);
		world.setBlock(i + 1, j + 1, k + 11, Blocks.stone, 0, 2);
		world.setBlock(i + 2, j + 1, k + 11, Blocks.stone, 0, 2);
		world.setBlock(i + 3, j + 1, k + 11, Blocks.stone, 0, 2);
		world.setBlock(i + 4, j + 1, k + 11, Blocks.stone, 0, 2);
		world.setBlock(i + 5, j + 1, k + 11, Blocks.stone, 0, 2);
		world.setBlock(i + 6, j + 1, k + 11, Blocks.stone, 0, 2);
		world.setBlock(i + 7, j + 1, k + 11, Blocks.stone, 0, 2);
		world.setBlock(i + 8, j + 1, k + 11, Blocks.stone, 0, 2);
		world.setBlock(i + 9, j + 1, k + 11, Blocks.stone, 0, 2);
		world.setBlock(i + 10, j + 1, k + 11, Blocks.stone, 0, 2);
		world.setBlock(i + 11, j + 1, k + 11, Blocks.stone, 0, 2);
		world.setBlock(i + 12, j + 1, k + 11, Blocks.stone, 0, 2);
		world.setBlock(i + 13, j + 1, k + 11, Blocks.stone, 0, 2);
		world.setBlock(i + 14, j + 1, k + 11, Blocks.stone, 0, 2);
		world.setBlock(i + 15, j + 1, k + 11, Blocks.stone, 0, 2);
		world.setBlock(i + 16, j + 1, k + 11, Blocks.stone, 0, 2);
		world.setBlock(i + 17, j + 1, k + 11, Blocks.stone, 0, 2);
		world.setBlock(i + 18, j + 1, k + 11, Blocks.stone, 0, 2);
		world.setBlock(i + 19, j + 1, k + 11, Blocks.stone, 0, 2);
		world.setBlock(i + 20, j + 1, k + 11, Blocks.stone, 0, 2);
		world.setBlock(i + 21, j + 1, k + 11, Blocks.stone, 0, 2);
		world.setBlock(i, j + 1, k + 12, Blocks.stone, 0, 2);
		world.setBlock(i + 1, j + 1, k + 12, Blocks.stone, 0, 2);
		world.setBlock(i + 2, j + 1, k + 12, Blocks.stone, 0, 2);
		world.setBlock(i + 3, j + 1, k + 12, Blocks.stone, 0, 2);
		world.setBlock(i + 4, j + 1, k + 12, Blocks.stone, 0, 2);
		world.setBlock(i + 5, j + 1, k + 12, Blocks.stone, 0, 2);
		world.setBlock(i + 6, j + 1, k + 12, Blocks.stone, 0, 2);
		world.setBlock(i + 7, j + 1, k + 12, Blocks.stone, 0, 2);
		world.setBlock(i + 8, j + 1, k + 12, Blocks.stone, 0, 2);
		world.setBlock(i + 9, j + 1, k + 12, Blocks.stone, 0, 2);
		world.setBlock(i + 10, j + 1, k + 12, Blocks.stone, 0, 2);
		world.setBlock(i + 11, j + 1, k + 12, Blocks.stone, 0, 2);
		world.setBlock(i + 12, j + 1, k + 12, Blocks.stone, 0, 2);
		world.setBlock(i + 13, j + 1, k + 12, Blocks.stone, 0, 2);
		world.setBlock(i + 14, j + 1, k + 12, Blocks.stone, 0, 2);
		world.setBlock(i + 15, j + 1, k + 12, Blocks.stone, 0, 2);
		world.setBlock(i + 16, j + 1, k + 12, Blocks.stone, 0, 2);
		world.setBlock(i + 17, j + 1, k + 12, Blocks.stone, 0, 2);
		world.setBlock(i + 18, j + 1, k + 12, Blocks.stone, 0, 2);
		world.setBlock(i + 19, j + 1, k + 12, Blocks.stone, 0, 2);
		world.setBlock(i + 20, j + 1, k + 12, Blocks.stone, 0, 2);
		world.setBlock(i + 21, j + 1, k + 12, Blocks.stone, 0, 2);
		world.setBlock(i, j + 1, k + 13, Blocks.stone, 0, 2);
		world.setBlock(i + 1, j + 1, k + 13, Blocks.stone, 0, 2);
		world.setBlock(i + 2, j + 1, k + 13, Blocks.stone, 0, 2);
		world.setBlock(i + 3, j + 1, k + 13, Blocks.stone, 0, 2);
		world.setBlock(i + 4, j + 1, k + 13, Blocks.stone, 0, 2);
		world.setBlock(i + 5, j + 1, k + 13, Blocks.stone, 0, 2);
		world.setBlock(i + 6, j + 1, k + 13, Blocks.stone, 0, 2);
		world.setBlock(i + 7, j + 1, k + 13, Blocks.stone, 0, 2);
		world.setBlock(i + 8, j + 1, k + 13, Blocks.stone, 0, 2);
		world.setBlock(i + 9, j + 1, k + 13, Blocks.stone, 0, 2);
		world.setBlock(i + 10, j + 1, k + 13, Blocks.stone, 0, 2);
		world.setBlock(i + 11, j + 1, k + 13, Blocks.stone, 0, 2);
		world.setBlock(i + 12, j + 1, k + 13, Blocks.stone, 0, 2);
		world.setBlock(i + 13, j + 1, k + 13, Blocks.stone, 0, 2);
		world.setBlock(i + 14, j + 1, k + 13, Blocks.stone, 0, 2);
		world.setBlock(i + 15, j + 1, k + 13, Blocks.stone, 0, 2);
		world.setBlock(i + 16, j + 1, k + 13, Blocks.stone, 0, 2);
		world.setBlock(i + 17, j + 1, k + 13, Blocks.stone, 0, 2);
		world.setBlock(i + 18, j + 1, k + 13, Blocks.stone, 0, 2);
		world.setBlock(i + 19, j + 1, k + 13, Blocks.stone, 0, 2);
		world.setBlock(i + 20, j + 1, k + 13, Blocks.stone, 0, 2);
		world.setBlock(i + 21, j + 1, k + 13, Blocks.stone, 0, 2);
		world.setBlock(i, j + 1, k + 14, Blocks.stone, 0, 2);
		world.setBlock(i + 1, j + 1, k + 14, Blocks.stone, 0, 2);
		world.setBlock(i + 2, j + 1, k + 14, Blocks.stone, 0, 2);
		world.setBlock(i + 3, j + 1, k + 14, Blocks.stone, 0, 2);
		world.setBlock(i + 4, j + 1, k + 14, Blocks.stone, 0, 2);
		world.setBlock(i + 5, j + 1, k + 14, Blocks.stone, 0, 2);
		world.setBlock(i + 6, j + 1, k + 14, Blocks.stone, 0, 2);
		world.setBlock(i + 7, j + 1, k + 14, Blocks.stone, 0, 2);
		world.setBlock(i + 8, j + 1, k + 14, Blocks.stone, 0, 2);
		world.setBlock(i + 9, j + 1, k + 14, Blocks.stone, 0, 2);
		world.setBlock(i + 10, j + 1, k + 14, Blocks.stone, 0, 2);
		world.setBlock(i + 11, j + 1, k + 14, Blocks.stone, 0, 2);
		world.setBlock(i + 12, j + 1, k + 14, Blocks.stone, 0, 2);
		world.setBlock(i + 13, j + 1, k + 14, Blocks.stone, 0, 2);
		world.setBlock(i + 14, j + 1, k + 14, Blocks.stone, 0, 2);
		world.setBlock(i + 15, j + 1, k + 14, Blocks.stone, 0, 2);
		world.setBlock(i + 16, j + 1, k + 14, Blocks.stone, 0, 2);
		world.setBlock(i + 17, j + 1, k + 14, Blocks.stone, 0, 2);
		world.setBlock(i + 18, j + 1, k + 14, Blocks.stone, 0, 2);
		world.setBlock(i + 19, j + 1, k + 14, Blocks.stone, 0, 2);
		world.setBlock(i + 20, j + 1, k + 14, Blocks.stone, 0, 2);
		world.setBlock(i + 21, j + 1, k + 14, Blocks.stone, 0, 2);
		world.setBlock(i, j + 1, k + 15, Blocks.stone, 0, 2);
		world.setBlock(i + 1, j + 1, k + 15, Blocks.stone, 0, 2);
		world.setBlock(i + 2, j + 1, k + 15, Blocks.stone, 0, 2);
		world.setBlock(i + 3, j + 1, k + 15, Blocks.stone, 0, 2);
		world.setBlock(i + 4, j + 1, k + 15, Blocks.stone, 0, 2);
		world.setBlock(i + 5, j + 1, k + 15, Blocks.stone, 0, 2);
		world.setBlock(i + 6, j + 1, k + 15, Blocks.stone, 0, 2);
		world.setBlock(i + 7, j + 1, k + 15, Blocks.stone, 0, 2);
		world.setBlock(i + 8, j + 1, k + 15, Blocks.stone, 0, 2);
		world.setBlock(i + 9, j + 1, k + 15, Blocks.stone, 0, 2);
		world.setBlock(i + 10, j + 1, k + 15, Blocks.stone, 0, 2);
		world.setBlock(i + 11, j + 1, k + 15, Blocks.stone, 0, 2);
		world.setBlock(i + 12, j + 1, k + 15, Blocks.stone, 0, 2);
		world.setBlock(i + 13, j + 1, k + 15, Blocks.stone, 0, 2);
		world.setBlock(i + 14, j + 1, k + 15, Blocks.stone, 0, 2);
		world.setBlock(i + 15, j + 1, k + 15, Blocks.stone, 0, 2);
		world.setBlock(i + 16, j + 1, k + 15, Blocks.stone, 0, 2);
		world.setBlock(i + 17, j + 1, k + 15, Blocks.stone, 0, 2);
		world.setBlock(i + 18, j + 1, k + 15, Blocks.stone, 0, 2);
		world.setBlock(i + 19, j + 1, k + 15, Blocks.stone, 0, 2);
		world.setBlock(i + 20, j + 1, k + 15, Blocks.stone, 0, 2);
		world.setBlock(i + 21, j + 1, k + 15, Blocks.stone, 0, 2);
		world.setBlock(i + 22, j + 1, k + 15, NovaCraftBlocks.sculk_block, 0, 2);
		world.setBlock(i, j + 1, k + 16, Blocks.stone, 0, 2);
		world.setBlock(i + 1, j + 1, k + 16, Blocks.stone, 0, 2);
		world.setBlock(i + 2, j + 1, k + 16, Blocks.stone, 0, 2);
		world.setBlock(i + 3, j + 1, k + 16, Blocks.stone, 0, 2);
		world.setBlock(i + 4, j + 1, k + 16, Blocks.stone, 0, 2);
		world.setBlock(i + 5, j + 1, k + 16, Blocks.stone, 0, 2);
		world.setBlock(i + 6, j + 1, k + 16, Blocks.stone, 0, 2);
		world.setBlock(i + 7, j + 1, k + 16, Blocks.stone, 0, 2);
		world.setBlock(i + 8, j + 1, k + 16, Blocks.stone, 0, 2);
		world.setBlock(i + 9, j + 1, k + 16, Blocks.stone, 0, 2);
		world.setBlock(i + 10, j + 1, k + 16, Blocks.stone, 0, 2);
		world.setBlock(i + 11, j + 1, k + 16, Blocks.stone, 0, 2);
		world.setBlock(i + 12, j + 1, k + 16, Blocks.stone, 0, 2);
		world.setBlock(i + 13, j + 1, k + 16, Blocks.stone, 0, 2);
		world.setBlock(i + 14, j + 1, k + 16, Blocks.stone, 0, 2);
		world.setBlock(i + 15, j + 1, k + 16, Blocks.stone, 0, 2);
		world.setBlock(i + 16, j + 1, k + 16, Blocks.stone, 0, 2);
		world.setBlock(i + 17, j + 1, k + 16, Blocks.stone, 0, 2);
		world.setBlock(i + 18, j + 1, k + 16, Blocks.stone, 0, 2);
		world.setBlock(i + 19, j + 1, k + 16, Blocks.stone, 0, 2);
		world.setBlock(i + 20, j + 1, k + 16, Blocks.stone, 0, 2);
		world.setBlock(i + 21, j + 1, k + 16, Blocks.stone, 0, 2);
		world.setBlock(i + 22, j + 1, k + 16, NovaCraftBlocks.sculk_block, 0, 2);
		world.setBlock(i, j + 1, k + 17, Blocks.stone, 0, 2);
		world.setBlock(i + 1, j + 1, k + 17, Blocks.stone, 0, 2);
		world.setBlock(i + 2, j + 1, k + 17, Blocks.stone, 0, 2);
		world.setBlock(i + 3, j + 1, k + 17, Blocks.stone, 0, 2);
		world.setBlock(i + 4, j + 1, k + 17, Blocks.stone, 0, 2);
		world.setBlock(i + 5, j + 1, k + 17, Blocks.stone, 0, 2);
		world.setBlock(i + 6, j + 1, k + 17, Blocks.stone, 0, 2);
		world.setBlock(i + 7, j + 1, k + 17, Blocks.stone, 0, 2);
		world.setBlock(i + 8, j + 1, k + 17, Blocks.stone, 0, 2);
		world.setBlock(i + 9, j + 1, k + 17, Blocks.stone, 0, 2);
		world.setBlock(i + 10, j + 1, k + 17, Blocks.stone, 0, 2);
		world.setBlock(i + 11, j + 1, k + 17, Blocks.stone, 0, 2);
		world.setBlock(i + 12, j + 1, k + 17, Blocks.stone, 0, 2);
		world.setBlock(i + 13, j + 1, k + 17, Blocks.stone, 0, 2);
		world.setBlock(i + 14, j + 1, k + 17, Blocks.stone, 0, 2);
		world.setBlock(i + 15, j + 1, k + 17, Blocks.stone, 0, 2);
		world.setBlock(i + 16, j + 1, k + 17, Blocks.stone, 0, 2);
		world.setBlock(i + 17, j + 1, k + 17, Blocks.stone, 0, 2);
		world.setBlock(i + 18, j + 1, k + 17, Blocks.stone, 0, 2);
		world.setBlock(i + 19, j + 1, k + 17, Blocks.stone, 0, 2);
		world.setBlock(i + 20, j + 1, k + 17, Blocks.stone, 0, 2);
		world.setBlock(i + 21, j + 1, k + 17, Blocks.stone, 0, 2);
		world.setBlock(i + 22, j + 1, k + 17, NovaCraftBlocks.sculk_block, 0, 2);
		world.setBlock(i + 1, j + 1, k + 18, Blocks.stone, 0, 2);
		world.setBlock(i + 2, j + 1, k + 18, Blocks.stone, 0, 2);
		world.setBlock(i + 3, j + 1, k + 18, Blocks.stone, 0, 2);
		world.setBlock(i + 4, j + 1, k + 18, Blocks.stone, 0, 2);
		world.setBlock(i + 5, j + 1, k + 18, Blocks.stone, 0, 2);
		world.setBlock(i + 6, j + 1, k + 18, Blocks.stone, 0, 2);
		world.setBlock(i + 7, j + 1, k + 18, Blocks.stone, 0, 2);
		world.setBlock(i + 8, j + 1, k + 18, Blocks.stone, 0, 2);
		world.setBlock(i + 9, j + 1, k + 18, Blocks.stone, 0, 2);
		world.setBlock(i + 10, j + 1, k + 18, Blocks.stone, 0, 2);
		world.setBlock(i + 11, j + 1, k + 18, Blocks.stone, 0, 2);
		world.setBlock(i + 12, j + 1, k + 18, Blocks.stone, 0, 2);
		world.setBlock(i + 13, j + 1, k + 18, Blocks.stone, 0, 2);
		world.setBlock(i + 14, j + 1, k + 18, Blocks.stone, 0, 2);
		world.setBlock(i + 15, j + 1, k + 18, Blocks.stone, 0, 2);
		world.setBlock(i + 16, j + 1, k + 18, Blocks.stone, 0, 2);
		world.setBlock(i + 17, j + 1, k + 18, Blocks.stone, 0, 2);
		world.setBlock(i + 18, j + 1, k + 18, Blocks.stone, 0, 2);
		world.setBlock(i + 19, j + 1, k + 18, Blocks.stone, 0, 2);
		world.setBlock(i + 20, j + 1, k + 18, Blocks.stone, 0, 2);
		world.setBlock(i + 21, j + 1, k + 18, NovaCraftBlocks.sculk_block, 0, 2);
		world.setBlock(i + 2, j + 1, k + 19, Blocks.stone, 0, 2);
		world.setBlock(i + 3, j + 1, k + 19, NovaCraftBlocks.sculk_block, 0, 2);
		world.setBlock(i + 4, j + 1, k + 19, NovaCraftBlocks.sculk_block, 0, 2);
		world.setBlock(i + 5, j + 1, k + 19, NovaCraftBlocks.sculk_block, 0, 2);
		world.setBlock(i + 6, j + 1, k + 19, NovaCraftBlocks.sculk_block, 0, 2);
		world.setBlock(i + 7, j + 1, k + 19, NovaCraftBlocks.sculk_block, 0, 2);
		world.setBlock(i + 8, j + 1, k + 19, NovaCraftBlocks.sculk_block, 0, 2);
		world.setBlock(i + 9, j + 1, k + 19, NovaCraftBlocks.sculk_block, 0, 2);
		world.setBlock(i + 10, j + 1, k + 19, NovaCraftBlocks.sculk_block, 0, 2);
		world.setBlock(i + 11, j + 1, k + 19, NovaCraftBlocks.sculk_block, 0, 2);
		world.setBlock(i + 12, j + 1, k + 19, NovaCraftBlocks.sculk_block, 0, 2);
		world.setBlock(i + 13, j + 1, k + 19, NovaCraftBlocks.sculk_block, 0, 2);
		world.setBlock(i + 14, j + 1, k + 19, NovaCraftBlocks.sculk_block, 0, 2);
		world.setBlock(i + 15, j + 1, k + 19, NovaCraftBlocks.sculk_block, 0, 2);
		world.setBlock(i + 16, j + 1, k + 19, NovaCraftBlocks.sculk_block, 0, 2);
		world.setBlock(i + 17, j + 1, k + 19, NovaCraftBlocks.sculk_block, 0, 2);
		world.setBlock(i + 18, j + 1, k + 19, NovaCraftBlocks.sculk_block, 0, 2);
		world.setBlock(i + 19, j + 1, k + 19, NovaCraftBlocks.sculk_block, 0, 2);
		world.setBlock(i + 20, j + 1, k + 19, NovaCraftBlocks.sculk_block, 0, 2);
		world.setBlock(i + 3, j + 2, k, Blocks.stone, 0, 2);
		world.setBlock(i + 4, j + 2, k, Blocks.stone, 0, 2);
		world.setBlock(i + 5, j + 2, k, Blocks.stone, 0, 2);
		world.setBlock(i + 6, j + 2, k, Blocks.stone, 0, 2);
		world.setBlock(i + 7, j + 2, k, Blocks.stone, 0, 2);
		world.setBlock(i + 8, j + 2, k, Blocks.stone, 0, 2);
		world.setBlock(i + 9, j + 2, k, Blocks.stone, 0, 2);
		world.setBlock(i + 10, j + 2, k, Blocks.stone, 0, 2);
		world.setBlock(i + 11, j + 2, k, Blocks.stone, 0, 2);
		world.setBlock(i + 12, j + 2, k, Blocks.stone, 0, 2);
		world.setBlock(i + 13, j + 2, k, Blocks.stone, 0, 2);
		world.setBlock(i + 14, j + 2, k, Blocks.stone, 0, 2);
		world.setBlock(i + 15, j + 2, k, Blocks.stone, 0, 2);
		world.setBlock(i + 16, j + 2, k, Blocks.stone, 0, 2);
		world.setBlock(i + 17, j + 2, k, Blocks.stone, 0, 2);
		world.setBlock(i + 2, j + 2, k + 1, Blocks.stone, 0, 2);
		world.setBlock(i + 3, j + 2, k + 1, Blocks.stone, 0, 2);
		world.setBlock(i + 4, j + 2, k + 1, Blocks.stone, 0, 2);
		world.setBlock(i + 5, j + 2, k + 1, Blocks.stone, 0, 2);
		world.setBlock(i + 6, j + 2, k + 1, Blocks.stone, 0, 2);
		world.setBlock(i + 7, j + 2, k + 1, Blocks.stone, 0, 2);
		world.setBlock(i + 8, j + 2, k + 1, Blocks.stone, 0, 2);
		world.setBlock(i + 9, j + 2, k + 1, Blocks.stone, 0, 2);
		world.setBlock(i + 10, j + 2, k + 1, Blocks.stone, 0, 2);
		world.setBlock(i + 11, j + 2, k + 1, Blocks.stone, 0, 2);
		world.setBlock(i + 12, j + 2, k + 1, Blocks.stone, 0, 2);
		world.setBlock(i + 13, j + 2, k + 1, Blocks.stone, 0, 2);
		world.setBlock(i + 14, j + 2, k + 1, Blocks.stone, 0, 2);
		world.setBlock(i + 15, j + 2, k + 1, Blocks.stone, 0, 2);
		world.setBlock(i + 16, j + 2, k + 1, Blocks.stone, 0, 2);
		world.setBlock(i + 17, j + 2, k + 1, Blocks.stone, 0, 2);
		world.setBlock(i + 18, j + 2, k + 1, Blocks.stone, 0, 2);
		world.setBlock(i + 1, j + 2, k + 2, Blocks.stone, 0, 2);
		world.setBlock(i + 2, j + 2, k + 2, Blocks.stone, 0, 2);
		world.setBlock(i + 3, j + 2, k + 2, Blocks.stone, 0, 2);
		world.setBlock(i + 4, j + 2, k + 2, Blocks.stone, 0, 2);
		world.setBlock(i + 5, j + 2, k + 2, Blocks.stone, 0, 2);
		world.setBlock(i + 6, j + 2, k + 2, Blocks.stone, 0, 2);
		world.setBlock(i + 7, j + 2, k + 2, Blocks.stone, 0, 2);
		world.setBlock(i + 8, j + 2, k + 2, Blocks.stone, 0, 2);
		world.setBlock(i + 9, j + 2, k + 2, Blocks.stone, 0, 2);
		world.setBlock(i + 10, j + 2, k + 2, Blocks.stone, 0, 2);
		world.setBlock(i + 11, j + 2, k + 2, Blocks.stone, 0, 2);
		world.setBlock(i + 12, j + 2, k + 2, Blocks.stone, 0, 2);
		world.setBlock(i + 13, j + 2, k + 2, Blocks.stone, 0, 2);
		world.setBlock(i + 14, j + 2, k + 2, Blocks.stone, 0, 2);
		world.setBlock(i + 15, j + 2, k + 2, Blocks.stone, 0, 2);
		world.setBlock(i + 16, j + 2, k + 2, Blocks.stone, 0, 2);
		world.setBlock(i + 17, j + 2, k + 2, Blocks.stone, 0, 2);
		world.setBlock(i + 18, j + 2, k + 2, Blocks.stone, 0, 2);
		world.setBlock(i, j + 2, k + 3, Blocks.stone, 0, 2);
		world.setBlock(i + 1, j + 2, k + 3, Blocks.stone, 0, 2);
		world.setBlock(i + 2, j + 2, k + 3, Blocks.stone, 0, 2);
		world.setBlock(i + 3, j + 2, k + 3, Blocks.stone, 0, 2);
		world.setBlock(i + 4, j + 2, k + 3, Blocks.stone, 0, 2);
		world.setBlock(i + 5, j + 2, k + 3, Blocks.stone, 0, 2);
		world.setBlock(i + 6, j + 2, k + 3, Blocks.stone, 0, 2);
		world.setBlock(i + 7, j + 2, k + 3, Blocks.stone, 0, 2);
		world.setBlock(i + 8, j + 2, k + 3, Blocks.stone, 0, 2);
		world.setBlock(i + 9, j + 2, k + 3, Blocks.stone, 0, 2);
		world.setBlock(i + 10, j + 2, k + 3, Blocks.stone, 0, 2);
		world.setBlock(i + 11, j + 2, k + 3, Blocks.stone, 0, 2);
		world.setBlock(i + 12, j + 2, k + 3, Blocks.stone, 0, 2);
		world.setBlock(i + 13, j + 2, k + 3, Blocks.stone, 0, 2);
		world.setBlock(i + 14, j + 2, k + 3, Blocks.stone, 0, 2);
		world.setBlock(i + 15, j + 2, k + 3, Blocks.stone, 0, 2);
		world.setBlock(i + 16, j + 2, k + 3, Blocks.stone, 0, 2);
		world.setBlock(i + 17, j + 2, k + 3, Blocks.stone, 0, 2);
		world.setBlock(i + 18, j + 2, k + 3, Blocks.stone, 0, 2);
		world.setBlock(i, j + 2, k + 4, Blocks.stone, 0, 2);
		world.setBlock(i + 1, j + 2, k + 4, Blocks.stone, 0, 2);
		world.setBlock(i + 2, j + 2, k + 4, Blocks.stone, 0, 2);
		world.setBlock(i + 3, j + 2, k + 4, Blocks.stone, 0, 2);
		world.setBlock(i + 4, j + 2, k + 4, Blocks.stone, 0, 2);
		world.setBlock(i + 5, j + 2, k + 4, Blocks.stone, 0, 2);
		world.setBlock(i + 6, j + 2, k + 4, Blocks.stone, 0, 2);
		world.setBlock(i + 7, j + 2, k + 4, Blocks.stone, 0, 2);
		world.setBlock(i + 8, j + 2, k + 4, Blocks.stone, 0, 2);
		world.setBlock(i + 9, j + 2, k + 4, Blocks.stone, 0, 2);
		world.setBlock(i + 10, j + 2, k + 4, Blocks.stone, 0, 2);
		world.setBlock(i + 11, j + 2, k + 4, Blocks.stone, 0, 2);
		world.setBlock(i + 12, j + 2, k + 4, Blocks.stone, 0, 2);
		world.setBlock(i + 13, j + 2, k + 4, Blocks.stone, 0, 2);
		world.setBlock(i + 14, j + 2, k + 4, Blocks.stone, 0, 2);
		world.setBlock(i + 15, j + 2, k + 4, Blocks.stone, 0, 2);
		world.setBlock(i + 16, j + 2, k + 4, Blocks.stone, 0, 2);
		world.setBlock(i + 17, j + 2, k + 4, Blocks.stone, 0, 2);
		world.setBlock(i + 18, j + 2, k + 4, Blocks.stone, 0, 2);
		world.setBlock(i, j + 2, k + 5, Blocks.stone, 0, 2);
		world.setBlock(i + 1, j + 2, k + 5, Blocks.stone, 0, 2);
		world.setBlock(i + 2, j + 2, k + 5, Blocks.stone, 0, 2);
		world.setBlock(i + 3, j + 2, k + 5, Blocks.stone, 0, 2);
		world.setBlock(i + 4, j + 2, k + 5, Blocks.stone, 0, 2);
		world.setBlock(i + 5, j + 2, k + 5, Blocks.stone, 0, 2);
		world.setBlock(i + 6, j + 2, k + 5, Blocks.stone, 0, 2);
		world.setBlock(i + 7, j + 2, k + 5, Blocks.stone, 0, 2);
		world.setBlock(i + 8, j + 2, k + 5, Blocks.stone, 0, 2);
		world.setBlock(i + 9, j + 2, k + 5, Blocks.stone, 0, 2);
		world.setBlock(i + 10, j + 2, k + 5, Blocks.stone, 0, 2);
		world.setBlock(i + 11, j + 2, k + 5, Blocks.stone, 0, 2);
		world.setBlock(i + 12, j + 2, k + 5, Blocks.stone, 0, 2);
		world.setBlock(i + 13, j + 2, k + 5, Blocks.stone, 0, 2);
		world.setBlock(i + 14, j + 2, k + 5, Blocks.stone, 0, 2);
		world.setBlock(i + 15, j + 2, k + 5, Blocks.stone, 0, 2);
		world.setBlock(i + 16, j + 2, k + 5, Blocks.stone, 0, 2);
		world.setBlock(i + 17, j + 2, k + 5, Blocks.stone, 0, 2);
		world.setBlock(i + 18, j + 2, k + 5, Blocks.stone, 0, 2);
		world.setBlock(i, j + 2, k + 6, Blocks.stone, 0, 2);
		world.setBlock(i + 1, j + 2, k + 6, Blocks.stone, 0, 2);
		world.setBlock(i + 2, j + 2, k + 6, Blocks.stone, 0, 2);
		world.setBlock(i + 3, j + 2, k + 6, Blocks.stone, 0, 2);
		world.setBlock(i + 4, j + 2, k + 6, Blocks.stone, 0, 2);
		world.setBlock(i + 5, j + 2, k + 6, Blocks.stone, 0, 2);
		world.setBlock(i + 6, j + 2, k + 6, Blocks.stone, 0, 2);
		world.setBlock(i + 7, j + 2, k + 6, Blocks.stone, 0, 2);
		world.setBlock(i + 8, j + 2, k + 6, Blocks.stone, 0, 2);
		world.setBlock(i + 9, j + 2, k + 6, Blocks.stone, 0, 2);
		world.setBlock(i + 10, j + 2, k + 6, Blocks.stone, 0, 2);
		world.setBlock(i + 11, j + 2, k + 6, Blocks.stone, 0, 2);
		world.setBlock(i + 12, j + 2, k + 6, Blocks.stone, 0, 2);
		world.setBlock(i + 13, j + 2, k + 6, Blocks.stone, 0, 2);
		world.setBlock(i + 14, j + 2, k + 6, Blocks.stone, 0, 2);
		world.setBlock(i + 15, j + 2, k + 6, Blocks.stone, 0, 2);
		world.setBlock(i + 16, j + 2, k + 6, Blocks.stone, 0, 2);
		world.setBlock(i + 17, j + 2, k + 6, Blocks.stone, 0, 2);
		world.setBlock(i + 18, j + 2, k + 6, Blocks.stone, 0, 2);
		world.setBlock(i, j + 2, k + 7, Blocks.stone, 0, 2);
		world.setBlock(i + 1, j + 2, k + 7, Blocks.stone, 0, 2);
		world.setBlock(i + 2, j + 2, k + 7, Blocks.stone, 0, 2);
		world.setBlock(i + 3, j + 2, k + 7, Blocks.stone, 0, 2);
		world.setBlock(i + 4, j + 2, k + 7, Blocks.stone, 0, 2);
		world.setBlock(i + 5, j + 2, k + 7, Blocks.stone, 0, 2);
		world.setBlock(i + 6, j + 2, k + 7, Blocks.stone, 0, 2);
		world.setBlock(i + 7, j + 2, k + 7, Blocks.stone, 0, 2);
		world.setBlock(i + 8, j + 2, k + 7, Blocks.stone, 0, 2);
		world.setBlock(i + 9, j + 2, k + 7, Blocks.stone, 0, 2);
		world.setBlock(i + 10, j + 2, k + 7, Blocks.stone, 0, 2);
		world.setBlock(i + 11, j + 2, k + 7, Blocks.stone, 0, 2);
		world.setBlock(i + 12, j + 2, k + 7, Blocks.stone, 0, 2);
		world.setBlock(i + 13, j + 2, k + 7, Blocks.stone, 0, 2);
		world.setBlock(i + 14, j + 2, k + 7, Blocks.stone, 0, 2);
		world.setBlock(i + 15, j + 2, k + 7, Blocks.stone, 0, 2);
		world.setBlock(i + 16, j + 2, k + 7, Blocks.stone, 0, 2);
		world.setBlock(i + 17, j + 2, k + 7, Blocks.stone, 0, 2);
		world.setBlock(i + 18, j + 2, k + 7, Blocks.stone, 0, 2);
		world.setBlock(i, j + 2, k + 8, Blocks.stone, 0, 2);
		world.setBlock(i + 1, j + 2, k + 8, Blocks.stone, 0, 2);
		world.setBlock(i + 2, j + 2, k + 8, Blocks.stone, 0, 2);
		world.setBlock(i + 3, j + 2, k + 8, Blocks.stone, 0, 2);
		world.setBlock(i + 4, j + 2, k + 8, Blocks.stone, 0, 2);
		world.setBlock(i + 5, j + 2, k + 8, Blocks.stone, 0, 2);
		world.setBlock(i + 6, j + 2, k + 8, Blocks.stone, 0, 2);
		world.setBlock(i + 7, j + 2, k + 8, Blocks.stone, 0, 2);
		world.setBlock(i + 8, j + 2, k + 8, Blocks.stone, 0, 2);
		world.setBlock(i + 9, j + 2, k + 8, Blocks.stone, 0, 2);
		world.setBlock(i + 10, j + 2, k + 8, Blocks.stone, 0, 2);
		world.setBlock(i + 11, j + 2, k + 8, Blocks.stone, 0, 2);
		world.setBlock(i + 12, j + 2, k + 8, Blocks.stone, 0, 2);
		world.setBlock(i + 13, j + 2, k + 8, Blocks.stone, 0, 2);
		world.setBlock(i + 14, j + 2, k + 8, Blocks.stone, 0, 2);
		world.setBlock(i + 15, j + 2, k + 8, Blocks.stone, 0, 2);
		world.setBlock(i + 16, j + 2, k + 8, Blocks.stone, 0, 2);
		world.setBlock(i + 17, j + 2, k + 8, Blocks.stone, 0, 2);
		world.setBlock(i + 18, j + 2, k + 8, Blocks.stone, 0, 2);
		world.setBlock(i + 19, j + 2, k + 8, Blocks.stone, 0, 2);
		world.setBlock(i, j + 2, k + 9, Blocks.stone, 0, 2);
		world.setBlock(i + 1, j + 2, k + 9, Blocks.stone, 0, 2);
		world.setBlock(i + 2, j + 2, k + 9, Blocks.stone, 0, 2);
		world.setBlock(i + 3, j + 2, k + 9, Blocks.stone, 0, 2);
		world.setBlock(i + 4, j + 2, k + 9, Blocks.stone, 0, 2);
		world.setBlock(i + 5, j + 2, k + 9, Blocks.stone, 0, 2);
		world.setBlock(i + 6, j + 2, k + 9, Blocks.stone, 0, 2);
		world.setBlock(i + 7, j + 2, k + 9, Blocks.stone, 0, 2);
		world.setBlock(i + 8, j + 2, k + 9, Blocks.stone, 0, 2);
		world.setBlock(i + 9, j + 2, k + 9, Blocks.stone, 0, 2);
		world.setBlock(i + 10, j + 2, k + 9, Blocks.stone, 0, 2);
		world.setBlock(i + 11, j + 2, k + 9, Blocks.stone, 0, 2);
		world.setBlock(i + 12, j + 2, k + 9, Blocks.stone, 0, 2);
		world.setBlock(i + 13, j + 2, k + 9, Blocks.stone, 0, 2);
		world.setBlock(i + 14, j + 2, k + 9, Blocks.stone, 0, 2);
		world.setBlock(i + 15, j + 2, k + 9, Blocks.stone, 0, 2);
		world.setBlock(i + 16, j + 2, k + 9, Blocks.stone, 0, 2);
		world.setBlock(i + 17, j + 2, k + 9, Blocks.stone, 0, 2);
		world.setBlock(i + 18, j + 2, k + 9, Blocks.stone, 0, 2);
		world.setBlock(i + 19, j + 2, k + 9, Blocks.stone, 0, 2);
		world.setBlock(i + 20, j + 2, k + 9, Blocks.stone, 0, 2);
		world.setBlock(i, j + 2, k + 10, Blocks.stone, 0, 2);
		world.setBlock(i + 1, j + 2, k + 10, Blocks.stone, 0, 2);
		world.setBlock(i + 2, j + 2, k + 10, Blocks.stone, 0, 2);
		world.setBlock(i + 3, j + 2, k + 10, Blocks.stone, 0, 2);
		world.setBlock(i + 4, j + 2, k + 10, Blocks.stone, 0, 2);
		world.setBlock(i + 5, j + 2, k + 10, Blocks.stone, 0, 2);
		world.setBlock(i + 6, j + 2, k + 10, Blocks.stone, 0, 2);
		world.setBlock(i + 7, j + 2, k + 10, Blocks.stone, 0, 2);
		world.setBlock(i + 8, j + 2, k + 10, Blocks.stone, 0, 2);
		world.setBlock(i + 9, j + 2, k + 10, Blocks.stone, 0, 2);
		world.setBlock(i + 10, j + 2, k + 10, Blocks.stone, 0, 2);
		world.setBlock(i + 11, j + 2, k + 10, Blocks.stone, 0, 2);
		world.setBlock(i + 12, j + 2, k + 10, Blocks.stone, 0, 2);
		world.setBlock(i + 13, j + 2, k + 10, Blocks.stone, 0, 2);
		world.setBlock(i + 14, j + 2, k + 10, Blocks.stone, 0, 2);
		world.setBlock(i + 15, j + 2, k + 10, Blocks.stone, 0, 2);
		world.setBlock(i + 16, j + 2, k + 10, Blocks.stone, 0, 2);
		world.setBlock(i + 17, j + 2, k + 10, Blocks.stone, 0, 2);
		world.setBlock(i + 18, j + 2, k + 10, Blocks.stone, 0, 2);
		world.setBlock(i + 19, j + 2, k + 10, Blocks.stone, 0, 2);
		world.setBlock(i + 20, j + 2, k + 10, Blocks.stone, 0, 2);
		world.setBlock(i + 21, j + 2, k + 10, Blocks.stone, 0, 2);
		world.setBlock(i, j + 2, k + 11, Blocks.stone, 0, 2);
		world.setBlock(i + 1, j + 2, k + 11, Blocks.stone, 0, 2);
		world.setBlock(i + 2, j + 2, k + 11, Blocks.stone, 0, 2);
		world.setBlock(i + 3, j + 2, k + 11, Blocks.stone, 0, 2);
		world.setBlock(i + 4, j + 2, k + 11, Blocks.stone, 0, 2);
		world.setBlock(i + 5, j + 2, k + 11, Blocks.stone, 0, 2);
		world.setBlock(i + 6, j + 2, k + 11, Blocks.stone, 0, 2);
		world.setBlock(i + 7, j + 2, k + 11, Blocks.stone, 0, 2);
		world.setBlock(i + 8, j + 2, k + 11, Blocks.stone, 0, 2);
		world.setBlock(i + 9, j + 2, k + 11, Blocks.stone, 0, 2);
		world.setBlock(i + 10, j + 2, k + 11, Blocks.stone, 0, 2);
		world.setBlock(i + 11, j + 2, k + 11, Blocks.stone, 0, 2);
		world.setBlock(i + 12, j + 2, k + 11, Blocks.stone, 0, 2);
		world.setBlock(i + 13, j + 2, k + 11, Blocks.stone, 0, 2);
		world.setBlock(i + 14, j + 2, k + 11, Blocks.stone, 0, 2);
		world.setBlock(i + 15, j + 2, k + 11, Blocks.stone, 0, 2);
		world.setBlock(i + 16, j + 2, k + 11, Blocks.stone, 0, 2);
		world.setBlock(i + 17, j + 2, k + 11, Blocks.stone, 0, 2);
		world.setBlock(i + 18, j + 2, k + 11, Blocks.stone, 0, 2);
		world.setBlock(i + 19, j + 2, k + 11, Blocks.stone, 0, 2);
		world.setBlock(i + 20, j + 2, k + 11, Blocks.stone, 0, 2);
		world.setBlock(i + 21, j + 2, k + 11, Blocks.stone, 0, 2);
		world.setBlock(i, j + 2, k + 12, Blocks.stone, 0, 2);
		world.setBlock(i + 1, j + 2, k + 12, Blocks.stone, 0, 2);
		world.setBlock(i + 2, j + 2, k + 12, Blocks.stone, 0, 2);
		world.setBlock(i + 3, j + 2, k + 12, Blocks.stone, 0, 2);
		world.setBlock(i + 4, j + 2, k + 12, Blocks.stone, 0, 2);
		world.setBlock(i + 5, j + 2, k + 12, Blocks.stone, 0, 2);
		world.setBlock(i + 6, j + 2, k + 12, Blocks.stone, 0, 2);
		world.setBlock(i + 7, j + 2, k + 12, Blocks.stone, 0, 2);
		world.setBlock(i + 8, j + 2, k + 12, Blocks.stone, 0, 2);
		world.setBlock(i + 9, j + 2, k + 12, Blocks.stone, 0, 2);
		world.setBlock(i + 10, j + 2, k + 12, Blocks.stone, 0, 2);
		world.setBlock(i + 11, j + 2, k + 12, Blocks.stone, 0, 2);
		world.setBlock(i + 12, j + 2, k + 12, Blocks.stone, 0, 2);
		world.setBlock(i + 13, j + 2, k + 12, Blocks.stone, 0, 2);
		world.setBlock(i + 14, j + 2, k + 12, Blocks.stone, 0, 2);
		world.setBlock(i + 15, j + 2, k + 12, Blocks.stone, 0, 2);
		world.setBlock(i + 16, j + 2, k + 12, Blocks.stone, 0, 2);
		world.setBlock(i + 17, j + 2, k + 12, Blocks.stone, 0, 2);
		world.setBlock(i + 18, j + 2, k + 12, Blocks.stone, 0, 2);
		world.setBlock(i + 19, j + 2, k + 12, Blocks.stone, 0, 2);
		world.setBlock(i + 20, j + 2, k + 12, Blocks.stone, 0, 2);
		world.setBlock(i + 21, j + 2, k + 12, Blocks.stone, 0, 2);
		world.setBlock(i, j + 2, k + 13, Blocks.stone, 0, 2);
		world.setBlock(i + 1, j + 2, k + 13, Blocks.stone, 0, 2);
		world.setBlock(i + 2, j + 2, k + 13, Blocks.stone, 0, 2);
		world.setBlock(i + 3, j + 2, k + 13, Blocks.stone, 0, 2);
		world.setBlock(i + 4, j + 2, k + 13, Blocks.stone, 0, 2);
		world.setBlock(i + 5, j + 2, k + 13, Blocks.stone, 0, 2);
		world.setBlock(i + 6, j + 2, k + 13, Blocks.stone, 0, 2);
		world.setBlock(i + 7, j + 2, k + 13, Blocks.stone, 0, 2);
		world.setBlock(i + 8, j + 2, k + 13, Blocks.stone, 0, 2);
		world.setBlock(i + 9, j + 2, k + 13, Blocks.stone, 0, 2);
		world.setBlock(i + 10, j + 2, k + 13, Blocks.stone, 0, 2);
		world.setBlock(i + 11, j + 2, k + 13, Blocks.stone, 0, 2);
		world.setBlock(i + 12, j + 2, k + 13, Blocks.stone, 0, 2);
		world.setBlock(i + 13, j + 2, k + 13, Blocks.stone, 0, 2);
		world.setBlock(i + 14, j + 2, k + 13, Blocks.stone, 0, 2);
		world.setBlock(i + 15, j + 2, k + 13, Blocks.stone, 0, 2);
		world.setBlock(i + 16, j + 2, k + 13, Blocks.stone, 0, 2);
		world.setBlock(i + 17, j + 2, k + 13, Blocks.stone, 0, 2);
		world.setBlock(i + 18, j + 2, k + 13, Blocks.stone, 0, 2);
		world.setBlock(i + 19, j + 2, k + 13, Blocks.stone, 0, 2);
		world.setBlock(i + 20, j + 2, k + 13, Blocks.stone, 0, 2);
		world.setBlock(i + 21, j + 2, k + 13, Blocks.stone, 0, 2);
		world.setBlock(i, j + 2, k + 14, Blocks.stone, 0, 2);
		world.setBlock(i + 1, j + 2, k + 14, Blocks.stone, 0, 2);
		world.setBlock(i + 2, j + 2, k + 14, Blocks.stone, 0, 2);
		world.setBlock(i + 3, j + 2, k + 14, Blocks.stone, 0, 2);
		world.setBlock(i + 4, j + 2, k + 14, Blocks.stone, 0, 2);
		world.setBlock(i + 5, j + 2, k + 14, Blocks.stone, 0, 2);
		world.setBlock(i + 6, j + 2, k + 14, Blocks.stone, 0, 2);
		world.setBlock(i + 7, j + 2, k + 14, Blocks.stone, 0, 2);
		world.setBlock(i + 8, j + 2, k + 14, Blocks.stone, 0, 2);
		world.setBlock(i + 9, j + 2, k + 14, Blocks.stone, 0, 2);
		world.setBlock(i + 10, j + 2, k + 14, Blocks.stone, 0, 2);
		world.setBlock(i + 11, j + 2, k + 14, Blocks.stone, 0, 2);
		world.setBlock(i + 12, j + 2, k + 14, Blocks.stone, 0, 2);
		world.setBlock(i + 13, j + 2, k + 14, Blocks.stone, 0, 2);
		world.setBlock(i + 14, j + 2, k + 14, Blocks.stone, 0, 2);
		world.setBlock(i + 15, j + 2, k + 14, Blocks.stone, 0, 2);
		world.setBlock(i + 16, j + 2, k + 14, Blocks.stone, 0, 2);
		world.setBlock(i + 17, j + 2, k + 14, Blocks.stone, 0, 2);
		world.setBlock(i + 18, j + 2, k + 14, Blocks.stone, 0, 2);
		world.setBlock(i + 19, j + 2, k + 14, Blocks.stone, 0, 2);
		world.setBlock(i + 20, j + 2, k + 14, Blocks.stone, 0, 2);
		world.setBlock(i + 21, j + 2, k + 14, Blocks.stone, 0, 2);
		world.setBlock(i, j + 2, k + 15, Blocks.stone, 0, 2);
		world.setBlock(i + 1, j + 2, k + 15, Blocks.stone, 0, 2);
		world.setBlock(i + 2, j + 2, k + 15, Blocks.stone, 0, 2);
		world.setBlock(i + 3, j + 2, k + 15, Blocks.stone, 0, 2);
		world.setBlock(i + 4, j + 2, k + 15, Blocks.stone, 0, 2);
		world.setBlock(i + 5, j + 2, k + 15, Blocks.stone, 0, 2);
		world.setBlock(i + 6, j + 2, k + 15, Blocks.stone, 0, 2);
		world.setBlock(i + 7, j + 2, k + 15, Blocks.stone, 0, 2);
		world.setBlock(i + 8, j + 2, k + 15, Blocks.stone, 0, 2);
		world.setBlock(i + 9, j + 2, k + 15, Blocks.stone, 0, 2);
		world.setBlock(i + 10, j + 2, k + 15, Blocks.stone, 0, 2);
		world.setBlock(i + 11, j + 2, k + 15, Blocks.stone, 0, 2);
		world.setBlock(i + 12, j + 2, k + 15, Blocks.stone, 0, 2);
		world.setBlock(i + 13, j + 2, k + 15, Blocks.stone, 0, 2);
		world.setBlock(i + 14, j + 2, k + 15, Blocks.stone, 0, 2);
		world.setBlock(i + 15, j + 2, k + 15, Blocks.stone, 0, 2);
		world.setBlock(i + 16, j + 2, k + 15, Blocks.stone, 0, 2);
		world.setBlock(i + 17, j + 2, k + 15, Blocks.stone, 0, 2);
		world.setBlock(i + 18, j + 2, k + 15, Blocks.stone, 0, 2);
		world.setBlock(i + 19, j + 2, k + 15, Blocks.stone, 0, 2);
		world.setBlock(i + 20, j + 2, k + 15, Blocks.stone, 0, 2);
		world.setBlock(i + 21, j + 2, k + 15, Blocks.stone, 0, 2);
		world.setBlock(i + 22, j + 2, k + 15, NovaCraftBlocks.sculk_block, 0, 2);
		world.setBlock(i, j + 2, k + 16, Blocks.stone, 0, 2);
		world.setBlock(i + 1, j + 2, k + 16, Blocks.stone, 0, 2);
		world.setBlock(i + 2, j + 2, k + 16, Blocks.stone, 0, 2);
		world.setBlock(i + 3, j + 2, k + 16, Blocks.stone, 0, 2);
		world.setBlock(i + 4, j + 2, k + 16, Blocks.stone, 0, 2);
		world.setBlock(i + 5, j + 2, k + 16, Blocks.stone, 0, 2);
		world.setBlock(i + 6, j + 2, k + 16, Blocks.stone, 0, 2);
		world.setBlock(i + 7, j + 2, k + 16, Blocks.stone, 0, 2);
		world.setBlock(i + 8, j + 2, k + 16, Blocks.stone, 0, 2);
		world.setBlock(i + 9, j + 2, k + 16, Blocks.stone, 0, 2);
		world.setBlock(i + 10, j + 2, k + 16, Blocks.stone, 0, 2);
		world.setBlock(i + 11, j + 2, k + 16, Blocks.stone, 0, 2);
		world.setBlock(i + 12, j + 2, k + 16, Blocks.stone, 0, 2);
		world.setBlock(i + 13, j + 2, k + 16, Blocks.stone, 0, 2);
		world.setBlock(i + 14, j + 2, k + 16, Blocks.stone, 0, 2);
		world.setBlock(i + 15, j + 2, k + 16, Blocks.stone, 0, 2);
		world.setBlock(i + 16, j + 2, k + 16, Blocks.stone, 0, 2);
		world.setBlock(i + 17, j + 2, k + 16, Blocks.stone, 0, 2);
		world.setBlock(i + 18, j + 2, k + 16, Blocks.stone, 0, 2);
		world.setBlock(i + 19, j + 2, k + 16, Blocks.stone, 0, 2);
		world.setBlock(i + 20, j + 2, k + 16, Blocks.stone, 0, 2);
		world.setBlock(i + 21, j + 2, k + 16, Blocks.stone, 0, 2);
		world.setBlock(i + 22, j + 2, k + 16, NovaCraftBlocks.sculk_block, 0, 2);
		world.setBlock(i, j + 2, k + 17, Blocks.stone, 0, 2);
		world.setBlock(i + 1, j + 2, k + 17, Blocks.stone, 0, 2);
		world.setBlock(i + 2, j + 2, k + 17, Blocks.stone, 0, 2);
		world.setBlock(i + 3, j + 2, k + 17, Blocks.stone, 0, 2);
		world.setBlock(i + 4, j + 2, k + 17, Blocks.stone, 0, 2);
		world.setBlock(i + 5, j + 2, k + 17, Blocks.stone, 0, 2);
		world.setBlock(i + 6, j + 2, k + 17, Blocks.stone, 0, 2);
		world.setBlock(i + 7, j + 2, k + 17, Blocks.stone, 0, 2);
		world.setBlock(i + 8, j + 2, k + 17, Blocks.stone, 0, 2);
		world.setBlock(i + 9, j + 2, k + 17, Blocks.stone, 0, 2);
		world.setBlock(i + 10, j + 2, k + 17, Blocks.stone, 0, 2);
		world.setBlock(i + 11, j + 2, k + 17, Blocks.stone, 0, 2);
		world.setBlock(i + 12, j + 2, k + 17, Blocks.stone, 0, 2);
		world.setBlock(i + 13, j + 2, k + 17, Blocks.stone, 0, 2);
		world.setBlock(i + 14, j + 2, k + 17, Blocks.stone, 0, 2);
		world.setBlock(i + 15, j + 2, k + 17, Blocks.stone, 0, 2);
		world.setBlock(i + 16, j + 2, k + 17, Blocks.stone, 0, 2);
		world.setBlock(i + 17, j + 2, k + 17, Blocks.stone, 0, 2);
		world.setBlock(i + 18, j + 2, k + 17, Blocks.stone, 0, 2);
		world.setBlock(i + 19, j + 2, k + 17, Blocks.stone, 0, 2);
		world.setBlock(i + 20, j + 2, k + 17, Blocks.stone, 0, 2);
		world.setBlock(i + 21, j + 2, k + 17, Blocks.stone, 0, 2);
		world.setBlock(i + 22, j + 2, k + 17, NovaCraftBlocks.sculk_block, 0, 2);
		world.setBlock(i + 1, j + 2, k + 18, Blocks.stone, 0, 2);
		world.setBlock(i + 2, j + 2, k + 18, Blocks.stone, 0, 2);
		world.setBlock(i + 3, j + 2, k + 18, Blocks.stone, 0, 2);
		world.setBlock(i + 4, j + 2, k + 18, Blocks.stone, 0, 2);
		world.setBlock(i + 5, j + 2, k + 18, Blocks.stone, 0, 2);
		world.setBlock(i + 6, j + 2, k + 18, Blocks.stone, 0, 2);
		world.setBlock(i + 7, j + 2, k + 18, Blocks.stone, 0, 2);
		world.setBlock(i + 8, j + 2, k + 18, Blocks.stone, 0, 2);
		world.setBlock(i + 9, j + 2, k + 18, Blocks.stone, 0, 2);
		world.setBlock(i + 10, j + 2, k + 18, Blocks.stone, 0, 2);
		world.setBlock(i + 11, j + 2, k + 18, Blocks.stone, 0, 2);
		world.setBlock(i + 12, j + 2, k + 18, Blocks.stone, 0, 2);
		world.setBlock(i + 13, j + 2, k + 18, Blocks.stone, 0, 2);
		world.setBlock(i + 14, j + 2, k + 18, Blocks.stone, 0, 2);
		world.setBlock(i + 15, j + 2, k + 18, Blocks.stone, 0, 2);
		world.setBlock(i + 16, j + 2, k + 18, Blocks.stone, 0, 2);
		world.setBlock(i + 17, j + 2, k + 18, Blocks.stone, 0, 2);
		world.setBlock(i + 18, j + 2, k + 18, Blocks.stone, 0, 2);
		world.setBlock(i + 19, j + 2, k + 18, Blocks.stone, 0, 2);
		world.setBlock(i + 20, j + 2, k + 18, Blocks.stone, 0, 2);
		world.setBlock(i + 21, j + 2, k + 18, NovaCraftBlocks.sculk_block, 0, 2);
		world.setBlock(i + 2, j + 2, k + 19, Blocks.stone, 0, 2);
		world.setBlock(i + 3, j + 2, k + 19, NovaCraftBlocks.sculk_block, 0, 2);
		world.setBlock(i + 4, j + 2, k + 19, NovaCraftBlocks.sculk_block, 0, 2);
		world.setBlock(i + 5, j + 2, k + 19, NovaCraftBlocks.sculk_block, 0, 2);
		world.setBlock(i + 6, j + 2, k + 19, NovaCraftBlocks.sculk_block, 0, 2);
		world.setBlock(i + 7, j + 2, k + 19, NovaCraftBlocks.sculk_block, 0, 2);
		world.setBlock(i + 8, j + 2, k + 19, NovaCraftBlocks.sculk_block, 0, 2);
		world.setBlock(i + 9, j + 2, k + 19, NovaCraftBlocks.sculk_block, 0, 2);
		world.setBlock(i + 10, j + 2, k + 19, NovaCraftBlocks.sculk_block, 0, 2);
		world.setBlock(i + 11, j + 2, k + 19, NovaCraftBlocks.sculk_block, 0, 2);
		world.setBlock(i + 12, j + 2, k + 19, NovaCraftBlocks.sculk_block, 0, 2);
		world.setBlock(i + 13, j + 2, k + 19, NovaCraftBlocks.sculk_block, 0, 2);
		world.setBlock(i + 14, j + 2, k + 19, NovaCraftBlocks.sculk_block, 0, 2);
		world.setBlock(i + 15, j + 2, k + 19, NovaCraftBlocks.sculk_block, 0, 2);
		world.setBlock(i + 16, j + 2, k + 19, NovaCraftBlocks.sculk_block, 0, 2);
		world.setBlock(i + 17, j + 2, k + 19, NovaCraftBlocks.sculk_block, 0, 2);
		world.setBlock(i + 18, j + 2, k + 19, NovaCraftBlocks.sculk_block, 0, 2);
		world.setBlock(i + 19, j + 2, k + 19, NovaCraftBlocks.sculk_block, 0, 2);
		world.setBlock(i + 20, j + 2, k + 19, NovaCraftBlocks.sculk_block, 0, 2);
		world.setBlock(i + 3, j + 3, k, Blocks.stone, 0, 2);
		world.setBlock(i + 4, j + 3, k, Blocks.stone, 0, 2);
		world.setBlock(i + 5, j + 3, k, Blocks.stone, 0, 2);
		world.setBlock(i + 6, j + 3, k, Blocks.stone, 0, 2);
		world.setBlock(i + 7, j + 3, k, Blocks.stone, 0, 2);
		world.setBlock(i + 8, j + 3, k, Blocks.stone, 0, 2);
		world.setBlock(i + 9, j + 3, k, Blocks.stone, 0, 2);
		world.setBlock(i + 10, j + 3, k, Blocks.stone, 0, 2);
		world.setBlock(i + 11, j + 3, k, Blocks.stone, 0, 2);
		world.setBlock(i + 12, j + 3, k, Blocks.stone, 0, 2);
		world.setBlock(i + 13, j + 3, k, Blocks.stone, 0, 2);
		world.setBlock(i + 14, j + 3, k, Blocks.stone, 0, 2);
		world.setBlock(i + 15, j + 3, k, Blocks.stone, 0, 2);
		world.setBlock(i + 16, j + 3, k, Blocks.stone, 0, 2);
		world.setBlock(i + 17, j + 3, k, Blocks.stone, 0, 2);
		world.setBlock(i + 2, j + 3, k + 1, Blocks.stone, 0, 2);
		world.setBlock(i + 3, j + 3, k + 1, Blocks.stone, 0, 2);
		world.setBlock(i + 4, j + 3, k + 1, Blocks.stone, 0, 2);
		world.setBlock(i + 5, j + 3, k + 1, Blocks.stone, 0, 2);
		world.setBlock(i + 6, j + 3, k + 1, Blocks.stone, 0, 2);
		world.setBlock(i + 7, j + 3, k + 1, Blocks.stone, 0, 2);
		world.setBlock(i + 8, j + 3, k + 1, Blocks.stone, 0, 2);
		world.setBlock(i + 9, j + 3, k + 1, Blocks.stone, 0, 2);
		world.setBlock(i + 10, j + 3, k + 1, Blocks.stone, 0, 2);
		world.setBlock(i + 11, j + 3, k + 1, Blocks.stone, 0, 2);
		world.setBlock(i + 12, j + 3, k + 1, Blocks.stone, 0, 2);
		world.setBlock(i + 13, j + 3, k + 1, Blocks.stone, 0, 2);
		world.setBlock(i + 14, j + 3, k + 1, Blocks.stone, 0, 2);
		world.setBlock(i + 15, j + 3, k + 1, Blocks.stone, 0, 2);
		world.setBlock(i + 16, j + 3, k + 1, Blocks.stone, 0, 2);
		world.setBlock(i + 17, j + 3, k + 1, Blocks.stone, 0, 2);
		world.setBlock(i + 18, j + 3, k + 1, Blocks.stone, 0, 2);
		world.setBlock(i + 1, j + 3, k + 2, Blocks.stone, 0, 2);
		world.setBlock(i + 2, j + 3, k + 2, Blocks.stone, 0, 2);
		world.setBlock(i + 3, j + 3, k + 2, Blocks.stone, 0, 2);
		world.setBlock(i + 4, j + 3, k + 2, Blocks.stone, 0, 2);
		world.setBlock(i + 5, j + 3, k + 2, Blocks.stone, 0, 2);
		world.setBlock(i + 6, j + 3, k + 2, Blocks.stone, 0, 2);
		world.setBlock(i + 7, j + 3, k + 2, Blocks.stone, 0, 2);
		world.setBlock(i + 8, j + 3, k + 2, Blocks.stone, 0, 2);
		world.setBlock(i + 9, j + 3, k + 2, Blocks.stone, 0, 2);
		world.setBlock(i + 10, j + 3, k + 2, Blocks.stone, 0, 2);
		world.setBlock(i + 11, j + 3, k + 2, Blocks.stone, 0, 2);
		world.setBlock(i + 12, j + 3, k + 2, Blocks.stone, 0, 2);
		world.setBlock(i + 13, j + 3, k + 2, Blocks.stone, 0, 2);
		world.setBlock(i + 14, j + 3, k + 2, Blocks.stone, 0, 2);
		world.setBlock(i + 15, j + 3, k + 2, Blocks.stone, 0, 2);
		world.setBlock(i + 16, j + 3, k + 2, Blocks.stone, 0, 2);
		world.setBlock(i + 17, j + 3, k + 2, Blocks.stone, 0, 2);
		world.setBlock(i + 18, j + 3, k + 2, Blocks.stone, 0, 2);
		world.setBlock(i, j + 3, k + 3, Blocks.stone, 0, 2);
		world.setBlock(i + 1, j + 3, k + 3, Blocks.stone, 0, 2);
		world.setBlock(i + 2, j + 3, k + 3, Blocks.stone, 0, 2);
		world.setBlock(i + 3, j + 3, k + 3, Blocks.stone, 0, 2);
		world.setBlock(i + 4, j + 3, k + 3, Blocks.stone, 0, 2);
		world.setBlock(i + 5, j + 3, k + 3, Blocks.stone, 0, 2);
		world.setBlock(i + 6, j + 3, k + 3, Blocks.stone, 0, 2);
		world.setBlock(i + 7, j + 3, k + 3, Blocks.stone, 0, 2);
		world.setBlock(i + 8, j + 3, k + 3, Blocks.stone, 0, 2);
		world.setBlock(i + 9, j + 3, k + 3, Blocks.stone, 0, 2);
		world.setBlock(i + 10, j + 3, k + 3, Blocks.stone, 0, 2);
		world.setBlock(i + 11, j + 3, k + 3, Blocks.stone, 0, 2);
		world.setBlock(i + 12, j + 3, k + 3, Blocks.stone, 0, 2);
		world.setBlock(i + 13, j + 3, k + 3, Blocks.stone, 0, 2);
		world.setBlock(i + 14, j + 3, k + 3, Blocks.stone, 0, 2);
		world.setBlock(i + 15, j + 3, k + 3, Blocks.stone, 0, 2);
		world.setBlock(i + 16, j + 3, k + 3, Blocks.stone, 0, 2);
		world.setBlock(i + 17, j + 3, k + 3, Blocks.stone, 0, 2);
		world.setBlock(i + 18, j + 3, k + 3, Blocks.stone, 0, 2);
		world.setBlock(i, j + 3, k + 4, Blocks.stone, 0, 2);
		world.setBlock(i + 1, j + 3, k + 4, Blocks.stone, 0, 2);
		world.setBlock(i + 2, j + 3, k + 4, Blocks.stone, 0, 2);
		world.setBlock(i + 3, j + 3, k + 4, Blocks.stone, 0, 2);
		world.setBlock(i + 4, j + 3, k + 4, Blocks.stone, 0, 2);
		world.setBlock(i + 5, j + 3, k + 4, Blocks.stone, 0, 2);
		world.setBlock(i + 6, j + 3, k + 4, Blocks.stone, 0, 2);
		world.setBlock(i + 7, j + 3, k + 4, Blocks.stone, 0, 2);
		world.setBlock(i + 8, j + 3, k + 4, Blocks.stone, 0, 2);
		world.setBlock(i + 9, j + 3, k + 4, Blocks.stone, 0, 2);
		world.setBlock(i + 10, j + 3, k + 4, Blocks.stone, 0, 2);
		world.setBlock(i + 11, j + 3, k + 4, Blocks.stone, 0, 2);
		world.setBlock(i + 12, j + 3, k + 4, Blocks.stone, 0, 2);
		world.setBlock(i + 13, j + 3, k + 4, Blocks.stone, 0, 2);
		world.setBlock(i + 14, j + 3, k + 4, Blocks.stone, 0, 2);
		world.setBlock(i + 15, j + 3, k + 4, Blocks.stone, 0, 2);
		world.setBlock(i + 16, j + 3, k + 4, Blocks.stone, 0, 2);
		world.setBlock(i + 17, j + 3, k + 4, Blocks.stone, 0, 2);
		world.setBlock(i + 18, j + 3, k + 4, Blocks.stone, 0, 2);
		world.setBlock(i, j + 3, k + 5, Blocks.stone, 0, 2);
		world.setBlock(i + 1, j + 3, k + 5, Blocks.stone, 0, 2);
		world.setBlock(i + 2, j + 3, k + 5, Blocks.stone, 0, 2);
		world.setBlock(i + 3, j + 3, k + 5, Blocks.stone, 0, 2);
		world.setBlock(i + 4, j + 3, k + 5, Blocks.stone, 0, 2);
		world.setBlock(i + 5, j + 3, k + 5, Blocks.stone, 0, 2);
		world.setBlock(i + 6, j + 3, k + 5, Blocks.stone, 0, 2);
		world.setBlock(i + 7, j + 3, k + 5, Blocks.stone, 0, 2);
		world.setBlock(i + 8, j + 3, k + 5, Blocks.stone, 0, 2);
		world.setBlock(i + 9, j + 3, k + 5, Blocks.stone, 0, 2);
		world.setBlock(i + 10, j + 3, k + 5, Blocks.stone, 0, 2);
		world.setBlock(i + 11, j + 3, k + 5, Blocks.stone, 0, 2);
		world.setBlock(i + 12, j + 3, k + 5, Blocks.stone, 0, 2);
		world.setBlock(i + 13, j + 3, k + 5, Blocks.stone, 0, 2);
		world.setBlock(i + 14, j + 3, k + 5, Blocks.stone, 0, 2);
		world.setBlock(i + 15, j + 3, k + 5, Blocks.stone, 0, 2);
		world.setBlock(i + 16, j + 3, k + 5, Blocks.stone, 0, 2);
		world.setBlock(i + 17, j + 3, k + 5, Blocks.stone, 0, 2);
		world.setBlock(i + 18, j + 3, k + 5, Blocks.stone, 0, 2);
		world.setBlock(i, j + 3, k + 6, Blocks.stone, 0, 2);
		world.setBlock(i + 1, j + 3, k + 6, Blocks.stone, 0, 2);
		world.setBlock(i + 2, j + 3, k + 6, Blocks.stone, 0, 2);
		world.setBlock(i + 3, j + 3, k + 6, Blocks.stone, 0, 2);
		world.setBlock(i + 4, j + 3, k + 6, Blocks.stone, 0, 2);
		world.setBlock(i + 5, j + 3, k + 6, Blocks.stone, 0, 2);
		world.setBlock(i + 6, j + 3, k + 6, Blocks.stone, 0, 2);
		world.setBlock(i + 7, j + 3, k + 6, Blocks.stone, 0, 2);
		world.setBlock(i + 8, j + 3, k + 6, Blocks.stone, 0, 2);
		world.setBlock(i + 9, j + 3, k + 6, Blocks.stone, 0, 2);
		world.setBlock(i + 10, j + 3, k + 6, Blocks.stone, 0, 2);
		world.setBlock(i + 11, j + 3, k + 6, Blocks.stone, 0, 2);
		world.setBlock(i + 12, j + 3, k + 6, Blocks.stone, 0, 2);
		world.setBlock(i + 13, j + 3, k + 6, Blocks.stone, 0, 2);
		world.setBlock(i + 14, j + 3, k + 6, Blocks.stone, 0, 2);
		world.setBlock(i + 15, j + 3, k + 6, Blocks.stone, 0, 2);
		world.setBlock(i + 16, j + 3, k + 6, Blocks.stone, 0, 2);
		world.setBlock(i + 17, j + 3, k + 6, Blocks.stone, 0, 2);
		world.setBlock(i + 18, j + 3, k + 6, Blocks.stone, 0, 2);
		world.setBlock(i, j + 3, k + 7, Blocks.stone, 0, 2);
		world.setBlock(i + 1, j + 3, k + 7, Blocks.stone, 0, 2);
		world.setBlock(i + 2, j + 3, k + 7, Blocks.stone, 0, 2);
		world.setBlock(i + 3, j + 3, k + 7, Blocks.stone, 0, 2);
		world.setBlock(i + 4, j + 3, k + 7, Blocks.stone, 0, 2);
		world.setBlock(i + 5, j + 3, k + 7, Blocks.stone, 0, 2);
		world.setBlock(i + 6, j + 3, k + 7, Blocks.stone, 0, 2);
		world.setBlock(i + 7, j + 3, k + 7, Blocks.stone, 0, 2);
		world.setBlock(i + 8, j + 3, k + 7, Blocks.stone, 0, 2);
		world.setBlock(i + 9, j + 3, k + 7, Blocks.stone, 0, 2);
		world.setBlock(i + 10, j + 3, k + 7, Blocks.stone, 0, 2);
		world.setBlock(i + 11, j + 3, k + 7, Blocks.stone, 0, 2);
		world.setBlock(i + 12, j + 3, k + 7, Blocks.stone, 0, 2);
		world.setBlock(i + 13, j + 3, k + 7, Blocks.stone, 0, 2);
		world.setBlock(i + 14, j + 3, k + 7, Blocks.stone, 0, 2);
		world.setBlock(i + 15, j + 3, k + 7, Blocks.stone, 0, 2);
		world.setBlock(i + 16, j + 3, k + 7, Blocks.stone, 0, 2);
		world.setBlock(i + 17, j + 3, k + 7, Blocks.stone, 0, 2);
		world.setBlock(i + 18, j + 3, k + 7, Blocks.stone, 0, 2);
		world.setBlock(i, j + 3, k + 8, Blocks.stone, 0, 2);
		world.setBlock(i + 1, j + 3, k + 8, Blocks.stone, 0, 2);
		world.setBlock(i + 2, j + 3, k + 8, Blocks.stone, 0, 2);
		world.setBlock(i + 3, j + 3, k + 8, Blocks.stone, 0, 2);
		world.setBlock(i + 4, j + 3, k + 8, Blocks.stone, 0, 2);
		world.setBlock(i + 5, j + 3, k + 8, Blocks.stone, 0, 2);
		world.setBlock(i + 6, j + 3, k + 8, Blocks.stone, 0, 2);
		world.setBlock(i + 7, j + 3, k + 8, Blocks.stone, 0, 2);
		world.setBlock(i + 8, j + 3, k + 8, Blocks.stone, 0, 2);
		world.setBlock(i + 9, j + 3, k + 8, Blocks.stone, 0, 2);
		world.setBlock(i + 10, j + 3, k + 8, Blocks.stone, 0, 2);
		world.setBlock(i + 11, j + 3, k + 8, Blocks.stone, 0, 2);
		world.setBlock(i + 12, j + 3, k + 8, Blocks.stone, 0, 2);
		world.setBlock(i + 13, j + 3, k + 8, Blocks.stone, 0, 2);
		world.setBlock(i + 14, j + 3, k + 8, Blocks.stone, 0, 2);
		world.setBlock(i + 15, j + 3, k + 8, Blocks.stone, 0, 2);
		world.setBlock(i + 16, j + 3, k + 8, Blocks.stone, 0, 2);
		world.setBlock(i + 17, j + 3, k + 8, Blocks.stone, 0, 2);
		world.setBlock(i + 18, j + 3, k + 8, Blocks.stone, 0, 2);
		world.setBlock(i + 19, j + 3, k + 8, Blocks.stone, 0, 2);
		world.setBlock(i, j + 3, k + 9, Blocks.stone, 0, 2);
		world.setBlock(i + 1, j + 3, k + 9, Blocks.stone, 0, 2);
		world.setBlock(i + 2, j + 3, k + 9, Blocks.stone, 0, 2);
		world.setBlock(i + 3, j + 3, k + 9, Blocks.stone, 0, 2);
		world.setBlock(i + 4, j + 3, k + 9, Blocks.stone, 0, 2);
		world.setBlock(i + 5, j + 3, k + 9, Blocks.stone, 0, 2);
		world.setBlock(i + 6, j + 3, k + 9, Blocks.stone, 0, 2);
		world.setBlock(i + 7, j + 3, k + 9, Blocks.stone, 0, 2);
		world.setBlock(i + 8, j + 3, k + 9, Blocks.stone, 0, 2);
		world.setBlock(i + 9, j + 3, k + 9, Blocks.stone, 0, 2);
		world.setBlock(i + 10, j + 3, k + 9, Blocks.stone, 0, 2);
		world.setBlock(i + 11, j + 3, k + 9, Blocks.stone, 0, 2);
		world.setBlock(i + 12, j + 3, k + 9, Blocks.stone, 0, 2);
		world.setBlock(i + 13, j + 3, k + 9, Blocks.stone, 0, 2);
		world.setBlock(i + 14, j + 3, k + 9, Blocks.stone, 0, 2);
		world.setBlock(i + 15, j + 3, k + 9, Blocks.stone, 0, 2);
		world.setBlock(i + 16, j + 3, k + 9, Blocks.stone, 0, 2);
		world.setBlock(i + 17, j + 3, k + 9, Blocks.stone, 0, 2);
		world.setBlock(i + 18, j + 3, k + 9, Blocks.stone, 0, 2);
		world.setBlock(i + 19, j + 3, k + 9, Blocks.stone, 0, 2);
		world.setBlock(i + 20, j + 3, k + 9, Blocks.stone, 0, 2);
		world.setBlock(i, j + 3, k + 10, Blocks.stone, 0, 2);
		world.setBlock(i + 1, j + 3, k + 10, Blocks.stone, 0, 2);
		world.setBlock(i + 2, j + 3, k + 10, Blocks.stone, 0, 2);
		world.setBlock(i + 3, j + 3, k + 10, Blocks.stone, 0, 2);
		world.setBlock(i + 4, j + 3, k + 10, Blocks.stone, 0, 2);
		world.setBlock(i + 5, j + 3, k + 10, Blocks.stone, 0, 2);
		world.setBlock(i + 6, j + 3, k + 10, Blocks.stone, 0, 2);
		world.setBlock(i + 7, j + 3, k + 10, Blocks.stone, 0, 2);
		world.setBlock(i + 8, j + 3, k + 10, Blocks.stone, 0, 2);
		world.setBlock(i + 9, j + 3, k + 10, Blocks.stone, 0, 2);
		world.setBlock(i + 10, j + 3, k + 10, Blocks.stone, 0, 2);
		world.setBlock(i + 11, j + 3, k + 10, Blocks.stone, 0, 2);
		world.setBlock(i + 12, j + 3, k + 10, Blocks.stone, 0, 2);
		world.setBlock(i + 13, j + 3, k + 10, Blocks.stone, 0, 2);
		world.setBlock(i + 14, j + 3, k + 10, Blocks.stone, 0, 2);
		world.setBlock(i + 15, j + 3, k + 10, Blocks.stone, 0, 2);
		world.setBlock(i + 16, j + 3, k + 10, Blocks.stone, 0, 2);
		world.setBlock(i + 17, j + 3, k + 10, Blocks.stone, 0, 2);
		world.setBlock(i + 18, j + 3, k + 10, Blocks.stone, 0, 2);
		world.setBlock(i + 19, j + 3, k + 10, Blocks.stone, 0, 2);
		world.setBlock(i + 20, j + 3, k + 10, Blocks.stone, 0, 2);
		world.setBlock(i + 21, j + 3, k + 10, Blocks.stone, 0, 2);
		world.setBlock(i, j + 3, k + 11, Blocks.stone, 0, 2);
		world.setBlock(i + 1, j + 3, k + 11, Blocks.stone, 0, 2);
		world.setBlock(i + 2, j + 3, k + 11, Blocks.stone, 0, 2);
		world.setBlock(i + 3, j + 3, k + 11, Blocks.stone, 0, 2);
		world.setBlock(i + 4, j + 3, k + 11, Blocks.stone, 0, 2);
		world.setBlock(i + 5, j + 3, k + 11, Blocks.stone, 0, 2);
		world.setBlock(i + 6, j + 3, k + 11, Blocks.stone, 0, 2);
		world.setBlock(i + 7, j + 3, k + 11, Blocks.stone, 0, 2);
		world.setBlock(i + 8, j + 3, k + 11, Blocks.stone, 0, 2);
		world.setBlock(i + 9, j + 3, k + 11, Blocks.stone, 0, 2);
		world.setBlock(i + 10, j + 3, k + 11, Blocks.stone, 0, 2);
		world.setBlock(i + 11, j + 3, k + 11, Blocks.stone, 0, 2);
		world.setBlock(i + 12, j + 3, k + 11, Blocks.stone, 0, 2);
		world.setBlock(i + 13, j + 3, k + 11, Blocks.stone, 0, 2);
		world.setBlock(i + 14, j + 3, k + 11, Blocks.stone, 0, 2);
		world.setBlock(i + 15, j + 3, k + 11, Blocks.stone, 0, 2);
		world.setBlock(i + 16, j + 3, k + 11, Blocks.stone, 0, 2);
		world.setBlock(i + 17, j + 3, k + 11, Blocks.stone, 0, 2);
		world.setBlock(i + 18, j + 3, k + 11, Blocks.stone, 0, 2);
		world.setBlock(i + 19, j + 3, k + 11, Blocks.stone, 0, 2);
		world.setBlock(i + 20, j + 3, k + 11, Blocks.stone, 0, 2);
		world.setBlock(i + 21, j + 3, k + 11, Blocks.stone, 0, 2);
		world.setBlock(i, j + 3, k + 12, Blocks.stone, 0, 2);
		world.setBlock(i + 1, j + 3, k + 12, Blocks.stone, 0, 2);
		world.setBlock(i + 2, j + 3, k + 12, Blocks.stone, 0, 2);
		world.setBlock(i + 3, j + 3, k + 12, Blocks.stone, 0, 2);
		world.setBlock(i + 4, j + 3, k + 12, Blocks.stone, 0, 2);
		world.setBlock(i + 5, j + 3, k + 12, Blocks.stone, 0, 2);
		world.setBlock(i + 6, j + 3, k + 12, Blocks.stone, 0, 2);
		world.setBlock(i + 7, j + 3, k + 12, Blocks.stone, 0, 2);
		world.setBlock(i + 8, j + 3, k + 12, Blocks.stone, 0, 2);
		world.setBlock(i + 9, j + 3, k + 12, Blocks.stone, 0, 2);
		world.setBlock(i + 10, j + 3, k + 12, Blocks.stone, 0, 2);
		world.setBlock(i + 11, j + 3, k + 12, Blocks.stone, 0, 2);
		world.setBlock(i + 12, j + 3, k + 12, Blocks.stone, 0, 2);
		world.setBlock(i + 13, j + 3, k + 12, Blocks.stone, 0, 2);
		world.setBlock(i + 14, j + 3, k + 12, Blocks.stone, 0, 2);
		world.setBlock(i + 15, j + 3, k + 12, Blocks.stone, 0, 2);
		world.setBlock(i + 16, j + 3, k + 12, Blocks.stone, 0, 2);
		world.setBlock(i + 17, j + 3, k + 12, Blocks.stone, 0, 2);
		world.setBlock(i + 18, j + 3, k + 12, Blocks.stone, 0, 2);
		world.setBlock(i + 19, j + 3, k + 12, Blocks.stone, 0, 2);
		world.setBlock(i + 20, j + 3, k + 12, Blocks.stone, 0, 2);
		world.setBlock(i + 21, j + 3, k + 12, Blocks.stone, 0, 2);
		world.setBlock(i, j + 3, k + 13, Blocks.stone, 0, 2);
		world.setBlock(i + 1, j + 3, k + 13, Blocks.stone, 0, 2);
		world.setBlock(i + 2, j + 3, k + 13, Blocks.stone, 0, 2);
		world.setBlock(i + 3, j + 3, k + 13, Blocks.stone, 0, 2);
		world.setBlock(i + 4, j + 3, k + 13, Blocks.stone, 0, 2);
		world.setBlock(i + 5, j + 3, k + 13, Blocks.stone, 0, 2);
		world.setBlock(i + 6, j + 3, k + 13, Blocks.stone, 0, 2);
		world.setBlock(i + 7, j + 3, k + 13, Blocks.stone, 0, 2);
		world.setBlock(i + 8, j + 3, k + 13, Blocks.stone, 0, 2);
		world.setBlock(i + 9, j + 3, k + 13, Blocks.stone, 0, 2);
		world.setBlock(i + 10, j + 3, k + 13, Blocks.stone, 0, 2);
		world.setBlock(i + 11, j + 3, k + 13, Blocks.stone, 0, 2);
		world.setBlock(i + 12, j + 3, k + 13, Blocks.stone, 0, 2);
		world.setBlock(i + 13, j + 3, k + 13, Blocks.stone, 0, 2);
		world.setBlock(i + 14, j + 3, k + 13, Blocks.stone, 0, 2);
		world.setBlock(i + 15, j + 3, k + 13, Blocks.stone, 0, 2);
		world.setBlock(i + 16, j + 3, k + 13, Blocks.stone, 0, 2);
		world.setBlock(i + 17, j + 3, k + 13, Blocks.stone, 0, 2);
		world.setBlock(i + 18, j + 3, k + 13, Blocks.stone, 0, 2);
		world.setBlock(i + 19, j + 3, k + 13, Blocks.stone, 0, 2);
		world.setBlock(i + 20, j + 3, k + 13, Blocks.stone, 0, 2);
		world.setBlock(i + 21, j + 3, k + 13, Blocks.stone, 0, 2);
		world.setBlock(i, j + 3, k + 14, Blocks.stone, 0, 2);
		world.setBlock(i + 1, j + 3, k + 14, Blocks.stone, 0, 2);
		world.setBlock(i + 2, j + 3, k + 14, Blocks.stone, 0, 2);
		world.setBlock(i + 3, j + 3, k + 14, Blocks.stone, 0, 2);
		world.setBlock(i + 4, j + 3, k + 14, Blocks.stone, 0, 2);
		world.setBlock(i + 5, j + 3, k + 14, Blocks.stone, 0, 2);
		world.setBlock(i + 6, j + 3, k + 14, Blocks.stone, 0, 2);
		world.setBlock(i + 7, j + 3, k + 14, Blocks.stone, 0, 2);
		world.setBlock(i + 8, j + 3, k + 14, Blocks.stone, 0, 2);
		world.setBlock(i + 9, j + 3, k + 14, Blocks.stone, 0, 2);
		world.setBlock(i + 10, j + 3, k + 14, Blocks.stone, 0, 2);
		world.setBlock(i + 11, j + 3, k + 14, Blocks.stone, 0, 2);
		world.setBlock(i + 12, j + 3, k + 14, Blocks.stone, 0, 2);
		world.setBlock(i + 13, j + 3, k + 14, Blocks.stone, 0, 2);
		world.setBlock(i + 14, j + 3, k + 14, Blocks.stone, 0, 2);
		world.setBlock(i + 15, j + 3, k + 14, Blocks.stone, 0, 2);
		world.setBlock(i + 16, j + 3, k + 14, Blocks.stone, 0, 2);
		world.setBlock(i + 17, j + 3, k + 14, Blocks.stone, 0, 2);
		world.setBlock(i + 18, j + 3, k + 14, Blocks.stone, 0, 2);
		world.setBlock(i + 19, j + 3, k + 14, Blocks.stone, 0, 2);
		world.setBlock(i + 20, j + 3, k + 14, Blocks.stone, 0, 2);
		world.setBlock(i + 21, j + 3, k + 14, Blocks.stone, 0, 2);
		world.setBlock(i, j + 3, k + 15, Blocks.stone, 0, 2);
		world.setBlock(i + 1, j + 3, k + 15, Blocks.stone, 0, 2);
		world.setBlock(i + 2, j + 3, k + 15, Blocks.stone, 0, 2);
		world.setBlock(i + 3, j + 3, k + 15, Blocks.stone, 0, 2);
		world.setBlock(i + 4, j + 3, k + 15, Blocks.stone, 0, 2);
		world.setBlock(i + 5, j + 3, k + 15, Blocks.stone, 0, 2);
		world.setBlock(i + 6, j + 3, k + 15, Blocks.stone, 0, 2);
		world.setBlock(i + 7, j + 3, k + 15, Blocks.stone, 0, 2);
		world.setBlock(i + 8, j + 3, k + 15, Blocks.stone, 0, 2);
		world.setBlock(i + 9, j + 3, k + 15, Blocks.stone, 0, 2);
		world.setBlock(i + 10, j + 3, k + 15, Blocks.stone, 0, 2);
		world.setBlock(i + 11, j + 3, k + 15, Blocks.stone, 0, 2);
		world.setBlock(i + 12, j + 3, k + 15, Blocks.stone, 0, 2);
		world.setBlock(i + 13, j + 3, k + 15, Blocks.stone, 0, 2);
		world.setBlock(i + 14, j + 3, k + 15, Blocks.stone, 0, 2);
		world.setBlock(i + 15, j + 3, k + 15, Blocks.stone, 0, 2);
		world.setBlock(i + 16, j + 3, k + 15, Blocks.stone, 0, 2);
		world.setBlock(i + 17, j + 3, k + 15, Blocks.stone, 0, 2);
		world.setBlock(i + 18, j + 3, k + 15, Blocks.stone, 0, 2);
		world.setBlock(i + 19, j + 3, k + 15, Blocks.stone, 0, 2);
		world.setBlock(i + 20, j + 3, k + 15, Blocks.stone, 0, 2);
		world.setBlock(i + 21, j + 3, k + 15, Blocks.stone, 0, 2);
		world.setBlock(i + 22, j + 3, k + 15, NovaCraftBlocks.sculk_block, 0, 2);
		world.setBlock(i, j + 3, k + 16, Blocks.stone, 0, 2);
		world.setBlock(i + 1, j + 3, k + 16, Blocks.stone, 0, 2);
		world.setBlock(i + 2, j + 3, k + 16, Blocks.stone, 0, 2);
		world.setBlock(i + 3, j + 3, k + 16, Blocks.stone, 0, 2);
		world.setBlock(i + 4, j + 3, k + 16, Blocks.stone, 0, 2);
		world.setBlock(i + 5, j + 3, k + 16, Blocks.stone, 0, 2);
		world.setBlock(i + 6, j + 3, k + 16, Blocks.stone, 0, 2);
		world.setBlock(i + 7, j + 3, k + 16, Blocks.stone, 0, 2);
		world.setBlock(i + 8, j + 3, k + 16, Blocks.stone, 0, 2);
		world.setBlock(i + 9, j + 3, k + 16, Blocks.stone, 0, 2);
		world.setBlock(i + 10, j + 3, k + 16, Blocks.stone, 0, 2);
		world.setBlock(i + 11, j + 3, k + 16, Blocks.stone, 0, 2);
		world.setBlock(i + 12, j + 3, k + 16, Blocks.stone, 0, 2);
		world.setBlock(i + 13, j + 3, k + 16, Blocks.stone, 0, 2);
		world.setBlock(i + 14, j + 3, k + 16, Blocks.stone, 0, 2);
		world.setBlock(i + 15, j + 3, k + 16, Blocks.stone, 0, 2);
		world.setBlock(i + 16, j + 3, k + 16, Blocks.stone, 0, 2);
		world.setBlock(i + 17, j + 3, k + 16, Blocks.stone, 0, 2);
		world.setBlock(i + 18, j + 3, k + 16, Blocks.stone, 0, 2);
		world.setBlock(i + 19, j + 3, k + 16, Blocks.stone, 0, 2);
		world.setBlock(i + 20, j + 3, k + 16, Blocks.stone, 0, 2);
		world.setBlock(i + 21, j + 3, k + 16, Blocks.stone, 0, 2);
		world.setBlock(i + 22, j + 3, k + 16, NovaCraftBlocks.sculk_block, 0, 2);
		world.setBlock(i, j + 3, k + 17, Blocks.stone, 0, 2);
		world.setBlock(i + 1, j + 3, k + 17, Blocks.stone, 0, 2);
		world.setBlock(i + 2, j + 3, k + 17, Blocks.stone, 0, 2);
		world.setBlock(i + 3, j + 3, k + 17, Blocks.stone, 0, 2);
		world.setBlock(i + 4, j + 3, k + 17, Blocks.stone, 0, 2);
		world.setBlock(i + 5, j + 3, k + 17, Blocks.stone, 0, 2);
		world.setBlock(i + 6, j + 3, k + 17, Blocks.stone, 0, 2);
		world.setBlock(i + 7, j + 3, k + 17, Blocks.stone, 0, 2);
		world.setBlock(i + 8, j + 3, k + 17, Blocks.stone, 0, 2);
		world.setBlock(i + 9, j + 3, k + 17, Blocks.stone, 0, 2);
		world.setBlock(i + 10, j + 3, k + 17, Blocks.stone, 0, 2);
		world.setBlock(i + 11, j + 3, k + 17, Blocks.stone, 0, 2);
		world.setBlock(i + 12, j + 3, k + 17, Blocks.stone, 0, 2);
		world.setBlock(i + 13, j + 3, k + 17, Blocks.stone, 0, 2);
		world.setBlock(i + 14, j + 3, k + 17, Blocks.stone, 0, 2);
		world.setBlock(i + 15, j + 3, k + 17, Blocks.stone, 0, 2);
		world.setBlock(i + 16, j + 3, k + 17, Blocks.stone, 0, 2);
		world.setBlock(i + 17, j + 3, k + 17, Blocks.stone, 0, 2);
		world.setBlock(i + 18, j + 3, k + 17, Blocks.stone, 0, 2);
		world.setBlock(i + 19, j + 3, k + 17, Blocks.stone, 0, 2);
		world.setBlock(i + 20, j + 3, k + 17, Blocks.stone, 0, 2);
		world.setBlock(i + 21, j + 3, k + 17, Blocks.stone, 0, 2);
		world.setBlock(i + 22, j + 3, k + 17, NovaCraftBlocks.sculk_block, 0, 2);
		world.setBlock(i + 1, j + 3, k + 18, Blocks.stone, 0, 2);
		world.setBlock(i + 2, j + 3, k + 18, Blocks.stone, 0, 2);
		world.setBlock(i + 3, j + 3, k + 18, Blocks.stone, 0, 2);
		world.setBlock(i + 4, j + 3, k + 18, Blocks.stone, 0, 2);
		world.setBlock(i + 5, j + 3, k + 18, Blocks.stone, 0, 2);
		world.setBlock(i + 6, j + 3, k + 18, Blocks.stone, 0, 2);
		world.setBlock(i + 7, j + 3, k + 18, Blocks.stone, 0, 2);
		world.setBlock(i + 8, j + 3, k + 18, Blocks.stone, 0, 2);
		world.setBlock(i + 9, j + 3, k + 18, Blocks.stone, 0, 2);
		world.setBlock(i + 10, j + 3, k + 18, Blocks.stone, 0, 2);
		world.setBlock(i + 11, j + 3, k + 18, Blocks.stone, 0, 2);
		world.setBlock(i + 12, j + 3, k + 18, Blocks.stone, 0, 2);
		world.setBlock(i + 13, j + 3, k + 18, Blocks.stone, 0, 2);
		world.setBlock(i + 14, j + 3, k + 18, Blocks.stone, 0, 2);
		world.setBlock(i + 15, j + 3, k + 18, Blocks.stone, 0, 2);
		world.setBlock(i + 16, j + 3, k + 18, Blocks.stone, 0, 2);
		world.setBlock(i + 17, j + 3, k + 18, Blocks.stone, 0, 2);
		world.setBlock(i + 18, j + 3, k + 18, Blocks.stone, 0, 2);
		world.setBlock(i + 19, j + 3, k + 18, Blocks.stone, 0, 2);
		world.setBlock(i + 20, j + 3, k + 18, Blocks.stone, 0, 2);
		world.setBlock(i + 21, j + 3, k + 18, NovaCraftBlocks.sculk_block, 0, 2);
		world.setBlock(i + 2, j + 3, k + 19, Blocks.stone, 0, 2);
		world.setBlock(i + 3, j + 3, k + 19, NovaCraftBlocks.sculk_block, 0, 2);
		world.setBlock(i + 4, j + 3, k + 19, NovaCraftBlocks.sculk_block, 0, 2);
		world.setBlock(i + 5, j + 3, k + 19, NovaCraftBlocks.sculk_block, 0, 2);
		world.setBlock(i + 6, j + 3, k + 19, NovaCraftBlocks.sculk_block, 0, 2);
		world.setBlock(i + 7, j + 3, k + 19, NovaCraftBlocks.sculk_block, 0, 2);
		world.setBlock(i + 8, j + 3, k + 19, NovaCraftBlocks.sculk_block, 0, 2);
		world.setBlock(i + 9, j + 3, k + 19, NovaCraftBlocks.sculk_block, 0, 2);
		world.setBlock(i + 10, j + 3, k + 19, NovaCraftBlocks.sculk_block, 0, 2);
		world.setBlock(i + 11, j + 3, k + 19, NovaCraftBlocks.sculk_block, 0, 2);
		world.setBlock(i + 12, j + 3, k + 19, NovaCraftBlocks.sculk_block, 0, 2);
		world.setBlock(i + 13, j + 3, k + 19, NovaCraftBlocks.sculk_block, 0, 2);
		world.setBlock(i + 14, j + 3, k + 19, NovaCraftBlocks.sculk_block, 0, 2);
		world.setBlock(i + 15, j + 3, k + 19, NovaCraftBlocks.sculk_block, 0, 2);
		world.setBlock(i + 16, j + 3, k + 19, NovaCraftBlocks.sculk_block, 0, 2);
		world.setBlock(i + 17, j + 3, k + 19, NovaCraftBlocks.sculk_block, 0, 2);
		world.setBlock(i + 18, j + 3, k + 19, NovaCraftBlocks.sculk_block, 0, 2);
		world.setBlock(i + 19, j + 3, k + 19, NovaCraftBlocks.sculk_block, 0, 2);
		world.setBlock(i + 20, j + 3, k + 19, NovaCraftBlocks.sculk_block, 0, 2);
		world.setBlock(i + 3, j + 4, k, Blocks.stone, 0, 2);
		world.setBlock(i + 4, j + 4, k, Blocks.stone, 0, 2);
		world.setBlock(i + 5, j + 4, k, Blocks.stone, 0, 2);
		world.setBlock(i + 6, j + 4, k, Blocks.stone, 0, 2);
		world.setBlock(i + 7, j + 4, k, Blocks.stone, 0, 2);
		world.setBlock(i + 8, j + 4, k, Blocks.stone, 0, 2);
		world.setBlock(i + 9, j + 4, k, Blocks.stone, 0, 2);
		world.setBlock(i + 10, j + 4, k, Blocks.stone, 0, 2);
		world.setBlock(i + 11, j + 4, k, Blocks.stone, 0, 2);
		world.setBlock(i + 12, j + 4, k, Blocks.stone, 0, 2);
		world.setBlock(i + 13, j + 4, k, Blocks.stone, 0, 2);
		world.setBlock(i + 14, j + 4, k, Blocks.stone, 0, 2);
		world.setBlock(i + 15, j + 4, k, Blocks.stone, 0, 2);
		world.setBlock(i + 16, j + 4, k, Blocks.stone, 0, 2);
		world.setBlock(i + 17, j + 4, k, Blocks.stone, 0, 2);
		world.setBlock(i + 2, j + 4, k + 1, Blocks.stone, 0, 2);
		world.setBlock(i + 3, j + 4, k + 1, Blocks.stone, 0, 2);
		world.setBlock(i + 4, j + 4, k + 1, Blocks.stone, 0, 2);
		world.setBlock(i + 5, j + 4, k + 1, Blocks.stone, 0, 2);
		world.setBlock(i + 6, j + 4, k + 1, Blocks.stone, 0, 2);
		world.setBlock(i + 7, j + 4, k + 1, Blocks.stone, 0, 2);
		world.setBlock(i + 8, j + 4, k + 1, Blocks.stone, 0, 2);
		world.setBlock(i + 9, j + 4, k + 1, Blocks.stone, 0, 2);
		world.setBlock(i + 10, j + 4, k + 1, Blocks.stone, 0, 2);
		world.setBlock(i + 11, j + 4, k + 1, Blocks.stone, 0, 2);
		world.setBlock(i + 12, j + 4, k + 1, Blocks.stone, 0, 2);
		world.setBlock(i + 13, j + 4, k + 1, Blocks.stone, 0, 2);
		world.setBlock(i + 14, j + 4, k + 1, Blocks.stone, 0, 2);
		world.setBlock(i + 15, j + 4, k + 1, Blocks.stone, 0, 2);
		world.setBlock(i + 16, j + 4, k + 1, Blocks.stone, 0, 2);
		world.setBlock(i + 17, j + 4, k + 1, Blocks.stone, 0, 2);
		world.setBlock(i + 18, j + 4, k + 1, Blocks.stone, 0, 2);
		world.setBlock(i + 22, j + 4, k + 1, Blocks.stone, 0, 2);
		world.setBlock(i + 1, j + 4, k + 2, Blocks.stone, 0, 2);
		world.setBlock(i + 2, j + 4, k + 2, Blocks.stone, 0, 2);
		world.setBlock(i + 3, j + 4, k + 2, Blocks.stone, 0, 2);
		world.setBlock(i + 4, j + 4, k + 2, Blocks.stone, 0, 2);
		world.setBlock(i + 5, j + 4, k + 2, Blocks.stone, 0, 2);
		world.setBlock(i + 6, j + 4, k + 2, Blocks.stone, 0, 2);
		world.setBlock(i + 7, j + 4, k + 2, Blocks.stone, 0, 2);
		world.setBlock(i + 8, j + 4, k + 2, Blocks.stone, 0, 2);
		world.setBlock(i + 9, j + 4, k + 2, Blocks.stone, 0, 2);
		world.setBlock(i + 10, j + 4, k + 2, Blocks.stone, 0, 2);
		world.setBlock(i + 11, j + 4, k + 2, Blocks.stone, 0, 2);
		world.setBlock(i + 12, j + 4, k + 2, Blocks.stone, 0, 2);
		world.setBlock(i + 13, j + 4, k + 2, Blocks.stone, 0, 2);
		world.setBlock(i + 14, j + 4, k + 2, Blocks.stone, 0, 2);
		world.setBlock(i + 15, j + 4, k + 2, Blocks.stone, 0, 2);
		world.setBlock(i + 16, j + 4, k + 2, Blocks.stone, 0, 2);
		world.setBlock(i + 17, j + 4, k + 2, Blocks.stone, 0, 2);
		world.setBlock(i + 18, j + 4, k + 2, Blocks.stone, 0, 2);
