package com.NovaCraft.world.ancient_city;

import net.minecraft.world.gen.feature.*;
import net.minecraft.block.*;
import net.minecraft.world.*;
import java.util.*;
import com.NovaCraft.Items.NovaCraftItems;
import com.NovaCraftBlocks.NovaCraftBlocks;
import net.minecraft.init.*;
import net.minecraft.item.ItemStack;
import net.minecraft.tileentity.TileEntityMobSpawner;

public class AncientCityWardenAltarNewGen1 extends WorldGenerator {

    public AncientCityWardenAltarNewGen1() {

    }

    public boolean generate(final World world, final Random random, final int i, final int j, final int k) {
        
        world.setBlock(i + 60, j, k + 26, NovaCraftBlocks.nullstone_bricks, 0, 2);
        world.setBlock(i + 60, j, k + 27, placeStoneBricks(random), 0, 2);
        world.setBlock(i + 60, j, k + 28, placeStoneBricks(random), 0, 2);
        world.setBlock(i + 60, j, k + 29, placeStoneBricks(random), 0, 2);
        world.setBlock(i + 60, j, k + 30, NovaCraftBlocks.sculk_block, 0, 2);
        world.setBlock(i + 59, j + 1, k + 26, placeStoneBricks(random), 0, 2);
        world.setBlock(i + 60, j + 1, k + 26, NovaCraftBlocks.nullstone_bricks, 0, 2);
        world.setBlock(i + 58, j + 1, k + 27, NovaCraftBlocks.nullstone_bricks, 0, 2);
        world.setBlock(i + 59, j + 1, k + 27, NovaCraftBlocks.nullstone_bricks, 0, 2);
        world.setBlock(i + 60, j + 1, k + 27, NovaCraftBlocks.nullstone_brick_stairs, 1, 2);
        world.setBlock(i + 58, j + 1, k + 28, NovaCraftBlocks.nullstone_bricks, 0, 2);
        world.setBlock(i + 59, j + 1, k + 28, NovaCraftBlocks.nullstone_bricks, 0, 2);
        world.setBlock(i + 60, j + 1, k + 28, NovaCraftBlocks.nullstone_brick_stairs, 1, 2);
        world.setBlock(i + 58, j + 1, k + 29, NovaCraftBlocks.nullstone_bricks, 0, 2);
        world.setBlock(i + 59, j + 1, k + 29, NovaCraftBlocks.nullstone_bricks, 0, 2);
        world.setBlock(i + 60, j + 1, k + 29, NovaCraftBlocks.nullstone_brick_stairs, 1, 2);
        world.setBlock(i + 59, j + 1, k + 30, placeStoneBricks(random), 0, 2);
        world.setBlock(i + 60, j + 1, k + 30, placeStoneBricks(random), 0, 2);
        world.setBlock(i + 58, j + 2, k + 26, placeStoneBricks(random), 0, 2);
        world.setBlock(i + 59, j + 2, k + 26, placeStoneBricks(random), 0, 2);
        world.setBlock(i + 60, j + 2, k + 26, NovaCraftBlocks.nullstone_brick_wall, 0, 2);
        world.setBlock(i + 56, j + 2, k + 27, NovaCraftBlocks.nullstone_bricks, 0, 2);
        world.setBlock(i + 57, j + 2, k + 27, NovaCraftBlocks.sculk_block, 0, 2);
        world.setBlock(i + 58, j + 2, k + 27, NovaCraftBlocks.nullstone_brick_stairs, 1, 2);
        world.setBlock(i + 56, j + 2, k + 28, NovaCraftBlocks.nullstone_bricks, 0, 2);
        world.setBlock(i + 57, j + 2, k + 28, NovaCraftBlocks.sculk_block, 0, 2);
        world.setBlock(i + 58, j + 2, k + 28, NovaCraftBlocks.nullstone_brick_stairs, 1, 2);
        world.setBlock(i + 56, j + 2, k + 29, NovaCraftBlocks.nullstone_bricks, 0, 2);
        world.setBlock(i + 57, j + 2, k + 29, NovaCraftBlocks.nullstone_bricks, 0, 2);
        world.setBlock(i + 58, j + 2, k + 29, NovaCraftBlocks.nullstone_brick_stairs, 1, 2);
        world.setBlock(i + 58, j + 2, k + 30, NovaCraftBlocks.sculk_block, 0, 2);
        world.setBlock(i + 59, j + 2, k + 30, placeStoneBricks(random), 0, 2);
        world.setBlock(i + 60, j + 2, k + 30, NovaCraftBlocks.nullstone_brick_wall, 0, 2);
        world.setBlock(i + 32, j + 3, k + 16, NovaCraftBlocks.sculk_block, 0, 2);
        world.setBlock(i + 56, j + 3, k + 26, placeStoneBricks(random), 0, 2);
        world.setBlock(i + 57, j + 3, k + 26, NovaCraftBlocks.sculk_block, 0, 2);
        world.setBlock(i + 58, j + 3, k + 26, NovaCraftBlocks.nullstone_brick_wall, 0, 2);
        world.setBlock(i + 59, j + 3, k + 26, NovaCraftBlocks.nullstone_brick_wall, 0, 2);
        world.setBlock(i + 60, j + 3, k + 26, NovaCraftBlocks.nullstone_brick_wall, 0, 2);
        world.setBlock(i + 54, j + 3, k + 27, NovaCraftBlocks.nullstone_bricks, 0, 2);
        world.setBlock(i + 55, j + 3, k + 27, NovaCraftBlocks.nullstone_bricks, 0, 2);
        world.setBlock(i + 56, j + 3, k + 27, NovaCraftBlocks.nullstone_brick_stairs, 1, 2);
        world.setBlock(i + 54, j + 3, k + 28, NovaCraftBlocks.nullstone_bricks, 0, 2);
        world.setBlock(i + 55, j + 3, k + 28, NovaCraftBlocks.nullstone_bricks, 0, 2);
        world.setBlock(i + 56, j + 3, k + 28, NovaCraftBlocks.nullstone_brick_stairs, 1, 2);
        world.setBlock(i + 54, j + 3, k + 29, NovaCraftBlocks.nullstone_bricks, 0, 2);
        world.setBlock(i + 55, j + 3, k + 29, NovaCraftBlocks.nullstone_bricks, 0, 2);
        world.setBlock(i + 56, j + 3, k + 29, NovaCraftBlocks.nullstone_brick_stairs, 1, 2);
        world.setBlock(i + 32, j + 3, k + 30, NovaCraftBlocks.sculk_block, 0, 2);
        world.setBlock(i + 56, j + 3, k + 30, NovaCraftBlocks.sculk_block, 0, 2);
        world.setBlock(i + 57, j + 3, k + 30, placeStoneBricks(random), 0, 2);
        world.setBlock(i + 58, j + 3, k + 30, NovaCraftBlocks.nullstone_brick_wall, 0, 2);
        world.setBlock(i + 59, j + 3, k + 30, NovaCraftBlocks.nullstone_brick_wall, 0, 2);
        world.setBlock(i + 60, j + 3, k + 30, NovaCraftBlocks.nullstone_brick_wall, 0, 2);
        world.setBlock(i + 23, j + 3, k + 32, NovaCraftBlocks.sculk_block, 0, 2);
        world.setBlock(i + 23, j + 3, k + 36, NovaCraftBlocks.sculk_block, 0, 2);
        world.setBlock(i + 32, j + 4, k + 16, NovaCraftBlocks.sculk_block, 0, 2);
        world.setBlock(i + 28, j + 4, k + 17, NovaCraftBlocks.sculk_block, 0, 2);
        world.setBlock(i + 22, j + 4, k + 20, NovaCraftBlocks.sculk_block, 0, 2);
        world.setBlock(i + 29, j + 4, k + 22, NovaCraftBlocks.sculk_block, 0, 2);
        world.setBlock(i + 38, j + 4, k + 22, NovaCraftBlocks.sculk_block, 0, 2);
        world.setBlock(i + 47, j + 4, k + 23, NovaCraftBlocks.sculk_block, 0, 2);
        world.setBlock(i + 48, j + 4, k + 23, NovaCraftBlocks.sculk_block, 0, 2);
        world.setBlock(i + 36, j + 4, k + 24, NovaCraftBlocks.sculk_block, 0, 2);
        world.setBlock(i + 54, j + 4, k + 26, NovaCraftBlocks.sculk_block, 0, 2);
        world.setBlock(i + 55, j + 4, k + 26, placeStoneBricks(random), 0, 2);
        world.setBlock(i + 56, j + 4, k + 26, NovaCraftBlocks.nullstone_brick_wall, 0, 2);
        world.setBlock(i + 57, j + 4, k + 26, NovaCraftBlocks.nullstone_brick_wall, 0, 2);
        world.setBlock(i + 58, j + 4, k + 26, NovaCraftBlocks.nullstone_brick_wall, 0, 2);
        world.setBlock(i + 52, j + 4, k + 27, NovaCraftBlocks.nullstone_bricks, 0, 2);
        world.setBlock(i + 53, j + 4, k + 27, NovaCraftBlocks.nullstone_bricks, 0, 2);
        world.setBlock(i + 54, j + 4, k + 27, NovaCraftBlocks.nullstone_brick_stairs, 1, 2);
        world.setBlock(i + 52, j + 4, k + 28, NovaCraftBlocks.nullstone_bricks, 0, 2);
        world.setBlock(i + 53, j + 4, k + 28, NovaCraftBlocks.sculk_block, 0, 2);
        world.setBlock(i + 54, j + 4, k + 28, NovaCraftBlocks.nullstone_brick_stairs, 1, 2);
        world.setBlock(i + 52, j + 4, k + 29, NovaCraftBlocks.sculk_block, 0, 2);
        world.setBlock(i + 53, j + 4, k + 29, NovaCraftBlocks.nullstone_bricks, 0, 2);
        world.setBlock(i + 54, j + 4, k + 29, NovaCraftBlocks.nullstone_brick_stairs, 1, 2);
        world.setBlock(i + 31, j + 4, k + 30, NovaCraftBlocks.sculk_block, 0, 2);
        world.setBlock(i + 32, j + 4, k + 30, NovaCraftBlocks.sculk_block, 0, 2);
        world.setBlock(i + 54, j + 4, k + 30, placeStoneBricks(random), 0, 2);
        world.setBlock(i + 55, j + 4, k + 30, placeStoneBricks(random), 0, 2);
        world.setBlock(i + 56, j + 4, k + 30, NovaCraftBlocks.nullstone_brick_wall, 0, 2);
        world.setBlock(i + 57, j + 4, k + 30, NovaCraftBlocks.nullstone_brick_wall, 0, 2);
        world.setBlock(i + 58, j + 4, k + 30, NovaCraftBlocks.nullstone_brick_wall, 0, 2);
        world.setBlock(i + 35, j + 4, k + 31, NovaCraftBlocks.sculk_block, 0, 2);
        world.setBlock(i + 45, j + 4, k + 31, NovaCraftBlocks.sculk_block, 0, 2);
        world.setBlock(i + 23, j + 4, k + 32, NovaCraftBlocks.sculk_block, 0, 2);
        world.setBlock(i + 24, j + 4, k + 32, NovaCraftBlocks.sculk_block, 0, 2);
        world.setBlock(i + 25, j + 4, k + 32, NovaCraftBlocks.sculk_block, 0, 2);
        world.setBlock(i + 48, j + 4, k + 33, NovaCraftBlocks.sculk_block, 0, 2);
        world.setBlock(i + 25, j + 4, k + 34, NovaCraftBlocks.sculk_block, 0, 2);
        world.setBlock(i + 26, j + 4, k + 34, NovaCraftBlocks.sculk_block, 0, 2);
        world.setBlock(i + 27, j + 4, k + 34, NovaCraftBlocks.sculk_block, 0, 2);
        world.setBlock(i + 23, j + 4, k + 36, NovaCraftBlocks.sculk_block, 0, 2);
        world.setBlock(i + 29, j + 4, k + 36, NovaCraftBlocks.sculk_block, 0, 2);
        world.setBlock(i + 29, j + 5, k + 16, NovaCraftBlocks.sculk_block, 0, 2);
        world.setBlock(i + 31, j + 5, k + 16, NovaCraftBlocks.sculk_block, 0, 2);
        world.setBlock(i + 32, j + 5, k + 16, NovaCraftBlocks.sculk_block, 0, 2);
        world.setBlock(i + 41, j + 5, k + 16, NovaCraftBlocks.sculk_block, 0, 2);
        world.setBlock(i + 42, j + 5, k + 16, NovaCraftBlocks.sculk_block, 0, 2);
        world.setBlock(i + 28, j + 5, k + 17, NovaCraftBlocks.sculk_block, 0, 2);
        world.setBlock(i + 30, j + 5, k + 17, NovaCraftBlocks.sculk_block, 0, 2);
        world.setBlock(i + 31, j + 5, k + 17, NovaCraftBlocks.sculk_block, 0, 2);
        world.setBlock(i + 38, j + 5, k + 17, NovaCraftBlocks.sculk_block, 0, 2);
        world.setBlock(i + 44, j + 5, k + 17, NovaCraftBlocks.sculk_block, 0, 2);
        world.setBlock(i + 25, j + 5, k + 18, NovaCraftBlocks.sculk_block, 0, 2);
        world.setBlock(i + 27, j + 5, k + 18, NovaCraftBlocks.sculk_block, 0, 2);
        world.setBlock(i + 29, j + 5, k + 18, NovaCraftBlocks.sculk_block, 0, 2);
        world.setBlock(i + 30, j + 5, k + 18, NovaCraftBlocks.sculk_block, 0, 2);
        world.setBlock(i + 32, j + 5, k + 18, NovaCraftBlocks.sculk_block, 0, 2);
        world.setBlock(i + 39, j + 5, k + 18, NovaCraftBlocks.sculk_block, 0, 2);
        world.setBlock(i + 44, j + 5, k + 18, NovaCraftBlocks.sculk_block, 0, 2);
        world.setBlock(i + 45, j + 5, k + 18, NovaCraftBlocks.sculk_block, 0, 2);
        world.setBlock(i + 23, j + 5, k + 19, NovaCraftBlocks.sculk_block, 0, 2);
        world.setBlock(i + 28, j + 5, k + 19, NovaCraftBlocks.sculk_block, 0, 2);
        world.setBlock(i + 40, j + 5, k + 19, NovaCraftBlocks.sculk_block, 0, 2);
        world.setBlock(i + 46, j + 5, k + 19, NovaCraftBlocks.sculk_block, 0, 2);
        world.setBlock(i + 22, j + 5, k + 20, NovaCraftBlocks.sculk_block, 0, 2);
        world.setBlock(i + 28, j + 5, k + 20, NovaCraftBlocks.sculk_block, 0, 2);
        world.setBlock(i + 29, j + 5, k + 20, NovaCraftBlocks.sculk_block, 0, 2);
        world.setBlock(i + 40, j + 5, k + 20, NovaCraftBlocks.sculk_block, 0, 2);
        world.setBlock(i + 47, j + 5, k + 20, NovaCraftBlocks.sculk_block, 0, 2);
        world.setBlock(i + 48, j + 5, k + 20, NovaCraftBlocks.sculk_block, 0, 2);
        world.setBlock(i + 49, j + 5, k + 20, NovaCraftBlocks.sculk_block, 0, 2);
        world.setBlock(i + 28, j + 5, k + 21, NovaCraftBlocks.sculk_block, 0, 2);
        world.setBlock(i + 39, j + 5, k + 21, NovaCraftBlocks.sculk_block, 0, 2);
        world.setBlock(i + 23, j + 5, k + 22, NovaCraftBlocks.sculk_block, 0, 2);
        world.setBlock(i + 26, j + 5, k + 22, NovaCraftBlocks.sculk_block, 0, 2);
        world.setBlock(i + 27, j + 5, k + 22, NovaCraftBlocks.sculk_block, 0, 2);
        world.setBlock(i + 29, j + 5, k + 22, NovaCraftBlocks.sculk_block, 0, 2);
        world.setBlock(i + 38, j + 5, k + 22, NovaCraftBlocks.sculk_block, 0, 2);
        world.setBlock(i + 47, j + 5, k + 23, NovaCraftBlocks.sculk_block, 0, 2);
        world.setBlock(i + 48, j + 5, k + 23, NovaCraftBlocks.sculk_block, 0, 2);
        world.setBlock(i + 30, j + 5, k + 24, NovaCraftBlocks.sculk_block, 0, 2);
        world.setBlock(i + 35, j + 5, k + 24, NovaCraftBlocks.sculk_block, 0, 2);
        world.setBlock(i + 36, j + 5, k + 24, NovaCraftBlocks.sculk_block, 0, 2);
        world.setBlock(i + 46, j + 5, k + 24, NovaCraftBlocks.sculk_block, 0, 2);
        world.setBlock(i + 47, j + 5, k + 24, NovaCraftBlocks.sculk_block, 0, 2);
        world.setBlock(i + 32, j + 5, k + 25, NovaCraftBlocks.sculk_block, 0, 2);
        world.setBlock(i + 34, j + 5, k + 25, NovaCraftBlocks.sculk_block, 0, 2);
        world.setBlock(i + 35, j + 5, k + 25, NovaCraftBlocks.sculk_block, 0, 2);
        world.setBlock(i + 37, j + 5, k + 25, NovaCraftBlocks.sculk_block, 0, 2);
        world.setBlock(i + 44, j + 5, k + 25, NovaCraftBlocks.sculk_block, 0, 2);
        world.setBlock(i + 46, j + 5, k + 25, NovaCraftBlocks.sculk_block, 0, 2);
        world.setBlock(i + 31, j + 5, k + 26, NovaCraftBlocks.sculk_block, 0, 2);
        world.setBlock(i + 33, j + 5, k + 26, NovaCraftBlocks.sculk_block, 0, 2);
        world.setBlock(i + 34, j + 5, k + 26, NovaCraftBlocks.sculk_block, 0, 2);
        world.setBlock(i + 36, j + 5, k + 26, NovaCraftBlocks.sculk_block, 0, 2);
        world.setBlock(i + 52, j + 5, k + 26, placeStoneBricks(random), 0, 2);
        world.setBlock(i + 53, j + 5, k + 26, NovaCraftBlocks.sculk_block, 0, 2);
        world.setBlock(i + 54, j + 5, k + 26, NovaCraftBlocks.nullstone_brick_wall, 0, 2);
        world.setBlock(i + 55, j + 5, k + 26, NovaCraftBlocks.nullstone_brick_wall, 0, 2);
        world.setBlock(i + 56, j + 5, k + 26, NovaCraftBlocks.nullstone_brick_wall, 0, 2);
        world.setBlock(i + 31, j + 5, k + 27, NovaCraftBlocks.sculk_block, 0, 2);
        world.setBlock(i + 32, j + 5, k + 27, NovaCraftBlocks.sculk_block, 0, 2);
        world.setBlock(i + 34, j + 5, k + 27, NovaCraftBlocks.sculk_block, 0, 2);
        world.setBlock(i + 36, j + 5, k + 27, NovaCraftBlocks.sculk_block, 0, 2);
        world.setBlock(i + 50, j + 5, k + 27, NovaCraftBlocks.nullstone_bricks, 0, 2);
        world.setBlock(i + 51, j + 5, k + 27, NovaCraftBlocks.nullstone_bricks, 0, 2);
        world.setBlock(i + 52, j + 5, k + 27, NovaCraftBlocks.nullstone_brick_stairs, 1, 2);
        world.setBlock(i + 33, j + 5, k + 28, NovaCraftBlocks.sculk_block, 0, 2);
        world.setBlock(i + 50, j + 5, k + 28, NovaCraftBlocks.nullstone_bricks, 0, 2);
        world.setBlock(i + 51, j + 5, k + 28, NovaCraftBlocks.nullstone_bricks, 0, 2);
        world.setBlock(i + 52, j + 5, k + 28, NovaCraftBlocks.nullstone_brick_stairs, 1, 2);
        world.setBlock(i + 31, j + 5, k + 29, NovaCraftBlocks.sculk_block, 0, 2);
        world.setBlock(i + 36, j + 5, k + 29, NovaCraftBlocks.sculk_block, 0, 2);
        world.setBlock(i + 37, j + 5, k + 29, NovaCraftBlocks.sculk_block, 0, 2);
        world.setBlock(i + 50, j + 5, k + 29, NovaCraftBlocks.sculk_block, 0, 2);
        world.setBlock(i + 51, j + 5, k + 29, NovaCraftBlocks.nullstone_bricks, 0, 2);
        world.setBlock(i + 52, j + 5, k + 29, NovaCraftBlocks.nullstone_brick_stairs, 1, 2);
        world.setBlock(i + 31, j + 5, k + 30, NovaCraftBlocks.sculk_block, 0, 2);
        world.setBlock(i + 32, j + 5, k + 30, NovaCraftBlocks.sculk_block, 0, 2);
        world.setBlock(i + 36, j + 5, k + 30, NovaCraftBlocks.sculk_block, 0, 2);
        world.setBlock(i + 52, j + 5, k + 30, NovaCraftBlocks.sculk_block, 0, 2);
        world.setBlock(i + 53, j + 5, k + 30, placeStoneBricks(random), 0, 2);
        world.setBlock(i + 54, j + 5, k + 30, NovaCraftBlocks.nullstone_brick_wall, 0, 2);
        world.setBlock(i + 55, j + 5, k + 30, NovaCraftBlocks.nullstone_brick_wall, 0, 2);
        world.setBlock(i + 56, j + 5, k + 30, NovaCraftBlocks.nullstone_brick_wall, 0, 2);
        world.setBlock(i + 26, j + 5, k + 31, NovaCraftBlocks.sculk_block, 0, 2);
        world.setBlock(i + 27, j + 5, k + 31, NovaCraftBlocks.sculk_block, 0, 2);
        world.setBlock(i + 35, j + 5, k + 31, NovaCraftBlocks.sculk_block, 0, 2);
        world.setBlock(i + 36, j + 5, k + 31, NovaCraftBlocks.sculk_block, 0, 2);
        world.setBlock(i + 43, j + 5, k + 31, NovaCraftBlocks.sculk_block, 0, 2);
        world.setBlock(i + 44, j + 5, k + 31, NovaCraftBlocks.sculk_block, 0, 2);
        world.setBlock(i + 45, j + 5, k + 31, NovaCraftBlocks.sculk_block, 0, 2);
        world.setBlock(i + 23, j + 5, k + 32, NovaCraftBlocks.sculk_block, 0, 2);
        world.setBlock(i + 24, j + 5, k + 32, NovaCraftBlocks.sculk_block, 0, 2);
        world.setBlock(i + 25, j + 5, k + 32, NovaCraftBlocks.sculk_block, 0, 2);
        world.setBlock(i + 27, j + 5, k + 32, NovaCraftBlocks.sculk_block, 0, 2);
        world.setBlock(i + 36, j + 5, k + 32, NovaCraftBlocks.sculk_block, 0, 2);
        world.setBlock(i + 43, j + 5, k + 32, NovaCraftBlocks.sculk_block, 0, 2);
        world.setBlock(i + 44, j + 5, k + 32, NovaCraftBlocks.sculk_block, 0, 2);
        world.setBlock(i + 23, j + 5, k + 33, NovaCraftBlocks.sculk_block, 0, 2);
        world.setBlock(i + 24, j + 5, k + 33, NovaCraftBlocks.sculk_block, 0, 2);
        world.setBlock(i + 25, j + 5, k + 33, NovaCraftBlocks.sculk_block, 0, 2);
        world.setBlock(i + 26, j + 5, k + 33, NovaCraftBlocks.sculk_block, 0, 2);
        world.setBlock(i + 43, j + 5, k + 33, NovaCraftBlocks.sculk_block, 0, 2);
        world.setBlock(i + 44, j + 5, k + 33, NovaCraftBlocks.sculk_block, 0, 2);
        world.setBlock(i + 48, j + 5, k + 33, NovaCraftBlocks.sculk_block, 0, 2);
        world.setBlock(i + 22, j + 5, k + 34, NovaCraftBlocks.sculk_block, 0, 2);
        world.setBlock(i + 23, j + 5, k + 34, NovaCraftBlocks.sculk_block, 0, 2);
        world.setBlock(i + 25, j + 5, k + 34, NovaCraftBlocks.sculk_block, 0, 2);
        world.setBlock(i + 26, j + 5, k + 34, NovaCraftBlocks.sculk_block, 0, 2);
        world.setBlock(i + 27, j + 5, k + 34, NovaCraftBlocks.sculk_block, 0, 2);
        world.setBlock(i + 46, j + 5, k + 34, NovaCraftBlocks.sculk_block, 0, 2);
        world.setBlock(i + 25, j + 5, k + 35, NovaCraftBlocks.sculk_block, 0, 2);
        world.setBlock(i + 26, j + 5, k + 35, NovaCraftBlocks.sculk_block, 0, 2);
        world.setBlock(i + 27, j + 5, k + 35, NovaCraftBlocks.sculk_block, 0, 2);
        world.setBlock(i + 44, j + 5, k + 35, NovaCraftBlocks.sculk_block, 0, 2);
        world.setBlock(i + 45, j + 5, k + 35, NovaCraftBlocks.sculk_block, 0, 2);
        world.setBlock(i + 46, j + 5, k + 35, NovaCraftBlocks.sculk_block, 0, 2);
        world.setBlock(i + 47, j + 5, k + 35, NovaCraftBlocks.sculk_block, 0, 2);
        world.setBlock(i + 48, j + 5, k + 35, NovaCraftBlocks.sculk_block, 0, 2);
        world.setBlock(i + 22, j + 5, k + 36, NovaCraftBlocks.sculk_block, 0, 2);
        world.setBlock(i + 23, j + 5, k + 36, NovaCraftBlocks.sculk_block, 0, 2);
        world.setBlock(i + 25, j + 5, k + 36, NovaCraftBlocks.sculk_block, 0, 2);
        world.setBlock(i + 29, j + 5, k + 36, NovaCraftBlocks.sculk_block, 0, 2);
        world.setBlock(i + 30, j + 5, k + 36, NovaCraftBlocks.sculk_block, 0, 2);
        world.setBlock(i + 39, j + 5, k + 36, NovaCraftBlocks.sculk_block, 0, 2);
        world.setBlock(i + 40, j + 5, k + 36, NovaCraftBlocks.sculk_block, 0, 2);
        world.setBlock(i + 24, j + 5, k + 37, NovaCraftBlocks.sculk_block, 0, 2);
        world.setBlock(i + 30, j + 5, k + 37, NovaCraftBlocks.sculk_block, 0, 2);
        world.setBlock(i + 41, j + 5, k + 37, NovaCraftBlocks.sculk_block, 0, 2);
        world.setBlock(i + 44, j + 5, k + 37, NovaCraftBlocks.sculk_block, 0, 2);
        world.setBlock(i + 42, j + 5, k + 38, NovaCraftBlocks.sculk_block, 0, 2);
        world.setBlock(i + 43, j + 5, k + 38, NovaCraftBlocks.sculk_block, 0, 2);
        world.setBlock(i + 44, j + 5, k + 38, NovaCraftBlocks.sculk_block, 0, 2);
        world.setBlock(i + 27, j + 5, k + 39, NovaCraftBlocks.sculk_block, 0, 2);
        world.setBlock(i + 27, j + 5, k + 40, NovaCraftBlocks.sculk_block, 0, 2);
        world.setBlock(i + 43, j + 5, k + 40, NovaCraftBlocks.sculk_block, 0, 2);
        world.setBlock(i + 27, j + 5, k + 41, NovaCraftBlocks.sculk_block, 0, 2);
        world.setBlock(i + 29, j + 5, k + 41, NovaCraftBlocks.sculk_block, 0, 2);
        world.setBlock(i + 34, j + 6, k + 13, placeStoneBricks(random), 0, 2);
        world.setBlock(i + 35, j + 6, k + 13, placeStoneBricks(random), 0, 2);
        world.setBlock(i + 36, j + 6, k + 13, placeStoneBricks(random), 0, 2);
        world.setBlock(i + 26, j + 6, k + 14, NovaCraftBlocks.glowing_carved_vanite_bricks, 0, 2);
        world.setBlock(i + 27, j + 6, k + 14, NovaCraftBlocks.carved_vanite_bricks, 0, 2);
        world.setBlock(i + 28, j + 6, k + 14, NovaCraftBlocks.carved_vanite_bricks, 0, 2);
        world.setBlock(i + 29, j + 6, k + 14, NovaCraftBlocks.carved_vanite_bricks, 0, 2);
        world.setBlock(i + 30, j + 6, k + 14, NovaCraftBlocks.carved_vanite_bricks, 0, 2);
        world.setBlock(i + 31, j + 6, k + 14, NovaCraftBlocks.carved_vanite_bricks, 0, 2);
        world.setBlock(i + 32, j + 6, k + 14, NovaCraftBlocks.carved_vanite_bricks, 0, 2);
        world.setBlock(i + 33, j + 6, k + 14, NovaCraftBlocks.carved_vanite_bricks, 0, 2);
        world.setBlock(i + 34, j + 6, k + 14, NovaCraftBlocks.nullstone_bricks, 0, 2);
        world.setBlock(i + 35, j + 6, k + 14, NovaCraftBlocks.nullstone_bricks, 0, 2);
        world.setBlock(i + 36, j + 6, k + 14, NovaCraftBlocks.nullstone_bricks, 0, 2);
        world.setBlock(i + 37, j + 6, k + 14, NovaCraftBlocks.carved_vanite_bricks, 0, 2);
        world.setBlock(i + 38, j + 6, k + 14, NovaCraftBlocks.carved_vanite_bricks, 0, 2);
        world.setBlock(i + 39, j + 6, k + 14, NovaCraftBlocks.carved_vanite_bricks, 0, 2);
        world.setBlock(i + 40, j + 6, k + 14, NovaCraftBlocks.carved_vanite_bricks, 0, 2);
        world.setBlock(i + 41, j + 6, k + 14, NovaCraftBlocks.carved_vanite_bricks, 0, 2);
        world.setBlock(i + 42, j + 6, k + 14, NovaCraftBlocks.carved_vanite_bricks, 0, 2);
        world.setBlock(i + 43, j + 6, k + 14, NovaCraftBlocks.carved_vanite_bricks, 0, 2);
        world.setBlock(i + 44, j + 6, k + 14, NovaCraftBlocks.glowing_carved_vanite_bricks, 0, 2);
        world.setBlock(i + 25, j + 6, k + 15, NovaCraftBlocks.carved_vanite_bricks, 0, 2);
        world.setBlock(i + 26, j + 6, k + 15, placeStoneBricks(random), 0, 2);
        world.setBlock(i + 27, j + 6, k + 15, placeStoneBricks(random), 0, 2);
        world.setBlock(i + 28, j + 6, k + 15, placeStoneBricks(random), 0, 2);
        world.setBlock(i + 29, j + 6, k + 15, placeStoneBricks(random), 0, 2);
        world.setBlock(i + 30, j + 6, k + 15, placeStoneBricks(random), 0, 2);
        world.setBlock(i + 31, j + 6, k + 15, NovaCraftBlocks.sculk_block, 0, 2);
        world.setBlock(i + 32, j + 6, k + 15, placeStoneBricks(random), 0, 2);
        world.setBlock(i + 33, j + 6, k + 15, NovaCraftBlocks.carved_vanite_bricks, 0, 2);
        world.setBlock(i + 34, j + 6, k + 15, NovaCraftBlocks.nullstone_bricks, 0, 2);
        world.setBlock(i + 35, j + 6, k + 15, NovaCraftBlocks.nullstone_bricks, 0, 2);
        world.setBlock(i + 36, j + 6, k + 15, NovaCraftBlocks.nullstone_bricks, 0, 2);
        world.setBlock(i + 37, j + 6, k + 15, NovaCraftBlocks.carved_vanite_bricks, 0, 2);
        world.setBlock(i + 38, j + 6, k + 15, placeStoneBricks(random), 0, 2);
        world.setBlock(i + 39, j + 6, k + 15, placeStoneBricks(random), 0, 2);
        world.setBlock(i + 40, j + 6, k + 15, NovaCraftBlocks.sculk_block, 0, 2);
        world.setBlock(i + 41, j + 6, k + 15, NovaCraftBlocks.sculk_block, 0, 2);
        world.setBlock(i + 42, j + 6, k + 15, placeStoneBricks(random), 0, 2);
        world.setBlock(i + 43, j + 6, k + 15, NovaCraftBlocks.sculk_block, 0, 2);
        world.setBlock(i + 44, j + 6, k + 15, placeStoneBricks(random), 0, 2);
        world.setBlock(i + 45, j + 6, k + 15, NovaCraftBlocks.carved_vanite_bricks, 0, 2);
        world.setBlock(i + 24, j + 6, k + 16, NovaCraftBlocks.carved_vanite_bricks, 0, 2);
        world.setBlock(i + 25, j + 6, k + 16, placeStoneBricks(random), 0, 2);
        world.setBlock(i + 26, j + 6, k + 16, placeStoneBricks(random), 0, 2);
        world.setBlock(i + 27, j + 6, k + 16, placeStoneBricks(random), 0, 2);
        world.setBlock(i + 28, j + 6, k + 16, NovaCraftBlocks.sculk_block, 0, 2);
        world.setBlock(i + 29, j + 6, k + 16, placeStoneBricks(random), 0, 2);
        world.setBlock(i + 30, j + 6, k + 16, NovaCraftBlocks.sculk_block, 0, 2);
        world.setBlock(i + 31, j + 6, k + 16, NovaCraftBlocks.sculk_block, 0, 2);
        world.setBlock(i + 32, j + 6, k + 16, placeStoneBricks(random), 0, 2);
        world.setBlock(i + 33, j + 6, k + 16, NovaCraftBlocks.carved_vanite_bricks, 0, 2);
        world.setBlock(i + 34, j + 6, k + 16, NovaCraftBlocks.nullstone_bricks, 0, 2);
        world.setBlock(i + 35, j + 6, k + 16, NovaCraftBlocks.nullstone_bricks, 0, 2);
        world.setBlock(i + 36, j + 6, k + 16, NovaCraftBlocks.nullstone_bricks, 0, 2);
        world.setBlock(i + 37, j + 6, k + 16, NovaCraftBlocks.carved_vanite_bricks, 0, 2);
        world.setBlock(i + 38, j + 6, k + 16, placeStoneBricks(random), 0, 2);
        world.setBlock(i + 39, j + 6, k + 16, placeStoneBricks(random), 0, 2);
        world.setBlock(i + 40, j + 6, k + 16, NovaCraftBlocks.sculk_block, 0, 2);
        world.setBlock(i + 41, j + 6, k + 16, placeStoneBricks(random), 0, 2);
        world.setBlock(i + 42, j + 6, k + 16, placeStoneBricks(random), 0, 2);
        world.setBlock(i + 43, j + 6, k + 16, NovaCraftBlocks.sculk_block, 0, 2);
        world.setBlock(i + 44, j + 6, k + 16, NovaCraftBlocks.sculk_block, 0, 2);
        world.setBlock(i + 45, j + 6, k + 16, placeStoneBricks(random), 0, 2);
        world.setBlock(i + 46, j + 6, k + 16, NovaCraftBlocks.carved_vanite_bricks, 0, 2);
        world.setBlock(i + 23, j + 6, k + 17, NovaCraftBlocks.carved_vanite_bricks, 0, 2);
        world.setBlock(i + 24, j + 6, k + 17, placeStoneBricks(random), 0, 2);
        world.setBlock(i + 25, j + 6, k + 17, placeStoneBricks(random), 0, 2);
        world.setBlock(i + 26, j + 6, k + 17, placeStoneBricks(random), 0, 2);
        world.setBlock(i + 27, j + 6, k + 17, placeStoneBricks(random), 0, 2);
        world.setBlock(i + 28, j + 6, k + 17, placeStoneBricks(random), 0, 2);
        world.setBlock(i + 29, j + 6, k + 17, placeStoneBricks(random), 0, 2);
        world.setBlock(i + 30, j + 6, k + 17, placeStoneBricks(random), 0, 2);
        world.setBlock(i + 31, j + 6, k + 17, placeStoneBricks(random), 0, 2);
        world.setBlock(i + 32, j + 6, k + 17, placeStoneBricks(random), 0, 2);
        world.setBlock(i + 33, j + 6, k + 17, NovaCraftBlocks.carved_vanite_bricks, 0, 2);
        world.setBlock(i + 34, j + 6, k + 17, NovaCraftBlocks.nullstone_bricks, 0, 2);
        world.setBlock(i + 35, j + 6, k + 17, NovaCraftBlocks.nullstone_bricks, 0, 2);
        world.setBlock(i + 36, j + 6, k + 17, NovaCraftBlocks.nullstone_bricks, 0, 2);
        world.setBlock(i + 37, j + 6, k + 17, NovaCraftBlocks.carved_vanite_bricks, 0, 2);
        world.setBlock(i + 38, j + 6, k + 17, NovaCraftBlocks.sculk_block, 0, 2);
        world.setBlock(i + 39, j + 6, k + 17, NovaCraftBlocks.sculk_block, 0, 2);
        world.setBlock(i + 40, j + 6, k + 17, placeStoneBricks(random), 0, 2);
        world.setBlock(i + 41, j + 6, k + 17, NovaCraftBlocks.sculk_block, 0, 2);
        world.setBlock(i + 42, j + 6, k + 17, placeStoneBricks(random), 0, 2);
        world.setBlock(i + 43, j + 6, k + 17, NovaCraftBlocks.sculk_block, 0, 2);
        world.setBlock(i + 44, j + 6, k + 17, placeStoneBricks(random), 0, 2);
        world.setBlock(i + 45, j + 6, k + 17, placeStoneBricks(random), 0, 2);
        world.setBlock(i + 46, j + 6, k + 17, placeStoneBricks(random), 0, 2);
        world.setBlock(i + 47, j + 6, k + 17, NovaCraftBlocks.carved_vanite_bricks, 0, 2);
        world.setBlock(i + 22, j + 6, k + 18, NovaCraftBlocks.carved_vanite_bricks, 0, 2);
        world.setBlock(i + 23, j + 6, k + 18, placeStoneBricks(random), 0, 2);
        world.setBlock(i + 24, j + 6, k + 18, NovaCraftBlocks.sculk_block, 0, 2);
        world.setBlock(i + 25, j + 6, k + 18, NovaCraftBlocks.sculk_block, 0, 2);
        world.setBlock(i + 26, j + 6, k + 18, placeStoneBricks(random), 0, 2);
        world.setBlock(i + 27, j + 6, k + 18, placeStoneBricks(random), 0, 2);
        world.setBlock(i + 28, j + 6, k + 18, placeStoneBricks(random), 0, 2);
        world.setBlock(i + 29, j + 6, k + 18, placeStoneBricks(random), 0, 2);
        world.setBlock(i + 30, j + 6, k + 18, NovaCraftBlocks.sculk_block, 0, 2);
        world.setBlock(i + 31, j + 6, k + 18, placeStoneBricks(random), 0, 2);
        world.setBlock(i + 32, j + 6, k + 18, NovaCraftBlocks.sculk_block, 0, 2);
        world.setBlock(i + 33, j + 6, k + 18, NovaCraftBlocks.carved_vanite_bricks, 0, 2);
        world.setBlock(i + 34, j + 6, k + 18, NovaCraftBlocks.nullstone_bricks, 0, 2);
        world.setBlock(i + 35, j + 6, k + 18, NovaCraftBlocks.nullstone_bricks, 0, 2);
        world.setBlock(i + 36, j + 6, k + 18, NovaCraftBlocks.nullstone_bricks, 0, 2);
        world.setBlock(i + 37, j + 6, k + 18, NovaCraftBlocks.carved_vanite_bricks, 0, 2);
        world.setBlock(i + 38, j + 6, k + 18, NovaCraftBlocks.sculk_block, 0, 2);
        world.setBlock(i + 39, j + 6, k + 18, placeStoneBricks(random), 0, 2);
        world.setBlock(i + 40, j + 6, k + 18, placeStoneBricks(random), 0, 2);
        world.setBlock(i + 41, j + 6, k + 18, NovaCraftBlocks.sculk_block, 0, 2);
        world.setBlock(i + 42, j + 6, k + 18, placeStoneBricks(random), 0, 2);
        world.setBlock(i + 43, j + 6, k + 18, placeStoneBricks(random), 0, 2);
        world.setBlock(i + 44, j + 6, k + 18, placeStoneBricks(random), 0, 2);
        world.setBlock(i + 45, j + 6, k + 18, placeStoneBricks(random), 0, 2);
        world.setBlock(i + 46, j + 6, k + 18, placeStoneBricks(random), 0, 2);
        world.setBlock(i + 47, j + 6, k + 18, placeStoneBricks(random), 0, 2);
        world.setBlock(i + 48, j + 6, k + 18, NovaCraftBlocks.carved_vanite_bricks, 0, 2);
        world.setBlock(i + 21, j + 6, k + 19, NovaCraftBlocks.glowing_carved_vanite_bricks, 0, 2);
        world.setBlock(i + 22, j + 6, k + 19, placeStoneBricks(random), 0, 2);
        world.setBlock(i + 23, j + 6, k + 19, placeStoneBricks(random), 0, 2);
        world.setBlock(i + 24, j + 6, k + 19, placeStoneBricks(random), 0, 2);
        world.setBlock(i + 25, j + 6, k + 19, NovaCraftBlocks.sculk_block, 0, 2);
        world.setBlock(i + 26, j + 6, k + 19, placeStoneBricks(random), 0, 2);
        world.setBlock(i + 27, j + 6, k + 19, placeStoneBricks(random), 0, 2);
        world.setBlock(i + 28, j + 6, k + 19, placeStoneBricks(random), 0, 2);
        world.setBlock(i + 29, j + 6, k + 19, placeStoneBricks(random), 0, 2);
        world.setBlock(i + 30, j + 6, k + 19, placeStoneBricks(random), 0, 2);
        world.setBlock(i + 31, j + 6, k + 19, NovaCraftBlocks.sculk_block, 0, 2);
        world.setBlock(i + 32, j + 6, k + 19, placeStoneBricks(random), 0, 2);
        world.setBlock(i + 33, j + 6, k + 19, NovaCraftBlocks.carved_vanite_bricks, 0, 2);
        world.setBlock(i + 34, j + 6, k + 19, NovaCraftBlocks.nullstone_bricks, 0, 2);
        world.setBlock(i + 35, j + 6, k + 19, NovaCraftBlocks.nullstone_bricks, 0, 2);
        world.setBlock(i + 36, j + 6, k + 19, NovaCraftBlocks.nullstone_bricks, 0, 2);
        world.setBlock(i + 37, j + 6, k + 19, NovaCraftBlocks.carved_vanite_bricks, 0, 2);
        world.setBlock(i + 38, j + 6, k + 19, NovaCraftBlocks.sculk_block, 0, 2);
        world.setBlock(i + 39, j + 6, k + 19, NovaCraftBlocks.sculk_block, 0, 2);
        world.setBlock(i + 40, j + 6, k + 19, NovaCraftBlocks.sculk_block, 0, 2);
        world.setBlock(i + 41, j + 6, k + 19, placeStoneBricks(random), 0, 2);
        world.setBlock(i + 42, j + 6, k + 19, placeStoneBricks(random), 0, 2);
        world.setBlock(i + 43, j + 6, k + 19, placeStoneBricks(random), 0, 2);
        world.setBlock(i + 44, j + 6, k + 19, placeStoneBricks(random), 0, 2);
        world.setBlock(i + 45, j + 6, k + 19, placeStoneBricks(random), 0, 2);
        world.setBlock(i + 46, j + 6, k + 19, placeStoneBricks(random), 0, 2);
        world.setBlock(i + 47, j + 6, k + 19, NovaCraftBlocks.sculk_block, 0, 2);
        world.setBlock(i + 48, j + 6, k + 19, placeStoneBricks(random), 0, 2);
        world.setBlock(i + 49, j + 6, k + 19, NovaCraftBlocks.glowing_carved_vanite_bricks, 0, 2);
        world.setBlock(i + 21, j + 6, k + 20, NovaCraftBlocks.carved_vanite_bricks, 0, 2);
        world.setBlock(i + 22, j + 6, k + 20, placeStoneBricks(random), 0, 2);
        world.setBlock(i + 23, j + 6, k + 20, placeStoneBricks(random), 0, 2);
        world.setBlock(i + 24, j + 6, k + 20, placeStoneBricks(random), 0, 2);
        world.setBlock(i + 25, j + 6, k + 20, placeStoneBricks(random), 0, 2);
        world.setBlock(i + 26, j + 6, k + 20, placeStoneBricks(random), 0, 2);
        world.setBlock(i + 27, j + 6, k + 20, placeStoneBricks(random), 0, 2);
        world.setBlock(i + 28, j + 6, k + 20, placeStoneBricks(random), 0, 2);
        world.setBlock(i + 29, j + 6, k + 20, placeStoneBricks(random), 0, 2);
        world.setBlock(i + 30, j + 6, k + 20, placeStoneBricks(random), 0, 2);
        world.setBlock(i + 31, j + 6, k + 20, NovaCraftBlocks.sculk_block, 0, 2);
        world.setBlock(i + 32, j + 6, k + 20, NovaCraftBlocks.sculk_block, 0, 2);
        world.setBlock(i + 33, j + 6, k + 20, NovaCraftBlocks.carved_vanite_bricks, 0, 2);
        world.setBlock(i + 34, j + 6, k + 20, NovaCraftBlocks.nullstone_bricks, 0, 2);
        world.setBlock(i + 35, j + 6, k + 20, NovaCraftBlocks.nullstone_bricks, 0, 2);
        world.setBlock(i + 36, j + 6, k + 20, NovaCraftBlocks.nullstone_bricks, 0, 2);
        world.setBlock(i + 37, j + 6, k + 20, NovaCraftBlocks.carved_vanite_bricks, 0, 2);
        world.setBlock(i + 38, j + 6, k + 20, placeStoneBricks(random), 0, 2);
        world.setBlock(i + 39, j + 6, k + 20, NovaCraftBlocks.sculk_block, 0, 2);
        world.setBlock(i + 40, j + 6, k + 20, placeStoneBricks(random), 0, 2);
        world.setBlock(i + 41, j + 6, k + 20, placeStoneBricks(random), 0, 2);
        world.setBlock(i + 42, j + 6, k + 20, placeStoneBricks(random), 0, 2);
        world.setBlock(i + 43, j + 6, k + 20, placeStoneBricks(random), 0, 2);
        world.setBlock(i + 44, j + 6, k + 20, placeStoneBricks(random), 0, 2);
        world.setBlock(i + 45, j + 6, k + 20, NovaCraftBlocks.sculk_block, 0, 2);
        world.setBlock(i + 46, j + 6, k + 20, NovaCraftBlocks.sculk_block, 0, 2);
        world.setBlock(i + 47, j + 6, k + 20, placeStoneBricks(random), 0, 2);
        world.setBlock(i + 48, j + 6, k + 20, placeStoneBricks(random), 0, 2);
        world.setBlock(i + 49, j + 6, k + 20, NovaCraftBlocks.carved_vanite_bricks, 0, 2);
        world.setBlock(i + 21, j + 6, k + 21, NovaCraftBlocks.carved_vanite_bricks, 0, 2);
        world.setBlock(i + 22, j + 6, k + 21, NovaCraftBlocks.sculk_block, 0, 2);
        world.setBlock(i + 23, j + 6, k + 21, placeStoneBricks(random), 0, 2);
        world.setBlock(i + 24, j + 6, k + 21, placeStoneBricks(random), 0, 2);
        world.setBlock(i + 25, j + 6, k + 21, placeStoneBricks(random), 0, 2);
        world.setBlock(i + 26, j + 6, k + 21, NovaCraftBlocks.sculk_block, 0, 2);
        world.setBlock(i + 27, j + 6, k + 21, placeStoneBricks(random), 0, 2);
        world.setBlock(i + 28, j + 6, k + 21, placeStoneBricks(random), 0, 2);
        world.setBlock(i + 29, j + 6, k + 21, placeStoneBricks(random), 0, 2);
        world.setBlock(i + 30, j + 6, k + 21, placeStoneBricks(random), 0, 2);
        world.setBlock(i + 31, j + 6, k + 21, NovaCraftBlocks.carved_vanite_bricks, 0, 2);
        world.setBlock(i + 32, j + 6, k + 21, NovaCraftBlocks.carved_vanite_bricks, 0, 2);
        world.setBlock(i + 33, j + 6, k + 21, NovaCraftBlocks.nullstone_bricks, 0, 2);
        world.setBlock(i + 34, j + 6, k + 21, NovaCraftBlocks.nullstone_bricks, 0, 2);
        world.setBlock(i + 35, j + 6, k + 21, NovaCraftBlocks.nullstone_bricks, 0, 2);
        world.setBlock(i + 36, j + 6, k + 21, NovaCraftBlocks.nullstone_bricks, 0, 2);
        world.setBlock(i + 37, j + 6, k + 21, NovaCraftBlocks.nullstone_bricks, 0, 2);
        world.setBlock(i + 38, j + 6, k + 21, NovaCraftBlocks.carved_vanite_bricks, 0, 2);
        world.setBlock(i + 39, j + 6, k + 21, NovaCraftBlocks.carved_vanite_bricks, 0, 2);
        world.setBlock(i + 40, j + 6, k + 21, placeStoneBricks(random), 0, 2);
        world.setBlock(i + 41, j + 6, k + 21, placeStoneBricks(random), 0, 2);
        world.setBlock(i + 42, j + 6, k + 21, placeStoneBricks(random), 0, 2);
        world.setBlock(i + 43, j + 6, k + 21, placeStoneBricks(random), 0, 2);
        world.setBlock(i + 44, j + 6, k + 21, NovaCraftBlocks.sculk_block, 0, 2);
        world.setBlock(i + 45, j + 6, k + 21, placeStoneBricks(random), 0, 2);
        world.setBlock(i + 46, j + 6, k + 21, placeStoneBricks(random), 0, 2);
        world.setBlock(i + 47, j + 6, k + 21, placeStoneBricks(random), 0, 2);
        world.setBlock(i + 48, j + 6, k + 21, placeStoneBricks(random), 0, 2);
        world.setBlock(i + 49, j + 6, k + 21, NovaCraftBlocks.carved_vanite_bricks, 0, 2);
        world.setBlock(i + 21, j + 6, k + 22, NovaCraftBlocks.carved_vanite_bricks, 0, 2);
        world.setBlock(i + 22, j + 6, k + 22, placeStoneBricks(random), 0, 2);
        world.setBlock(i + 23, j + 6, k + 22, NovaCraftBlocks.sculk_block, 0, 2);
        world.setBlock(i + 24, j + 6, k + 22, NovaCraftBlocks.sculk_block, 0, 2);
        world.setBlock(i + 25, j + 6, k + 22, placeStoneBricks(random), 0, 2);
        world.setBlock(i + 26, j + 6, k + 22, placeStoneBricks(random), 0, 2);
        world.setBlock(i + 27, j + 6, k + 22, NovaCraftBlocks.sculk_block, 0, 2);
        world.setBlock(i + 28, j + 6, k + 22, placeStoneBricks(random), 0, 2);
        world.setBlock(i + 29, j + 6, k + 22, NovaCraftBlocks.sculk_block, 0, 2);
        world.setBlock(i + 30, j + 6, k + 22, NovaCraftBlocks.carved_vanite_bricks, 0, 2);
        world.setBlock(i + 31, j + 6, k + 22, NovaCraftBlocks.nullstone_bricks, 0, 2);
        world.setBlock(i + 32, j + 6, k + 22, NovaCraftBlocks.nullstone_bricks, 0, 2);
        world.setBlock(i + 33, j + 6, k + 22, NovaCraftBlocks.nullstone_bricks, 0, 2);
        world.setBlock(i + 34, j + 6, k + 22, NovaCraftBlocks.nullstone_bricks, 0, 2);
        world.setBlock(i + 35, j + 6, k + 22, NovaCraftBlocks.nullstone_bricks, 0, 2);
        world.setBlock(i + 36, j + 6, k + 22, NovaCraftBlocks.nullstone_bricks, 0, 2);
        world.setBlock(i + 37, j + 6, k + 22, NovaCraftBlocks.nullstone_bricks, 0, 2);
        world.setBlock(i + 38, j + 6, k + 22, NovaCraftBlocks.nullstone_bricks, 0, 2);
        world.setBlock(i + 39, j + 6, k + 22, NovaCraftBlocks.nullstone_bricks, 0, 2);
        world.setBlock(i + 40, j + 6, k + 22, NovaCraftBlocks.carved_vanite_bricks, 0, 2);
        world.setBlock(i + 41, j + 6, k + 22, placeStoneBricks(random), 0, 2);
        world.setBlock(i + 42, j + 6, k + 22, placeStoneBricks(random), 0, 2);
        world.setBlock(i + 43, j + 6, k + 22, NovaCraftBlocks.sculk_block, 0, 2);
        world.setBlock(i + 44, j + 6, k + 22, NovaCraftBlocks.sculk_block, 0, 2);
        world.setBlock(i + 45, j + 6, k + 22, placeStoneBricks(random), 0, 2);
        world.setBlock(i + 46, j + 6, k + 22, placeStoneBricks(random), 0, 2);
        world.setBlock(i + 47, j + 6, k + 22, placeStoneBricks(random), 0, 2);
        world.setBlock(i + 48, j + 6, k + 22, placeStoneBricks(random), 0, 2);
        world.setBlock(i + 49, j + 6, k + 22, NovaCraftBlocks.carved_vanite_bricks, 0, 2);
        world.setBlock(i + 21, j + 6, k + 23, NovaCraftBlocks.carved_vanite_bricks, 0, 2);
        world.setBlock(i + 22, j + 6, k + 23, placeStoneBricks(random), 0, 2);
        world.setBlock(i + 23, j + 6, k + 23, placeStoneBricks(random), 0, 2);
        world.setBlock(i + 24, j + 6, k + 23, placeStoneBricks(random), 0, 2);
        world.setBlock(i + 25, j + 6, k + 23, placeStoneBricks(random), 0, 2);
        world.setBlock(i + 26, j + 6, k + 23, NovaCraftBlocks.sculk_block, 0, 2);
        world.setBlock(i + 27, j + 6, k + 23, NovaCraftBlocks.sculk_block, 0, 2);
        world.setBlock(i + 28, j + 6, k + 23, placeStoneBricks(random), 0, 2);
        world.setBlock(i + 29, j + 6, k + 23, NovaCraftBlocks.carved_vanite_bricks, 0, 2);
        world.setBlock(i + 30, j + 6, k + 23, NovaCraftBlocks.nullstone_bricks, 0, 2);
        world.setBlock(i + 31, j + 6, k + 23, NovaCraftBlocks.nullstone_bricks, 0, 2);
        world.setBlock(i + 32, j + 6, k + 23, NovaCraftBlocks.nullstone_bricks, 0, 2);
        world.setBlock(i + 33, j + 6, k + 23, NovaCraftBlocks.nullstone_bricks, 0, 2);
        world.setBlock(i + 34, j + 6, k + 23, NovaCraftBlocks.nullstone_bricks, 0, 2);
        world.setBlock(i + 35, j + 6, k + 23, NovaCraftBlocks.nullstone_bricks, 0, 2);
        world.setBlock(i + 36, j + 6, k + 23, NovaCraftBlocks.nullstone_bricks, 0, 2);
        world.setBlock(i + 37, j + 6, k + 23, NovaCraftBlocks.nullstone_bricks, 0, 2);
        world.setBlock(i + 38, j + 6, k + 23, NovaCraftBlocks.nullstone_bricks, 0, 2);
        world.setBlock(i + 39, j + 6, k + 23, NovaCraftBlocks.nullstone_bricks, 0, 2);
        world.setBlock(i + 40, j + 6, k + 23, NovaCraftBlocks.nullstone_bricks, 0, 2);
        world.setBlock(i + 41, j + 6, k + 23, NovaCraftBlocks.carved_vanite_bricks, 0, 2);
        world.setBlock(i + 42, j + 6, k + 23, NovaCraftBlocks.sculk_block, 0, 2);
        world.setBlock(i + 43, j + 6, k + 23, placeStoneBricks(random), 0, 2);
        world.setBlock(i + 44, j + 6, k + 23, NovaCraftBlocks.sculk_block, 0, 2);
        world.setBlock(i + 45, j + 6, k + 23, NovaCraftBlocks.sculk_block, 0, 2);
        world.setBlock(i + 46, j + 6, k + 23, NovaCraftBlocks.sculk_block, 0, 2);
        world.setBlock(i + 47, j + 6, k + 23, NovaCraftBlocks.sculk_block, 0, 2);
        world.setBlock(i + 48, j + 6, k + 23, placeStoneBricks(random), 0, 2);
        world.setBlock(i + 49, j + 6, k + 23, NovaCraftBlocks.carved_vanite_bricks, 0, 2);
        world.setBlock(i + 21, j + 6, k + 24, NovaCraftBlocks.carved_vanite_bricks, 0, 2);
        world.setBlock(i + 22, j + 6, k + 24, placeStoneBricks(random), 0, 2);
        world.setBlock(i + 23, j + 6, k + 24, placeStoneBricks(random), 0, 2);
        world.setBlock(i + 24, j + 6, k + 24, placeStoneBricks(random), 0, 2);
        world.setBlock(i + 25, j + 6, k + 24, placeStoneBricks(random), 0, 2);
        world.setBlock(i + 26, j + 6, k + 24, placeStoneBricks(random), 0, 2);
        world.setBlock(i + 27, j + 6, k + 24, placeStoneBricks(random), 0, 2);
        world.setBlock(i + 28, j + 6, k + 24, NovaCraftBlocks.carved_vanite_bricks, 0, 2);
        world.setBlock(i + 29, j + 6, k + 24, NovaCraftBlocks.nullstone_bricks, 0, 2);
        world.setBlock(i + 30, j + 6, k + 24, NovaCraftBlocks.nullstone_bricks, 0, 2);
        world.setBlock(i + 31, j + 6, k + 24, NovaCraftBlocks.nullstone_bricks, 0, 2);
        world.setBlock(i + 32, j + 6, k + 24, placeStoneBricks(random), 0, 2);
        world.setBlock(i + 33, j + 6, k + 24, placeStoneBricks(random), 0, 2);
        world.setBlock(i + 34, j + 6, k + 24, placeStoneBricks(random), 0, 2);
        world.setBlock(i + 35, j + 6, k + 24, placeStoneBricks(random), 0, 2);
        world.setBlock(i + 36, j + 6, k + 24, placeStoneBricks(random), 0, 2);
        world.setBlock(i + 37, j + 6, k + 24, placeStoneBricks(random), 0, 2);
        world.setBlock(i + 38, j + 6, k + 24, placeStoneBricks(random), 0, 2);
        world.setBlock(i + 39, j + 6, k + 24, placeStoneBricks(random), 0, 2);
        world.setBlock(i + 40, j + 6, k + 24, NovaCraftBlocks.nullstone_bricks, 0, 2);
        world.setBlock(i + 41, j + 6, k + 24, NovaCraftBlocks.nullstone_bricks, 0, 2);
        world.setBlock(i + 42, j + 6, k + 24, NovaCraftBlocks.carved_vanite_bricks, 0, 2);
        world.setBlock(i + 43, j + 6, k + 24, placeStoneBricks(random), 0, 2);
        world.setBlock(i + 44, j + 6, k + 24, NovaCraftBlocks.sculk_block, 0, 2);
        world.setBlock(i + 45, j + 6, k + 24, placeStoneBricks(random), 0, 2);
        world.setBlock(i + 46, j + 6, k + 24, placeStoneBricks(random), 0, 2);
        world.setBlock(i + 47, j + 6, k + 24, placeStoneBricks(random), 0, 2);
        world.setBlock(i + 48, j + 6, k + 24, NovaCraftBlocks.sculk_block, 0, 2);
        world.setBlock(i + 49, j + 6, k + 24, NovaCraftBlocks.carved_vanite_bricks, 0, 2);
        world.setBlock(i + 21, j + 6, k + 25, NovaCraftBlocks.carved_vanite_bricks, 0, 2);
        world.setBlock(i + 22, j + 6, k + 25, placeStoneBricks(random), 0, 2);
        world.setBlock(i + 23, j + 6, k + 25, placeStoneBricks(random), 0, 2);
        world.setBlock(i + 24, j + 6, k + 25, placeStoneBricks(random), 0, 2);
        world.setBlock(i + 25, j + 6, k + 25, placeStoneBricks(random), 0, 2);
        world.setBlock(i + 26, j + 6, k + 25, placeStoneBricks(random), 0, 2);
        world.setBlock(i + 27, j + 6, k + 25, placeStoneBricks(random), 0, 2);
        world.setBlock(i + 28, j + 6, k + 25, NovaCraftBlocks.carved_vanite_bricks, 0, 2);
        world.setBlock(i + 29, j + 6, k + 25, NovaCraftBlocks.nullstone_bricks, 0, 2);
        world.setBlock(i + 30, j + 6, k + 25, NovaCraftBlocks.nullstone_bricks, 0, 2);
        world.setBlock(i + 31, j + 6, k + 25, placeStoneBricks(random), 0, 2);
        world.setBlock(i + 32, j + 6, k + 25, placeStoneBricks(random), 0, 2);
        world.setBlock(i + 33, j + 6, k + 25, placeStoneBricks(random), 0, 2);
        world.setBlock(i + 34, j + 6, k + 25, placeStoneBricks(random), 0, 2);
        world.setBlock(i + 35, j + 6, k + 25, placeStoneBricks(random), 0, 2);
        world.setBlock(i + 36, j + 6, k + 25, placeStoneBricks(random), 0, 2);
        world.setBlock(i + 37, j + 6, k + 25, placeStoneBricks(random), 0, 2);
        world.setBlock(i + 38, j + 6, k + 25, placeStoneBricks(random), 0, 2);
        world.setBlock(i + 39, j + 6, k + 25, placeStoneBricks(random), 0, 2);
        world.setBlock(i + 40, j + 6, k + 25, NovaCraftBlocks.nullstone_bricks, 0, 2);
        world.setBlock(i + 41, j + 6, k + 25, NovaCraftBlocks.nullstone_bricks, 0, 2);
        world.setBlock(i + 42, j + 6, k + 25, NovaCraftBlocks.carved_vanite_bricks, 0, 2);
        world.setBlock(i + 43, j + 6, k + 25, NovaCraftBlocks.sculk_block, 0, 2);
        world.setBlock(i + 44, j + 6, k + 25, NovaCraftBlocks.sculk_block, 0, 2);
        world.setBlock(i + 45, j + 6, k + 25, NovaCraftBlocks.sculk_block, 0, 2);
        world.setBlock(i + 46, j + 6, k + 25, placeStoneBricks(random), 0, 2);
        world.setBlock(i + 47, j + 6, k + 25, placeStoneBricks(random), 0, 2);
        world.setBlock(i + 48, j + 6, k + 25, placeStoneBricks(random), 0, 2);
        world.setBlock(i + 49, j + 6, k + 25, NovaCraftBlocks.carved_vanite_bricks, 0, 2);
        world.setBlock(i + 21, j + 6, k + 26, NovaCraftBlocks.carved_vanite_bricks, 0, 2);
        world.setBlock(i + 22, j + 6, k + 26, NovaCraftBlocks.carved_vanite_bricks, 0, 2);
        world.setBlock(i + 23, j + 6, k + 26, NovaCraftBlocks.carved_vanite_bricks, 0, 2);
        world.setBlock(i + 24, j + 6, k + 26, NovaCraftBlocks.carved_vanite_bricks, 0, 2);
        world.setBlock(i + 25, j + 6, k + 26, NovaCraftBlocks.carved_vanite_bricks, 0, 2);
        world.setBlock(i + 26, j + 6, k + 26, NovaCraftBlocks.carved_vanite_bricks, 0, 2);
        world.setBlock(i + 27, j + 6, k + 26, NovaCraftBlocks.carved_vanite_bricks, 0, 2);
        world.setBlock(i + 28, j + 6, k + 26, NovaCraftBlocks.nullstone_bricks, 0, 2);
        world.setBlock(i + 29, j + 6, k + 26, NovaCraftBlocks.nullstone_bricks, 0, 2);
        world.setBlock(i + 30, j + 6, k + 26, NovaCraftBlocks.nullstone_bricks, 0, 2);
        world.setBlock(i + 31, j + 6, k + 26, placeStoneBricks(random), 0, 2);
        world.setBlock(i + 32, j + 6, k + 26, placeStoneBricks(random), 0, 2);
        world.setBlock(i + 33, j + 6, k + 26, placeStoneBricks(random), 0, 2);
        world.setBlock(i + 34, j + 6, k + 26, placeStoneBricks(random), 0, 2);
        world.setBlock(i + 35, j + 6, k + 26, placeStoneBricks(random), 0, 2);
        world.setBlock(i + 36, j + 6, k + 26, placeStoneBricks(random), 0, 2);
        world.setBlock(i + 37, j + 6, k + 26, placeStoneBricks(random), 0, 2);
        world.setBlock(i + 38, j + 6, k + 26, placeStoneBricks(random), 0, 2);
        world.setBlock(i + 39, j + 6, k + 26, placeStoneBricks(random), 0, 2);
        world.setBlock(i + 40, j + 6, k + 26, NovaCraftBlocks.nullstone_bricks, 0, 2);
        world.setBlock(i + 41, j + 6, k + 26, NovaCraftBlocks.nullstone_bricks, 0, 2);
        world.setBlock(i + 42, j + 6, k + 26, NovaCraftBlocks.nullstone_bricks, 0, 2);
        world.setBlock(i + 43, j + 6, k + 26, NovaCraftBlocks.carved_vanite_bricks, 0, 2);
        world.setBlock(i + 44, j + 6, k + 26, NovaCraftBlocks.carved_vanite_bricks, 0, 2);
        world.setBlock(i + 45, j + 6, k + 26, NovaCraftBlocks.carved_vanite_bricks, 0, 2);
        world.setBlock(i + 46, j + 6, k + 26, NovaCraftBlocks.carved_vanite_bricks, 0, 2);
        world.setBlock(i + 47, j + 6, k + 26, NovaCraftBlocks.carved_vanite_bricks, 0, 2);
        world.setBlock(i + 48, j + 6, k + 26, NovaCraftBlocks.carved_vanite_bricks, 0, 2);
        world.setBlock(i + 49, j + 6, k + 26, NovaCraftBlocks.carved_vanite_bricks, 0, 2);
        world.setBlock(i + 50, j + 6, k + 26, NovaCraftBlocks.sculk_block, 0, 2);
        world.setBlock(i + 51, j + 6, k + 26, placeStoneBricks(random), 0, 2);
        world.setBlock(i + 52, j + 6, k + 26, NovaCraftBlocks.nullstone_brick_wall, 0, 2);
        world.setBlock(i + 53, j + 6, k + 26, NovaCraftBlocks.nullstone_brick_wall, 0, 2);
        world.setBlock(i + 54, j + 6, k + 26, NovaCraftBlocks.nullstone_brick_wall, 0, 2);
        world.setBlock(i + 20, j + 6, k + 27, placeStoneBricks(random), 0, 2);
        world.setBlock(i + 21, j + 6, k + 27, NovaCraftBlocks.nullstone_bricks, 0, 2);
        world.setBlock(i + 22, j + 6, k + 27, NovaCraftBlocks.nullstone_bricks, 0, 2);
        world.setBlock(i + 23, j + 6, k + 27, NovaCraftBlocks.nullstone_bricks, 0, 2);
        world.setBlock(i + 24, j + 6, k + 27, NovaCraftBlocks.nullstone_bricks, 0, 2);
        world.setBlock(i + 25, j + 6, k + 27, NovaCraftBlocks.nullstone_bricks, 0, 2);
        world.setBlock(i + 26, j + 6, k + 27, NovaCraftBlocks.nullstone_bricks, 0, 2);
        world.setBlock(i + 27, j + 6, k + 27, NovaCraftBlocks.nullstone_bricks, 0, 2);
        world.setBlock(i + 28, j + 6, k + 27, NovaCraftBlocks.nullstone_bricks, 0, 2);
        world.setBlock(i + 29, j + 6, k + 27, NovaCraftBlocks.nullstone_bricks, 0, 2);
        world.setBlock(i + 30, j + 6, k + 27, NovaCraftBlocks.nullstone_bricks, 0, 2);
        world.setBlock(i + 31, j + 6, k + 27, placeStoneBricks(random), 0, 2);
        world.setBlock(i + 32, j + 6, k + 27, placeStoneBricks(random), 0, 2);
        world.setBlock(i + 33, j + 6, k + 27, placeStoneBricks(random), 0, 2);
        world.setBlock(i + 34, j + 6, k + 27, placeStoneBricks(random), 0, 2);
        world.setBlock(i + 35, j + 6, k + 27, placeStoneBricks(random), 0, 2);
        world.setBlock(i + 36, j + 6, k + 27, placeStoneBricks(random), 0, 2);
        world.setBlock(i + 37, j + 6, k + 27, placeStoneBricks(random), 0, 2);
        world.setBlock(i + 38, j + 6, k + 27, placeStoneBricks(random), 0, 2);
        world.setBlock(i + 39, j + 6, k + 27, placeStoneBricks(random), 0, 2);
        world.setBlock(i + 40, j + 6, k + 27, NovaCraftBlocks.nullstone_bricks, 0, 2);
        world.setBlock(i + 41, j + 6, k + 27, NovaCraftBlocks.nullstone_bricks, 0, 2);
        world.setBlock(i + 42, j + 6, k + 27, NovaCraftBlocks.nullstone_bricks, 0, 2);
        world.setBlock(i + 43, j + 6, k + 27, NovaCraftBlocks.nullstone_bricks, 0, 2);
        world.setBlock(i + 44, j + 6, k + 27, NovaCraftBlocks.nullstone_bricks, 0, 2);
        world.setBlock(i + 45, j + 6, k + 27, NovaCraftBlocks.nullstone_bricks, 0, 2);
        world.setBlock(i + 46, j + 6, k + 27, NovaCraftBlocks.nullstone_bricks, 0, 2);
        world.setBlock(i + 47, j + 6, k + 27, NovaCraftBlocks.nullstone_bricks, 0, 2);
        world.setBlock(i + 48, j + 6, k + 27, NovaCraftBlocks.nullstone_bricks, 0, 2);
        world.setBlock(i + 49, j + 6, k + 27, NovaCraftBlocks.nullstone_bricks, 0, 2);
        world.setBlock(i + 50, j + 6, k + 27, NovaCraftBlocks.nullstone_brick_stairs, 1, 2);
        world.setBlock(i + 20, j + 6, k + 28, placeStoneBricks(random), 0, 2);
        world.setBlock(i + 21, j + 6, k + 28, NovaCraftBlocks.nullstone_bricks, 0, 2);
        world.setBlock(i + 22, j + 6, k + 28, NovaCraftBlocks.nullstone_bricks, 0, 2);
        world.setBlock(i + 23, j + 6, k + 28, NovaCraftBlocks.nullstone_bricks, 0, 2);
        world.setBlock(i + 24, j + 6, k + 28, NovaCraftBlocks.nullstone_bricks, 0, 2);
        world.setBlock(i + 25, j + 6, k + 28, NovaCraftBlocks.nullstone_bricks, 0, 2);
        world.setBlock(i + 26, j + 6, k + 28, NovaCraftBlocks.nullstone_bricks, 0, 2);
        world.setBlock(i + 27, j + 6, k + 28, NovaCraftBlocks.nullstone_bricks, 0, 2);
        world.setBlock(i + 28, j + 6, k + 28, NovaCraftBlocks.nullstone_bricks, 0, 2);
        world.setBlock(i + 29, j + 6, k + 28, NovaCraftBlocks.nullstone_bricks, 0, 2);
        world.setBlock(i + 30, j + 6, k + 28, NovaCraftBlocks.nullstone_bricks, 0, 2);
        world.setBlock(i + 31, j + 6, k + 28, placeStoneBricks(random), 0, 2);
        world.setBlock(i + 32, j + 6, k + 28, placeStoneBricks(random), 0, 2);
        world.setBlock(i + 33, j + 6, k + 28, placeStoneBricks(random), 0, 2);
        world.setBlock(i + 34, j + 6, k + 28, placeStoneBricks(random), 0, 2);
        world.setBlock(i + 35, j + 6, k + 28, placeStoneBricks(random), 0, 2);
        world.setBlock(i + 36, j + 6, k + 28, placeStoneBricks(random), 0, 2);
        world.setBlock(i + 37, j + 6, k + 28, placeStoneBricks(random), 0, 2);
        world.setBlock(i + 38, j + 6, k + 28, placeStoneBricks(random), 0, 2);
        world.setBlock(i + 39, j + 6, k + 28, placeStoneBricks(random), 0, 2);
        world.setBlock(i + 40, j + 6, k + 28, NovaCraftBlocks.nullstone_bricks, 0, 2);
        world.setBlock(i + 41, j + 6, k + 28, NovaCraftBlocks.nullstone_bricks, 0, 2);
        world.setBlock(i + 42, j + 6, k + 28, NovaCraftBlocks.nullstone_bricks, 0, 2);
        world.setBlock(i + 43, j + 6, k + 28, NovaCraftBlocks.nullstone_bricks, 0, 2);
        world.setBlock(i + 44, j + 6, k + 28, NovaCraftBlocks.nullstone_bricks, 0, 2);
        world.setBlock(i + 45, j + 6, k + 28, NovaCraftBlocks.nullstone_bricks, 0, 2);
        world.setBlock(i + 46, j + 6, k + 28, NovaCraftBlocks.nullstone_bricks, 0, 2);
        world.setBlock(i + 47, j + 6, k + 28, NovaCraftBlocks.nullstone_bricks, 0, 2);
        world.setBlock(i + 48, j + 6, k + 28, NovaCraftBlocks.nullstone_bricks, 0, 2);
        world.setBlock(i + 49, j + 6, k + 28, NovaCraftBlocks.nullstone_bricks, 0, 2);
        world.setBlock(i + 50, j + 6, k + 28, NovaCraftBlocks.nullstone_brick_stairs, 1, 2);
        world.setBlock(i + 20, j + 6, k + 29, placeStoneBricks(random), 0, 2);
        world.setBlock(i + 21, j + 6, k + 29, NovaCraftBlocks.nullstone_bricks, 0, 2);
        world.setBlock(i + 22, j + 6, k + 29, NovaCraftBlocks.nullstone_bricks, 0, 2);
        world.setBlock(i + 23, j + 6, k + 29, NovaCraftBlocks.nullstone_bricks, 0, 2);
        world.setBlock(i + 24, j + 6, k + 29, NovaCraftBlocks.nullstone_bricks, 0, 2);
        world.setBlock(i + 25, j + 6, k + 29, NovaCraftBlocks.nullstone_bricks, 0, 2);
        world.setBlock(i + 26, j + 6, k + 29, NovaCraftBlocks.nullstone_bricks, 0, 2);
        world.setBlock(i + 27, j + 6, k + 29, NovaCraftBlocks.nullstone_bricks, 0, 2);
        world.setBlock(i + 28, j + 6, k + 29, NovaCraftBlocks.nullstone_bricks, 0, 2);
        world.setBlock(i + 29, j + 6, k + 29, NovaCraftBlocks.nullstone_bricks, 0, 2);
        world.setBlock(i + 30, j + 6, k + 29, NovaCraftBlocks.nullstone_bricks, 0, 2);
        world.setBlock(i + 31, j + 6, k + 29, placeStoneBricks(random), 0, 2);
        world.setBlock(i + 32, j + 6, k + 29, placeStoneBricks(random), 0, 2);
        world.setBlock(i + 33, j + 6, k + 29, placeStoneBricks(random), 0, 2);
        world.setBlock(i + 34, j + 6, k + 29, placeStoneBricks(random), 0, 2);
        world.setBlock(i + 35, j + 6, k + 29, placeStoneBricks(random), 0, 2);
        world.setBlock(i + 36, j + 6, k + 29, placeStoneBricks(random), 0, 2);
        world.setBlock(i + 37, j + 6, k + 29, placeStoneBricks(random), 0, 2);
        world.setBlock(i + 38, j + 6, k + 29, placeStoneBricks(random), 0, 2);
        world.setBlock(i + 39, j + 6, k + 29, placeStoneBricks(random), 0, 2);
        world.setBlock(i + 40, j + 6, k + 29, NovaCraftBlocks.nullstone_bricks, 0, 2);
        world.setBlock(i + 41, j + 6, k + 29, NovaCraftBlocks.nullstone_bricks, 0, 2);
        world.setBlock(i + 42, j + 6, k + 29, NovaCraftBlocks.nullstone_bricks, 0, 2);
        world.setBlock(i + 43, j + 6, k + 29, NovaCraftBlocks.nullstone_bricks, 0, 2);
        world.setBlock(i + 44, j + 6, k + 29, NovaCraftBlocks.nullstone_bricks, 0, 2);
        world.setBlock(i + 45, j + 6, k + 29, NovaCraftBlocks.nullstone_bricks, 0, 2);
        world.setBlock(i + 46, j + 6, k + 29, NovaCraftBlocks.nullstone_bricks, 0, 2);
        world.setBlock(i + 47, j + 6, k + 29, NovaCraftBlocks.nullstone_bricks, 0, 2);
        world.setBlock(i + 48, j + 6, k + 29, NovaCraftBlocks.nullstone_bricks, 0, 2);
        world.setBlock(i + 49, j + 6, k + 29, NovaCraftBlocks.nullstone_bricks, 0, 2);
        world.setBlock(i + 50, j + 6, k + 29, NovaCraftBlocks.nullstone_brick_stairs, 1, 2);
        world.setBlock(i + 21, j + 6, k + 30, NovaCraftBlocks.carved_vanite_bricks, 0, 2);
        world.setBlock(i + 22, j + 6, k + 30, NovaCraftBlocks.carved_vanite_bricks, 0, 2);
        world.setBlock(i + 23, j + 6, k + 30, NovaCraftBlocks.carved_vanite_bricks, 0, 2);
        world.setBlock(i + 24, j + 6, k + 30, NovaCraftBlocks.carved_vanite_bricks, 0, 2);
        world.setBlock(i + 25, j + 6, k + 30, NovaCraftBlocks.carved_vanite_bricks, 0, 2);
        world.setBlock(i + 26, j + 6, k + 30, NovaCraftBlocks.carved_vanite_bricks, 0, 2);
        world.setBlock(i + 27, j + 6, k + 30, NovaCraftBlocks.carved_vanite_bricks, 0, 2);
        world.setBlock(i + 28, j + 6, k + 30, NovaCraftBlocks.nullstone_bricks, 0, 2);
        world.setBlock(i + 29, j + 6, k + 30, NovaCraftBlocks.nullstone_bricks, 0, 2);
        world.setBlock(i + 30, j + 6, k + 30, NovaCraftBlocks.nullstone_bricks, 0, 2);
        world.setBlock(i + 31, j + 6, k + 30, placeStoneBricks(random), 0, 2);
        world.setBlock(i + 32, j + 6, k + 30, placeStoneBricks(random), 0, 2);
        world.setBlock(i + 33, j + 6, k + 30, placeStoneBricks(random), 0, 2);
        world.setBlock(i + 34, j + 6, k + 30, placeStoneBricks(random), 0, 2);
        world.setBlock(i + 35, j + 6, k + 30, placeStoneBricks(random), 0, 2);
        world.setBlock(i + 36, j + 6, k + 30, placeStoneBricks(random), 0, 2);
        world.setBlock(i + 37, j + 6, k + 30, placeStoneBricks(random), 0, 2);
        world.setBlock(i + 38, j + 6, k + 30, placeStoneBricks(random), 0, 2);
        world.setBlock(i + 39, j + 6, k + 30, placeStoneBricks(random), 0, 2);
        world.setBlock(i + 40, j + 6, k + 30, NovaCraftBlocks.nullstone_bricks, 0, 2);
        world.setBlock(i + 41, j + 6, k + 30, NovaCraftBlocks.nullstone_bricks, 0, 2);
        world.setBlock(i + 42, j + 6, k + 30, NovaCraftBlocks.nullstone_bricks, 0, 2);
        world.setBlock(i + 43, j + 6, k + 30, NovaCraftBlocks.carved_vanite_bricks, 0, 2);
        world.setBlock(i + 44, j + 6, k + 30, NovaCraftBlocks.carved_vanite_bricks, 0, 2);
        world.setBlock(i + 45, j + 6, k + 30, NovaCraftBlocks.carved_vanite_bricks, 0, 2);
        world.setBlock(i + 46, j + 6, k + 30, NovaCraftBlocks.carved_vanite_bricks, 0, 2);
        world.setBlock(i + 47, j + 6, k + 30, NovaCraftBlocks.carved_vanite_bricks, 0, 2);
        world.setBlock(i + 48, j + 6, k + 30, NovaCraftBlocks.carved_vanite_bricks, 0, 2);
        world.setBlock(i + 49, j + 6, k + 30, NovaCraftBlocks.carved_vanite_bricks, 0, 2);
        world.setBlock(i + 50, j + 6, k + 30, placeStoneBricks(random), 0, 2);
        world.setBlock(i + 51, j + 6, k + 30, NovaCraftBlocks.sculk_block, 0, 2);
        world.setBlock(i + 52, j + 6, k + 30, NovaCraftBlocks.nullstone_brick_wall, 0, 2);
        world.setBlock(i + 53, j + 6, k + 30, NovaCraftBlocks.nullstone_brick_wall, 0, 2);
        world.setBlock(i + 54, j + 6, k + 30, NovaCraftBlocks.nullstone_brick_wall, 0, 2);
        world.setBlock(i + 21, j + 6, k + 31, NovaCraftBlocks.carved_vanite_bricks, 0, 2);
        world.setBlock(i + 22, j + 6, k + 31, placeStoneBricks(random), 0, 2);
        world.setBlock(i + 23, j + 6, k + 31, placeStoneBricks(random), 0, 2);
        world.setBlock(i + 24, j + 6, k + 31, placeStoneBricks(random), 0, 2);
        world.setBlock(i + 25, j + 6, k + 31, placeStoneBricks(random), 0, 2);
        world.setBlock(i + 26, j + 6, k + 31, placeStoneBricks(random), 0, 2);
        world.setBlock(i + 27, j + 6, k + 31, placeStoneBricks(random), 0, 2);
        world.setBlock(i + 28, j + 6, k + 31, NovaCraftBlocks.carved_vanite_bricks, 0, 2);
        world.setBlock(i + 29, j + 6, k + 31, NovaCraftBlocks.nullstone_bricks, 0, 2);
        world.setBlock(i + 30, j + 6, k + 31, NovaCraftBlocks.nullstone_bricks, 0, 2);
        world.setBlock(i + 31, j + 6, k + 31, placeStoneBricks(random), 0, 2);
        world.setBlock(i + 32, j + 6, k + 31, placeStoneBricks(random), 0, 2);
        world.setBlock(i + 33, j + 6, k + 31, placeStoneBricks(random), 0, 2);
        world.setBlock(i + 34, j + 6, k + 31, placeStoneBricks(random), 0, 2);
        world.setBlock(i + 35, j + 6, k + 31, placeStoneBricks(random), 0, 2);
        world.setBlock(i + 36, j + 6, k + 31, placeStoneBricks(random), 0, 2);
        world.setBlock(i + 37, j + 6, k + 31, placeStoneBricks(random), 0, 2);
        world.setBlock(i + 38, j + 6, k + 31, placeStoneBricks(random), 0, 2);
        world.setBlock(i + 39, j + 6, k + 31, placeStoneBricks(random), 0, 2);
        world.setBlock(i + 40, j + 6, k + 31, NovaCraftBlocks.nullstone_bricks, 0, 2);
        world.setBlock(i + 41, j + 6, k + 31, NovaCraftBlocks.nullstone_bricks, 0, 2);
        world.setBlock(i + 42, j + 6, k + 31, NovaCraftBlocks.carved_vanite_bricks, 0, 2);
        world.setBlock(i + 43, j + 6, k + 31, placeStoneBricks(random), 0, 2);
        world.setBlock(i + 44, j + 6, k + 31, placeStoneBricks(random), 0, 2);
        world.setBlock(i + 45, j + 6, k + 31, placeStoneBricks(random), 0, 2);
        world.setBlock(i + 46, j + 6, k + 31, placeStoneBricks(random), 0, 2);
        world.setBlock(i + 47, j + 6, k + 31, NovaCraftBlocks.sculk_block, 0, 2);
        world.setBlock(i + 48, j + 6, k + 31, placeStoneBricks(random), 0, 2);
        world.setBlock(i + 49, j + 6, k + 31, NovaCraftBlocks.carved_vanite_bricks, 0, 2);
        world.setBlock(i + 21, j + 6, k + 32, NovaCraftBlocks.carved_vanite_bricks, 0, 2);
        world.setBlock(i + 22, j + 6, k + 32, placeStoneBricks(random), 0, 2);
        world.setBlock(i + 23, j + 6, k + 32, placeStoneBricks(random), 0, 2);
        world.setBlock(i + 24, j + 6, k + 32, placeStoneBricks(random), 0, 2);
        world.setBlock(i + 25, j + 6, k + 32, placeStoneBricks(random), 0, 2);
        world.setBlock(i + 26, j + 6, k + 32, placeStoneBricks(random), 0, 2);
        world.setBlock(i + 27, j + 6, k + 32, placeStoneBricks(random), 0, 2);
        world.setBlock(i + 28, j + 6, k + 32, NovaCraftBlocks.carved_vanite_bricks, 0, 2);
        world.setBlock(i + 29, j + 6, k + 32, NovaCraftBlocks.nullstone_bricks, 0, 2);
        world.setBlock(i + 30, j + 6, k + 32, NovaCraftBlocks.nullstone_bricks, 0, 2);
        world.setBlock(i + 31, j + 6, k + 32, NovaCraftBlocks.nullstone_bricks, 0, 2);
        world.setBlock(i + 32, j + 6, k + 32, placeStoneBricks(random), 0, 2);
        world.setBlock(i + 33, j + 6, k + 32, placeStoneBricks(random), 0, 2);
        world.setBlock(i + 34, j + 6, k + 32, placeStoneBricks(random), 0, 2);
        world.setBlock(i + 35, j + 6, k + 32, placeStoneBricks(random), 0, 2);
        world.setBlock(i + 36, j + 6, k + 32, placeStoneBricks(random), 0, 2);
        world.setBlock(i + 37, j + 6, k + 32, placeStoneBricks(random), 0, 2);
        world.setBlock(i + 38, j + 6, k + 32, placeStoneBricks(random), 0, 2);
        world.setBlock(i + 39, j + 6, k + 32, NovaCraftBlocks.nullstone_bricks, 0, 2);
        world.setBlock(i + 40, j + 6, k + 32, NovaCraftBlocks.nullstone_bricks, 0, 2);
        world.setBlock(i + 41, j + 6, k + 32, NovaCraftBlocks.nullstone_bricks, 0, 2);
        world.setBlock(i + 42, j + 6, k + 32, NovaCraftBlocks.carved_vanite_bricks, 0, 2);
        world.setBlock(i + 43, j + 6, k + 32, placeStoneBricks(random), 0, 2);
        world.setBlock(i + 44, j + 6, k + 32, placeStoneBricks(random), 0, 2);
        world.setBlock(i + 45, j + 6, k + 32, placeStoneBricks(random), 0, 2);
        world.setBlock(i + 46, j + 6, k + 32, NovaCraftBlocks.sculk_block, 0, 2);
        world.setBlock(i + 47, j + 6, k + 32, placeStoneBricks(random), 0, 2);
        world.setBlock(i + 48, j + 6, k + 32, placeStoneBricks(random), 0, 2);
        world.setBlock(i + 49, j + 6, k + 32, NovaCraftBlocks.carved_vanite_bricks, 0, 2);
        world.setBlock(i + 21, j + 6, k + 33, NovaCraftBlocks.carved_vanite_bricks, 0, 2);
        world.setBlock(i + 22, j + 6, k + 33, placeStoneBricks(random), 0, 2);
        world.setBlock(i + 23, j + 6, k + 33, placeStoneBricks(random), 0, 2);
        world.setBlock(i + 24, j + 6, k + 33, placeStoneBricks(random), 0, 2);
        world.setBlock(i + 25, j + 6, k + 33, placeStoneBricks(random), 0, 2);
        world.setBlock(i + 26, j + 6, k + 33, placeStoneBricks(random), 0, 2);
        world.setBlock(i + 27, j + 6, k + 33, placeStoneBricks(random), 0, 2);
        world.setBlock(i + 28, j + 6, k + 33, NovaCraftBlocks.sculk_block, 0, 2);
        world.setBlock(i + 29, j + 6, k + 33, NovaCraftBlocks.carved_vanite_bricks, 0, 2);
        world.setBlock(i + 30, j + 6, k + 33, NovaCraftBlocks.nullstone_bricks, 0, 2);
        world.setBlock(i + 31, j + 6, k + 33, NovaCraftBlocks.nullstone_bricks, 0, 2);
        world.setBlock(i + 32, j + 6, k + 33, NovaCraftBlocks.nullstone_bricks, 0, 2);
        world.setBlock(i + 33, j + 6, k + 33, NovaCraftBlocks.nullstone_bricks, 0, 2);
        world.setBlock(i + 34, j + 6, k + 33, NovaCraftBlocks.nullstone_bricks, 0, 2);
        world.setBlock(i + 35, j + 6, k + 33, NovaCraftBlocks.nullstone_bricks, 0, 2);
        world.setBlock(i + 36, j + 6, k + 33, NovaCraftBlocks.nullstone_bricks, 0, 2);
        world.setBlock(i + 37, j + 6, k + 33, NovaCraftBlocks.nullstone_bricks, 0, 2);
        world.setBlock(i + 38, j + 6, k + 33, NovaCraftBlocks.nullstone_bricks, 0, 2);
        world.setBlock(i + 39, j + 6, k + 33, NovaCraftBlocks.nullstone_bricks, 0, 2);
        world.setBlock(i + 40, j + 6, k + 33, NovaCraftBlocks.nullstone_bricks, 0, 2);
        world.setBlock(i + 41, j + 6, k + 33, NovaCraftBlocks.carved_vanite_bricks, 0, 2);
        world.setBlock(i + 42, j + 6, k + 33, NovaCraftBlocks.sculk_block, 0, 2);
        world.setBlock(i + 43, j + 6, k + 33, placeStoneBricks(random), 0, 2);
        world.setBlock(i + 44, j + 6, k + 33, NovaCraftBlocks.sculk_block, 0, 2);
        world.setBlock(i + 45, j + 6, k + 33, NovaCraftBlocks.sculk_block, 0, 2);
        world.setBlock(i + 46, j + 6, k + 33, placeStoneBricks(random), 0, 2);
        world.setBlock(i + 47, j + 6, k + 33, placeStoneBricks(random), 0, 2);
        world.setBlock(i + 48, j + 6, k + 33, placeStoneBricks(random), 0, 2);
        world.setBlock(i + 49, j + 6, k + 33, NovaCraftBlocks.carved_vanite_bricks, 0, 2);
        world.setBlock(i + 21, j + 6, k + 34, NovaCraftBlocks.carved_vanite_bricks, 0, 2);
        world.setBlock(i + 22, j + 6, k + 34, placeStoneBricks(random), 0, 2);
        world.setBlock(i + 23, j + 6, k + 34, placeStoneBricks(random), 0, 2);
        world.setBlock(i + 24, j + 6, k + 34, placeStoneBricks(random), 0, 2);
        world.setBlock(i + 25, j + 6, k + 34, NovaCraftBlocks.sculk_block, 0, 2);
        world.setBlock(i + 26, j + 6, k + 34, placeStoneBricks(random), 0, 2);
        world.setBlock(i + 27, j + 6, k + 34, NovaCraftBlocks.sculk_block, 0, 2);
        world.setBlock(i + 28, j + 6, k + 34, placeStoneBricks(random), 0, 2);
        world.setBlock(i + 29, j + 6, k + 34, placeStoneBricks(random), 0, 2);
        world.setBlock(i + 30, j + 6, k + 34, NovaCraftBlocks.carved_vanite_bricks, 0, 2);
        world.setBlock(i + 31, j + 6, k + 34, NovaCraftBlocks.nullstone_bricks, 0, 2);
        world.setBlock(i + 32, j + 6, k + 34, NovaCraftBlocks.nullstone_bricks, 0, 2);
        world.setBlock(i + 33, j + 6, k + 34, NovaCraftBlocks.nullstone_bricks, 0, 2);
        world.setBlock(i + 34, j + 6, k + 34, NovaCraftBlocks.nullstone_bricks, 0, 2);
        world.setBlock(i + 35, j + 6, k + 34, NovaCraftBlocks.nullstone_bricks, 0, 2);
        world.setBlock(i + 36, j + 6, k + 34, NovaCraftBlocks.nullstone_bricks, 0, 2);
        world.setBlock(i + 37, j + 6, k + 34, NovaCraftBlocks.nullstone_bricks, 0, 2);
        world.setBlock(i + 38, j + 6, k + 34, NovaCraftBlocks.nullstone_bricks, 0, 2);
        world.setBlock(i + 39, j + 6, k + 34, NovaCraftBlocks.nullstone_bricks, 0, 2);
        world.setBlock(i + 40, j + 6, k + 34, NovaCraftBlocks.carved_vanite_bricks, 0, 2);
        world.setBlock(i + 41, j + 6, k + 34, placeStoneBricks(random), 0, 2);
        world.setBlock(i + 42, j + 6, k + 34, NovaCraftBlocks.sculk_block, 0, 2);
        world.setBlock(i + 43, j + 6, k + 34, placeStoneBricks(random), 0, 2);
        world.setBlock(i + 44, j + 6, k + 34, NovaCraftBlocks.sculk_block, 0, 2);
        world.setBlock(i + 45, j + 6, k + 34, placeStoneBricks(random), 0, 2);
        world.setBlock(i + 46, j + 6, k + 34, NovaCraftBlocks.sculk_block, 0, 2);
        world.setBlock(i + 47, j + 6, k + 34, NovaCraftBlocks.sculk_block, 0, 2);
        world.setBlock(i + 48, j + 6, k + 34, NovaCraftBlocks.sculk_block, 0, 2);
        world.setBlock(i + 49, j + 6, k + 34, NovaCraftBlocks.carved_vanite_bricks, 0, 2);
        world.setBlock(i + 21, j + 6, k + 35, NovaCraftBlocks.carved_vanite_bricks, 0, 2);
        world.setBlock(i + 22, j + 6, k + 35, NovaCraftBlocks.sculk_block, 0, 2);
        world.setBlock(i + 23, j + 6, k + 35, NovaCraftBlocks.sculk_block, 0, 2);
        world.setBlock(i + 24, j + 6, k + 35, NovaCraftBlocks.sculk_block, 0, 2);
        world.setBlock(i + 25, j + 6, k + 35, placeStoneBricks(random), 0, 2);
        world.setBlock(i + 26, j + 6, k + 35, placeStoneBricks(random), 0, 2);
        world.setBlock(i + 27, j + 6, k + 35, placeStoneBricks(random), 0, 2);
        world.setBlock(i + 28, j + 6, k + 35, placeStoneBricks(random), 0, 2);
        world.setBlock(i + 29, j + 6, k + 35, placeStoneBricks(random), 0, 2);
        world.setBlock(i + 30, j + 6, k + 35, NovaCraftBlocks.sculk_block, 0, 2);
        world.setBlock(i + 31, j + 6, k + 35, NovaCraftBlocks.carved_vanite_bricks, 0, 2);
        world.setBlock(i + 32, j + 6, k + 35, NovaCraftBlocks.carved_vanite_bricks, 0, 2);
        world.setBlock(i + 33, j + 6, k + 35, NovaCraftBlocks.nullstone_bricks, 0, 2);
        world.setBlock(i + 34, j + 6, k + 35, NovaCraftBlocks.nullstone_bricks, 0, 2);
        world.setBlock(i + 35, j + 6, k + 35, NovaCraftBlocks.nullstone_bricks, 0, 2);
        world.setBlock(i + 36, j + 6, k + 35, NovaCraftBlocks.nullstone_bricks, 0, 2);
        world.setBlock(i + 37, j + 6, k + 35, NovaCraftBlocks.nullstone_bricks, 0, 2);
        world.setBlock(i + 38, j + 6, k + 35, NovaCraftBlocks.carved_vanite_bricks, 0, 2);
        world.setBlock(i + 39, j + 6, k + 35, NovaCraftBlocks.carved_vanite_bricks, 0, 2);
        world.setBlock(i + 40, j + 6, k + 35, NovaCraftBlocks.sculk_block, 0, 2);
        world.setBlock(i + 41, j + 6, k + 35, placeStoneBricks(random), 0, 2);
        world.setBlock(i + 42, j + 6, k + 35, placeStoneBricks(random), 0, 2);
        world.setBlock(i + 43, j + 6, k + 35, placeStoneBricks(random), 0, 2);
        world.setBlock(i + 44, j + 6, k + 35, placeStoneBricks(random), 0, 2);
        world.setBlock(i + 45, j + 6, k + 35, placeStoneBricks(random), 0, 2);
        world.setBlock(i + 46, j + 6, k + 35, NovaCraftBlocks.sculk_block, 0, 2);
        world.setBlock(i + 47, j + 6, k + 35, NovaCraftBlocks.sculk_block, 0, 2);
        world.setBlock(i + 48, j + 6, k + 35, placeStoneBricks(random), 0, 2);
        world.setBlock(i + 49, j + 6, k + 35, NovaCraftBlocks.carved_vanite_bricks, 0, 2);
        world.setBlock(i + 21, j + 6, k + 36, NovaCraftBlocks.carved_vanite_bricks, 0, 2);
        world.setBlock(i + 22, j + 6, k + 36, placeStoneBricks(random), 0, 2);
        world.setBlock(i + 23, j + 6, k + 36, placeStoneBricks(random), 0, 2);
        world.setBlock(i + 24, j + 6, k + 36, placeStoneBricks(random), 0, 2);
        world.setBlock(i + 25, j + 6, k + 36, placeStoneBricks(random), 0, 2);
        world.setBlock(i + 26, j + 6, k + 36, placeStoneBricks(random), 0, 2);
        world.setBlock(i + 27, j + 6, k + 36, placeStoneBricks(random), 0, 2);
        world.setBlock(i + 28, j + 6, k + 36, placeStoneBricks(random), 0, 2);
        world.setBlock(i + 29, j + 6, k + 36, placeStoneBricks(random), 0, 2);
        world.setBlock(i + 30, j + 6, k + 36, placeStoneBricks(random), 0, 2);
        world.setBlock(i + 31, j + 6, k + 36, NovaCraftBlocks.sculk_block, 0, 2);
        world.setBlock(i + 32, j + 6, k + 36, placeStoneBricks(random), 0, 2);
        world.setBlock(i + 33, j + 6, k + 36, NovaCraftBlocks.carved_vanite_bricks, 0, 2);
        world.setBlock(i + 34, j + 6, k + 36, NovaCraftBlocks.nullstone_bricks, 0, 2);
        world.setBlock(i + 35, j + 6, k + 36, NovaCraftBlocks.nullstone_bricks, 0, 2);
        world.setBlock(i + 36, j + 6, k + 36, NovaCraftBlocks.nullstone_bricks, 0, 2);
        world.setBlock(i + 37, j + 6, k + 36, NovaCraftBlocks.carved_vanite_bricks, 0, 2);
        world.setBlock(i + 38, j + 6, k + 36, placeStoneBricks(random), 0, 2);
        world.setBlock(i + 39, j + 6, k + 36, placeStoneBricks(random), 0, 2);
        world.setBlock(i + 40, j + 6, k + 36, placeStoneBricks(random), 0, 2);
        world.setBlock(i + 41, j + 6, k + 36, placeStoneBricks(random), 0, 2);
        world.setBlock(i + 42, j + 6, k + 36, placeStoneBricks(random), 0, 2);
        world.setBlock(i + 43, j + 6, k + 36, placeStoneBricks(random), 0, 2);
        world.setBlock(i + 44, j + 6, k + 36, placeStoneBricks(random), 0, 2);
        world.setBlock(i + 45, j + 6, k + 36, placeStoneBricks(random), 0, 2);
        world.setBlock(i + 46, j + 6, k + 36, placeStoneBricks(random), 0, 2);
        world.setBlock(i + 47, j + 6, k + 36, NovaCraftBlocks.sculk_block, 0, 2);
        world.setBlock(i + 48, j + 6, k + 36, NovaCraftBlocks.sculk_block, 0, 2);
        world.setBlock(i + 49, j + 6, k + 36, NovaCraftBlocks.carved_vanite_bricks, 0, 2);
        world.setBlock(i + 21, j + 6, k + 37, NovaCraftBlocks.glowing_carved_vanite_bricks, 0, 2);
        world.setBlock(i + 22, j + 6, k + 37, placeStoneBricks(random), 0, 2);
        world.setBlock(i + 23, j + 6, k + 37, NovaCraftBlocks.sculk_block, 0, 2);
        world.setBlock(i + 24, j + 6, k + 37, placeStoneBricks(random), 0, 2);
        world.setBlock(i + 25, j + 6, k + 37, NovaCraftBlocks.sculk_block, 0, 2);
        world.setBlock(i + 26, j + 6, k + 37, placeStoneBricks(random), 0, 2);
        world.setBlock(i + 27, j + 6, k + 37, placeStoneBricks(random), 0, 2);
        world.setBlock(i + 28, j + 6, k + 37, placeStoneBricks(random), 0, 2);
        world.setBlock(i + 29, j + 6, k + 37, placeStoneBricks(random), 0, 2);
        world.setBlock(i + 30, j + 6, k + 37, placeStoneBricks(random), 0, 2);
        world.setBlock(i + 31, j + 6, k + 37, placeStoneBricks(random), 0, 2);
        world.setBlock(i + 32, j + 6, k + 37, placeStoneBricks(random), 0, 2);
        world.setBlock(i + 33, j + 6, k + 37, NovaCraftBlocks.carved_vanite_bricks, 0, 2);
        world.setBlock(i + 34, j + 6, k + 37, NovaCraftBlocks.nullstone_bricks, 0, 2);
        world.setBlock(i + 35, j + 6, k + 37, NovaCraftBlocks.nullstone_bricks, 0, 2);
        world.setBlock(i + 36, j + 6, k + 37, NovaCraftBlocks.nullstone_bricks, 0, 2);
        world.setBlock(i + 37, j + 6, k + 37, NovaCraftBlocks.carved_vanite_bricks, 0, 2);
        world.setBlock(i + 38, j + 6, k + 37, NovaCraftBlocks.sculk_block, 0, 2);
        world.setBlock(i + 39, j + 6, k + 37, NovaCraftBlocks.sculk_block, 0, 2);
        world.setBlock(i + 40, j + 6, k + 37, placeStoneBricks(random), 0, 2);
        world.setBlock(i + 41, j + 6, k + 37, placeStoneBricks(random), 0, 2);
        world.setBlock(i + 42, j + 6, k + 37, placeStoneBricks(random), 0, 2);
        world.setBlock(i + 43, j + 6, k + 37, placeStoneBricks(random), 0, 2);
        world.setBlock(i + 44, j + 6, k + 37, placeStoneBricks(random), 0, 2);
        world.setBlock(i + 45, j + 6, k + 37, placeStoneBricks(random), 0, 2);
        world.setBlock(i + 46, j + 6, k + 37, placeStoneBricks(random), 0, 2);
        world.setBlock(i + 47, j + 6, k + 37, placeStoneBricks(random), 0, 2);
        world.setBlock(i + 48, j + 6, k + 37, placeStoneBricks(random), 0, 2);
        world.setBlock(i + 49, j + 6, k + 37, NovaCraftBlocks.glowing_carved_vanite_bricks, 0, 2);
        world.setBlock(i + 22, j + 6, k + 38, NovaCraftBlocks.carved_vanite_bricks, 0, 2);
        world.setBlock(i + 23, j + 6, k + 38, NovaCraftBlocks.sculk_block, 0, 2);
        world.setBlock(i + 24, j + 6, k + 38, NovaCraftBlocks.sculk_block, 0, 2);
        world.setBlock(i + 25, j + 6, k + 38, NovaCraftBlocks.sculk_block, 0, 2);
        world.setBlock(i + 26, j + 6, k + 38, placeStoneBricks(random), 0, 2);
        world.setBlock(i + 27, j + 6, k + 38, placeStoneBricks(random), 0, 2);
        world.setBlock(i + 28, j + 6, k + 38, NovaCraftBlocks.sculk_block, 0, 2);
        world.setBlock(i + 29, j + 6, k + 38, NovaCraftBlocks.sculk_block, 0, 2);
        world.setBlock(i + 30, j + 6, k + 38, placeStoneBricks(random), 0, 2);
        world.setBlock(i + 31, j + 6, k + 38, NovaCraftBlocks.sculk_block, 0, 2);
        world.setBlock(i + 32, j + 6, k + 38, NovaCraftBlocks.sculk_block, 0, 2);
        world.setBlock(i + 33, j + 6, k + 38, NovaCraftBlocks.carved_vanite_bricks, 0, 2);
        world.setBlock(i + 34, j + 6, k + 38, NovaCraftBlocks.nullstone_bricks, 0, 2);
        world.setBlock(i + 35, j + 6, k + 38, NovaCraftBlocks.nullstone_bricks, 0, 2);
        world.setBlock(i + 36, j + 6, k + 38, NovaCraftBlocks.nullstone_bricks, 0, 2);
        world.setBlock(i + 37, j + 6, k + 38, NovaCraftBlocks.carved_vanite_bricks, 0, 2);
        world.setBlock(i + 38, j + 6, k + 38, placeStoneBricks(random), 0, 2);
        world.setBlock(i + 39, j + 6, k + 38, placeStoneBricks(random), 0, 2);
        world.setBlock(i + 40, j + 6, k + 38, NovaCraftBlocks.sculk_block, 0, 2);
        world.setBlock(i + 41, j + 6, k + 38, placeStoneBricks(random), 0, 2);
        world.setBlock(i + 42, j + 6, k + 38, placeStoneBricks(random), 0, 2);
        world.setBlock(i + 43, j + 6, k + 38, placeStoneBricks(random), 0, 2);
        world.setBlock(i + 44, j + 6, k + 38, placeStoneBricks(random), 0, 2);
        world.setBlock(i + 45, j + 6, k + 38, placeStoneBricks(random), 0, 2);
        world.setBlock(i + 46, j + 6, k + 38, placeStoneBricks(random), 0, 2);
        world.setBlock(i + 47, j + 6, k + 38, placeStoneBricks(random), 0, 2);
        world.setBlock(i + 48, j + 6, k + 38, NovaCraftBlocks.carved_vanite_bricks, 0, 2);
        world.setBlock(i + 23, j + 6, k + 39, NovaCraftBlocks.carved_vanite_bricks, 0, 2);
        world.setBlock(i + 24, j + 6, k + 39, placeStoneBricks(random), 0, 2);
        world.setBlock(i + 25, j + 6, k + 39, placeStoneBricks(random), 0, 2);
        world.setBlock(i + 26, j + 6, k + 39, placeStoneBricks(random), 0, 2);
        world.setBlock(i + 27, j + 6, k + 39, NovaCraftBlocks.sculk_block, 0, 2);
        world.setBlock(i + 28, j + 6, k + 39, NovaCraftBlocks.sculk_block, 0, 2);
        world.setBlock(i + 29, j + 6, k + 39, placeStoneBricks(random), 0, 2);
        world.setBlock(i + 30, j + 6, k + 39, placeStoneBricks(random), 0, 2);
        world.setBlock(i + 31, j + 6, k + 39, NovaCraftBlocks.sculk_block, 0, 2);
        world.setBlock(i + 32, j + 6, k + 39, placeStoneBricks(random), 0, 2);
        world.setBlock(i + 33, j + 6, k + 39, NovaCraftBlocks.carved_vanite_bricks, 0, 2);
        world.setBlock(i + 34, j + 6, k + 39, NovaCraftBlocks.nullstone_bricks, 0, 2);
        world.setBlock(i + 35, j + 6, k + 39, NovaCraftBlocks.nullstone_bricks, 0, 2);
        world.setBlock(i + 36, j + 6, k + 39, NovaCraftBlocks.nullstone_bricks, 0, 2);
        world.setBlock(i + 37, j + 6, k + 39, NovaCraftBlocks.carved_vanite_bricks, 0, 2);
        world.setBlock(i + 38, j + 6, k + 39, placeStoneBricks(random), 0, 2);
        world.setBlock(i + 39, j + 6, k + 39, placeStoneBricks(random), 0, 2);
        world.setBlock(i + 40, j + 6, k + 39, NovaCraftBlocks.sculk_block, 0, 2);
        world.setBlock(i + 41, j + 6, k + 39, placeStoneBricks(random), 0, 2);
        world.setBlock(i + 42, j + 6, k + 39, placeStoneBricks(random), 0, 2);
        world.setBlock(i + 43, j + 6, k + 39, placeStoneBricks(random), 0, 2);
        world.setBlock(i + 44, j + 6, k + 39, placeStoneBricks(random), 0, 2);
        world.setBlock(i + 45, j + 6, k + 39, placeStoneBricks(random), 0, 2);
        world.setBlock(i + 46, j + 6, k + 39, placeStoneBricks(random), 0, 2);
        world.setBlock(i + 47, j + 6, k + 39, NovaCraftBlocks.carved_vanite_bricks, 0, 2);
        world.setBlock(i + 24, j + 6, k + 40, NovaCraftBlocks.carved_vanite_bricks, 0, 2);
        world.setBlock(i + 25, j + 6, k + 40, placeStoneBricks(random), 0, 2);
        world.setBlock(i + 26, j + 6, k + 40, NovaCraftBlocks.sculk_block, 0, 2);
        world.setBlock(i + 27, j + 6, k + 40, placeStoneBricks(random), 0, 2);
        world.setBlock(i + 28, j + 6, k + 40, placeStoneBricks(random), 0, 2);
        world.setBlock(i + 29, j + 6, k + 40, NovaCraftBlocks.sculk_block, 0, 2);
        world.setBlock(i + 30, j + 6, k + 40, NovaCraftBlocks.sculk_block, 0, 2);
        world.setBlock(i + 31, j + 6, k + 40, placeStoneBricks(random), 0, 2);
        world.setBlock(i + 32, j + 6, k + 40, NovaCraftBlocks.sculk_block, 0, 2);
        world.setBlock(i + 33, j + 6, k + 40, NovaCraftBlocks.carved_vanite_bricks, 0, 2);
        world.setBlock(i + 34, j + 6, k + 40, NovaCraftBlocks.nullstone_bricks, 0, 2);
        world.setBlock(i + 35, j + 6, k + 40, NovaCraftBlocks.nullstone_bricks, 0, 2);
        world.setBlock(i + 36, j + 6, k + 40, NovaCraftBlocks.nullstone_bricks, 0, 2);
        world.setBlock(i + 37, j + 6, k + 40, NovaCraftBlocks.carved_vanite_bricks, 0, 2);
        world.setBlock(i + 38, j + 6, k + 40, placeStoneBricks(random), 0, 2);
        world.setBlock(i + 39, j + 6, k + 40, placeStoneBricks(random), 0, 2);
        world.setBlock(i + 40, j + 6, k + 40, placeStoneBricks(random), 0, 2);
        world.setBlock(i + 41, j + 6, k + 40, NovaCraftBlocks.sculk_block, 0, 2);
        world.setBlock(i + 42, j + 6, k + 40, NovaCraftBlocks.sculk_block, 0, 2);
        world.setBlock(i + 43, j + 6, k + 40, placeStoneBricks(random), 0, 2);
        world.setBlock(i + 44, j + 6, k + 40, placeStoneBricks(random), 0, 2);
        world.setBlock(i + 45, j + 6, k + 40, placeStoneBricks(random), 0, 2);
        world.setBlock(i + 46, j + 6, k + 40, NovaCraftBlocks.carved_vanite_bricks, 0, 2);
        world.setBlock(i + 25, j + 6, k + 41, NovaCraftBlocks.carved_vanite_bricks, 0, 2);
        world.setBlock(i + 26, j + 6, k + 41, NovaCraftBlocks.sculk_block, 0, 2);
        world.setBlock(i + 27, j + 6, k + 41, placeStoneBricks(random), 0, 2);
        world.setBlock(i + 28, j + 6, k + 41, placeStoneBricks(random), 0, 2);
        world.setBlock(i + 29, j + 6, k + 41, NovaCraftBlocks.sculk_block, 0, 2);
        world.setBlock(i + 30, j + 6, k + 41, placeStoneBricks(random), 0, 2);
        world.setBlock(i + 31, j + 6, k + 41, placeStoneBricks(random), 0, 2);
        world.setBlock(i + 32, j + 6, k + 41, placeStoneBricks(random), 0, 2);
        world.setBlock(i + 33, j + 6, k + 41, NovaCraftBlocks.carved_vanite_bricks, 0, 2);
        world.setBlock(i + 34, j + 6, k + 41, NovaCraftBlocks.nullstone_bricks, 0, 2);
        world.setBlock(i + 35, j + 6, k + 41, NovaCraftBlocks.nullstone_bricks, 0, 2);
        world.setBlock(i + 36, j + 6, k + 41, NovaCraftBlocks.nullstone_bricks, 0, 2);
        world.setBlock(i + 37, j + 6, k + 41, NovaCraftBlocks.carved_vanite_bricks, 0, 2);
        world.setBlock(i + 38, j + 6, k + 41, placeStoneBricks(random), 0, 2);
        world.setBlock(i + 39, j + 6, k + 41, placeStoneBricks(random), 0, 2);
        world.setBlock(i + 40, j + 6, k + 41, placeStoneBricks(random), 0, 2);
        world.setBlock(i + 41, j + 6, k + 41, placeStoneBricks(random), 0, 2);
        world.setBlock(i + 42, j + 6, k + 41, placeStoneBricks(random), 0, 2);
        world.setBlock(i + 43, j + 6, k + 41, NovaCraftBlocks.sculk_block, 0, 2);
        world.setBlock(i + 44, j + 6, k + 41, placeStoneBricks(random), 0, 2);
        world.setBlock(i + 45, j + 6, k + 41, NovaCraftBlocks.carved_vanite_bricks, 0, 2);
        world.setBlock(i + 26, j + 6, k + 42, NovaCraftBlocks.glowing_carved_vanite_bricks, 0, 2);
        world.setBlock(i + 27, j + 6, k + 42, NovaCraftBlocks.carved_vanite_bricks, 0, 2);
        world.setBlock(i + 28, j + 6, k + 42, NovaCraftBlocks.carved_vanite_bricks, 0, 2);
        world.setBlock(i + 29, j + 6, k + 42, NovaCraftBlocks.carved_vanite_bricks, 0, 2);
        world.setBlock(i + 30, j + 6, k + 42, NovaCraftBlocks.carved_vanite_bricks, 0, 2);
        world.setBlock(i + 31, j + 6, k + 42, NovaCraftBlocks.carved_vanite_bricks, 0, 2);
        world.setBlock(i + 32, j + 6, k + 42, NovaCraftBlocks.carved_vanite_bricks, 0, 2);
        world.setBlock(i + 33, j + 6, k + 42, NovaCraftBlocks.carved_vanite_bricks, 0, 2);
        world.setBlock(i + 34, j + 6, k + 42, NovaCraftBlocks.nullstone_bricks, 0, 2);
        world.setBlock(i + 35, j + 6, k + 42, NovaCraftBlocks.nullstone_bricks, 0, 2);
        world.setBlock(i + 36, j + 6, k + 42, NovaCraftBlocks.nullstone_bricks, 0, 2);
        world.setBlock(i + 37, j + 6, k + 42, NovaCraftBlocks.carved_vanite_bricks, 0, 2);
        world.setBlock(i + 38, j + 6, k + 42, NovaCraftBlocks.carved_vanite_bricks, 0, 2);
        world.setBlock(i + 39, j + 6, k + 42, NovaCraftBlocks.carved_vanite_bricks, 0, 2);
        world.setBlock(i + 40, j + 6, k + 42, NovaCraftBlocks.carved_vanite_bricks, 0, 2);
        world.setBlock(i + 41, j + 6, k + 42, NovaCraftBlocks.carved_vanite_bricks, 0, 2);
        world.setBlock(i + 42, j + 6, k + 42, NovaCraftBlocks.carved_vanite_bricks, 0, 2);
        world.setBlock(i + 43, j + 6, k + 42, NovaCraftBlocks.carved_vanite_bricks, 0, 2);
        world.setBlock(i + 44, j + 6, k + 42, NovaCraftBlocks.glowing_carved_vanite_bricks, 0, 2);
        world.setBlock(i + 34, j + 6, k + 43, placeStoneBricks(random), 0, 2);
        world.setBlock(i + 35, j + 6, k + 43, placeStoneBricks(random), 0, 2);
        world.setBlock(i + 36, j + 6, k + 43, placeStoneBricks(random), 0, 2);
        world.setBlock(i + 34, j + 7, k + 11, NovaCraftBlocks.sculk_block, 0, 2);
        world.setBlock(i + 35, j + 7, k + 11, NovaCraftBlocks.sculk_block, 0, 2);
        world.setBlock(i + 36, j + 7, k + 11, placeStoneBricks(random), 0, 2);
        world.setBlock(i + 33, j + 7, k + 12, NovaCraftBlocks.carved_vanite_bricks, 0, 2);
        world.setBlock(i + 34, j + 7, k + 12, placeStoneBricks(random), 0, 2);
        world.setBlock(i + 35, j + 7, k + 12, NovaCraftBlocks.sculk_block, 0, 2);
        world.setBlock(i + 36, j + 7, k + 12, placeStoneBricks(random), 0, 2);
        world.setBlock(i + 37, j + 7, k + 12, NovaCraftBlocks.carved_vanite_bricks, 0, 2);
        world.setBlock(i + 33, j + 7, k + 13, NovaCraftBlocks.carved_vanite_bricks, 0, 2);
        world.setBlock(i + 34, j + 7, k + 13, NovaCraftBlocks.nullstone_brick_stairs, 3, 2);
        world.setBlock(i + 35, j + 7, k + 13, NovaCraftBlocks.nullstone_brick_stairs, 3, 2);
        world.setBlock(i + 36, j + 7, k + 13, NovaCraftBlocks.nullstone_brick_stairs, 3, 2);
        world.setBlock(i + 37, j + 7, k + 13, NovaCraftBlocks.carved_vanite_bricks, 0, 2);
        world.setBlock(i + 26, j + 7, k + 14, NovaCraftBlocks.nullstone_brick_wall, 0, 2);
        world.setBlock(i + 27, j + 7, k + 14, NovaCraftBlocks.nullstone_brick_wall, 0, 2);
        world.setBlock(i + 28, j + 7, k + 14, NovaCraftBlocks.nullstone_brick_wall, 0, 2);
        world.setBlock(i + 29, j + 7, k + 14, NovaCraftBlocks.nullstone_brick_wall, 0, 2);
        world.setBlock(i + 30, j + 7, k + 14, NovaCraftBlocks.nullstone_brick_wall, 0, 2);
        world.setBlock(i + 31, j + 7, k + 14, NovaCraftBlocks.nullstone_brick_wall, 0, 2);
        world.setBlock(i + 32, j + 7, k + 14, NovaCraftBlocks.nullstone_brick_wall, 0, 2);
        world.setBlock(i + 33, j + 7, k + 14, NovaCraftBlocks.nullstone_brick_wall, 0, 2);
        world.setBlock(i + 37, j + 7, k + 14, NovaCraftBlocks.nullstone_brick_wall, 0, 2);
        world.setBlock(i + 38, j + 7, k + 14, NovaCraftBlocks.nullstone_brick_wall, 0, 2);
        world.setBlock(i + 39, j + 7, k + 14, NovaCraftBlocks.nullstone_brick_wall, 0, 2);
        world.setBlock(i + 40, j + 7, k + 14, NovaCraftBlocks.nullstone_brick_wall, 0, 2);
        world.setBlock(i + 41, j + 7, k + 14, NovaCraftBlocks.nullstone_brick_wall, 0, 2);
        world.setBlock(i + 42, j + 7, k + 14, NovaCraftBlocks.nullstone_brick_wall, 0, 2);
        world.setBlock(i + 43, j + 7, k + 14, NovaCraftBlocks.nullstone_brick_wall, 0, 2);
        world.setBlock(i + 44, j + 7, k + 14, NovaCraftBlocks.nullstone_brick_wall, 0, 2);
        world.setBlock(i + 25, j + 7, k + 15, NovaCraftBlocks.nullstone_brick_wall, 0, 2);
        world.setBlock(i + 26, j + 7, k + 15, NovaCraftBlocks.nullstone_brick_wall, 0, 2);
        world.setBlock(i + 44, j + 7, k + 15, NovaCraftBlocks.nullstone_brick_wall, 0, 2);
        world.setBlock(i + 45, j + 7, k + 15, NovaCraftBlocks.nullstone_brick_wall, 0, 2);
        world.setBlock(i + 24, j + 7, k + 16, NovaCraftBlocks.nullstone_brick_wall, 0, 2);
        world.setBlock(i + 25, j + 7, k + 16, NovaCraftBlocks.nullstone_brick_wall, 0, 2);
        world.setBlock(i + 45, j + 7, k + 16, NovaCraftBlocks.nullstone_brick_wall, 0, 2);
        world.setBlock(i + 46, j + 7, k + 16, NovaCraftBlocks.nullstone_brick_wall, 0, 2);
        world.setBlock(i + 23, j + 7, k + 17, NovaCraftBlocks.nullstone_brick_wall, 0, 2);
        world.setBlock(i + 24, j + 7, k + 17, NovaCraftBlocks.nullstone_brick_wall, 0, 2);
        world.setBlock(i + 46, j + 7, k + 17, NovaCraftBlocks.nullstone_brick_wall, 0, 2);
        world.setBlock(i + 47, j + 7, k + 17, NovaCraftBlocks.nullstone_brick_wall, 0, 2);
        world.setBlock(i + 22, j + 7, k + 18, NovaCraftBlocks.nullstone_brick_wall, 0, 2);
        world.setBlock(i + 23, j + 7, k + 18, NovaCraftBlocks.nullstone_brick_wall, 0, 2);
        world.setBlock(i + 27, j + 7, k + 18, placeStoneBricks(random), 0, 2);
        world.setBlock(i + 28, j + 7, k + 18, placeStoneBricks(random), 0, 2);
        world.setBlock(i + 42, j + 7, k + 18, placeStoneBricks(random), 0, 2);
        world.setBlock(i + 43, j + 7, k + 18, NovaCraftBlocks.sculk_block, 0, 2);
        world.setBlock(i + 47, j + 7, k + 18, NovaCraftBlocks.nullstone_brick_wall, 0, 2);
        world.setBlock(i + 48, j + 7, k + 18, NovaCraftBlocks.nullstone_brick_wall, 0, 2);
        world.setBlock(i + 21, j + 7, k + 19, NovaCraftBlocks.nullstone_brick_wall, 0, 2);
        world.setBlock(i + 22, j + 7, k + 19, NovaCraftBlocks.nullstone_brick_wall, 0, 2);
        world.setBlock(i + 26, j + 7, k + 19, NovaCraftBlocks.sculk_block, 0, 2);
        world.setBlock(i + 27, j + 7, k + 19, placeStoneBricks(random), 0, 2);
        world.setBlock(i + 28, j + 7, k + 19, placeStoneBricks(random), 0, 2);
        world.setBlock(i + 29, j + 7, k + 19, NovaCraftBlocks.sculk_block, 0, 2);
        world.setBlock(i + 41, j + 7, k + 19, NovaCraftBlocks.sculk_block, 0, 2);
        world.setBlock(i + 42, j + 7, k + 19, NovaCraftBlocks.sculk_block, 0, 2);
        world.setBlock(i + 43, j + 7, k + 19, placeStoneBricks(random), 0, 2);
        world.setBlock(i + 44, j + 7, k + 19, NovaCraftBlocks.sculk_block, 0, 2);
        world.setBlock(i + 48, j + 7, k + 19, NovaCraftBlocks.nullstone_brick_wall, 0, 2);
        world.setBlock(i + 49, j + 7, k + 19, NovaCraftBlocks.nullstone_brick_wall, 0, 2);
        world.setBlock(i + 21, j + 7, k + 20, NovaCraftBlocks.nullstone_brick_wall, 0, 2);
        world.setBlock(i + 26, j + 7, k + 20, NovaCraftBlocks.sculk_block, 0, 2);
        world.setBlock(i + 27, j + 7, k + 20, placeStoneBricks(random), 0, 2);
        world.setBlock(i + 28, j + 7, k + 20, placeStoneBricks(random), 0, 2);
        world.setBlock(i + 29, j + 7, k + 20, placeStoneBricks(random), 0, 2);
        world.setBlock(i + 41, j + 7, k + 20, NovaCraftBlocks.sculk_block, 0, 2);
        world.setBlock(i + 42, j + 7, k + 20, placeStoneBricks(random), 0, 2);
        world.setBlock(i + 43, j + 7, k + 20, placeStoneBricks(random), 0, 2);
        world.setBlock(i + 44, j + 7, k + 20, placeStoneBricks(random), 0, 2);
        world.setBlock(i + 49, j + 7, k + 20, NovaCraftBlocks.nullstone_brick_wall, 0, 2);
        world.setBlock(i + 21, j + 7, k + 21, NovaCraftBlocks.nullstone_brick_wall, 0, 2);
        world.setBlock(i + 27, j + 7, k + 21, NovaCraftBlocks.sculk_block, 0, 2);
        world.setBlock(i + 28, j + 7, k + 21, placeStoneBricks(random), 0, 2);
        world.setBlock(i + 42, j + 7, k + 21, NovaCraftBlocks.sculk_block, 0, 2);
        world.setBlock(i + 43, j + 7, k + 21, placeStoneBricks(random), 0, 2);
        world.setBlock(i + 49, j + 7, k + 21, NovaCraftBlocks.nullstone_brick_wall, 0, 2);
        world.setBlock(i + 21, j + 7, k + 22, NovaCraftBlocks.nullstone_brick_wall, 0, 2);
        world.setBlock(i + 49, j + 7, k + 22, NovaCraftBlocks.nullstone_brick_wall, 0, 2);
        world.setBlock(i + 21, j + 7, k + 23, NovaCraftBlocks.nullstone_brick_wall, 0, 2);
        world.setBlock(i + 49, j + 7, k + 23, NovaCraftBlocks.nullstone_brick_wall, 0, 2);
        world.setBlock(i + 21, j + 7, k + 24, NovaCraftBlocks.nullstone_brick_wall, 0, 2);
        world.setBlock(i + 31, j + 7, k + 24, NovaCraftBlocks.nullstone_bricks, 0, 2);
        world.setBlock(i + 32, j + 7, k + 24, NovaCraftBlocks.nullstone, 0, 2);
        world.setBlock(i + 33, j + 7, k + 24, NovaCraftBlocks.nullstone, 0, 2);
        world.setBlock(i + 34, j + 7, k + 24, NovaCraftBlocks.nullstone, 0, 2);
        world.setBlock(i + 36, j + 7, k + 24, NovaCraftBlocks.nullstone, 0, 2);
        world.setBlock(i + 37, j + 7, k + 24, NovaCraftBlocks.nullstone, 0, 2);
        world.setBlock(i + 38, j + 7, k + 24, NovaCraftBlocks.nullstone, 0, 2);
        world.setBlock(i + 39, j + 7, k + 24, NovaCraftBlocks.crystallized_end, 0, 2);
        world.setBlock(i + 49, j + 7, k + 24, NovaCraftBlocks.nullstone_brick_wall, 0, 2);
        world.setBlock(i + 21, j + 7, k + 25, NovaCraftBlocks.nullstone_brick_wall, 0, 2);
        world.setBlock(i + 31, j + 7, k + 25, NovaCraftBlocks.nullstone, 0, 2);
        world.setBlock(i + 32, j + 7, k + 25, NovaCraftBlocks.sculk_block, 0, 2);
        world.setBlock(i + 33, j + 7, k + 25, NovaCraftBlocks.sculk_block, 0, 2);
        world.setBlock(i + 34, j + 7, k + 25, NovaCraftBlocks.sculk_block, 0, 2);
        world.setBlock(i + 35, j + 7, k + 25, NovaCraftBlocks.sculk_block, 0, 2);
        world.setBlock(i + 36, j + 7, k + 25, NovaCraftBlocks.sculk_block, 0, 2);
        world.setBlock(i + 37, j + 7, k + 25, NovaCraftBlocks.sculk_block, 0, 2);
        world.setBlock(i + 38, j + 7, k + 25, NovaCraftBlocks.sculk_block, 0, 2);
        world.setBlock(i + 39, j + 7, k + 25, NovaCraftBlocks.nullstone, 0, 2);
        world.setBlock(i + 49, j + 7, k + 25, NovaCraftBlocks.nullstone_brick_wall, 0, 2);
        world.setBlock(i + 19, j + 7, k + 26, NovaCraftBlocks.carved_vanite_bricks, 0, 2);
        world.setBlock(i + 20, j + 7, k + 26, NovaCraftBlocks.carved_vanite_bricks, 0, 2);
        world.setBlock(i + 21, j + 7, k + 26, NovaCraftBlocks.nullstone_brick_wall, 0, 2);
        world.setBlock(i + 31, j + 7, k + 26, NovaCraftBlocks.nullstone, 0, 2);
        world.setBlock(i + 32, j + 7, k + 26, NovaCraftBlocks.sculk_block, 0, 2);
        world.setBlock(i + 33, j + 7, k + 26, NovaCraftBlocks.sculk_bricks, 0, 2);
        world.setBlock(i + 34, j + 7, k + 26, NovaCraftBlocks.budding_echo_block, 0, 2);
        world.setBlock(i + 35, j + 7, k + 26, NovaCraftBlocks.budding_echo_block, 0, 2);
        world.setBlock(i + 36, j + 7, k + 26, NovaCraftBlocks.budding_echo_block, 0, 2);
        world.setBlock(i + 37, j + 7, k + 26, NovaCraftBlocks.sculk_bricks, 0, 2);
        world.setBlock(i + 38, j + 7, k + 26, NovaCraftBlocks.sculk_block, 0, 2);
        world.setBlock(i + 39, j + 7, k + 26, NovaCraftBlocks.nullstone, 0, 2);
        world.setBlock(i + 49, j + 7, k + 26, NovaCraftBlocks.nullstone_brick_wall, 0, 2);
        world.setBlock(i + 50, j + 7, k + 26, NovaCraftBlocks.nullstone_brick_wall, 0, 2);
        world.setBlock(i + 51, j + 7, k + 26, NovaCraftBlocks.nullstone_brick_wall, 0, 2);
        world.setBlock(i + 52, j + 7, k + 26, NovaCraftBlocks.nullstone_brick_wall, 0, 2);
        world.setBlock(i + 18, j + 7, k + 27, placeStoneBricks(random), 0, 2);
        world.setBlock(i + 19, j + 7, k + 27, placeStoneBricks(random), 0, 2);
        world.setBlock(i + 20, j + 7, k + 27, NovaCraftBlocks.nullstone_brick_stairs, 1, 2);
        world.setBlock(i + 31, j + 7, k + 27, NovaCraftBlocks.nullstone, 0, 2);
        world.setBlock(i + 32, j + 7, k + 27, NovaCraftBlocks.sculk_block, 0, 2);
        world.setBlock(i + 33, j + 7, k + 27, NovaCraftBlocks.budding_echo_block, 0, 2);
        world.setBlock(i + 34, j + 7, k + 27, NovaCraftBlocks.sculk_bricks, 0, 2);
        world.setBlock(i + 35, j + 7, k + 27, NovaCraftBlocks.sculk_bricks, 0, 2);
        world.setBlock(i + 36, j + 7, k + 27, NovaCraftBlocks.sculk_bricks, 0, 2);
        world.setBlock(i + 37, j + 7, k + 27, NovaCraftBlocks.budding_echo_block, 0, 2);
        world.setBlock(i + 38, j + 7, k + 27, NovaCraftBlocks.sculk_block, 0, 2);
        world.setBlock(i + 39, j + 7, k + 27, NovaCraftBlocks.nullstone, 0, 2);
        world.setBlock(i + 18, j + 7, k + 28, placeStoneBricks(random), 0, 2);
        world.setBlock(i + 19, j + 7, k + 28, placeStoneBricks(random), 0, 2);
        world.setBlock(i + 20, j + 7, k + 28, NovaCraftBlocks.nullstone_brick_stairs, 1, 2);
        world.setBlock(i + 31, j + 7, k + 28, NovaCraftBlocks.block_of_vanite, 0, 2);
        world.setBlock(i + 32, j + 7, k + 28, NovaCraftBlocks.sculk_block, 0, 2);
        world.setBlock(i + 33, j + 7, k + 28, NovaCraftBlocks.budding_echo_block, 0, 2);
        world.setBlock(i + 34, j + 7, k + 28, NovaCraftBlocks.sculk_bricks, 0, 2);
        world.setBlock(i + 35, j + 7, k + 28, NovaCraftBlocks.sculk_bricks, 0, 2);
        world.setBlock(i + 36, j + 7, k + 28, NovaCraftBlocks.sculk_bricks, 0, 2);
        world.setBlock(i + 37, j + 7, k + 28, NovaCraftBlocks.budding_echo_block, 0, 2);
        world.setBlock(i + 38, j + 7, k + 28, NovaCraftBlocks.sculk_block, 0, 2);
        world.setBlock(i + 39, j + 7, k + 28, NovaCraftBlocks.crystallized_end, 0, 2);
        world.setBlock(i + 18, j + 7, k + 29, placeStoneBricks(random), 0, 2);
        world.setBlock(i + 19, j + 7, k + 29, NovaCraftBlocks.sculk_block, 0, 2);
        world.setBlock(i + 20, j + 7, k + 29, NovaCraftBlocks.nullstone_brick_stairs, 1, 2);
        world.setBlock(i + 31, j + 7, k + 29, NovaCraftBlocks.nullstone, 0, 2);
        world.setBlock(i + 32, j + 7, k + 29, NovaCraftBlocks.sculk_block, 0, 2);
