package com.NovaCraft.world.ancient_city;

import com.NovaCraft.config.ConfigsCompact;
import cpw.mods.fml.common.registry.GameRegistry;
import net.minecraft.world.gen.feature.*;
import net.minecraft.block.*;
import net.minecraft.world.*;
import java.util.*;
import com.NovaCraft.config.Configs;
import com.NovaCraft.registry.OtherModBlocks;
import com.NovaCraftBlocks.NovaCraftBlocks;
import cpw.mods.fml.common.Loader;
import net.minecraft.init.*;

public class AncientCityPositiveXHallwayRightGen1 extends WorldGenerator
{
	public AncientCityPositiveXHallwayRightGen1() {

	}
	
	private Block PlaceDeepslate;
	private Block PlaceDeepslateBricks;
	private Block PlaceDeepslateTiles;
	private Block PlaceCrackedDeepslateTiles;
	private Block PlaceCrackedDeepslateBricks;
	private Block PlacePolishedDeepslate;
	private Block PlaceBasalt;
	private Block PlaceDeepslateTileStairs;
	private Block PlaceDeepslateBrickStairs;

	private Block determineIfDeepslateExists(World world, int x, int y, int z) {
		Block existingBlock = world.getBlock(x, y, z);
		if (ConfigsCompact.enableDeepslate && Loader.isModLoaded("etfuturum")) {
			try {
				Block deepslate = GameRegistry.findBlock("etfuturum", "deepslate");
				if (deepslate != null && (existingBlock == null || existingBlock != deepslate)) {
					return deepslate;
				}
			} catch (Exception ex) {
				if (Configs.enableDebugMode) {
					System.out.println("Missing Deepslate from Et Futurum Requiem, using Grimstone instead...");
				}
				return NovaCraftBlocks.grimstone;
			}
		}

		return NovaCraftBlocks.grimstone;
	}

	private Block determineIfDeepslateBricksExists(World world, int x, int y, int z) {
		Block existingBlock = world.getBlock(x, y, z);
		if (ConfigsCompact.enableDeepslateBricks && Loader.isModLoaded("etfuturum")) {
			try {
				Block deepslate_bricks = GameRegistry.findBlock("etfuturum", "deepslate_bricks");
				if (deepslate_bricks != null && (existingBlock == null || existingBlock != deepslate_bricks)) {
					return deepslate_bricks;
				}
			} catch (Exception ex) {
				if (Configs.enableDebugMode) {
					System.out.println("Missing Deepslate Bricks from Et Futurum Requiem, using Grimstone Bricks instead...");
				}
				return NovaCraftBlocks.grimstone_bricks;
			}
		}

		return NovaCraftBlocks.grimstone_bricks;
	}

	private Block determineIfCrackedDeepslateBricksExists(World world, int x, int y, int z) {
		Block existingBlock = world.getBlock(x, y, z);
		if (ConfigsCompact.enableDeepslateBricks && Loader.isModLoaded("etfuturum")) {
			try {
				Block deepslate_bricks = GameRegistry.findBlock("etfuturum", "deepslate_bricks");
				if (deepslate_bricks != null && (existingBlock == null || existingBlock != deepslate_bricks)) {
					return deepslate_bricks;
				}
			} catch (Exception ex) {
				if (Configs.enableDebugMode) {
					System.out.println("Missing Cracked Deepslate Bricks from Et Futurum Requiem, using Cracked Grimstone Bricks instead...");
				}
				return NovaCraftBlocks.cracked_grimstone_bricks;
			}
		}

		return NovaCraftBlocks.cracked_grimstone_bricks;
	}

	private Block determineIfDeepslateTilesExist(World world, int x, int y, int z) {
		Block existingBlock = world.getBlock(x, y, z);
		if (ConfigsCompact.enableDeepslateBricks && Loader.isModLoaded("etfuturum")) {
			try {
				Block deepslate_bricks = GameRegistry.findBlock("etfuturum", "deepslate_bricks");
				if (deepslate_bricks != null && (existingBlock == null || existingBlock != deepslate_bricks)) {
					return deepslate_bricks;
				}
			} catch (Exception ex) {
				if (Configs.enableDebugMode) {
					System.out.println("Missing Deepslate Tiles from Et Futurum Requiem, using Grimstone Tiles instead...");
				}
				return NovaCraftBlocks.grimstone_tiles;
			}
		}

		return NovaCraftBlocks.grimstone_tiles;
	}

	private Block determineIfCrackedDeepslateTilesExist(World world, int x, int y, int z) {
		Block existingBlock = world.getBlock(x, y, z);
		if (ConfigsCompact.enableDeepslateBricks && Loader.isModLoaded("etfuturum")) {
			try {
				Block deepslate_bricks = GameRegistry.findBlock("etfuturum", "deepslate_bricks");
				if (deepslate_bricks != null && (existingBlock == null || existingBlock != deepslate_bricks)) {
					return deepslate_bricks;
				}
			} catch (Exception ex) {
				if (Configs.enableDebugMode) {
					System.out.println("Missing Cracked Deepslate Tiles from Et Futurum Requiem, using Cracked Grimstone Tiles instead...");
				}
				return NovaCraftBlocks.cracked_grimstone_tiles;
			}
		}

		return NovaCraftBlocks.cracked_grimstone_tiles;
	}

	private Block determineIfPolishedDeepslateExists(World world, int x, int y, int z) {
		Block existingBlock = world.getBlock(x, y, z);
		if (ConfigsCompact.enableDeepslateBricks && Loader.isModLoaded("etfuturum")) {
			try {
				Block polished_deepslate = GameRegistry.findBlock("etfuturum", "polished_deepslate");
				if (polished_deepslate != null && (existingBlock == null || existingBlock != polished_deepslate)) {
					return polished_deepslate;
				}
			} catch (Exception ex) {
				if (Configs.enableDebugMode) {
					System.out.println("Missing Polished Deepslate from Et Futurum Requiem, using Polished Grimstone instead...");
				}
				return NovaCraftBlocks.polished_grimstone;
			}
		}

		return NovaCraftBlocks.polished_grimstone;
	}

	private Block determineIfDeepslateTileStairsExists(World world, int x, int y, int z) {
		Block existingBlock = world.getBlock(x, y, z);
		if (ConfigsCompact.enableDeepslateBricks && Loader.isModLoaded("etfuturum")) {
			try {
				Block deepslate_tile_stairs = GameRegistry.findBlock("etfuturum", "deepslate_tile_stairs");
				if (deepslate_tile_stairs != null && (existingBlock == null || existingBlock != deepslate_tile_stairs)) {
					return deepslate_tile_stairs;
				}
			} catch (Exception ex) {
				if (Configs.enableDebugMode) {
					System.out.println("Missing Deepslate Tile Stairs from Et Futurum Requiem, using Grimstone Tile Stairs instead...");
				}
				return NovaCraftBlocks.grimstone_tiled_stairs;
			}
		}

		return NovaCraftBlocks.grimstone_tiled_stairs;
	}

	private Block determineIfBasaltExists(World world, int x, int y, int z) {
		Block existingBlock = world.getBlock(x, y, z);

		if (!(ConfigsCompact.disableBasalt) && Loader.isModLoaded("netherlicious")) {
			try {
				Block nether_Basalt = GameRegistry.findBlock("netherlicious", "Basalt");
				if (nether_Basalt != null && (existingBlock == null || existingBlock != nether_Basalt)) {
					return nether_Basalt;
				}
			} catch (Exception ex) {
				if (Configs.enableDebugMode) {
					System.out.println("Failed to Find Netherlicious basalt, trying Et Futurum Requiem...");
				}
			}
		}

		if (Loader.isModLoaded("etfuturum")) {
			try {
				Block et_basalt = GameRegistry.findBlock("etfuturum", "basalt");
				if (et_basalt != null && (existingBlock == null || existingBlock != et_basalt)) {
					return et_basalt;
				}
			} catch (Exception ex) {
				if (Configs.enableDebugMode) {
					System.out.println("Failed to Find Et Futurum Requiem basalt, placing Polished Vanite Bricks...");
				}
			}
		}

		return NovaCraftBlocks.polished_vanite_bricks;
	}

	private Block determineIfDeepslateBrickStairsExists(World world, int x, int y, int z) {
		Block existingBlock = world.getBlock(x, y, z);
		if (ConfigsCompact.enableDeepslateBricks && Loader.isModLoaded("etfuturum")) {
			try {
				Block deepslate_brick_stairs = GameRegistry.findBlock("etfuturum", "deepslate_brick_stairs");
				if (deepslate_brick_stairs != null && (existingBlock == null || existingBlock != deepslate_brick_stairs)) {
					return deepslate_brick_stairs;
				}
			} catch (Exception ex) {
				if (Configs.enableDebugMode) {
					System.out.println("Missing Deepslate Tile Stairs from Et Futurum Requiem, using Grimstone Tile Stairs instead...");
				}
				return NovaCraftBlocks.grimstone_brick_stairs;
			}
		}

		return NovaCraftBlocks.grimstone_brick_stairs;
	}
    
    public boolean generate(final World world, final Random random, final int i, final int j, final int k) {
    	PlaceDeepslate = determineIfDeepslateExists(world, i + 5, j, k);
    	PlaceBasalt = determineIfBasaltExists(world, i, j, k);
    	
    	PlaceDeepslateBricks = determineIfDeepslateBricksExists(world, i + 4, j + 2, k + 8);
    	PlaceCrackedDeepslateBricks = determineIfCrackedDeepslateBricksExists(world, i + 14, j + 2, k + 8);
    	PlaceDeepslateTiles = determineIfDeepslateTilesExist(world, i + 26, j, k);
    	PlaceCrackedDeepslateTiles = determineIfCrackedDeepslateTilesExist(world, i + 27, j, k);
    	PlacePolishedDeepslate = determineIfPolishedDeepslateExists(world, i + 45, j + 1, k + 3);
    	
    	PlaceDeepslateTileStairs = determineIfDeepslateTileStairsExists(world, i + 5, j + 1, k + 3);
    	PlaceDeepslateBrickStairs = determineIfDeepslateBrickStairsExists(world, i + 13, j + 2, k + 8);
    	
		world.setBlock(i, j, k, PlaceBasalt, 1, 2);
		world.setBlock(i + 1, j, k, PlaceBasalt, 5, 2);
		world.setBlock(i + 2, j, k, PlaceBasalt, 5, 2);
		world.setBlock(i + 3, j, k, PlaceBasalt, 5, 2);
		world.setBlock(i + 4, j, k, PlaceBasalt, 1, 2);
		world.setBlock(i + 5, j, k, PlaceDeepslate, 0, 2);
		world.setBlock(i + 6, j, k, NovaCraftBlocks.sculk_block, 0, 2);
		world.setBlock(i + 7, j, k, PlaceBasalt, 1, 2);
		world.setBlock(i + 8, j, k, PlaceBasalt, 5, 2);
		world.setBlock(i + 9, j, k, PlaceBasalt, 5, 2);
		world.setBlock(i + 10, j, k, PlaceBasalt, 5, 2);
		world.setBlock(i + 11, j, k, PlaceBasalt, 5, 2);
		world.setBlock(i + 12, j, k, PlaceBasalt, 5, 2);
		world.setBlock(i + 13, j, k, PlaceBasalt, 5, 2);
		world.setBlock(i + 14, j, k, PlaceBasalt, 1, 2);
		world.setBlock(i + 15, j, k, NovaCraftBlocks.sculk_block, 0, 2);
		world.setBlock(i + 16, j, k, PlaceDeepslate, 0, 2);
		world.setBlock(i + 17, j, k, PlaceBasalt, 1, 2);
		world.setBlock(i + 18, j, k, PlaceBasalt, 5, 2);
		world.setBlock(i + 19, j, k, PlaceBasalt, 5, 2);
		world.setBlock(i + 20, j, k, PlaceBasalt, 5, 2);
		world.setBlock(i + 21, j, k, PlaceBasalt, 5, 2);
		world.setBlock(i + 22, j, k, PlaceBasalt, 5, 2);
		world.setBlock(i + 23, j, k, PlaceBasalt, 5, 2);
		world.setBlock(i + 24, j, k, PlaceBasalt, 1, 2);
		world.setBlock(i + 25, j, k, PlaceDeepslate, 0, 2);
		world.setBlock(i + 26, j, k, PlaceDeepslateTiles, 2, 2);
		world.setBlock(i + 27, j, k, PlaceCrackedDeepslateTiles, 3, 2);
		world.setBlock(i + 28, j, k, PlaceDeepslateTiles, 2, 2);
		world.setBlock(i + 29, j, k, PlaceDeepslateTiles, 2, 2);
		world.setBlock(i + 30, j, k, PlaceDeepslateTiles, 2, 2);
		world.setBlock(i + 31, j, k, PlaceCrackedDeepslateTiles, 3, 2);
		world.setBlock(i + 32, j, k, NovaCraftBlocks.sculk_block, 0, 2);
		world.setBlock(i + 33, j, k, PlaceDeepslateTiles, 2, 2);
		world.setBlock(i + 34, j, k, PlaceDeepslateTiles, 2, 2);
		world.setBlock(i + 35, j, k, PlaceDeepslateTiles, 2, 2);
		world.setBlock(i + 36, j, k, PlaceDeepslateTiles, 2, 2);
		world.setBlock(i + 37, j, k, PlaceDeepslateTiles, 2, 2);
		world.setBlock(i + 38, j, k, PlaceCrackedDeepslateTiles, 3, 2);
		world.setBlock(i + 39, j, k, PlaceCrackedDeepslateTiles, 3, 2);
		world.setBlock(i + 40, j, k, PlaceDeepslateTiles, 2, 2);
		world.setBlock(i + 41, j, k, PlaceDeepslateTiles, 2, 2);
		world.setBlock(i + 42, j, k, PlaceCrackedDeepslateTiles, 3, 2);
		world.setBlock(i + 43, j, k, PlaceDeepslateTiles, 2, 2);
		world.setBlock(i + 44, j, k, PlaceDeepslateTiles, 2, 2);
		world.setBlock(i + 45, j, k, PlaceDeepslateTiles, 2, 2);
		world.setBlock(i + 46, j, k, PlaceDeepslateTiles, 2, 2);
		world.setBlock(i + 47, j, k, PlaceCrackedDeepslateTiles, 3, 2);
		world.setBlock(i + 48, j, k, PlaceDeepslateTiles, 2, 2);
		world.setBlock(i + 49, j, k, PlaceCrackedDeepslateTiles, 3, 2);
		world.setBlock(i + 50, j, k, PlaceDeepslateTiles, 2, 2);
		world.setBlock(i + 51, j, k, PlaceDeepslateTiles, 2, 2);
		world.setBlock(i + 52, j, k, PlaceDeepslateTiles, 2, 2);
		world.setBlock(i + 53, j, k, PlaceCrackedDeepslateTiles, 3, 2);
		world.setBlock(i + 54, j, k, PlaceCrackedDeepslateTiles, 3, 2);
		world.setBlock(i + 55, j, k, PlaceCrackedDeepslateTiles, 3, 2);
		world.setBlock(i + 56, j, k, PlaceDeepslateTiles, 2, 2);
		world.setBlock(i + 57, j, k, Blocks.air, 0, 2);
		world.setBlock(i + 58, j, k, Blocks.air, 0, 2);
		world.setBlock(i, j, k + 1, PlaceBasalt, 9, 2);
		world.setBlock(i + 1, j, k + 1, PlaceDeepslate, 0, 2);
		world.setBlock(i + 2, j, k + 1, PlaceDeepslate, 0, 2);
		world.setBlock(i + 3, j, k + 1, PlaceDeepslate, 0, 2);
		world.setBlock(i + 4, j, k + 1, PlaceDeepslate, 0, 2);
		world.setBlock(i + 5, j, k + 1, PlaceDeepslate, 0, 2);
		world.setBlock(i + 6, j, k + 1, PlaceDeepslate, 0, 2);
		world.setBlock(i + 7, j, k + 1, PlaceDeepslate, 0, 2);
		world.setBlock(i + 8, j, k + 1, PlaceDeepslate, 0, 2);
		world.setBlock(i + 9, j, k + 1, PlaceDeepslate, 0, 2);
		world.setBlock(i + 10, j, k + 1, PlaceDeepslate, 0, 2);
		world.setBlock(i + 11, j, k + 1, PlaceDeepslate, 0, 2);
		world.setBlock(i + 12, j, k + 1, PlaceDeepslate, 0, 2);
		world.setBlock(i + 13, j, k + 1, PlaceDeepslate, 0, 2);
		world.setBlock(i + 14, j, k + 1, PlaceDeepslate, 0, 2);
		world.setBlock(i + 15, j, k + 1, PlaceDeepslate, 0, 2);
		world.setBlock(i + 16, j, k + 1, PlaceDeepslate, 0, 2);
		world.setBlock(i + 17, j, k + 1, PlaceDeepslate, 0, 2);
		world.setBlock(i + 18, j, k + 1, PlaceDeepslate, 0, 2);
		world.setBlock(i + 19, j, k + 1, PlaceDeepslate, 0, 2);
		world.setBlock(i + 20, j, k + 1, PlaceDeepslate, 0, 2);
		world.setBlock(i + 21, j, k + 1, PlaceDeepslate, 0, 2);
		world.setBlock(i + 22, j, k + 1, PlaceDeepslate, 0, 2);
		world.setBlock(i + 23, j, k + 1, PlaceDeepslate, 0, 2);
		world.setBlock(i + 24, j, k + 1, PlaceDeepslate, 0, 2);
		world.setBlock(i + 25, j, k + 1, PlaceDeepslate, 0, 2);
		world.setBlock(i + 26, j, k + 1, PlaceDeepslateTiles, 2, 2);
		world.setBlock(i + 27, j, k + 1, PlaceDeepslateTiles, 2, 2);
		world.setBlock(i + 28, j, k + 1, PlaceCrackedDeepslateTiles, 3, 2);
		world.setBlock(i + 29, j, k + 1, PlaceDeepslateTiles, 2, 2);
		world.setBlock(i + 30, j, k + 1, PlaceDeepslateTiles, 2, 2);
		world.setBlock(i + 31, j, k + 1, PlaceCrackedDeepslateTiles, 3, 2);
		world.setBlock(i + 32, j, k + 1, PlaceDeepslateTiles, 2, 2);
		world.setBlock(i + 33, j, k + 1, PlaceDeepslateTiles, 2, 2);
		world.setBlock(i + 34, j, k + 1, PlaceDeepslateTiles, 2, 2);
		world.setBlock(i + 35, j, k + 1, Blocks.air, 0, 2);
		world.setBlock(i + 36, j, k + 1, PlaceDeepslateTiles, 2, 2);
		world.setBlock(i + 37, j, k + 1, PlaceDeepslateTiles, 2, 2);
		world.setBlock(i + 38, j, k + 1, PlaceDeepslateTiles, 2, 2);
		world.setBlock(i + 39, j, k + 1, PlaceDeepslateTiles, 2, 2);
		world.setBlock(i + 40, j, k + 1, PlaceDeepslateTiles, 2, 2);
		world.setBlock(i + 41, j, k + 1, PlaceDeepslateTiles, 2, 2);
		world.setBlock(i + 42, j, k + 1, PlaceDeepslateTiles, 2, 2);
		world.setBlock(i + 43, j, k + 1, PlaceDeepslateTiles, 2, 2);
		world.setBlock(i + 44, j, k + 1, Blocks.air, 0, 2);
		world.setBlock(i + 45, j, k + 1, PlaceDeepslateTiles, 2, 2);
		world.setBlock(i + 46, j, k + 1, PlaceDeepslateTiles, 2, 2);
		world.setBlock(i + 47, j, k + 1, PlaceDeepslateTiles, 2, 2);
		world.setBlock(i + 48, j, k + 1, PlaceDeepslateTiles, 2, 2);
		world.setBlock(i + 49, j, k + 1, PlaceDeepslateTiles, 2, 2);
		world.setBlock(i + 50, j, k + 1, PlaceDeepslateTiles, 2, 2);
		world.setBlock(i + 51, j, k + 1, PlaceDeepslateTiles, 2, 2);
		world.setBlock(i + 52, j, k + 1, PlaceDeepslateTiles, 2, 2);
		world.setBlock(i + 53, j, k + 1, PlaceDeepslateTiles, 2, 2);
		world.setBlock(i + 54, j, k + 1, PlaceDeepslateTiles, 2, 2);
		world.setBlock(i + 55, j, k + 1, PlaceDeepslateTiles, 2, 2);
		world.setBlock(i + 56, j, k + 1, PlaceDeepslateTiles, 2, 2);
		world.setBlock(i + 57, j, k + 1, Blocks.air, 0, 2);
		world.setBlock(i + 58, j, k + 1, Blocks.air, 0, 2);
		world.setBlock(i, j, k + 2, PlaceBasalt, 9, 2);
		world.setBlock(i + 1, j, k + 2, PlaceDeepslate, 0, 2);
		world.setBlock(i + 2, j, k + 2, PlaceDeepslate, 0, 2);
		world.setBlock(i + 3, j, k + 2, PlaceDeepslate, 0, 2);
		world.setBlock(i + 4, j, k + 2, PlaceDeepslate, 0, 2);
		world.setBlock(i + 5, j, k + 2, PlaceDeepslate, 0, 2);
		world.setBlock(i + 6, j, k + 2, PlaceDeepslate, 0, 2);
		world.setBlock(i + 7, j, k + 2, PlaceDeepslate, 0, 2);
		world.setBlock(i + 8, j, k + 2, PlaceDeepslate, 0, 2);
		world.setBlock(i + 9, j, k + 2, PlaceDeepslate, 0, 2);
		world.setBlock(i + 10, j, k + 2, NovaCraftBlocks.sculk_block, 0, 2);
		world.setBlock(i + 11, j, k + 2, PlaceDeepslate, 0, 2);
		world.setBlock(i + 12, j, k + 2, PlaceDeepslate, 0, 2);
		world.setBlock(i + 13, j, k + 2, PlaceDeepslate, 0, 2);
		world.setBlock(i + 14, j, k + 2, PlaceDeepslate, 0, 2);
		world.setBlock(i + 15, j, k + 2, PlaceDeepslate, 0, 2);
		world.setBlock(i + 16, j, k + 2, PlaceDeepslate, 0, 2);
		world.setBlock(i + 17, j, k + 2, PlaceDeepslate, 0, 2);
		world.setBlock(i + 18, j, k + 2, PlaceDeepslate, 0, 2);
		world.setBlock(i + 19, j, k + 2, PlaceDeepslate, 0, 2);
		world.setBlock(i + 20, j, k + 2, PlaceDeepslate, 0, 2);
		world.setBlock(i + 21, j, k + 2, PlaceDeepslate, 0, 2);
		world.setBlock(i + 22, j, k + 2, PlaceDeepslate, 0, 2);
		world.setBlock(i + 23, j, k + 2, PlaceDeepslate, 0, 2);
		world.setBlock(i + 24, j, k + 2, PlaceDeepslate, 0, 2);
		world.setBlock(i + 25, j, k + 2, PlaceDeepslate, 0, 2);
		world.setBlock(i + 26, j, k + 2, PlaceDeepslateTiles, 2, 2);
		world.setBlock(i + 27, j, k + 2, PlaceCrackedDeepslateTiles, 3, 2);
		world.setBlock(i + 28, j, k + 2, PlaceCrackedDeepslateTiles, 3, 2);
		world.setBlock(i + 29, j, k + 2, PlaceDeepslateTiles, 2, 2);
		world.setBlock(i + 30, j, k + 2, PlaceCrackedDeepslateTiles, 3, 2);
		world.setBlock(i + 31, j, k + 2, PlaceDeepslateTiles, 2, 2);
		world.setBlock(i + 32, j, k + 2, PlaceCrackedDeepslateTiles, 3, 2);
		world.setBlock(i + 33, j, k + 2, PlaceDeepslateTiles, 2, 2);
		world.setBlock(i + 34, j, k + 2, PlaceCrackedDeepslateTiles, 3, 2);
		world.setBlock(i + 35, j, k + 2, PlaceDeepslateTiles, 2, 2);
		world.setBlock(i + 36, j, k + 2, PlaceCrackedDeepslateTiles, 3, 2);
		world.setBlock(i + 37, j, k + 2, PlaceDeepslateTiles, 2, 2);
		world.setBlock(i + 38, j, k + 2, PlaceDeepslateTiles, 2, 2);
		world.setBlock(i + 39, j, k + 2, NovaCraftBlocks.sculk_block, 0, 2);
		world.setBlock(i + 40, j, k + 2, PlaceDeepslateTiles, 2, 2);
		world.setBlock(i + 41, j, k + 2, PlaceDeepslateTiles, 2, 2);
		world.setBlock(i + 42, j, k + 2, PlaceCrackedDeepslateTiles, 3, 2);
		world.setBlock(i + 43, j, k + 2, PlaceCrackedDeepslateTiles, 3, 2);
		world.setBlock(i + 44, j, k + 2, PlaceCrackedDeepslateTiles, 3, 2);
		world.setBlock(i + 45, j, k + 2, PlaceCrackedDeepslateTiles, 3, 2);
		world.setBlock(i + 46, j, k + 2, PlaceCrackedDeepslateTiles, 3, 2);
		world.setBlock(i + 47, j, k + 2, PlaceDeepslateTiles, 2, 2);
		world.setBlock(i + 48, j, k + 2, PlaceDeepslateTiles, 2, 2);
		world.setBlock(i + 49, j, k + 2, PlaceCrackedDeepslateTiles, 3, 2);
		world.setBlock(i + 50, j, k + 2, PlaceDeepslateTiles, 2, 2);
		world.setBlock(i + 51, j, k + 2, PlaceDeepslateTiles, 2, 2);
		world.setBlock(i + 52, j, k + 2, NovaCraftBlocks.sculk_block, 0, 2);
		world.setBlock(i + 53, j, k + 2, Blocks.air, 0, 2);
		world.setBlock(i + 54, j, k + 2, PlaceCrackedDeepslateTiles, 3, 2);
		world.setBlock(i + 55, j, k + 2, PlaceDeepslateTiles, 2, 2);
		world.setBlock(i + 56, j, k + 2, Blocks.air, 0, 2);
		world.setBlock(i + 57, j, k + 2, Blocks.air, 0, 2);
		world.setBlock(i + 58, j, k + 2, Blocks.air, 0, 2);
		world.setBlock(i, j, k + 3, PlaceBasalt, 9, 2);
		world.setBlock(i + 1, j, k + 3, PlaceDeepslate, 0, 2);
		world.setBlock(i + 2, j, k + 3, PlaceDeepslate, 0, 2);
		world.setBlock(i + 3, j, k + 3, PlaceDeepslate, 0, 2);
		world.setBlock(i + 4, j, k + 3, PlaceDeepslate, 0, 2);
		world.setBlock(i + 5, j, k + 3, PlaceDeepslate, 0, 2);
		world.setBlock(i + 6, j, k + 3, PlaceDeepslate, 0, 2);
		world.setBlock(i + 7, j, k + 3, PlaceDeepslate, 0, 2);
		world.setBlock(i + 8, j, k + 3, PlaceDeepslate, 0, 2);
		world.setBlock(i + 9, j, k + 3, PlaceDeepslate, 0, 2);
		world.setBlock(i + 10, j, k + 3, PlaceDeepslate, 0, 2);
		world.setBlock(i + 11, j, k + 3, PlaceDeepslate, 0, 2);
		world.setBlock(i + 12, j, k + 3, PlaceDeepslate, 0, 2);
		world.setBlock(i + 13, j, k + 3, NovaCraftBlocks.sculk_block, 0, 2);
		world.setBlock(i + 14, j, k + 3, PlaceDeepslate, 0, 2);
		world.setBlock(i + 15, j, k + 3, PlaceDeepslate, 0, 2);
		world.setBlock(i + 16, j, k + 3, PlaceDeepslate, 0, 2);
		world.setBlock(i + 17, j, k + 3, PlaceDeepslate, 0, 2);
		world.setBlock(i + 18, j, k + 3, PlaceDeepslate, 0, 2);
		world.setBlock(i + 19, j, k + 3, PlaceDeepslate, 0, 2);
		world.setBlock(i + 20, j, k + 3, PlaceDeepslate, 0, 2);
		world.setBlock(i + 21, j, k + 3, PlaceDeepslate, 0, 2);
		world.setBlock(i + 22, j, k + 3, PlaceDeepslate, 0, 2);
		world.setBlock(i + 23, j, k + 3, PlaceDeepslate, 0, 2);
		world.setBlock(i + 24, j, k + 3, PlaceDeepslate, 0, 2);
		world.setBlock(i + 25, j, k + 3, PlaceDeepslate, 0, 2);
		world.setBlock(i + 26, j, k + 3, PlaceCrackedDeepslateTiles, 3, 2);
		world.setBlock(i + 27, j, k + 3, PlaceDeepslateTiles, 2, 2);
		world.setBlock(i + 28, j, k + 3, PlaceDeepslateTiles, 2, 2);
		world.setBlock(i + 29, j, k + 3, PlaceDeepslateTiles, 2, 2);
		world.setBlock(i + 30, j, k + 3, PlaceDeepslateTiles, 2, 2);
		world.setBlock(i + 31, j, k + 3, PlaceCrackedDeepslateTiles, 3, 2);
		world.setBlock(i + 32, j, k + 3, PlaceCrackedDeepslateTiles, 3, 2);
		world.setBlock(i + 33, j, k + 3, PlaceDeepslateTiles, 2, 2);
		world.setBlock(i + 34, j, k + 3, PlaceDeepslateTiles, 2, 2);
		world.setBlock(i + 35, j, k + 3, PlaceDeepslateTiles, 2, 2);
		world.setBlock(i + 36, j, k + 3, PlaceDeepslateTiles, 2, 2);
		world.setBlock(i + 37, j, k + 3, PlaceDeepslateTiles, 2, 2);
		world.setBlock(i + 38, j, k + 3, PlaceCrackedDeepslateTiles, 3, 2);
		world.setBlock(i + 39, j, k + 3, PlaceDeepslateTiles, 2, 2);
		world.setBlock(i + 40, j, k + 3, PlaceDeepslateTiles, 2, 2);
		world.setBlock(i + 41, j, k + 3, PlaceCrackedDeepslateTiles, 3, 2);
		world.setBlock(i + 42, j, k + 3, PlaceDeepslateTiles, 2, 2);
		world.setBlock(i + 43, j, k + 3, PlaceCrackedDeepslateTiles, 3, 2);
		world.setBlock(i + 44, j, k + 3, PlaceDeepslateTiles, 2, 2);
		world.setBlock(i + 45, j, k + 3, PlaceCrackedDeepslateTiles, 3, 2);
		world.setBlock(i + 46, j, k + 3, PlaceDeepslateTiles, 2, 2);
		world.setBlock(i + 47, j, k + 3, PlaceDeepslateTiles, 2, 2);
		world.setBlock(i + 48, j, k + 3, PlaceDeepslateTiles, 2, 2);
		world.setBlock(i + 49, j, k + 3, PlaceCrackedDeepslateTiles, 3, 2);
		world.setBlock(i + 50, j, k + 3, PlaceDeepslateTiles, 2, 2);
		world.setBlock(i + 51, j, k + 3, PlaceCrackedDeepslateTiles, 3, 2);
		world.setBlock(i + 52, j, k + 3, PlaceDeepslateTiles, 2, 2);
		world.setBlock(i + 53, j, k + 3, PlaceDeepslateTiles, 2, 2);
		world.setBlock(i + 54, j, k + 3, PlaceCrackedDeepslateTiles, 3, 2);
		world.setBlock(i + 55, j, k + 3, PlaceDeepslateTiles, 2, 2);
		world.setBlock(i + 56, j, k + 3, Blocks.air, 0, 2);
		world.setBlock(i + 57, j, k + 3, Blocks.air, 0, 2);
		world.setBlock(i + 58, j, k + 3, Blocks.air, 0, 2);
		world.setBlock(i, j, k + 4, PlaceBasalt, 9, 2);
		world.setBlock(i + 1, j, k + 4, PlaceDeepslate, 0, 2);
		world.setBlock(i + 2, j, k + 4, PlaceDeepslate, 0, 2);
		world.setBlock(i + 3, j, k + 4, PlaceDeepslate, 0, 2);
		world.setBlock(i + 4, j, k + 4, PlaceDeepslate, 0, 2);
		world.setBlock(i + 5, j, k + 4, PlaceDeepslate, 0, 2);
		world.setBlock(i + 6, j, k + 4, PlaceDeepslate, 0, 2);
		world.setBlock(i + 7, j, k + 4, PlaceDeepslate, 0, 2);
		world.setBlock(i + 8, j, k + 4, PlaceDeepslate, 0, 2);
		world.setBlock(i + 9, j, k + 4, PlaceDeepslate, 0, 2);
		world.setBlock(i + 10, j, k + 4, PlaceDeepslate, 0, 2);
		world.setBlock(i + 11, j, k + 4, PlaceDeepslate, 0, 2);
		world.setBlock(i + 12, j, k + 4, PlaceDeepslate, 0, 2);
		world.setBlock(i + 13, j, k + 4, PlaceDeepslate, 0, 2);
		world.setBlock(i + 14, j, k + 4, PlaceDeepslate, 0, 2);
		world.setBlock(i + 15, j, k + 4, PlaceDeepslate, 0, 2);
		world.setBlock(i + 16, j, k + 4, PlaceDeepslate, 0, 2);
		world.setBlock(i + 17, j, k + 4, PlaceDeepslate, 0, 2);
		world.setBlock(i + 18, j, k + 4, PlaceDeepslate, 0, 2);
		world.setBlock(i + 19, j, k + 4, PlaceDeepslate, 0, 2);
		world.setBlock(i + 20, j, k + 4, PlaceDeepslate, 0, 2);
		world.setBlock(i + 21, j, k + 4, PlaceDeepslate, 0, 2);
		world.setBlock(i + 22, j, k + 4, PlaceDeepslate, 0, 2);
		world.setBlock(i + 23, j, k + 4, PlaceDeepslate, 0, 2);
		world.setBlock(i + 24, j, k + 4, PlaceDeepslate, 0, 2);
		world.setBlock(i + 25, j, k + 4, PlaceDeepslate, 0, 2);
		world.setBlock(i + 26, j, k + 4, PlaceCrackedDeepslateTiles, 3, 2);
		world.setBlock(i + 27, j, k + 4, PlaceCrackedDeepslateTiles, 3, 2);
		world.setBlock(i + 28, j, k + 4, PlaceDeepslateTiles, 2, 2);
		world.setBlock(i + 29, j, k + 4, PlaceDeepslateTiles, 2, 2);
		world.setBlock(i + 30, j, k + 4, PlaceDeepslateTiles, 2, 2);
		world.setBlock(i + 31, j, k + 4, PlaceCrackedDeepslateTiles, 3, 2);
		world.setBlock(i + 32, j, k + 4, PlaceDeepslateTiles, 2, 2);
		world.setBlock(i + 33, j, k + 4, PlaceDeepslateTiles, 2, 2);
		world.setBlock(i + 34, j, k + 4, PlaceDeepslateTiles, 2, 2);
		world.setBlock(i + 35, j, k + 4, PlaceDeepslateTiles, 2, 2);
		world.setBlock(i + 36, j, k + 4, PlaceCrackedDeepslateTiles, 3, 2);
		world.setBlock(i + 37, j, k + 4, PlaceDeepslateTiles, 2, 2);
		world.setBlock(i + 38, j, k + 4, PlaceDeepslateTiles, 2, 2);
		world.setBlock(i + 39, j, k + 4, PlaceDeepslateTiles, 2, 2);
		world.setBlock(i + 40, j, k + 4, PlaceDeepslateTiles, 2, 2);
		world.setBlock(i + 41, j, k + 4, PlaceCrackedDeepslateTiles, 3, 2);
		world.setBlock(i + 42, j, k + 4, PlaceCrackedDeepslateTiles, 3, 2);
		world.setBlock(i + 43, j, k + 4, PlaceDeepslateTiles, 2, 2);
		world.setBlock(i + 44, j, k + 4, PlaceDeepslateTiles, 2, 2);
		world.setBlock(i + 45, j, k + 4, PlaceCrackedDeepslateTiles, 3, 2);
		world.setBlock(i + 46, j, k + 4, PlaceDeepslateTiles, 2, 2);
		world.setBlock(i + 47, j, k + 4, PlaceDeepslateTiles, 2, 2);
		world.setBlock(i + 48, j, k + 4, PlaceDeepslateTiles, 2, 2);
		world.setBlock(i + 49, j, k + 4, PlaceCrackedDeepslateTiles, 3, 2);
		world.setBlock(i + 50, j, k + 4, PlaceDeepslateTiles, 2, 2);
		world.setBlock(i + 51, j, k + 4, PlaceDeepslateTiles, 2, 2);
		world.setBlock(i + 52, j, k + 4, PlaceDeepslateTiles, 2, 2);
		world.setBlock(i + 53, j, k + 4, PlaceCrackedDeepslateTiles, 3, 2);
		world.setBlock(i + 54, j, k + 4, PlaceDeepslateTiles, 2, 2);
		world.setBlock(i + 55, j, k + 4, PlaceCrackedDeepslateTiles, 3, 2);
		world.setBlock(i + 56, j, k + 4, PlaceCrackedDeepslateTiles, 3, 2);
		world.setBlock(i + 57, j, k + 4, PlaceDeepslateTiles, 2, 2);
		world.setBlock(i + 58, j, k + 4, PlaceDeepslateTiles, 2, 2);
		world.setBlock(i, j, k + 5, PlaceBasalt, 9, 2);
		world.setBlock(i + 1, j, k + 5, PlaceDeepslate, 0, 2);
		world.setBlock(i + 2, j, k + 5, PlaceDeepslate, 0, 2);
		world.setBlock(i + 3, j, k + 5, PlaceDeepslate, 0, 2);
		world.setBlock(i + 4, j, k + 5, PlaceDeepslate, 0, 2);
		world.setBlock(i + 5, j, k + 5, PlaceDeepslate, 0, 2);
		world.setBlock(i + 6, j, k + 5, PlaceDeepslate, 0, 2);
		world.setBlock(i + 7, j, k + 5, PlaceDeepslate, 0, 2);
		world.setBlock(i + 8, j, k + 5, PlaceDeepslate, 0, 2);
		world.setBlock(i + 9, j, k + 5, PlaceDeepslate, 0, 2);
		world.setBlock(i + 10, j, k + 5, PlaceDeepslate, 0, 2);
		world.setBlock(i + 11, j, k + 5, PlaceDeepslate, 0, 2);
		world.setBlock(i + 12, j, k + 5, PlaceDeepslate, 0, 2);
		world.setBlock(i + 13, j, k + 5, PlaceDeepslate, 0, 2);
		world.setBlock(i + 14, j, k + 5, PlaceDeepslate, 0, 2);
		world.setBlock(i + 15, j, k + 5, Blocks.air, 0, 2);
		world.setBlock(i + 16, j, k + 5, PlaceDeepslate, 0, 2);
		world.setBlock(i + 17, j, k + 5, PlaceDeepslate, 0, 2);
		world.setBlock(i + 18, j, k + 5, PlaceDeepslate, 0, 2);
		world.setBlock(i + 19, j, k + 5, PlaceDeepslate, 0, 2);
		world.setBlock(i + 20, j, k + 5, PlaceDeepslate, 0, 2);
		world.setBlock(i + 21, j, k + 5, PlaceDeepslate, 0, 2);
		world.setBlock(i + 22, j, k + 5, PlaceDeepslate, 0, 2);
		world.setBlock(i + 23, j, k + 5, PlaceDeepslate, 0, 2);
		world.setBlock(i + 24, j, k + 5, PlaceDeepslate, 0, 2);
		world.setBlock(i + 25, j, k + 5, PlaceDeepslate, 0, 2);
		world.setBlock(i + 26, j, k + 5, PlaceDeepslateTiles, 2, 2);
		world.setBlock(i + 27, j, k + 5, PlaceCrackedDeepslateTiles, 3, 2);
		world.setBlock(i + 28, j, k + 5, PlaceDeepslateTiles, 2, 2);
		world.setBlock(i + 29, j, k + 5, PlaceCrackedDeepslateTiles, 3, 2);
		world.setBlock(i + 30, j, k + 5, PlaceDeepslateTiles, 2, 2);
		world.setBlock(i + 31, j, k + 5, PlaceDeepslateTiles, 2, 2);
		world.setBlock(i + 32, j, k + 5, PlaceDeepslateTiles, 2, 2);
		world.setBlock(i + 33, j, k + 5, PlaceDeepslateTiles, 2, 2);
		world.setBlock(i + 34, j, k + 5, PlaceDeepslateTiles, 2, 2);
		world.setBlock(i + 35, j, k + 5, PlaceCrackedDeepslateTiles, 3, 2);
		world.setBlock(i + 36, j, k + 5, PlaceDeepslateTiles, 2, 2);
		world.setBlock(i + 37, j, k + 5, PlaceDeepslateTiles, 2, 2);
		world.setBlock(i + 38, j, k + 5, PlaceCrackedDeepslateTiles, 3, 2);
		world.setBlock(i + 39, j, k + 5, PlaceDeepslateTiles, 2, 2);
		world.setBlock(i + 40, j, k + 5, PlaceDeepslateTiles, 2, 2);
		world.setBlock(i + 41, j, k + 5, Blocks.air, 0, 2);
		world.setBlock(i + 42, j, k + 5, PlaceDeepslateTiles, 2, 2);
		world.setBlock(i + 43, j, k + 5, Blocks.air, 0, 2);
		world.setBlock(i + 44, j, k + 5, Blocks.air, 0, 2);
		world.setBlock(i + 45, j, k + 5, Blocks.air, 0, 2);
		world.setBlock(i + 46, j, k + 5, Blocks.air, 0, 2);
		world.setBlock(i + 47, j, k + 5, Blocks.air, 0, 2);
		world.setBlock(i + 48, j, k + 5, PlaceCrackedDeepslateTiles, 3, 2);
		world.setBlock(i + 49, j, k + 5, PlaceDeepslateTiles, 2, 2);
		world.setBlock(i + 50, j, k + 5, PlaceDeepslateTiles, 2, 2);
		world.setBlock(i + 51, j, k + 5, PlaceDeepslateTiles, 2, 2);
		world.setBlock(i + 52, j, k + 5, PlaceCrackedDeepslateTiles, 3, 2);
		world.setBlock(i + 53, j, k + 5, PlaceDeepslateTiles, 2, 2);
		world.setBlock(i + 54, j, k + 5, NovaCraftBlocks.sculk_block, 0, 2);
		world.setBlock(i + 55, j, k + 5, PlaceDeepslateTiles, 2, 2);
		world.setBlock(i + 56, j, k + 5, PlaceDeepslateTiles, 2, 2);
		world.setBlock(i + 57, j, k + 5, Blocks.air, 0, 2);
		world.setBlock(i + 58, j, k + 5, Blocks.air, 0, 2);
		world.setBlock(i, j, k + 6, PlaceBasalt, 9, 2);
		world.setBlock(i + 1, j, k + 6, PlaceDeepslate, 0, 2);
		world.setBlock(i + 2, j, k + 6, PlaceDeepslate, 0, 2);
		world.setBlock(i + 3, j, k + 6, PlaceDeepslate, 0, 2);
		world.setBlock(i + 4, j, k + 6, PlaceDeepslate, 0, 2);
		world.setBlock(i + 5, j, k + 6, PlaceDeepslate, 0, 2);
		world.setBlock(i + 6, j, k + 6, PlaceDeepslate, 0, 2);
		world.setBlock(i + 7, j, k + 6, PlaceDeepslate, 0, 2);
		world.setBlock(i + 8, j, k + 6, PlaceDeepslate, 0, 2);
		world.setBlock(i + 9, j, k + 6, PlaceDeepslate, 0, 2);
		world.setBlock(i + 10, j, k + 6, PlaceDeepslate, 0, 2);
		world.setBlock(i + 11, j, k + 6, PlaceDeepslate, 0, 2);
		world.setBlock(i + 12, j, k + 6, PlaceDeepslate, 0, 2);
		world.setBlock(i + 13, j, k + 6, PlaceDeepslate, 0, 2);
		world.setBlock(i + 14, j, k + 6, PlaceDeepslate, 0, 2);
		world.setBlock(i + 15, j, k + 6, PlaceDeepslate, 0, 2);
		world.setBlock(i + 16, j, k + 6, PlaceDeepslate, 0, 2);
		world.setBlock(i + 17, j, k + 6, PlaceDeepslate, 0, 2);
		world.setBlock(i + 18, j, k + 6, PlaceDeepslate, 0, 2);
		world.setBlock(i + 19, j, k + 6, PlaceDeepslate, 0, 2);
		world.setBlock(i + 20, j, k + 6, PlaceDeepslate, 0, 2);
		world.setBlock(i + 21, j, k + 6, PlaceDeepslate, 0, 2);
		world.setBlock(i + 22, j, k + 6, PlaceDeepslate, 0, 2);
		world.setBlock(i + 23, j, k + 6, PlaceDeepslate, 0, 2);
		world.setBlock(i + 24, j, k + 6, PlaceDeepslate, 0, 2);
		world.setBlock(i + 25, j, k + 6, PlaceDeepslate, 0, 2);
		world.setBlock(i + 26, j, k + 6, PlaceDeepslateTiles, 2, 2);
		world.setBlock(i + 27, j, k + 6, PlaceDeepslateTiles, 2, 2);
		world.setBlock(i + 28, j, k + 6, PlaceDeepslateTiles, 2, 2);
		world.setBlock(i + 29, j, k + 6, PlaceDeepslateTiles, 2, 2);
		world.setBlock(i + 30, j, k + 6, PlaceCrackedDeepslateTiles, 3, 2);
		world.setBlock(i + 31, j, k + 6, PlaceCrackedDeepslateTiles, 3, 2);
		world.setBlock(i + 32, j, k + 6, PlaceDeepslateTiles, 2, 2);
		world.setBlock(i + 33, j, k + 6, PlaceDeepslateTiles, 2, 2);
		world.setBlock(i + 34, j, k + 6, PlaceDeepslateTiles, 2, 2);
		world.setBlock(i + 35, j, k + 6, PlaceDeepslateTiles, 2, 2);
		world.setBlock(i + 36, j, k + 6, PlaceDeepslateTiles, 2, 2);
		world.setBlock(i + 37, j, k + 6, PlaceCrackedDeepslateTiles, 3, 2);
		world.setBlock(i + 38, j, k + 6, Blocks.air, 0, 2);
		world.setBlock(i + 39, j, k + 6, Blocks.air, 0, 2);
		world.setBlock(i + 40, j, k + 6, PlaceDeepslateTiles, 2, 2);
		world.setBlock(i + 41, j, k + 6, PlaceCrackedDeepslateTiles, 3, 2);
		world.setBlock(i + 42, j, k + 6, PlaceDeepslateTiles, 2, 2);
		world.setBlock(i + 43, j, k + 6, PlaceDeepslateTiles, 2, 2);
		world.setBlock(i + 44, j, k + 6, Blocks.air, 0, 2);
		world.setBlock(i + 45, j, k + 6, Blocks.air, 0, 2);
		world.setBlock(i + 46, j, k + 6, Blocks.air, 0, 2);
		world.setBlock(i + 47, j, k + 6, Blocks.air, 0, 2);
		world.setBlock(i + 48, j, k + 6, Blocks.air, 0, 2);
		world.setBlock(i + 49, j, k + 6, PlaceDeepslateTiles, 2, 2);
		world.setBlock(i + 50, j, k + 6, PlaceCrackedDeepslateTiles, 3, 2);
		world.setBlock(i + 51, j, k + 6, PlaceDeepslateTiles, 2, 2);
		world.setBlock(i + 52, j, k + 6, PlaceDeepslateTiles, 2, 2);
		world.setBlock(i + 53, j, k + 6, PlaceDeepslateTiles, 2, 2);
		world.setBlock(i + 54, j, k + 6, PlaceCrackedDeepslateTiles, 3, 2);
		world.setBlock(i + 55, j, k + 6, PlaceDeepslateTiles, 2, 2);
		world.setBlock(i + 56, j, k + 6, PlaceDeepslateTiles, 2, 2);
		world.setBlock(i + 57, j, k + 6, Blocks.air, 0, 2);
		world.setBlock(i + 58, j, k + 6, Blocks.air, 0, 2);
		world.setBlock(i, j, k + 7, PlaceBasalt, 9, 2);
		world.setBlock(i + 1, j, k + 7, PlaceDeepslate, 0, 2);
		world.setBlock(i + 2, j, k + 7, PlaceDeepslate, 0, 2);
		world.setBlock(i + 3, j, k + 7, PlaceDeepslate, 0, 2);
		world.setBlock(i + 4, j, k + 7, PlaceDeepslate, 0, 2);
		world.setBlock(i + 5, j, k + 7, PlaceDeepslate, 0, 2);
		world.setBlock(i + 6, j, k + 7, PlaceDeepslate, 0, 2);
		world.setBlock(i + 7, j, k + 7, PlaceDeepslate, 0, 2);
		world.setBlock(i + 8, j, k + 7, PlaceDeepslate, 0, 2);
		world.setBlock(i + 9, j, k + 7, PlaceDeepslate, 0, 2);
		world.setBlock(i + 10, j, k + 7, PlaceDeepslate, 0, 2);
		world.setBlock(i + 11, j, k + 7, PlaceDeepslate, 0, 2);
		world.setBlock(i + 12, j, k + 7, PlaceDeepslate, 0, 2);
		world.setBlock(i + 13, j, k + 7, PlaceDeepslate, 0, 2);
		world.setBlock(i + 14, j, k + 7, PlaceDeepslate, 0, 2);
		world.setBlock(i + 15, j, k + 7, Blocks.air, 0, 2);
		world.setBlock(i + 16, j, k + 7, Blocks.air, 0, 2);
		world.setBlock(i + 17, j, k + 7, PlaceDeepslate, 0, 2);
		world.setBlock(i + 18, j, k + 7, PlaceDeepslate, 0, 2);
		world.setBlock(i + 19, j, k + 7, PlaceDeepslate, 0, 2);
		world.setBlock(i + 20, j, k + 7, PlaceDeepslate, 0, 2);
		world.setBlock(i + 21, j, k + 7, PlaceDeepslate, 0, 2);
		world.setBlock(i + 22, j, k + 7, PlaceDeepslate, 0, 2);
		world.setBlock(i + 23, j, k + 7, PlaceDeepslate, 0, 2);
		world.setBlock(i + 24, j, k + 7, PlaceDeepslate, 0, 2);
		world.setBlock(i + 25, j, k + 7, Blocks.air, 0, 2);
		world.setBlock(i + 26, j, k + 7, PlaceDeepslateTiles, 2, 2);
		world.setBlock(i + 27, j, k + 7, PlaceDeepslateTiles, 2, 2);
		world.setBlock(i + 28, j, k + 7, PlaceCrackedDeepslateTiles, 3, 2);
		world.setBlock(i + 29, j, k + 7, PlaceDeepslateTiles, 2, 2);
		world.setBlock(i + 30, j, k + 7, PlaceDeepslateTiles, 2, 2);
		world.setBlock(i + 31, j, k + 7, PlaceDeepslateTiles, 2, 2);
		world.setBlock(i + 32, j, k + 7, PlaceDeepslateTiles, 2, 2);
		world.setBlock(i + 33, j, k + 7, PlaceCrackedDeepslateTiles, 3, 2);
		world.setBlock(i + 34, j, k + 7, PlaceDeepslateTiles, 2, 2);
		world.setBlock(i + 35, j, k + 7, PlaceCrackedDeepslateTiles, 3, 2);
		world.setBlock(i + 36, j, k + 7, PlaceDeepslateTiles, 2, 2);
		world.setBlock(i + 37, j, k + 7, PlaceDeepslateTiles, 2, 2);
		world.setBlock(i + 38, j, k + 7, PlaceDeepslateTiles, 2, 2);
		world.setBlock(i + 39, j, k + 7, PlaceCrackedDeepslateTiles, 3, 2);
		world.setBlock(i + 40, j, k + 7, PlaceDeepslateTiles, 2, 2);
		world.setBlock(i + 41, j, k + 7, PlaceDeepslateTiles, 2, 2);
		world.setBlock(i + 42, j, k + 7, PlaceCrackedDeepslateTiles, 3, 2);
		world.setBlock(i + 43, j, k + 7, PlaceCrackedDeepslateTiles, 3, 2);
		world.setBlock(i + 44, j, k + 7, NovaCraftBlocks.sculk_block, 0, 2);
		world.setBlock(i + 45, j, k + 7, Blocks.air, 0, 2);
		world.setBlock(i + 46, j, k + 7, Blocks.air, 0, 2);
		world.setBlock(i + 47, j, k + 7, Blocks.air, 0, 2);
		world.setBlock(i + 48, j, k + 7, Blocks.air, 0, 2);
		world.setBlock(i + 49, j, k + 7, PlaceCrackedDeepslateTiles, 3, 2);
		world.setBlock(i + 50, j, k + 7, PlaceCrackedDeepslateTiles, 3, 2);
		world.setBlock(i + 51, j, k + 7, PlaceDeepslateTiles, 2, 2);
		world.setBlock(i + 52, j, k + 7, PlaceCrackedDeepslateTiles, 3, 2);
		world.setBlock(i + 53, j, k + 7, PlaceCrackedDeepslateTiles, 3, 2);
		world.setBlock(i + 54, j, k + 7, PlaceDeepslateTiles, 2, 2);
		world.setBlock(i + 55, j, k + 7, PlaceDeepslateTiles, 2, 2);
		world.setBlock(i + 56, j, k + 7, PlaceCrackedDeepslateTiles, 3, 2);
		world.setBlock(i + 57, j, k + 7, PlaceCrackedDeepslateTiles, 3, 2);
		world.setBlock(i + 58, j, k + 7, Blocks.air, 0, 2);
		world.setBlock(i, j, k + 8, PlaceBasalt, 1, 2);
		world.setBlock(i + 1, j, k + 8, PlaceBasalt, 5, 2);
		world.setBlock(i + 2, j, k + 8, PlaceBasalt, 5, 2);
		world.setBlock(i + 3, j, k + 8, PlaceDeepslate, 0, 2);
		world.setBlock(i + 4, j, k + 8, PlaceDeepslate, 0, 2);
		world.setBlock(i + 5, j, k + 8, PlaceDeepslate, 0, 2);
		world.setBlock(i + 6, j, k + 8, PlaceDeepslate, 0, 2);
		world.setBlock(i + 7, j, k + 8, PlaceDeepslate, 0, 2);
		world.setBlock(i + 8, j, k + 8, PlaceDeepslate, 0, 2);
		world.setBlock(i + 9, j, k + 8, PlaceBasalt, 5, 2);
		world.setBlock(i + 10, j, k + 8, PlaceBasalt, 5, 2);
		world.setBlock(i + 11, j, k + 8, PlaceBasalt, 5, 2);
		world.setBlock(i + 12, j, k + 8, PlaceBasalt, 5, 2);
		world.setBlock(i + 13, j, k + 8, PlaceDeepslate, 0, 2);
		world.setBlock(i + 14, j, k + 8, PlaceDeepslate, 0, 2);
		world.setBlock(i + 15, j, k + 8, PlaceDeepslate, 0, 2);
		world.setBlock(i + 16, j, k + 8, PlaceDeepslate, 0, 2);
		world.setBlock(i + 17, j, k + 8, PlaceDeepslate, 0, 2);
		world.setBlock(i + 18, j, k + 8, PlaceDeepslate, 0, 2);
		world.setBlock(i + 19, j, k + 8, PlaceBasalt, 5, 2);
		world.setBlock(i + 20, j, k + 8, PlaceBasalt, 5, 2);
		world.setBlock(i + 21, j, k + 8, PlaceBasalt, 5, 2);
		world.setBlock(i + 22, j, k + 8, PlaceBasalt, 5, 2);
		world.setBlock(i + 23, j, k + 8, PlaceDeepslate, 0, 2);
		world.setBlock(i + 24, j, k + 8, PlaceDeepslate, 0, 2);
		world.setBlock(i + 25, j, k + 8, PlaceDeepslate, 0, 2);
		world.setBlock(i + 26, j, k + 8, PlaceDeepslateTiles, 2, 2);
		world.setBlock(i + 27, j, k + 8, PlaceCrackedDeepslateTiles, 3, 2);
		world.setBlock(i + 28, j, k + 8, PlaceDeepslateTiles, 2, 2);
		world.setBlock(i + 29, j, k + 8, PlaceDeepslateTiles, 2, 2);
		world.setBlock(i + 30, j, k + 8, PlaceDeepslateTiles, 2, 2);
		world.setBlock(i + 31, j, k + 8, PlaceDeepslateTiles, 2, 2);
		world.setBlock(i + 32, j, k + 8, PlaceDeepslateTiles, 2, 2);
		world.setBlock(i + 33, j, k + 8, Blocks.air, 0, 2);
		world.setBlock(i + 34, j, k + 8, Blocks.air, 0, 2);
		world.setBlock(i + 35, j, k + 8, PlaceCrackedDeepslateTiles, 3, 2);
		world.setBlock(i + 36, j, k + 8, PlaceDeepslateTiles, 2, 2);
		world.setBlock(i + 37, j, k + 8, PlaceDeepslateTiles, 2, 2);
		world.setBlock(i + 38, j, k + 8, PlaceDeepslateTiles, 2, 2);
		world.setBlock(i + 39, j, k + 8, PlaceDeepslateTiles, 2, 2);
		world.setBlock(i + 40, j, k + 8, PlaceDeepslateTiles, 2, 2);
		world.setBlock(i + 41, j, k + 8, PlaceDeepslateTiles, 2, 2);
		world.setBlock(i + 42, j, k + 8, PlaceDeepslateTiles, 2, 2);
		world.setBlock(i + 43, j, k + 8, PlaceDeepslateTiles, 2, 2);
		world.setBlock(i + 44, j, k + 8, PlaceDeepslateTiles, 2, 2);
		world.setBlock(i + 45, j, k + 8, NovaCraftBlocks.sculk_block, 0, 2);
		world.setBlock(i + 46, j, k + 8, Blocks.air, 0, 2);
		world.setBlock(i + 47, j, k + 8, Blocks.air, 0, 2);
		world.setBlock(i + 48, j, k + 8, Blocks.air, 0, 2);
		world.setBlock(i + 49, j, k + 8, PlaceCrackedDeepslateTiles, 3, 2);
		world.setBlock(i + 50, j, k + 8, PlaceDeepslateTiles, 2, 2);
		world.setBlock(i + 51, j, k + 8, PlaceDeepslateTiles, 2, 2);
		world.setBlock(i + 52, j, k + 8, PlaceDeepslateTiles, 2, 2);
		world.setBlock(i + 53, j, k + 8, PlaceCrackedDeepslateTiles, 3, 2);
		world.setBlock(i + 54, j, k + 8, PlaceDeepslateTiles, 2, 2);
		world.setBlock(i + 55, j, k + 8, PlaceDeepslateTiles, 2, 2);
		world.setBlock(i + 56, j, k + 8, Blocks.air, 0, 2);
		world.setBlock(i + 57, j, k + 8, Blocks.air, 0, 2);
		world.setBlock(i + 58, j, k + 8, Blocks.air, 0, 2);
		world.setBlock(i, j + 1, k, Blocks.air, 0, 2);
		world.setBlock(i + 1, j + 1, k, Blocks.air, 0, 2);
		world.setBlock(i + 2, j + 1, k, Blocks.air, 0, 2);
		world.setBlock(i + 3, j + 1, k, Blocks.air, 0, 2);
		world.setBlock(i + 4, j + 1, k, Blocks.air, 0, 2);
		world.setBlock(i + 5, j + 1, k, Blocks.air, 0, 2);
		world.setBlock(i + 6, j + 1, k, Blocks.air, 0, 2);
		world.setBlock(i + 7, j + 1, k, Blocks.air, 0, 2);
		world.setBlock(i + 8, j + 1, k, Blocks.air, 0, 2);
		world.setBlock(i + 9, j + 1, k, Blocks.air, 0, 2);
		world.setBlock(i + 10, j + 1, k, Blocks.air, 0, 2);
		world.setBlock(i + 11, j + 1, k, Blocks.air, 0, 2);
		world.setBlock(i + 12, j + 1, k, Blocks.air, 0, 2);
		world.setBlock(i + 13, j + 1, k, Blocks.air, 0, 2);
		world.setBlock(i + 14, j + 1, k, Blocks.air, 0, 2);
		world.setBlock(i + 15, j + 1, k, Blocks.air, 0, 2);
		world.setBlock(i + 16, j + 1, k, Blocks.air, 0, 2);
		world.setBlock(i + 17, j + 1, k, Blocks.air, 0, 2);
		world.setBlock(i + 18, j + 1, k, Blocks.air, 0, 2);
		world.setBlock(i + 19, j + 1, k, Blocks.air, 0, 2);
		world.setBlock(i + 20, j + 1, k, Blocks.air, 0, 2);
		world.setBlock(i + 21, j + 1, k, Blocks.air, 0, 2);
		world.setBlock(i + 22, j + 1, k, Blocks.air, 0, 2);
		world.setBlock(i + 23, j + 1, k, Blocks.air, 0, 2);
		world.setBlock(i + 24, j + 1, k, Blocks.air, 0, 2);
		world.setBlock(i + 25, j + 1, k, Blocks.air, 0, 2);
		world.setBlock(i + 26, j + 1, k, Blocks.air, 0, 2);
		world.setBlock(i + 27, j + 1, k, Blocks.air, 0, 2);
		world.setBlock(i + 28, j + 1, k, PlaceDeepslateTiles, 2, 2);
		world.setBlock(i + 29, j + 1, k, PlaceCrackedDeepslateTiles, 3, 2);
		world.setBlock(i + 30, j + 1, k, Blocks.air, 0, 2);
		world.setBlock(i + 31, j + 1, k, Blocks.air, 0, 2);
		world.setBlock(i + 32, j + 1, k, Blocks.air, 0, 2);
		world.setBlock(i + 33, j + 1, k, PlaceCrackedDeepslateTiles, 3, 2);
		world.setBlock(i + 34, j + 1, k, PlaceDeepslateTiles, 2, 2);
		world.setBlock(i + 35, j + 1, k, PlaceDeepslateTiles, 2, 2);
		world.setBlock(i + 36, j + 1, k, PlaceDeepslateTiles, 2, 2);
		world.setBlock(i + 37, j + 1, k, PlaceDeepslateTiles, 2, 2);
		world.setBlock(i + 38, j + 1, k, PlaceCrackedDeepslateTiles, 3, 2);
		world.setBlock(i + 39, j + 1, k, PlaceDeepslateTiles, 2, 2);
		world.setBlock(i + 40, j + 1, k, Blocks.air, 0, 2);
		world.setBlock(i + 41, j + 1, k, Blocks.air, 0, 2);
		world.setBlock(i + 42, j + 1, k, Blocks.air, 0, 2);
		world.setBlock(i + 43, j + 1, k, PlaceCrackedDeepslateTiles, 3, 2);
		world.setBlock(i + 44, j + 1, k, PlaceDeepslateTiles, 2, 2);
		world.setBlock(i + 45, j + 1, k, PlaceCrackedDeepslateTiles, 3, 2);
		world.setBlock(i + 46, j + 1, k, PlaceDeepslateTiles, 2, 2);
		world.setBlock(i + 47, j + 1, k, PlaceDeepslateTiles, 2, 2);
		world.setBlock(i + 48, j + 1, k, PlaceDeepslateTiles, 2, 2);
		world.setBlock(i + 49, j + 1, k, PlaceDeepslateTiles, 2, 2);
		world.setBlock(i + 50, j + 1, k, Blocks.air, 0, 2);
		world.setBlock(i + 51, j + 1, k, Blocks.air, 0, 2);
		world.setBlock(i + 52, j + 1, k, Blocks.air, 0, 2);
		world.setBlock(i + 53, j + 1, k, Blocks.air, 0, 2);
		world.setBlock(i + 54, j + 1, k, Blocks.air, 0, 2);
		world.setBlock(i + 55, j + 1, k, Blocks.air, 0, 2);
		world.setBlock(i + 56, j + 1, k, Blocks.air, 0, 2);
		world.setBlock(i + 57, j + 1, k, Blocks.air, 0, 2);
		world.setBlock(i + 58, j + 1, k, Blocks.air, 0, 2);
		world.setBlock(i, j + 1, k + 1, Blocks.air, 0, 2);
		world.setBlock(i + 1, j + 1, k + 1, Blocks.air, 0, 2);
		world.setBlock(i + 2, j + 1, k + 1, Blocks.air, 0, 2);
		world.setBlock(i + 3, j + 1, k + 1, Blocks.air, 0, 2);
		world.setBlock(i + 4, j + 1, k + 1, Blocks.air, 0, 2);
		world.setBlock(i + 5, j + 1, k + 1, Blocks.air, 0, 2);
		world.setBlock(i + 6, j + 1, k + 1, Blocks.air, 0, 2);
		world.setBlock(i + 7, j + 1, k + 1, Blocks.air, 0, 2);
		world.setBlock(i + 8, j + 1, k + 1, Blocks.air, 0, 2);
		world.setBlock(i + 9, j + 1, k + 1, Blocks.air, 0, 2);
		world.setBlock(i + 10, j + 1, k + 1, Blocks.air, 0, 2);
		world.setBlock(i + 11, j + 1, k + 1, Blocks.air, 0, 2);
		world.setBlock(i + 12, j + 1, k + 1, Blocks.air, 0, 2);
		world.setBlock(i + 13, j + 1, k + 1, Blocks.air, 0, 2);
		world.setBlock(i + 14, j + 1, k + 1, Blocks.air, 0, 2);
		world.setBlock(i + 15, j + 1, k + 1, Blocks.air, 0, 2);
		world.setBlock(i + 16, j + 1, k + 1, Blocks.air, 0, 2);
		world.setBlock(i + 17, j + 1, k + 1, Blocks.air, 0, 2);
		world.setBlock(i + 18, j + 1, k + 1, Blocks.air, 0, 2);
		world.setBlock(i + 19, j + 1, k + 1, Blocks.air, 0, 2);
		world.setBlock(i + 20, j + 1, k + 1, Blocks.air, 0, 2);
		world.setBlock(i + 21, j + 1, k + 1, Blocks.air, 0, 2);
		world.setBlock(i + 22, j + 1, k + 1, Blocks.air, 0, 2);
		world.setBlock(i + 23, j + 1, k + 1, Blocks.air, 0, 2);
		world.setBlock(i + 24, j + 1, k + 1, Blocks.air, 0, 2);
		world.setBlock(i + 25, j + 1, k + 1, Blocks.air, 0, 2);
		world.setBlock(i + 26, j + 1, k + 1, PlaceCrackedDeepslateTiles, 3, 2);
		world.setBlock(i + 27, j + 1, k + 1, PlaceDeepslateTiles, 2, 2);
		world.setBlock(i + 28, j + 1, k + 1, PlaceCrackedDeepslateTiles, 3, 2);
		world.setBlock(i + 29, j + 1, k + 1, Blocks.air, 0, 2);
		world.setBlock(i + 30, j + 1, k + 1, Blocks.air, 0, 2);
		world.setBlock(i + 31, j + 1, k + 1, PlaceCrackedDeepslateTiles, 3, 2);
		world.setBlock(i + 32, j + 1, k + 1, PlaceDeepslateTiles, 2, 2);
		world.setBlock(i + 33, j + 1, k + 1, PlaceCrackedDeepslateTiles, 3, 2);
		world.setBlock(i + 34, j + 1, k + 1, PlaceDeepslateTiles, 2, 2);
		world.setBlock(i + 35, j + 1, k + 1, PlaceDeepslateTiles, 2, 2);
		world.setBlock(i + 36, j + 1, k + 1, PlaceDeepslateTiles, 2, 2);
		world.setBlock(i + 37, j + 1, k + 1, PlaceCrackedDeepslateTiles, 3, 2);
		world.setBlock(i + 38, j + 1, k + 1, PlaceDeepslateTiles, 2, 2);
		world.setBlock(i + 39, j + 1, k + 1, PlaceCrackedDeepslateTiles, 3, 2);
		world.setBlock(i + 40, j + 1, k + 1, NovaCraftBlocks.sculk_block, 0, 2);
		world.setBlock(i + 41, j + 1, k + 1, PlaceDeepslateTiles, 2, 2);
		world.setBlock(i + 42, j + 1, k + 1, PlaceDeepslateTiles, 2, 2);
		world.setBlock(i + 43, j + 1, k + 1, PlaceCrackedDeepslateTiles, 3, 2);
		world.setBlock(i + 44, j + 1, k + 1, PlaceCrackedDeepslateTiles, 3, 2);
		world.setBlock(i + 45, j + 1, k + 1, PlaceDeepslateTiles, 2, 2);
		world.setBlock(i + 46, j + 1, k + 1, PlaceDeepslateTiles, 2, 2);
		world.setBlock(i + 47, j + 1, k + 1, PlaceDeepslateTiles, 2, 2);
		world.setBlock(i + 48, j + 1, k + 1, PlaceDeepslateTiles, 2, 2);
		world.setBlock(i + 49, j + 1, k + 1, PlaceCrackedDeepslateTiles, 3, 2);
		world.setBlock(i + 50, j + 1, k + 1, Blocks.air, 0, 2);
		world.setBlock(i + 51, j + 1, k + 1, Blocks.air, 0, 2);
		world.setBlock(i + 52, j + 1, k + 1, PlaceDeepslateTiles, 2, 2);
		world.setBlock(i + 53, j + 1, k + 1, PlaceDeepslateTiles, 2, 2);
		world.setBlock(i + 54, j + 1, k + 1, Blocks.air, 0, 2);
		world.setBlock(i + 55, j + 1, k + 1, Blocks.air, 0, 2);
		world.setBlock(i + 56, j + 1, k + 1, Blocks.air, 0, 2);
		world.setBlock(i + 57, j + 1, k + 1, Blocks.air, 0, 2);
		world.setBlock(i + 58, j + 1, k + 1, Blocks.air, 0, 2);
		world.setBlock(i, j + 1, k + 2, Blocks.air, 0, 2);
		world.setBlock(i + 1, j + 1, k + 2, Blocks.air, 0, 2);
		world.setBlock(i + 2, j + 1, k + 2, Blocks.air, 0, 2);
		world.setBlock(i + 3, j + 1, k + 2, Blocks.air, 0, 2);
		world.setBlock(i + 4, j + 1, k + 2, Blocks.air, 0, 2);
		world.setBlock(i + 5, j + 1, k + 2, Blocks.air, 0, 2);
		world.setBlock(i + 6, j + 1, k + 2, Blocks.air, 0, 2);
		world.setBlock(i + 7, j + 1, k + 2, Blocks.air, 0, 2);
		world.setBlock(i + 8, j + 1, k + 2, Blocks.air, 0, 2);
		world.setBlock(i + 9, j + 1, k + 2, Blocks.air, 0, 2);
		world.setBlock(i + 10, j + 1, k + 2, Blocks.air, 0, 2);
		world.setBlock(i + 11, j + 1, k + 2, Blocks.air, 0, 2);
		world.setBlock(i + 12, j + 1, k + 2, Blocks.air, 0, 2);
		world.setBlock(i + 13, j + 1, k + 2, Blocks.air, 0, 2);
		world.setBlock(i + 14, j + 1, k + 2, Blocks.air, 0, 2);
		world.setBlock(i + 15, j + 1, k + 2, Blocks.air, 0, 2);
		world.setBlock(i + 16, j + 1, k + 2, Blocks.air, 0, 2);
		world.setBlock(i + 17, j + 1, k + 2, Blocks.air, 0, 2);
		world.setBlock(i + 18, j + 1, k + 2, Blocks.air, 0, 2);
		world.setBlock(i + 19, j + 1, k + 2, Blocks.air, 0, 2);
		world.setBlock(i + 20, j + 1, k + 2, Blocks.air, 0, 2);
		world.setBlock(i + 21, j + 1, k + 2, Blocks.air, 0, 2);
		world.setBlock(i + 22, j + 1, k + 2, Blocks.air, 0, 2);
		world.setBlock(i + 23, j + 1, k + 2, Blocks.air, 0, 2);
		world.setBlock(i + 24, j + 1, k + 2, Blocks.air, 0, 2);
		world.setBlock(i + 25, j + 1, k + 2, Blocks.air, 0, 2);
		world.setBlock(i + 26, j + 1, k + 2, PlaceDeepslateTiles, 2, 2);
		world.setBlock(i + 27, j + 1, k + 2, PlaceCrackedDeepslateTiles, 3, 2);
		world.setBlock(i + 28, j + 1, k + 2, PlaceDeepslateTiles, 2, 2);
		world.setBlock(i + 29, j + 1, k + 2, PlaceDeepslateTiles, 2, 2);
		world.setBlock(i + 30, j + 1, k + 2, PlaceCrackedDeepslateTiles, 3, 2);
		world.setBlock(i + 31, j + 1, k + 2, PlaceDeepslateTiles, 2, 2);
		world.setBlock(i + 32, j + 1, k + 2, PlaceDeepslateTiles, 2, 2);
		world.setBlock(i + 33, j + 1, k + 2, PlaceDeepslateTiles, 2, 2);
		world.setBlock(i + 34, j + 1, k + 2, PlaceCrackedDeepslateTiles, 3, 2);
		world.setBlock(i + 35, j + 1, k + 2, PlaceCrackedDeepslateTiles, 3, 2);
		world.setBlock(i + 36, j + 1, k + 2, PlaceDeepslateTiles, 2, 2);
		world.setBlock(i + 37, j + 1, k + 2, PlaceCrackedDeepslateTiles, 3, 2);
		world.setBlock(i + 38, j + 1, k + 2, PlaceDeepslateTiles, 2, 2);
		world.setBlock(i + 39, j + 1, k + 2, NovaCraftBlocks.sculk_block, 0, 2);
		world.setBlock(i + 40, j + 1, k + 2, PlaceDeepslateTiles, 2, 2);
		world.setBlock(i + 41, j + 1, k + 2, PlaceDeepslateTiles, 2, 2);
		world.setBlock(i + 42, j + 1, k + 2, PlaceCrackedDeepslateTiles, 3, 2);
		world.setBlock(i + 43, j + 1, k + 2, PlaceDeepslateTiles, 2, 2);
		world.setBlock(i + 44, j + 1, k + 2, PlaceDeepslateTiles, 2, 2);
		world.setBlock(i + 45, j + 1, k + 2, PlaceDeepslateTiles, 2, 2);
		world.setBlock(i + 46, j + 1, k + 2, PlaceDeepslateTiles, 2, 2);
		world.setBlock(i + 47, j + 1, k + 2, PlaceCrackedDeepslateTiles, 3, 2);
		world.setBlock(i + 48, j + 1, k + 2, PlaceCrackedDeepslateTiles, 3, 2);
		world.setBlock(i + 49, j + 1, k + 2, PlaceCrackedDeepslateTiles, 3, 2);
		world.setBlock(i + 50, j + 1, k + 2, PlaceCrackedDeepslateTiles, 3, 2);
		world.setBlock(i + 51, j + 1, k + 2, PlaceCrackedDeepslateTiles, 3, 2);
		world.setBlock(i + 52, j + 1, k + 2, PlaceDeepslateTiles, 2, 2);
		world.setBlock(i + 53, j + 1, k + 2, Blocks.air, 0, 2);
		world.setBlock(i + 54, j + 1, k + 2, Blocks.air, 0, 2);
		world.setBlock(i + 55, j + 1, k + 2, Blocks.air, 0, 2);
		world.setBlock(i + 56, j + 1, k + 2, Blocks.air, 0, 2);
		world.setBlock(i + 57, j + 1, k + 2, Blocks.air, 0, 2);
		world.setBlock(i + 58, j + 1, k + 2, Blocks.air, 0, 2);
		world.setBlock(i, j + 1, k + 3, Blocks.air, 0, 2);
		world.setBlock(i + 1, j + 1, k + 3, Blocks.air, 0, 2);
		world.setBlock(i + 2, j + 1, k + 3, Blocks.air, 0, 2);
		world.setBlock(i + 3, j + 1, k + 3, Blocks.air, 0, 2);
		world.setBlock(i + 4, j + 1, k + 3, Blocks.air, 0, 2);
		world.setBlock(i + 5, j + 1, k + 3, PlaceDeepslateTileStairs, 2, 2);
		world.setBlock(i + 6, j + 1, k + 3, PlaceDeepslateTileStairs, 2, 2);
		world.setBlock(i + 7, j + 1, k + 3, PlaceDeepslateTileStairs, 2, 2);
		world.setBlock(i + 8, j + 1, k + 3, PlaceDeepslateTileStairs, 2, 2);
		world.setBlock(i + 9, j + 1, k + 3, Blocks.air, 0, 2);
		world.setBlock(i + 10, j + 1, k + 3, Blocks.air, 0, 2);
		world.setBlock(i + 11, j + 1, k + 3, Blocks.air, 0, 2);
		world.setBlock(i + 12, j + 1, k + 3, Blocks.air, 0, 2);
		world.setBlock(i + 13, j + 1, k + 3, PlaceDeepslateTileStairs, 0, 2);
		world.setBlock(i + 14, j + 1, k + 3, PlaceDeepslateTileStairs, 2, 2);
		world.setBlock(i + 15, j + 1, k + 3, PlaceDeepslateTileStairs, 2, 2);
		world.setBlock(i + 16, j + 1, k + 3, PlaceDeepslateTileStairs, 2, 2);
		world.setBlock(i + 17, j + 1, k + 3, Blocks.air, 0, 2);
		world.setBlock(i + 18, j + 1, k + 3, Blocks.air, 0, 2);
		world.setBlock(i + 19, j + 1, k + 3, Blocks.air, 0, 2);
		world.setBlock(i + 20, j + 1, k + 3, Blocks.air, 0, 2);
		world.setBlock(i + 21, j + 1, k + 3, Blocks.air, 0, 2);
		world.setBlock(i + 22, j + 1, k + 3, Blocks.air, 0, 2);
		world.setBlock(i + 23, j + 1, k + 3, Blocks.air, 0, 2);
		world.setBlock(i + 24, j + 1, k + 3, PlaceDeepslateTileStairs, 2, 2);
		world.setBlock(i + 25, j + 1, k + 3, PlaceDeepslateTileStairs, 2, 2);
		world.setBlock(i + 26, j + 1, k + 3, PlaceDeepslateTiles, 2, 2);
		world.setBlock(i + 27, j + 1, k + 3, PlaceDeepslateTiles, 2, 2);
		world.setBlock(i + 28, j + 1, k + 3, PlaceDeepslateTiles, 2, 2);
		world.setBlock(i + 29, j + 1, k + 3, PlaceDeepslateTiles, 2, 2);
		world.setBlock(i + 30, j + 1, k + 3, NovaCraftBlocks.sculk_block, 0, 2);
		world.setBlock(i + 31, j + 1, k + 3, PlaceDeepslateTiles, 2, 2);
		world.setBlock(i + 32, j + 1, k + 3, PlaceDeepslateTiles, 2, 2);
		world.setBlock(i + 33, j + 1, k + 3, PlaceDeepslateTiles, 2, 2);
		world.setBlock(i + 34, j + 1, k + 3, PlaceDeepslateTiles, 2, 2);
		world.setBlock(i + 35, j + 1, k + 3, PlaceCrackedDeepslateTiles, 3, 2);
		world.setBlock(i + 36, j + 1, k + 3, PlaceDeepslateTiles, 2, 2);
		world.setBlock(i + 37, j + 1, k + 3, PlaceDeepslateTiles, 2, 2);
		world.setBlock(i + 38, j + 1, k + 3, PlaceCrackedDeepslateTiles, 3, 2);
		world.setBlock(i + 39, j + 1, k + 3, PlaceDeepslateTiles, 2, 2);
		world.setBlock(i + 40, j + 1, k + 3, PlaceDeepslateTiles, 2, 2);
		world.setBlock(i + 41, j + 1, k + 3, PlaceDeepslateTiles, 2, 2);
		world.setBlock(i + 42, j + 1, k + 3, PlaceDeepslateTiles, 2, 2);
		world.setBlock(i + 43, j + 1, k + 3, NovaCraftBlocks.sculk_block, 0, 2);
		world.setBlock(i + 44, j + 1, k + 3, NovaCraftBlocks.sculk_block, 0, 2);
		world.setBlock(i + 45, j + 1, k + 3, PlacePolishedDeepslate, 0, 2);
		world.setBlock(i + 46, j + 1, k + 3, PlaceCrackedDeepslateTiles, 3, 2);
		world.setBlock(i + 47, j + 1, k + 3, PlaceCrackedDeepslateTiles, 3, 2);
		world.setBlock(i + 48, j + 1, k + 3, PlaceDeepslateTiles, 2, 2);
		world.setBlock(i + 49, j + 1, k + 3, PlaceDeepslateTiles, 2, 2);
		world.setBlock(i + 50, j + 1, k + 3, PlaceDeepslateTiles, 2, 2);
		world.setBlock(i + 51, j + 1, k + 3, PlaceDeepslateTiles, 2, 2);
		world.setBlock(i + 52, j + 1, k + 3, PlaceDeepslateTiles, 2, 2);
		world.setBlock(i + 53, j + 1, k + 3, PlaceCrackedDeepslateTiles, 3, 2);
		world.setBlock(i + 54, j + 1, k + 3, Blocks.air, 0, 2);
		world.setBlock(i + 55, j + 1, k + 3, Blocks.air, 0, 2);
		world.setBlock(i + 56, j + 1, k + 3, Blocks.air, 0, 2);
		world.setBlock(i + 57, j + 1, k + 3, Blocks.air, 0, 2);
		world.setBlock(i + 58, j + 1, k + 3, Blocks.air, 0, 2);
		world.setBlock(i, j + 1, k + 4, Blocks.air, 0, 2);
		world.setBlock(i + 1, j + 1, k + 4, Blocks.air, 0, 2);
		world.setBlock(i + 2, j + 1, k + 4, Blocks.air, 0, 2);
		world.setBlock(i + 3, j + 1, k + 4, Blocks.air, 0, 2);
		world.setBlock(i + 4, j + 1, k + 4, PlaceDeepslate, 0, 2);
		world.setBlock(i + 5, j + 1, k + 4, Blocks.air, 0, 2);
		world.setBlock(i + 6, j + 1, k + 4, PlaceDeepslate, 0, 2);
		world.setBlock(i + 7, j + 1, k + 4, PlaceDeepslate, 0, 2);
		world.setBlock(i + 8, j + 1, k + 4, PlaceDeepslateTileStairs, 1, 2);
		world.setBlock(i + 9, j + 1, k + 4, Blocks.air, 0, 2);
		world.setBlock(i + 10, j + 1, k + 4, Blocks.air, 0, 2);
		world.setBlock(i + 11, j + 1, k + 4, Blocks.air, 0, 2);
		world.setBlock(i + 12, j + 1, k + 4, Blocks.air, 0, 2);
		world.setBlock(i + 13, j + 1, k + 4, PlaceDeepslateTileStairs, 0, 2);
		world.setBlock(i + 14, j + 1, k + 4, PlaceDeepslate, 0, 2);
		world.setBlock(i + 15, j + 1, k + 4, PlaceDeepslate, 0, 2);
		world.setBlock(i + 16, j + 1, k + 4, PlaceDeepslate, 0, 2);
		world.setBlock(i + 17, j + 1, k + 4, NovaCraftBlocks.sculk_block, 0, 2);
		world.setBlock(i + 18, j + 1, k + 4, Blocks.air, 0, 2);
		world.setBlock(i + 19, j + 1, k + 4, Blocks.air, 0, 2);
		world.setBlock(i + 20, j + 1, k + 4, Blocks.air, 0, 2);
		world.setBlock(i + 21, j + 1, k + 4, Blocks.air, 0, 2);
		world.setBlock(i + 22, j + 1, k + 4, Blocks.air, 0, 2);
		world.setBlock(i + 23, j + 1, k + 4, Blocks.air, 0, 2);
		world.setBlock(i + 24, j + 1, k + 4, PlaceDeepslate, 0, 2);
		world.setBlock(i + 25, j + 1, k + 4, PlaceDeepslate, 0, 2);
		world.setBlock(i + 26, j + 1, k + 4, Blocks.air, 0, 2);
		world.setBlock(i + 27, j + 1, k + 4, PlaceDeepslateTiles, 2, 2);
		world.setBlock(i + 28, j + 1, k + 4, PlaceDeepslateTiles, 2, 2);
		world.setBlock(i + 29, j + 1, k + 4, PlaceDeepslateTiles, 2, 2);
		world.setBlock(i + 30, j + 1, k + 4, PlaceDeepslateTiles, 2, 2);
		world.setBlock(i + 31, j + 1, k + 4, PlaceDeepslateTiles, 2, 2);
		world.setBlock(i + 32, j + 1, k + 4, PlaceCrackedDeepslateTiles, 3, 2);
		world.setBlock(i + 33, j + 1, k + 4, PlaceDeepslateTiles, 2, 2);
		world.setBlock(i + 34, j + 1, k + 4, PlaceDeepslateTiles, 2, 2);
		world.setBlock(i + 35, j + 1, k + 4, PlaceCrackedDeepslateTiles, 3, 2);
		world.setBlock(i + 36, j + 1, k + 4, PlaceDeepslateTiles, 2, 2);
		world.setBlock(i + 37, j + 1, k + 4, PlaceDeepslateTiles, 2, 2);
		world.setBlock(i + 38, j + 1, k + 4, PlaceDeepslateTiles, 2, 2);
		world.setBlock(i + 39, j + 1, k + 4, PlaceDeepslateTiles, 2, 2);
		world.setBlock(i + 40, j + 1, k + 4, PlaceDeepslateTiles, 2, 2);
		world.setBlock(i + 41, j + 1, k + 4, PlaceDeepslateTiles, 2, 2);
		world.setBlock(i + 42, j + 1, k + 4, PlaceDeepslateTiles, 2, 2);
		world.setBlock(i + 43, j + 1, k + 4, Blocks.air, 0, 2);
		world.setBlock(i + 44, j + 1, k + 4, Blocks.air, 0, 2);
		world.setBlock(i + 45, j + 1, k + 4, PlaceDeepslate, 0, 2);
		world.setBlock(i + 46, j + 1, k + 4, PlaceCrackedDeepslateTiles, 3, 2);
		world.setBlock(i + 47, j + 1, k + 4, PlaceDeepslateTiles, 2, 2);
		world.setBlock(i + 48, j + 1, k + 4, PlaceDeepslateTileStairs, 1, 2);
		world.setBlock(i + 49, j + 1, k + 4, PlaceDeepslateTiles, 2, 2);
		world.setBlock(i + 50, j + 1, k + 4, PlaceCrackedDeepslateTiles, 3, 2);
		world.setBlock(i + 51, j + 1, k + 4, PlaceDeepslateTiles, 2, 2);
		world.setBlock(i + 52, j + 1, k + 4, PlaceCrackedDeepslateTiles, 3, 2);
		world.setBlock(i + 53, j + 1, k + 4, Blocks.air, 0, 2);
		world.setBlock(i + 54, j + 1, k + 4, Blocks.air, 0, 2);
		world.setBlock(i + 55, j + 1, k + 4, Blocks.air, 0, 2);
		world.setBlock(i + 56, j + 1, k + 4, Blocks.air, 0, 2);
		world.setBlock(i + 57, j + 1, k + 4, Blocks.air, 0, 2);
		world.setBlock(i + 58, j + 1, k + 4, Blocks.air, 0, 2);
		world.setBlock(i, j + 1, k + 5, Blocks.air, 0, 2);
		world.setBlock(i + 1, j + 1, k + 5, Blocks.air, 0, 2);
		world.setBlock(i + 2, j + 1, k + 5, Blocks.air, 0, 2);
		world.setBlock(i + 3, j + 1, k + 5, PlaceDeepslateTileStairs, 0, 2);
		world.setBlock(i + 4, j + 1, k + 5, PlaceDeepslate, 0, 2);
		world.setBlock(i + 5, j + 1, k + 5, PlaceDeepslate, 0, 2);
		world.setBlock(i + 6, j + 1, k + 5, PlaceDeepslate, 0, 2);
		world.setBlock(i + 7, j + 1, k + 5, PlaceDeepslate, 0, 2);
		world.setBlock(i + 8, j + 1, k + 5, PlaceDeepslateTileStairs, 1, 2);
		world.setBlock(i + 9, j + 1, k + 5, Blocks.air, 0, 2);
		world.setBlock(i + 10, j + 1, k + 5, Blocks.air, 0, 2);
		world.setBlock(i + 11, j + 1, k + 5, Blocks.air, 0, 2);
		world.setBlock(i + 12, j + 1, k + 5, Blocks.air, 0, 2);
		world.setBlock(i + 13, j + 1, k + 5, PlaceDeepslateTileStairs, 0, 2);
		world.setBlock(i + 14, j + 1, k + 5, PlaceDeepslate, 0, 2);
		world.setBlock(i + 15, j + 1, k + 5, PlaceDeepslate, 0, 2);
		world.setBlock(i + 16, j + 1, k + 5, PlaceDeepslate, 0, 2);
		world.setBlock(i + 17, j + 1, k + 5, PlaceDeepslate, 0, 2);
		world.setBlock(i + 18, j + 1, k + 5, Blocks.air, 0, 2);
		world.setBlock(i + 19, j + 1, k + 5, Blocks.air, 0, 2);
		world.setBlock(i + 20, j + 1, k + 5, Blocks.air, 0, 2);
		world.setBlock(i + 21, j + 1, k + 5, Blocks.air, 0, 2);
		world.setBlock(i + 22, j + 1, k + 5, Blocks.air, 0, 2);
		world.setBlock(i + 23, j + 1, k + 5, Blocks.air, 0, 2);
		world.setBlock(i + 24, j + 1, k + 5, PlaceDeepslate, 0, 2);
		world.setBlock(i + 25, j + 1, k + 5, PlaceDeepslate, 0, 2);
		world.setBlock(i + 26, j + 1, k + 5, PlaceDeepslateTiles, 2, 2);
		world.setBlock(i + 27, j + 1, k + 5, PlaceDeepslateTiles, 2, 2);
		world.setBlock(i + 28, j + 1, k + 5, PlaceDeepslateTiles, 2, 2);
		world.setBlock(i + 29, j + 1, k + 5, PlaceDeepslateTiles, 2, 2);
		world.setBlock(i + 30, j + 1, k + 5, PlaceDeepslateTiles, 2, 2);
		world.setBlock(i + 31, j + 1, k + 5, NovaCraftBlocks.sculk_block, 0, 2);
		world.setBlock(i + 32, j + 1, k + 5, PlaceDeepslateTiles, 2, 2);
		world.setBlock(i + 33, j + 1, k + 5, PlaceDeepslateTiles, 2, 2);
		world.setBlock(i + 34, j + 1, k + 5, PlaceDeepslateTiles, 2, 2);
		world.setBlock(i + 35, j + 1, k + 5, PlaceDeepslateTiles, 2, 2);
		world.setBlock(i + 36, j + 1, k + 5, PlaceDeepslateTiles, 2, 2);
		world.setBlock(i + 37, j + 1, k + 5, PlaceDeepslateTiles, 2, 2);
		world.setBlock(i + 38, j + 1, k + 5, PlaceDeepslateTiles, 2, 2);
		world.setBlock(i + 39, j + 1, k + 5, PlaceDeepslateTiles, 2, 2);
		world.setBlock(i + 40, j + 1, k + 5, PlaceCrackedDeepslateTiles, 3, 2);
		world.setBlock(i + 41, j + 1, k + 5, PlaceCrackedDeepslateTiles, 3, 2);
		world.setBlock(i + 42, j + 1, k + 5, PlaceDeepslateTiles, 2, 2);
		world.setBlock(i + 43, j + 1, k + 5, Blocks.air, 0, 2);
		world.setBlock(i + 44, j + 1, k + 5, Blocks.air, 0, 2);
		world.setBlock(i + 45, j + 1, k + 5, Blocks.air, 0, 2);
		world.setBlock(i + 46, j + 1, k + 5, Blocks.air, 0, 2);
		world.setBlock(i + 47, j + 1, k + 5, Blocks.air, 0, 2);
		world.setBlock(i + 48, j + 1, k + 5, Blocks.air, 0, 2);
		world.setBlock(i + 49, j + 1, k + 5, Blocks.air, 0, 2);
		world.setBlock(i + 50, j + 1, k + 5, PlaceDeepslateTiles, 2, 2);
		world.setBlock(i + 51, j + 1, k + 5, PlaceCrackedDeepslateTiles, 3, 2);
		world.setBlock(i + 52, j + 1, k + 5, PlaceDeepslateTiles, 2, 2);
		world.setBlock(i + 53, j + 1, k + 5, Blocks.air, 0, 2);
		world.setBlock(i + 54, j + 1, k + 5, Blocks.air, 0, 2);
		world.setBlock(i + 55, j + 1, k + 5, Blocks.air, 0, 2);
		world.setBlock(i + 56, j + 1, k + 5, PlaceDeepslateTiles, 2, 2);
		world.setBlock(i + 57, j + 1, k + 5, PlaceDeepslateTiles, 2, 2);
		world.setBlock(i + 58, j + 1, k + 5, Blocks.air, 0, 2);
		world.setBlock(i, j + 1, k + 6, Blocks.air, 0, 2);
		world.setBlock(i + 1, j + 1, k + 6, Blocks.air, 0, 2);
		world.setBlock(i + 2, j + 1, k + 6, Blocks.air, 0, 2);
		world.setBlock(i + 3, j + 1, k + 6, Blocks.air, 0, 2);
		world.setBlock(i + 4, j + 1, k + 6, PlaceDeepslate, 0, 2);
		world.setBlock(i + 5, j + 1, k + 6, PlaceDeepslate, 0, 2);
		world.setBlock(i + 6, j + 1, k + 6, PlaceDeepslate, 0, 2);
		world.setBlock(i + 7, j + 1, k + 6, PlaceDeepslate, 0, 2);
		world.setBlock(i + 8, j + 1, k + 6, PlaceDeepslateTileStairs, 1, 2);
		world.setBlock(i + 9, j + 1, k + 6, Blocks.air, 0, 2);
		world.setBlock(i + 10, j + 1, k + 6, Blocks.air, 0, 2);
		world.setBlock(i + 11, j + 1, k + 6, Blocks.air, 0, 2);
		world.setBlock(i + 12, j + 1, k + 6, Blocks.air, 0, 2);
		world.setBlock(i + 13, j + 1, k + 6, PlaceDeepslateTileStairs, 0, 2);
		world.setBlock(i + 14, j + 1, k + 6, PlaceDeepslate, 0, 2);
		world.setBlock(i + 15, j + 1, k + 6, PlaceDeepslate, 0, 2);
		world.setBlock(i + 16, j + 1, k + 6, PlaceDeepslate, 0, 2);
		world.setBlock(i + 17, j + 1, k + 6, PlaceDeepslate, 0, 2);
		world.setBlock(i + 18, j + 1, k + 6, Blocks.air, 0, 2);
		world.setBlock(i + 19, j + 1, k + 6, Blocks.air, 0, 2);
		world.setBlock(i + 20, j + 1, k + 6, Blocks.air, 0, 2);
		world.setBlock(i + 21, j + 1, k + 6, Blocks.air, 0, 2);
		world.setBlock(i + 22, j + 1, k + 6, Blocks.air, 0, 2);
		world.setBlock(i + 23, j + 1, k + 6, PlaceDeepslateTileStairs, 0, 2);
		world.setBlock(i + 24, j + 1, k + 6, PlaceDeepslate, 0, 2);
		world.setBlock(i + 25, j + 1, k + 6, PlaceDeepslate, 0, 2);
		world.setBlock(i + 26, j + 1, k + 6, PlaceDeepslateTiles, 2, 2);
		world.setBlock(i + 27, j + 1, k + 6, PlaceCrackedDeepslateTiles, 3, 2);
		world.setBlock(i + 28, j + 1, k + 6, PlaceDeepslateTiles, 2, 2);
		world.setBlock(i + 29, j + 1, k + 6, PlaceDeepslateTiles, 2, 2);
		world.setBlock(i + 30, j + 1, k + 6, PlaceCrackedDeepslateTiles, 3, 2);
		world.setBlock(i + 31, j + 1, k + 6, PlaceDeepslateTiles, 2, 2);
		world.setBlock(i + 32, j + 1, k + 6, PlaceDeepslateTiles, 2, 2);
		world.setBlock(i + 33, j + 1, k + 6, PlaceDeepslateTiles, 2, 2);
		world.setBlock(i + 34, j + 1, k + 6, PlaceDeepslateTiles, 2, 2);
		world.setBlock(i + 35, j + 1, k + 6, PlaceDeepslateTiles, 2, 2);
		world.setBlock(i + 36, j + 1, k + 6, Blocks.air, 0, 2);
		world.setBlock(i + 37, j + 1, k + 6, PlaceCrackedDeepslateTiles, 3, 2);
		world.setBlock(i + 38, j + 1, k + 6, PlaceDeepslateTiles, 2, 2);
		world.setBlock(i + 39, j + 1, k + 6, PlaceCrackedDeepslateTiles, 3, 2);
		world.setBlock(i + 40, j + 1, k + 6, PlaceDeepslateTiles, 2, 2);
		world.setBlock(i + 41, j + 1, k + 6, PlaceDeepslateTiles, 2, 2);
		world.setBlock(i + 42, j + 1, k + 6, PlaceDeepslateTiles, 2, 2);
		world.setBlock(i + 43, j + 1, k + 6, Blocks.air, 0, 2);
		world.setBlock(i + 44, j + 1, k + 6, Blocks.air, 0, 2);
		world.setBlock(i + 45, j + 1, k + 6, Blocks.air, 0, 2);
		world.setBlock(i + 46, j + 1, k + 6, Blocks.air, 0, 2);
		world.setBlock(i + 47, j + 1, k + 6, Blocks.air, 0, 2);
		world.setBlock(i + 48, j + 1, k + 6, Blocks.air, 0, 2);
		world.setBlock(i + 49, j + 1, k + 6, Blocks.air, 0, 2);
		world.setBlock(i + 50, j + 1, k + 6, Blocks.air, 0, 2);
		world.setBlock(i + 51, j + 1, k + 6, PlaceCrackedDeepslateTiles, 3, 2);
		world.setBlock(i + 52, j + 1, k + 6, Blocks.air, 0, 2);
		world.setBlock(i + 53, j + 1, k + 6, Blocks.air, 0, 2);
		world.setBlock(i + 54, j + 1, k + 6, Blocks.air, 0, 2);
		world.setBlock(i + 55, j + 1, k + 6, PlaceDeepslateTiles, 2, 2);
		world.setBlock(i + 56, j + 1, k + 6, Blocks.air, 0, 2);
		world.setBlock(i + 57, j + 1, k + 6, Blocks.air, 0, 2);
		world.setBlock(i + 58, j + 1, k + 6, Blocks.air, 0, 2);
		world.setBlock(i, j + 1, k + 7, Blocks.air, 0, 2);
		world.setBlock(i + 1, j + 1, k + 7, Blocks.air, 0, 2);
		world.setBlock(i + 2, j + 1, k + 7, Blocks.air, 0, 2);
		world.setBlock(i + 3, j + 1, k + 7, PlaceDeepslateTileStairs, 0, 2);
		world.setBlock(i + 4, j + 1, k + 7, PlaceDeepslate, 0, 2);
		world.setBlock(i + 5, j + 1, k + 7, PlaceDeepslate, 0, 2);
		world.setBlock(i + 6, j + 1, k + 7, PlaceDeepslate, 0, 2);
		world.setBlock(i + 7, j + 1, k + 7, PlaceDeepslate, 0, 2);
		world.setBlock(i + 8, j + 1, k + 7, PlaceDeepslateTileStairs, 1, 2);
		world.setBlock(i + 9, j + 1, k + 7, Blocks.air, 0, 2);
		world.setBlock(i + 10, j + 1, k + 7, Blocks.air, 0, 2);
		world.setBlock(i + 11, j + 1, k + 7, Blocks.air, 0, 2);
		world.setBlock(i + 12, j + 1, k + 7, Blocks.air, 0, 2);
		world.setBlock(i + 13, j + 1, k + 7, PlaceDeepslateTileStairs, 0, 2);
		world.setBlock(i + 14, j + 1, k + 7, PlaceDeepslate, 0, 2);
		world.setBlock(i + 15, j + 1, k + 7, PlaceDeepslate, 0, 2);
		world.setBlock(i + 16, j + 1, k + 7, PlaceDeepslate, 0, 2);
		world.setBlock(i + 17, j + 1, k + 7, PlaceDeepslate, 0, 2);
		world.setBlock(i + 18, j + 1, k + 7, PlaceDeepslateTileStairs, 1, 2);
		world.setBlock(i + 19, j + 1, k + 7, Blocks.air, 0, 2);
		world.setBlock(i + 20, j + 1, k + 7, Blocks.air, 0, 2);
		world.setBlock(i + 21, j + 1, k + 7, Blocks.air, 0, 2);
		world.setBlock(i + 22, j + 1, k + 7, Blocks.air, 0, 2);
		world.setBlock(i + 23, j + 1, k + 7, PlaceDeepslateTileStairs, 0, 2);
		world.setBlock(i + 24, j + 1, k + 7, PlaceDeepslate, 0, 2);
		world.setBlock(i + 25, j + 1, k + 7, PlaceDeepslate, 0, 2);
		world.setBlock(i + 26, j + 1, k + 7, PlaceDeepslateTiles, 2, 2);
		world.setBlock(i + 27, j + 1, k + 7, PlaceDeepslateTiles, 2, 2);
		world.setBlock(i + 28, j + 1, k + 7, PlaceCrackedDeepslateTiles, 3, 2);
		world.setBlock(i + 29, j + 1, k + 7, PlaceDeepslateTiles, 2, 2);
		world.setBlock(i + 30, j + 1, k + 7, PlaceDeepslateTiles, 2, 2);
		world.setBlock(i + 31, j + 1, k + 7, PlaceDeepslateTiles, 2, 2);
		world.setBlock(i + 32, j + 1, k + 7, PlaceDeepslateTiles, 2, 2);
		world.setBlock(i + 33, j + 1, k + 7, PlaceDeepslateTiles, 2, 2);
		world.setBlock(i + 34, j + 1, k + 7, PlaceCrackedDeepslateTiles, 3, 2);
		world.setBlock(i + 35, j + 1, k + 7, PlaceDeepslateTiles, 2, 2);
		world.setBlock(i + 36, j + 1, k + 7, Blocks.air, 0, 2);
		world.setBlock(i + 37, j + 1, k + 7, PlaceDeepslateTiles, 2, 2);
		world.setBlock(i + 38, j + 1, k + 7, PlaceDeepslateTiles, 2, 2);
		world.setBlock(i + 39, j + 1, k + 7, PlaceDeepslateTiles, 2, 2);
		world.setBlock(i + 40, j + 1, k + 7, PlaceDeepslateTiles, 2, 2);
		world.setBlock(i + 41, j + 1, k + 7, PlaceCrackedDeepslateTiles, 3, 2);
		world.setBlock(i + 42, j + 1, k + 7, PlaceDeepslateTiles, 2, 2);
		world.setBlock(i + 43, j + 1, k + 7, PlaceDeepslateTiles, 2, 2);
		world.setBlock(i + 44, j + 1, k + 7, Blocks.air, 0, 2);
		world.setBlock(i + 45, j + 1, k + 7, Blocks.air, 0, 2);
		world.setBlock(i + 46, j + 1, k + 7, Blocks.air, 0, 2);
		world.setBlock(i + 47, j + 1, k + 7, Blocks.air, 0, 2);
		world.setBlock(i + 48, j + 1, k + 7, Blocks.air, 0, 2);
		world.setBlock(i + 49, j + 1, k + 7, Blocks.air, 0, 2);
		world.setBlock(i + 50, j + 1, k + 7, PlaceDeepslateTiles, 2, 2);
		world.setBlock(i + 51, j + 1, k + 7, PlaceDeepslateTiles, 2, 2);
		world.setBlock(i + 52, j + 1, k + 7, PlaceCrackedDeepslateTiles, 3, 2);
		world.setBlock(i + 53, j + 1, k + 7, Blocks.air, 0, 2);
		world.setBlock(i + 54, j + 1, k + 7, PlaceDeepslateTiles, 2, 2);
		world.setBlock(i + 55, j + 1, k + 7, PlaceDeepslateTiles, 2, 2);
		world.setBlock(i + 56, j + 1, k + 7, Blocks.air, 0, 2);
		world.setBlock(i + 57, j + 1, k + 7, Blocks.air, 0, 2);
		world.setBlock(i + 58, j + 1, k + 7, Blocks.air, 0, 2);
		world.setBlock(i, j + 1, k + 8, Blocks.air, 0, 2);
		world.setBlock(i + 1, j + 1, k + 8, Blocks.air, 0, 2);
		world.setBlock(i + 2, j + 1, k + 8, Blocks.air, 0, 2);
		world.setBlock(i + 3, j + 1, k + 8, PlaceDeepslateTileStairs, 0, 2);
		world.setBlock(i + 4, j + 1, k + 8, PlaceDeepslateTiles, 2, 2);
		world.setBlock(i + 5, j + 1, k + 8, PlaceCrackedDeepslateTiles, 3, 2);
		world.setBlock(i + 6, j + 1, k + 8, PlaceDeepslateTiles, 2, 2);
		world.setBlock(i + 7, j + 1, k + 8, PlaceCrackedDeepslateTiles, 3, 2);
		world.setBlock(i + 8, j + 1, k + 8, PlaceCrackedDeepslateTiles, 3, 2);
		world.setBlock(i + 9, j + 1, k + 8, PlaceDeepslateTileStairs, 1, 2);
		world.setBlock(i + 10, j + 1, k + 8, Blocks.air, 0, 2);
		world.setBlock(i + 11, j + 1, k + 8, Blocks.air, 0, 2);
		world.setBlock(i + 12, j + 1, k + 8, PlaceDeepslateTileStairs, 0, 2);
		world.setBlock(i + 13, j + 1, k + 8, PlaceDeepslateTiles, 2, 2);
		world.setBlock(i + 14, j + 1, k + 8, PlaceDeepslateTiles, 2, 2);
		world.setBlock(i + 15, j + 1, k + 8, PlaceDeepslateTiles, 2, 2);
		world.setBlock(i + 16, j + 1, k + 8, PlaceDeepslateTiles, 2, 2);
		world.setBlock(i + 17, j + 1, k + 8, PlaceDeepslateTiles, 2, 2);
		world.setBlock(i + 18, j + 1, k + 8, PlaceDeepslateTileStairs, 1, 2);
		world.setBlock(i + 19, j + 1, k + 8, Blocks.air, 0, 2);
		world.setBlock(i + 20, j + 1, k + 8, Blocks.air, 0, 2);
		world.setBlock(i + 21, j + 1, k + 8, Blocks.air, 0, 2);
		world.setBlock(i + 22, j + 1, k + 8, Blocks.air, 0, 2);
		world.setBlock(i + 23, j + 1, k + 8, PlaceDeepslateTileStairs, 0, 2);
		world.setBlock(i + 24, j + 1, k + 8, PlaceDeepslateTiles, 2, 2);
		world.setBlock(i + 25, j + 1, k + 8, PlaceDeepslateTiles, 2, 2);
		world.setBlock(i + 26, j + 1, k + 8, PlaceCrackedDeepslateTiles, 3, 2);
		world.setBlock(i + 27, j + 1, k + 8, PlaceDeepslateTiles, 2, 2);
		world.setBlock(i + 28, j + 1, k + 8, PlaceDeepslateTiles, 2, 2);
		world.setBlock(i + 29, j + 1, k + 8, PlaceDeepslateTiles, 2, 2);
		world.setBlock(i + 30, j + 1, k + 8, PlaceCrackedDeepslateTiles, 3, 2);
		world.setBlock(i + 31, j + 1, k + 8, PlaceDeepslateTiles, 2, 2);
		world.setBlock(i + 32, j + 1, k + 8, PlaceCrackedDeepslateTiles, 3, 2);
		world.setBlock(i + 33, j + 1, k + 8, PlaceDeepslateTiles, 2, 2);
		world.setBlock(i + 34, j + 1, k + 8, PlaceCrackedDeepslateTiles, 3, 2);
		world.setBlock(i + 35, j + 1, k + 8, PlaceDeepslateTiles, 2, 2);
		world.setBlock(i + 36, j + 1, k + 8, PlaceDeepslateTiles, 2, 2);
		world.setBlock(i + 37, j + 1, k + 8, Blocks.air, 0, 2);
		world.setBlock(i + 38, j + 1, k + 8, PlaceDeepslateTiles, 2, 2);
		world.setBlock(i + 39, j + 1, k + 8, PlaceDeepslateTiles, 2, 2);
		world.setBlock(i + 40, j + 1, k + 8, PlaceDeepslateTiles, 2, 2);
		world.setBlock(i + 41, j + 1, k + 8, PlaceDeepslateTiles, 2, 2);
		world.setBlock(i + 42, j + 1, k + 8, PlaceDeepslateTiles, 2, 2);
		world.setBlock(i + 43, j + 1, k + 8, PlaceDeepslateTiles, 2, 2);
		world.setBlock(i + 44, j + 1, k + 8, Blocks.air, 0, 2);
		world.setBlock(i + 45, j + 1, k + 8, Blocks.air, 0, 2);
		world.setBlock(i + 46, j + 1, k + 8, Blocks.air, 0, 2);
		world.setBlock(i + 47, j + 1, k + 8, Blocks.air, 0, 2);
		world.setBlock(i + 48, j + 1, k + 8, Blocks.air, 0, 2);
		world.setBlock(i + 49, j + 1, k + 8, Blocks.air, 0, 2);
		world.setBlock(i + 50, j + 1, k + 8, PlaceDeepslateTiles, 2, 2);
		world.setBlock(i + 51, j + 1, k + 8, PlaceDeepslateTiles, 2, 2);
		world.setBlock(i + 52, j + 1, k + 8, PlaceDeepslateTiles, 2, 2);
		world.setBlock(i + 53, j + 1, k + 8, PlaceCrackedDeepslateTiles, 3, 2);
		world.setBlock(i + 54, j + 1, k + 8, PlaceDeepslateTiles, 2, 2);
		world.setBlock(i + 55, j + 1, k + 8, PlaceDeepslateTiles, 2, 2);
		world.setBlock(i + 56, j + 1, k + 8, PlaceDeepslateTiles, 2, 2);
		world.setBlock(i + 57, j + 1, k + 8, Blocks.air, 0, 2);
		world.setBlock(i + 58, j + 1, k + 8, Blocks.air, 0, 2);
		world.setBlock(i, j + 2, k, Blocks.air, 0, 2);
		world.setBlock(i + 1, j + 2, k, Blocks.air, 0, 2);
		world.setBlock(i + 2, j + 2, k, Blocks.air, 0, 2);
		world.setBlock(i + 3, j + 2, k, Blocks.air, 0, 2);
		world.setBlock(i + 4, j + 2, k, Blocks.air, 0, 2);
		world.setBlock(i + 5, j + 2, k, Blocks.air, 0, 2);
		world.setBlock(i + 6, j + 2, k, Blocks.air, 0, 2);
		world.setBlock(i + 7, j + 2, k, Blocks.air, 0, 2);
		world.setBlock(i + 8, j + 2, k, Blocks.air, 0, 2);
		world.setBlock(i + 9, j + 2, k, Blocks.air, 0, 2);
		world.setBlock(i + 10, j + 2, k, Blocks.air, 0, 2);
		world.setBlock(i + 11, j + 2, k, Blocks.air, 0, 2);
		world.setBlock(i + 12, j + 2, k, Blocks.air, 0, 2);
		world.setBlock(i + 13, j + 2, k, Blocks.air, 0, 2);
		world.setBlock(i + 14, j + 2, k, Blocks.air, 0, 2);
		world.setBlock(i + 15, j + 2, k, Blocks.air, 0, 2);
		world.setBlock(i + 16, j + 2, k, Blocks.air, 0, 2);
		world.setBlock(i + 17, j + 2, k, Blocks.air, 0, 2);
		world.setBlock(i + 18, j + 2, k, Blocks.air, 0, 2);
		world.setBlock(i + 19, j + 2, k, Blocks.air, 0, 2);
		world.setBlock(i + 20, j + 2, k, Blocks.air, 0, 2);
		world.setBlock(i + 21, j + 2, k, Blocks.air, 0, 2);
		world.setBlock(i + 22, j + 2, k, Blocks.air, 0, 2);
		world.setBlock(i + 23, j + 2, k, Blocks.air, 0, 2);
		world.setBlock(i + 24, j + 2, k, Blocks.air, 0, 2);
		world.setBlock(i + 25, j + 2, k, Blocks.air, 0, 2);
		world.setBlock(i + 26, j + 2, k, Blocks.air, 0, 2);
		world.setBlock(i + 27, j + 2, k, Blocks.air, 0, 2);
		world.setBlock(i + 28, j + 2, k, Blocks.air, 0, 2);
		world.setBlock(i + 29, j + 2, k, Blocks.air, 0, 2);
		world.setBlock(i + 30, j + 2, k, Blocks.air, 0, 2);
		world.setBlock(i + 31, j + 2, k, Blocks.air, 0, 2);
		world.setBlock(i + 32, j + 2, k, Blocks.air, 0, 2);
		world.setBlock(i + 33, j + 2, k, Blocks.air, 0, 2);
		world.setBlock(i + 34, j + 2, k, PlaceBasalt, 1, 2);
		world.setBlock(i + 35, j + 2, k, PlaceDeepslate, 0, 2);
		world.setBlock(i + 36, j + 2, k, Blocks.planks, 5, 2);
		world.setBlock(i + 37, j + 2, k, Blocks.planks, 5, 2);
		world.setBlock(i + 38, j + 2, k, Blocks.air, 0, 2);
		world.setBlock(i + 39, j + 2, k, Blocks.air, 0, 2);
		world.setBlock(i + 40, j + 2, k, Blocks.air, 0, 2);
		world.setBlock(i + 41, j + 2, k, Blocks.air, 0, 2);
		world.setBlock(i + 42, j + 2, k, Blocks.air, 0, 2);
		world.setBlock(i + 43, j + 2, k, Blocks.air, 0, 2);
		world.setBlock(i + 44, j + 2, k, Blocks.planks, 5, 2);
		world.setBlock(i + 45, j + 2, k, Blocks.air, 0, 2);
		world.setBlock(i + 46, j + 2, k, Blocks.planks, 5, 2);
		world.setBlock(i + 47, j + 2, k, Blocks.air, 0, 2);
		world.setBlock(i + 48, j + 2, k, Blocks.air, 0, 2);
		world.setBlock(i + 49, j + 2, k, PlaceBasalt, 5, 2);
		world.setBlock(i + 50, j + 2, k, Blocks.air, 0, 2);
		world.setBlock(i + 51, j + 2, k, Blocks.air, 0, 2);
		world.setBlock(i + 52, j + 2, k, Blocks.air, 0, 2);
		world.setBlock(i + 53, j + 2, k, Blocks.air, 0, 2);
		world.setBlock(i + 54, j + 2, k, Blocks.air, 0, 2);
		world.setBlock(i + 55, j + 2, k, Blocks.air, 0, 2);
		world.setBlock(i + 56, j + 2, k, Blocks.air, 0, 2);
		world.setBlock(i + 57, j + 2, k, Blocks.air, 0, 2);
		world.setBlock(i + 58, j + 2, k, Blocks.air, 0, 2);
		world.setBlock(i, j + 2, k + 1, Blocks.air, 0, 2);
		world.setBlock(i + 1, j + 2, k + 1, Blocks.air, 0, 2);
		world.setBlock(i + 2, j + 2, k + 1, Blocks.air, 0, 2);
		world.setBlock(i + 3, j + 2, k + 1, Blocks.air, 0, 2);
		world.setBlock(i + 4, j + 2, k + 1, Blocks.air, 0, 2);
		world.setBlock(i + 5, j + 2, k + 1, Blocks.air, 0, 2);
		world.setBlock(i + 6, j + 2, k + 1, Blocks.air, 0, 2);
		world.setBlock(i + 7, j + 2, k + 1, Blocks.air, 0, 2);
		world.setBlock(i + 8, j + 2, k + 1, Blocks.air, 0, 2);
		world.setBlock(i + 9, j + 2, k + 1, Blocks.air, 0, 2);
		world.setBlock(i + 10, j + 2, k + 1, Blocks.air, 0, 2);
		world.setBlock(i + 11, j + 2, k + 1, Blocks.air, 0, 2);
		world.setBlock(i + 12, j + 2, k + 1, Blocks.air, 0, 2);
		world.setBlock(i + 13, j + 2, k + 1, Blocks.air, 0, 2);
		world.setBlock(i + 14, j + 2, k + 1, Blocks.air, 0, 2);
		world.setBlock(i + 15, j + 2, k + 1, Blocks.air, 0, 2);
		world.setBlock(i + 16, j + 2, k + 1, Blocks.air, 0, 2);
		world.setBlock(i + 17, j + 2, k + 1, Blocks.air, 0, 2);
		world.setBlock(i + 18, j + 2, k + 1, Blocks.air, 0, 2);
		world.setBlock(i + 19, j + 2, k + 1, Blocks.air, 0, 2);
		world.setBlock(i + 20, j + 2, k + 1, Blocks.air, 0, 2);
		world.setBlock(i + 21, j + 2, k + 1, Blocks.air, 0, 2);
		world.setBlock(i + 22, j + 2, k + 1, Blocks.air, 0, 2);
		world.setBlock(i + 23, j + 2, k + 1, Blocks.air, 0, 2);
		world.setBlock(i + 24, j + 2, k + 1, Blocks.air, 0, 2);
		world.setBlock(i + 25, j + 2, k + 1, Blocks.air, 0, 2);
		world.setBlock(i + 26, j + 2, k + 1, PlaceDeepslate, 0, 2);
		world.setBlock(i + 27, j + 2, k + 1, PlaceDeepslate, 0, 2);
		world.setBlock(i + 28, j + 2, k + 1, PlaceDeepslate, 0, 2);
		world.setBlock(i + 29, j + 2, k + 1, Blocks.air, 0, 2);
		world.setBlock(i + 30, j + 2, k + 1, Blocks.air, 0, 2);
		world.setBlock(i + 31, j + 2, k + 1, Blocks.air, 0, 2);
		world.setBlock(i + 32, j + 2, k + 1, PlaceDeepslate, 0, 2);
		world.setBlock(i + 33, j + 2, k + 1, PlaceDeepslate, 0, 2);
		world.setBlock(i + 34, j + 2, k + 1, NovaCraftBlocks.sculk_block, 0, 2);
		world.setBlock(i + 35, j + 2, k + 1, PlaceDeepslate, 0, 2);
		world.setBlock(i + 36, j + 2, k + 1, NovaCraftBlocks.sculk_block, 0, 2);
		world.setBlock(i + 37, j + 2, k + 1, Blocks.planks, 5, 2);
		world.setBlock(i + 38, j + 2, k + 1, NovaCraftBlocks.sculk_block, 0, 2);
		world.setBlock(i + 39, j + 2, k + 1, Blocks.air, 0, 2);
		world.setBlock(i + 40, j + 2, k + 1, Blocks.air, 0, 2);
		world.setBlock(i + 41, j + 2, k + 1, Blocks.air, 0, 2);
		world.setBlock(i + 42, j + 2, k + 1, Blocks.air, 0, 2);
		world.setBlock(i + 43, j + 2, k + 1, Blocks.air, 0, 2);
		world.setBlock(i + 44, j + 2, k + 1, Blocks.planks, 5, 2);
		world.setBlock(i + 45, j + 2, k + 1, Blocks.planks, 5, 2);
		world.setBlock(i + 46, j + 2, k + 1, PlaceDeepslate, 0, 2);
		world.setBlock(i + 47, j + 2, k + 1, Blocks.air, 0, 2);
		world.setBlock(i + 48, j + 2, k + 1, Blocks.air, 0, 2);
		world.setBlock(i + 49, j + 2, k + 1, Blocks.air, 0, 2);
		world.setBlock(i + 50, j + 2, k + 1, Blocks.air, 0, 2);
		world.setBlock(i + 51, j + 2, k + 1, Blocks.air, 0, 2);
		world.setBlock(i + 52, j + 2, k + 1, Blocks.air, 0, 2);
		world.setBlock(i + 53, j + 2, k + 1, Blocks.air, 0, 2);
		world.setBlock(i + 54, j + 2, k + 1, Blocks.air, 0, 2);
		world.setBlock(i + 55, j + 2, k + 1, Blocks.air, 0, 2);
		world.setBlock(i + 56, j + 2, k + 1, Blocks.air, 0, 2);
		world.setBlock(i + 57, j + 2, k + 1, Blocks.air, 0, 2);
		world.setBlock(i + 58, j + 2, k + 1, Blocks.air, 0, 2);
		world.setBlock(i, j + 2, k + 2, Blocks.air, 0, 2);
		world.setBlock(i + 1, j + 2, k + 2, Blocks.air, 0, 2);
		world.setBlock(i + 2, j + 2, k + 2, Blocks.air, 0, 2);
		world.setBlock(i + 3, j + 2, k + 2, Blocks.air, 0, 2);
		world.setBlock(i + 4, j + 2, k + 2, Blocks.air, 0, 2);
		world.setBlock(i + 5, j + 2, k + 2, Blocks.air, 0, 2);
		world.setBlock(i + 6, j + 2, k + 2, Blocks.air, 0, 2);
		world.setBlock(i + 7, j + 2, k + 2, Blocks.air, 0, 2);
		world.setBlock(i + 8, j + 2, k + 2, Blocks.air, 0, 2);
		world.setBlock(i + 9, j + 2, k + 2, Blocks.air, 0, 2);
		world.setBlock(i + 10, j + 2, k + 2, Blocks.air, 0, 2);
		world.setBlock(i + 11, j + 2, k + 2, Blocks.air, 0, 2);
		world.setBlock(i + 12, j + 2, k + 2, Blocks.air, 0, 2);
		world.setBlock(i + 13, j + 2, k + 2, Blocks.air, 0, 2);
		world.setBlock(i + 14, j + 2, k + 2, Blocks.air, 0, 2);
		world.setBlock(i + 15, j + 2, k + 2, Blocks.air, 0, 2);
		world.setBlock(i + 16, j + 2, k + 2, Blocks.air, 0, 2);
		world.setBlock(i + 17, j + 2, k + 2, Blocks.air, 0, 2);
		world.setBlock(i + 18, j + 2, k + 2, Blocks.air, 0, 2);
		world.setBlock(i + 19, j + 2, k + 2, Blocks.air, 0, 2);
		world.setBlock(i + 20, j + 2, k + 2, Blocks.air, 0, 2);
		world.setBlock(i + 21, j + 2, k + 2, Blocks.air, 0, 2);
		world.setBlock(i + 22, j + 2, k + 2, Blocks.air, 0, 2);
		world.setBlock(i + 23, j + 2, k + 2, Blocks.air, 0, 2);
		world.setBlock(i + 24, j + 2, k + 2, Blocks.air, 0, 2);
		world.setBlock(i + 25, j + 2, k + 2, Blocks.air, 0, 2);
		world.setBlock(i + 26, j + 2, k + 2, PlaceDeepslate, 0, 2);
		world.setBlock(i + 27, j + 2, k + 2, Blocks.air, 0, 2);
		world.setBlock(i + 28, j + 2, k + 2, Blocks.air, 0, 2);
		world.setBlock(i + 29, j + 2, k + 2, Blocks.air, 0, 2);
		world.setBlock(i + 30, j + 2, k + 2, PlaceDeepslate, 0, 2);
		world.setBlock(i + 31, j + 2, k + 2, Blocks.air, 0, 2);
		world.setBlock(i + 32, j + 2, k + 2, PlaceDeepslate, 0, 2);
		world.setBlock(i + 33, j + 2, k + 2, PlaceDeepslate, 0, 2);
		world.setBlock(i + 34, j + 2, k + 2, PlaceDeepslate, 0, 2);
		world.setBlock(i + 35, j + 2, k + 2, PlaceDeepslate, 0, 2);
		world.setBlock(i + 36, j + 2, k + 2, PlaceDeepslate, 0, 2);
		world.setBlock(i + 37, j + 2, k + 2, PlaceDeepslate, 0, 2);
		world.setBlock(i + 38, j + 2, k + 2, PlaceDeepslate, 0, 2);
		world.setBlock(i + 39, j + 2, k + 2, NovaCraftBlocks.sculk_block, 0, 2);
		world.setBlock(i + 40, j + 2, k + 2, Blocks.air, 0, 2);
		world.setBlock(i + 41, j + 2, k + 2, PlaceDeepslate, 0, 2);
		world.setBlock(i + 42, j + 2, k + 2, Blocks.air, 0, 2);
		world.setBlock(i + 43, j + 2, k + 2, PlaceDeepslate, 0, 2);
		world.setBlock(i + 44, j + 2, k + 2, Blocks.air, 0, 2);
		world.setBlock(i + 45, j + 2, k + 2, Blocks.air, 0, 2);
		world.setBlock(i + 46, j + 2, k + 2, PlaceDeepslate, 0, 2);
		world.setBlock(i + 47, j + 2, k + 2, Blocks.air, 0, 2);
		world.setBlock(i + 48, j + 2, k + 2, Blocks.air, 0, 2);
		world.setBlock(i + 49, j + 2, k + 2, Blocks.air, 0, 2);
		world.setBlock(i + 50, j + 2, k + 2, PlacePolishedDeepslate, 0, 2);
		world.setBlock(i + 51, j + 2, k + 2, Blocks.air, 0, 2);
		world.setBlock(i + 52, j + 2, k + 2, Blocks.air, 0, 2);
		world.setBlock(i + 53, j + 2, k + 2, Blocks.air, 0, 2);
		world.setBlock(i + 54, j + 2, k + 2, Blocks.air, 0, 2);
		world.setBlock(i + 55, j + 2, k + 2, Blocks.air, 0, 2);
		world.setBlock(i + 56, j + 2, k + 2, Blocks.air, 0, 2);
		world.setBlock(i + 57, j + 2, k + 2, Blocks.air, 0, 2);
		world.setBlock(i + 58, j + 2, k + 2, Blocks.air, 0, 2);
		world.setBlock(i, j + 2, k + 3, Blocks.air, 0, 2);
		world.setBlock(i + 1, j + 2, k + 3, Blocks.air, 0, 2);
		world.setBlock(i + 2, j + 2, k + 3, Blocks.air, 0, 2);
		world.setBlock(i + 3, j + 2, k + 3, Blocks.air, 0, 2);
		world.setBlock(i + 4, j + 2, k + 3, Blocks.air, 0, 2);
		world.setBlock(i + 5, j + 2, k + 3, Blocks.air, 0, 2);
		world.setBlock(i + 6, j + 2, k + 3, Blocks.air, 0, 2);
		world.setBlock(i + 7, j + 2, k + 3, Blocks.air, 0, 2);
		world.setBlock(i + 8, j + 2, k + 3, Blocks.air, 0, 2);
		world.setBlock(i + 9, j + 2, k + 3, Blocks.air, 0, 2);
		world.setBlock(i + 10, j + 2, k + 3, Blocks.air, 0, 2);
		world.setBlock(i + 11, j + 2, k + 3, Blocks.air, 0, 2);
		world.setBlock(i + 12, j + 2, k + 3, Blocks.air, 0, 2);
		world.setBlock(i + 13, j + 2, k + 3, Blocks.air, 0, 2);
		world.setBlock(i + 14, j + 2, k + 3, Blocks.air, 0, 2);
		world.setBlock(i + 15, j + 2, k + 3, Blocks.air, 0, 2);
		world.setBlock(i + 16, j + 2, k + 3, Blocks.air, 0, 2);
		world.setBlock(i + 17, j + 2, k + 3, Blocks.air, 0, 2);
		world.setBlock(i + 18, j + 2, k + 3, Blocks.air, 0, 2);
		world.setBlock(i + 19, j + 2, k + 3, Blocks.air, 0, 2);
		world.setBlock(i + 20, j + 2, k + 3, Blocks.air, 0, 2);
		world.setBlock(i + 21, j + 2, k + 3, Blocks.air, 0, 2);
		world.setBlock(i + 22, j + 2, k + 3, Blocks.air, 0, 2);
		world.setBlock(i + 23, j + 2, k + 3, Blocks.air, 0, 2);
		world.setBlock(i + 24, j + 2, k + 3, Blocks.air, 0, 2);
		world.setBlock(i + 25, j + 2, k + 3, Blocks.air, 0, 2);
		world.setBlock(i + 26, j + 2, k + 3, PlaceDeepslate, 0, 2);
		world.setBlock(i + 27, j + 2, k + 3, PlaceDeepslate, 0, 2);
		world.setBlock(i + 28, j + 2, k + 3, Blocks.air, 0, 2);
		world.setBlock(i + 29, j + 2, k + 3, Blocks.air, 0, 2);
		world.setBlock(i + 30, j + 2, k + 3, Blocks.air, 0, 2);
		world.setBlock(i + 31, j + 2, k + 3, Blocks.air, 0, 2);
		world.setBlock(i + 32, j + 2, k + 3, PlaceDeepslate, 0, 2);
		world.setBlock(i + 33, j + 2, k + 3, PlaceDeepslate, 0, 2);
		world.setBlock(i + 34, j + 2, k + 3, PlaceDeepslate, 0, 2);
		world.setBlock(i + 35, j + 2, k + 3, Blocks.air, 0, 2);
		world.setBlock(i + 36, j + 2, k + 3, PlaceDeepslate, 0, 2);
		world.setBlock(i + 37, j + 2, k + 3, PlaceDeepslate, 0, 2);
		world.setBlock(i + 38, j + 2, k + 3, PlaceDeepslate, 0, 2);
		world.setBlock(i + 39, j + 2, k + 3, PlaceDeepslate, 0, 2);
		world.setBlock(i + 40, j + 2, k + 3, PlaceDeepslate, 0, 2);
		world.setBlock(i + 41, j + 2, k + 3, PlaceDeepslate, 0, 2);
		world.setBlock(i + 42, j + 2, k + 3, PlaceDeepslate, 0, 2);
		world.setBlock(i + 43, j + 2, k + 3, PlaceDeepslate, 0, 2);
		world.setBlock(i + 44, j + 2, k + 3, Blocks.air, 0, 2);
		world.setBlock(i + 45, j + 2, k + 3, PlacePolishedDeepslate, 0, 2);
		world.setBlock(i + 46, j + 2, k + 3, Blocks.air, 0, 2);
		world.setBlock(i + 47, j + 2, k + 3, PlaceDeepslateTileStairs, 2, 2);
		world.setBlock(i + 48, j + 2, k + 3, Blocks.air, 0, 2);
		world.setBlock(i + 49, j + 2, k + 3, PlacePolishedDeepslate, 0, 2);
		world.setBlock(i + 50, j + 2, k + 3, PlacePolishedDeepslate, 0, 2);
		world.setBlock(i + 51, j + 2, k + 3, PlaceBasalt, 9, 2);
		world.setBlock(i + 52, j + 2, k + 3, Blocks.air, 0, 2);
		world.setBlock(i + 53, j + 2, k + 3, Blocks.air, 0, 2);
		world.setBlock(i + 54, j + 2, k + 3, Blocks.air, 0, 2);
		world.setBlock(i + 55, j + 2, k + 3, Blocks.air, 0, 2);
		world.setBlock(i + 56, j + 2, k + 3, Blocks.air, 0, 2);
		world.setBlock(i + 57, j + 2, k + 3, Blocks.air, 0, 2);
		world.setBlock(i + 58, j + 2, k + 3, Blocks.air, 0, 2);
		world.setBlock(i, j + 2, k + 4, Blocks.air, 0, 2);
		world.setBlock(i + 1, j + 2, k + 4, Blocks.air, 0, 2);
		world.setBlock(i + 2, j + 2, k + 4, Blocks.air, 0, 2);
		world.setBlock(i + 3, j + 2, k + 4, Blocks.air, 0, 2);
		world.setBlock(i + 4, j + 2, k + 4, NovaCraftBlocks.sculk_block, 0, 2);
		world.setBlock(i + 5, j + 2, k + 4, PlaceDeepslate, 0, 2);
		world.setBlock(i + 6, j + 2, k + 4, PlaceDeepslate, 0, 2);
		world.setBlock(i + 7, j + 2, k + 4, PlaceDeepslate, 0, 2);
		world.setBlock(i + 8, j + 2, k + 4, Blocks.air, 0, 2);
		world.setBlock(i + 9, j + 2, k + 4, Blocks.air, 0, 2);
		world.setBlock(i + 10, j + 2, k + 4, Blocks.air, 0, 2);
		world.setBlock(i + 11, j + 2, k + 4, Blocks.air, 0, 2);
		world.setBlock(i + 12, j + 2, k + 4, Blocks.air, 0, 2);
		world.setBlock(i + 13, j + 2, k + 4, Blocks.air, 0, 2);
		world.setBlock(i + 14, j + 2, k + 4, PlaceDeepslate, 0, 2);
		world.setBlock(i + 15, j + 2, k + 4, PlaceDeepslate, 0, 2);
		world.setBlock(i + 16, j + 2, k + 4, PlaceDeepslate, 0, 2);
		world.setBlock(i + 17, j + 2, k + 4, Blocks.air, 0, 2);
		world.setBlock(i + 18, j + 2, k + 4, Blocks.air, 0, 2);
		world.setBlock(i + 19, j + 2, k + 4, Blocks.air, 0, 2);
		world.setBlock(i + 20, j + 2, k + 4, Blocks.air, 0, 2);
		world.setBlock(i + 21, j + 2, k + 4, Blocks.air, 0, 2);
		world.setBlock(i + 22, j + 2, k + 4, Blocks.air, 0, 2);
		world.setBlock(i + 23, j + 2, k + 4, Blocks.air, 0, 2);
		world.setBlock(i + 24, j + 2, k + 4, NovaCraftBlocks.sculk_block, 0, 2);
		world.setBlock(i + 25, j + 2, k + 4, PlaceDeepslate, 0, 2);
		world.setBlock(i + 26, j + 2, k + 4, PlaceDeepslate, 0, 2);
		world.setBlock(i + 27, j + 2, k + 4, PlaceDeepslate, 0, 2);
		world.setBlock(i + 28, j + 2, k + 4, PlaceDeepslate, 0, 2);
		world.setBlock(i + 29, j + 2, k + 4, Blocks.air, 0, 2);
		world.setBlock(i + 30, j + 2, k + 4, Blocks.air, 0, 2);
		world.setBlock(i + 31, j + 2, k + 4, Blocks.air, 0, 2);
		world.setBlock(i + 32, j + 2, k + 4, Blocks.air, 0, 2);
		world.setBlock(i + 33, j + 2, k + 4, PlaceDeepslate, 0, 2);
		world.setBlock(i + 34, j + 2, k + 4, PlaceDeepslate, 0, 2);
		world.setBlock(i + 35, j + 2, k + 4, PlaceDeepslate, 0, 2);
		world.setBlock(i + 36, j + 2, k + 4, Blocks.air, 0, 2);
		world.setBlock(i + 37, j + 2, k + 4, PlaceDeepslate, 0, 2);
		world.setBlock(i + 38, j + 2, k + 4, PlaceDeepslate, 0, 2);
		world.setBlock(i + 39, j + 2, k + 4, PlaceDeepslate, 0, 2);
		world.setBlock(i + 40, j + 2, k + 4, PlaceDeepslate, 0, 2);
		world.setBlock(i + 41, j + 2, k + 4, PlaceDeepslate, 0, 2);
		world.setBlock(i + 42, j + 2, k + 4, PlaceDeepslate, 0, 2);
		world.setBlock(i + 43, j + 2, k + 4, Blocks.air, 0, 2);
		world.setBlock(i + 44, j + 2, k + 4, Blocks.air, 0, 2);
		world.setBlock(i + 45, j + 2, k + 4, Blocks.air, 0, 2);
		world.setBlock(i + 46, j + 2, k + 4, PlaceDeepslate, 0, 2);
		world.setBlock(i + 47, j + 2, k + 4, PlaceDeepslate, 0, 2);
		world.setBlock(i + 48, j + 2, k + 4, Blocks.air, 0, 2);
		world.setBlock(i + 49, j + 2, k + 4, Blocks.air, 0, 2);
		world.setBlock(i + 50, j + 2, k + 4, PlacePolishedDeepslate, 0, 2);
		world.setBlock(i + 51, j + 2, k + 4, PlaceBasalt, 9, 2);
		world.setBlock(i + 52, j + 2, k + 4, Blocks.air, 0, 2);
		world.setBlock(i + 53, j + 2, k + 4, Blocks.air, 0, 2);
		world.setBlock(i + 54, j + 2, k + 4, Blocks.air, 0, 2);
		world.setBlock(i + 55, j + 2, k + 4, Blocks.air, 0, 2);
		world.setBlock(i + 56, j + 2, k + 4, Blocks.air, 0, 2);
		world.setBlock(i + 57, j + 2, k + 4, Blocks.air, 0, 2);
		world.setBlock(i + 58, j + 2, k + 4, Blocks.air, 0, 2);
		world.setBlock(i, j + 2, k + 5, Blocks.air, 0, 2);
		world.setBlock(i + 1, j + 2, k + 5, Blocks.air, 0, 2);
		world.setBlock(i + 2, j + 2, k + 5, Blocks.air, 0, 2);
		world.setBlock(i + 3, j + 2, k + 5, Blocks.air, 0, 2);
		world.setBlock(i + 4, j + 2, k + 5, PlaceDeepslate, 0, 2);
		world.setBlock(i + 5, j + 2, k + 5, PlaceDeepslate, 0, 2);
		world.setBlock(i + 6, j + 2, k + 5, PlaceDeepslate, 0, 2);
		world.setBlock(i + 7, j + 2, k + 5, PlaceDeepslate, 0, 2);
		world.setBlock(i + 8, j + 2, k + 5, Blocks.air, 0, 2);
		world.setBlock(i + 9, j + 2, k + 5, Blocks.air, 0, 2);
		world.setBlock(i + 10, j + 2, k + 5, Blocks.air, 0, 2);
		world.setBlock(i + 11, j + 2, k + 5, Blocks.air, 0, 2);
		world.setBlock(i + 12, j + 2, k + 5, Blocks.air, 0, 2);
		world.setBlock(i + 13, j + 2, k + 5, Blocks.air, 0, 2);
		world.setBlock(i + 14, j + 2, k + 5, PlaceDeepslate, 0, 2);
		world.setBlock(i + 15, j + 2, k + 5, PlaceDeepslate, 0, 2);
		world.setBlock(i + 16, j + 2, k + 5, PlaceDeepslate, 0, 2);
		world.setBlock(i + 17, j + 2, k + 5, NovaCraftBlocks.sculk_block, 0, 2);
		world.setBlock(i + 18, j + 2, k + 5, Blocks.air, 0, 2);
		world.setBlock(i + 19, j + 2, k + 5, Blocks.air, 0, 2);
		world.setBlock(i + 20, j + 2, k + 5, Blocks.air, 0, 2);
		world.setBlock(i + 21, j + 2, k + 5, Blocks.air, 0, 2);
		world.setBlock(i + 22, j + 2, k + 5, Blocks.air, 0, 2);
		world.setBlock(i + 23, j + 2, k + 5, Blocks.air, 0, 2);
		world.setBlock(i + 24, j + 2, k + 5, PlaceDeepslate, 0, 2);
		world.setBlock(i + 25, j + 2, k + 5, PlaceDeepslate, 0, 2);
		world.setBlock(i + 26, j + 2, k + 5, PlaceDeepslate, 0, 2);
		world.setBlock(i + 27, j + 2, k + 5, Blocks.air, 0, 2);
		world.setBlock(i + 28, j + 2, k + 5, Blocks.air, 0, 2);
		world.setBlock(i + 29, j + 2, k + 5, Blocks.air, 0, 2);
		world.setBlock(i + 30, j + 2, k + 5, Blocks.air, 0, 2);
		world.setBlock(i + 31, j + 2, k + 5, Blocks.air, 0, 2);
		world.setBlock(i + 32, j + 2, k + 5, Blocks.air, 0, 2);
		world.setBlock(i + 33, j + 2, k + 5, PlaceDeepslate, 0, 2);
		world.setBlock(i + 34, j + 2, k + 5, PlaceDeepslate, 0, 2);
		world.setBlock(i + 35, j + 2, k + 5, PlaceDeepslate, 0, 2);
		world.setBlock(i + 36, j + 2, k + 5, PlaceDeepslate, 0, 2);
		world.setBlock(i + 37, j + 2, k + 5, PlaceDeepslate, 0, 2);
		world.setBlock(i + 38, j + 2, k + 5, PlaceDeepslate, 0, 2);
		world.setBlock(i + 39, j + 2, k + 5, PlaceDeepslate, 0, 2);
		world.setBlock(i + 40, j + 2, k + 5, PlaceDeepslate, 0, 2);
		world.setBlock(i + 41, j + 2, k + 5, PlaceDeepslate, 0, 2);
		world.setBlock(i + 42, j + 2, k + 5, PlaceDeepslate, 0, 2);
		world.setBlock(i + 43, j + 2, k + 5, Blocks.air, 0, 2);
		world.setBlock(i + 44, j + 2, k + 5, Blocks.air, 0, 2);
		world.setBlock(i + 45, j + 2, k + 5, Blocks.air, 0, 2);
		world.setBlock(i + 46, j + 2, k + 5, Blocks.air, 0, 2);
		world.setBlock(i + 47, j + 2, k + 5, Blocks.air, 0, 2);
		world.setBlock(i + 48, j + 2, k + 5, Blocks.air, 0, 2);
		world.setBlock(i + 49, j + 2, k + 5, Blocks.air, 0, 2);
		world.setBlock(i + 50, j + 2, k + 5, Blocks.air, 0, 2);
		world.setBlock(i + 51, j + 2, k + 5, PlaceBasalt, 9, 2);
		world.setBlock(i + 52, j + 2, k + 5, Blocks.air, 0, 2);
		world.setBlock(i + 53, j + 2, k + 5, Blocks.air, 0, 2);
		world.setBlock(i + 54, j + 2, k + 5, Blocks.air, 0, 2);
		world.setBlock(i + 55, j + 2, k + 5, Blocks.air, 0, 2);
		world.setBlock(i + 56, j + 2, k + 5, Blocks.air, 0, 2);
		world.setBlock(i + 57, j + 2, k + 5, Blocks.air, 0, 2);
		world.setBlock(i + 58, j + 2, k + 5, Blocks.air, 0, 2);
		world.setBlock(i, j + 2, k + 6, Blocks.air, 0, 2);
		world.setBlock(i + 1, j + 2, k + 6, Blocks.air, 0, 2);
		world.setBlock(i + 2, j + 2, k + 6, Blocks.air, 0, 2);
		world.setBlock(i + 3, j + 2, k + 6, Blocks.air, 0, 2);
		world.setBlock(i + 4, j + 2, k + 6, PlaceDeepslate, 0, 2);
		world.setBlock(i + 5, j + 2, k + 6, PlaceDeepslate, 0, 2);
		world.setBlock(i + 6, j + 2, k + 6, PlaceDeepslate, 0, 2);
		world.setBlock(i + 7, j + 2, k + 6, PlaceDeepslate, 0, 2);
		world.setBlock(i + 8, j + 2, k + 6, Blocks.air, 0, 2);
		world.setBlock(i + 9, j + 2, k + 6, Blocks.air, 0, 2);
		world.setBlock(i + 10, j + 2, k + 6, Blocks.air, 0, 2);
		world.setBlock(i + 11, j + 2, k + 6, Blocks.air, 0, 2);
		world.setBlock(i + 12, j + 2, k + 6, Blocks.air, 0, 2);
		world.setBlock(i + 13, j + 2, k + 6, Blocks.air, 0, 2);
		world.setBlock(i + 14, j + 2, k + 6, PlaceDeepslate, 0, 2);
		world.setBlock(i + 15, j + 2, k + 6, PlaceDeepslate, 0, 2);
		world.setBlock(i + 16, j + 2, k + 6, PlaceDeepslate, 0, 2);
		world.setBlock(i + 17, j + 2, k + 6, PlaceDeepslate, 0, 2);
		world.setBlock(i + 18, j + 2, k + 6, Blocks.air, 0, 2);
		world.setBlock(i + 19, j + 2, k + 6, Blocks.air, 0, 2);
		world.setBlock(i + 20, j + 2, k + 6, Blocks.air, 0, 2);
		world.setBlock(i + 21, j + 2, k + 6, Blocks.air, 0, 2);
		world.setBlock(i + 22, j + 2, k + 6, Blocks.air, 0, 2);
		world.setBlock(i + 23, j + 2, k + 6, Blocks.air, 0, 2);
		world.setBlock(i + 24, j + 2, k + 6, PlaceDeepslate, 0, 2);
		world.setBlock(i + 25, j + 2, k + 6, PlaceDeepslate, 0, 2);
		world.setBlock(i + 26, j + 2, k + 6, PlaceDeepslate, 0, 2);
		world.setBlock(i + 27, j + 2, k + 6, Blocks.air, 0, 2);
		world.setBlock(i + 28, j + 2, k + 6, Blocks.air, 0, 2);
		world.setBlock(i + 29, j + 2, k + 6, Blocks.air, 0, 2);
		world.setBlock(i + 30, j + 2, k + 6, Blocks.air, 0, 2);
		world.setBlock(i + 31, j + 2, k + 6, Blocks.air, 0, 2);
		world.setBlock(i + 32, j + 2, k + 6, PlaceDeepslate, 0, 2);
		world.setBlock(i + 33, j + 2, k + 6, PlaceDeepslate, 0, 2);
		world.setBlock(i + 34, j + 2, k + 6, Blocks.air, 0, 2);
		world.setBlock(i + 35, j + 2, k + 6, PlaceDeepslate, 0, 2);
		world.setBlock(i + 36, j + 2, k + 6, PlaceDeepslate, 0, 2);
		world.setBlock(i + 37, j + 2, k + 6, PlaceDeepslate, 0, 2);
		world.setBlock(i + 38, j + 2, k + 6, PlaceDeepslate, 0, 2);
		world.setBlock(i + 39, j + 2, k + 6, PlaceDeepslate, 0, 2);
		world.setBlock(i + 40, j + 2, k + 6, PlaceDeepslate, 0, 2);
		world.setBlock(i + 41, j + 2, k + 6, PlaceDeepslate, 0, 2);
		world.setBlock(i + 42, j + 2, k + 6, PlaceDeepslate, 0, 2);
		world.setBlock(i + 43, j + 2, k + 6, Blocks.air, 0, 2);
		world.setBlock(i + 44, j + 2, k + 6, Blocks.air, 0, 2);
		world.setBlock(i + 45, j + 2, k + 6, Blocks.air, 0, 2);
		world.setBlock(i + 46, j + 2, k + 6, Blocks.air, 0, 2);
		world.setBlock(i + 47, j + 2, k + 6, Blocks.air, 0, 2);
		world.setBlock(i + 48, j + 2, k + 6, Blocks.air, 0, 2);
		world.setBlock(i + 49, j + 2, k + 6, Blocks.air, 0, 2);
		world.setBlock(i + 50, j + 2, k + 6, Blocks.air, 0, 2);
		world.setBlock(i + 51, j + 2, k + 6, PlaceBasalt, 9, 2);
		world.setBlock(i + 52, j + 2, k + 6, Blocks.air, 0, 2);
		world.setBlock(i + 53, j + 2, k + 6, Blocks.air, 0, 2);
		world.setBlock(i + 54, j + 2, k + 6, Blocks.air, 0, 2);
		world.setBlock(i + 55, j + 2, k + 6, Blocks.air, 0, 2);
		world.setBlock(i + 56, j + 2, k + 6, Blocks.air, 0, 2);
		world.setBlock(i + 57, j + 2, k + 6, Blocks.air, 0, 2);
		world.setBlock(i + 58, j + 2, k + 6, Blocks.air, 0, 2);
		world.setBlock(i, j + 2, k + 7, Blocks.air, 0, 2);
		world.setBlock(i + 1, j + 2, k + 7, Blocks.air, 0, 2);
		world.setBlock(i + 2, j + 2, k + 7, Blocks.air, 0, 2);
		world.setBlock(i + 3, j + 2, k + 7, Blocks.air, 0, 2);
		world.setBlock(i + 4, j + 2, k + 7, PlaceDeepslate, 0, 2);
		world.setBlock(i + 5, j + 2, k + 7, PlaceDeepslate, 0, 2);
		world.setBlock(i + 6, j + 2, k + 7, PlaceDeepslate, 0, 2);
		world.setBlock(i + 7, j + 2, k + 7, PlaceDeepslate, 0, 2);
		world.setBlock(i + 8, j + 2, k + 7, Blocks.air, 0, 2);
		world.setBlock(i + 9, j + 2, k + 7, Blocks.air, 0, 2);
		world.setBlock(i + 10, j + 2, k + 7, Blocks.air, 0, 2);
		world.setBlock(i + 11, j + 2, k + 7, Blocks.air, 0, 2);
		world.setBlock(i + 12, j + 2, k + 7, Blocks.air, 0, 2);
		world.setBlock(i + 13, j + 2, k + 7, Blocks.air, 0, 2);
		world.setBlock(i + 14, j + 2, k + 7, PlaceDeepslate, 0, 2);
		world.setBlock(i + 15, j + 2, k + 7, PlaceDeepslate, 0, 2);
		world.setBlock(i + 16, j + 2, k + 7, PlaceDeepslate, 0, 2);
		world.setBlock(i + 17, j + 2, k + 7, PlaceDeepslate, 0, 2);
		world.setBlock(i + 18, j + 2, k + 7, Blocks.air, 0, 2);
		world.setBlock(i + 19, j + 2, k + 7, Blocks.air, 0, 2);
		world.setBlock(i + 20, j + 2, k + 7, Blocks.air, 0, 2);
		world.setBlock(i + 21, j + 2, k + 7, Blocks.air, 0, 2);
		world.setBlock(i + 22, j + 2, k + 7, Blocks.air, 0, 2);
		world.setBlock(i + 23, j + 2, k + 7, Blocks.air, 0, 2);
		world.setBlock(i + 24, j + 2, k + 7, PlaceDeepslate, 0, 2);
