package com.NovaCraft.world.ancient_city;

import com.NovaCraft.config.ConfigsCompact;
import cpw.mods.fml.common.registry.GameRegistry;
import net.minecraft.world.gen.feature.*;
import net.minecraft.block.*;
import net.minecraft.world.*;
import java.util.*;
import com.NovaCraft.config.Configs;
import com.NovaCraftBlocks.NovaCraftBlocks;
import cpw.mods.fml.common.Loader;
import net.minecraft.init.*;

public class AncientCityNegativeXLeftBranchGen1 extends WorldGenerator
{
	public AncientCityNegativeXLeftBranchGen1() {

	}

	private Block PlaceDeepslateBricks;
	private Block PlaceDeepslateTiles;
	private Block PlaceCrackedDeepslateTiles;
	private Block PlaceCrackedDeepslateBricks;
	private Block PlaceChiseledDeepslate;
	private Block PlacePolishedDeepslate;
	private Block PlaceDeepslateTileStairs;

	private Block determineIfDeepslateBricksExists(World world, int x, int y, int z) {
		Block existingBlock = world.getBlock(x, y, z);
		if (ConfigsCompact.enableDeepslateBricks && Loader.isModLoaded("etfuturum")) {
			try {
				Block deepslate_bricks = GameRegistry.findBlock("etfuturum", "deepslate_bricks");
				if (deepslate_bricks != null && (existingBlock == null || existingBlock != deepslate_bricks)) {
					return deepslate_bricks;
				}
			} catch (Exception ex) {
				if (Configs.enableDebugMode) {
					System.out.println("Missing Deepslate Bricks from Et Futurum Requiem, using Grimstone Bricks instead...");
				}
				return NovaCraftBlocks.grimstone_bricks;
			}
		}

		return NovaCraftBlocks.grimstone_bricks;
	}

	private Block determineIfCrackedDeepslateBricksExists(World world, int x, int y, int z) {
		Block existingBlock = world.getBlock(x, y, z);
		if (ConfigsCompact.enableDeepslateBricks && Loader.isModLoaded("etfuturum")) {
			try {
				Block deepslate_bricks = GameRegistry.findBlock("etfuturum", "deepslate_bricks");
				if (deepslate_bricks != null && (existingBlock == null || existingBlock != deepslate_bricks)) {
					return deepslate_bricks;
				}
			} catch (Exception ex) {
				if (Configs.enableDebugMode) {
					System.out.println("Missing Cracked Deepslate Bricks from Et Futurum Requiem, using Cracked Grimstone Bricks instead...");
				}
				return NovaCraftBlocks.cracked_grimstone_bricks;
			}
		}

		return NovaCraftBlocks.cracked_grimstone_bricks;
	}

	private Block determineIfDeepslateTilesExist(World world, int x, int y, int z) {
		Block existingBlock = world.getBlock(x, y, z);
		if (ConfigsCompact.enableDeepslateBricks && Loader.isModLoaded("etfuturum")) {
			try {
				Block deepslate_bricks = GameRegistry.findBlock("etfuturum", "deepslate_bricks");
				if (deepslate_bricks != null && (existingBlock == null || existingBlock != deepslate_bricks)) {
					return deepslate_bricks;
				}
			} catch (Exception ex) {
				if (Configs.enableDebugMode) {
					System.out.println("Missing Deepslate Tiles from Et Futurum Requiem, using Grimstone Tiles instead...");
				}
				return NovaCraftBlocks.grimstone_tiles;
			}
		}

		return NovaCraftBlocks.grimstone_tiles;
	}

	private Block determineIfCrackedDeepslateTilesExist(World world, int x, int y, int z) {
		Block existingBlock = world.getBlock(x, y, z);
		if (ConfigsCompact.enableDeepslateBricks && Loader.isModLoaded("etfuturum")) {
			try {
				Block deepslate_bricks = GameRegistry.findBlock("etfuturum", "deepslate_bricks");
				if (deepslate_bricks != null && (existingBlock == null || existingBlock != deepslate_bricks)) {
					return deepslate_bricks;
				}
			} catch (Exception ex) {
				if (Configs.enableDebugMode) {
					System.out.println("Missing Cracked Deepslate Tiles from Et Futurum Requiem, using Cracked Grimstone Tiles instead...");
				}
				return NovaCraftBlocks.cracked_grimstone_tiles;
			}
		}

		return NovaCraftBlocks.cracked_grimstone_tiles;
	}

	private Block determineIfPolishedDeepslateExists(World world, int x, int y, int z) {
		Block existingBlock = world.getBlock(x, y, z);
		if (ConfigsCompact.enableDeepslateBricks && Loader.isModLoaded("etfuturum")) {
			try {
				Block polished_deepslate = GameRegistry.findBlock("etfuturum", "polished_deepslate");
				if (polished_deepslate != null && (existingBlock == null || existingBlock != polished_deepslate)) {
					return polished_deepslate;
				}
			} catch (Exception ex) {
				if (Configs.enableDebugMode) {
					System.out.println("Missing Polished Deepslate from Et Futurum Requiem, using Polished Grimstone instead...");
				}
				return NovaCraftBlocks.polished_grimstone;
			}
		}

		return NovaCraftBlocks.polished_grimstone;
	}

	private Block determineIfChiseledDeepslateExist(World world, int x, int y, int z) {
		Block existingBlock = world.getBlock(x, y, z);
		if (ConfigsCompact.enableDeepslateBricks && Loader.isModLoaded("etfuturum")) {
			try {
				Block deepslate_bricks = GameRegistry.findBlock("etfuturum", "deepslate_bricks");
				if (deepslate_bricks != null && (existingBlock == null || existingBlock != deepslate_bricks)) {
					return deepslate_bricks;
				}
			} catch (Exception ex) {
				if (Configs.enableDebugMode) {
					System.out.println("Missing Chiseled Deepslate from Et Futurum Requiem, using Chiseled Grimstone instead...");
				}
				return NovaCraftBlocks.chiseled_grimstone;
			}
		}

		return NovaCraftBlocks.chiseled_grimstone;
	}

	private Block determineIfDeepslateTileStairsExists(World world, int x, int y, int z) {
		Block existingBlock = world.getBlock(x, y, z);
		if (ConfigsCompact.enableDeepslateBricks && Loader.isModLoaded("etfuturum")) {
			try {
				Block deepslate_tile_stairs = GameRegistry.findBlock("etfuturum", "deepslate_tile_stairs");
				if (deepslate_tile_stairs != null && (existingBlock == null || existingBlock != deepslate_tile_stairs)) {
					return deepslate_tile_stairs;
				}
			} catch (Exception ex) {
				if (Configs.enableDebugMode) {
					System.out.println("Missing Deepslate Tile Stairs from Et Futurum Requiem, using Grimstone Tile Stairs instead...");
				}
				return NovaCraftBlocks.grimstone_tiled_stairs;
			}
		}

		return NovaCraftBlocks.grimstone_tiled_stairs;
	}
    
    public boolean generate(final World world, final Random random, final int i, final int j, final int k) {
    	PlaceDeepslateBricks = determineIfDeepslateBricksExists(world, i + 1, j + 1, k);
    	PlaceCrackedDeepslateBricks = determineIfCrackedDeepslateBricksExists(world, i + 7, j + 1, k);
    	PlaceDeepslateTiles = determineIfDeepslateTilesExist(world, i + 7, j, k);
    	PlaceCrackedDeepslateTiles = determineIfCrackedDeepslateTilesExist(world, i + 1, j, k);
    	PlaceChiseledDeepslate = determineIfChiseledDeepslateExist(world, i + 4, j, k + 8);
    	PlacePolishedDeepslate = determineIfPolishedDeepslateExists(world, i + 1, j + 2, k + 1);

    	PlaceDeepslateTileStairs = determineIfDeepslateTileStairsExists(world, i + 9, j, k + 30);
    	
    	world.setBlock(i, j, k, Blocks.air, 0, 2);
		world.setBlock(i + 1, j, k, PlaceCrackedDeepslateTiles, 3, 2);
		world.setBlock(i + 2, j, k, Blocks.wool, 7, 2);
		world.setBlock(i + 3, j, k, Blocks.wool, 7, 2);
		world.setBlock(i + 4, j, k, PlaceCrackedDeepslateTiles, 3, 2);
		world.setBlock(i + 5, j, k, Blocks.wool, 7, 2);
		world.setBlock(i + 6, j, k, Blocks.wool, 7, 2);
		world.setBlock(i + 7, j, k, PlaceDeepslateTiles, 2, 2);
		world.setBlock(i + 8, j, k, Blocks.air, 0, 2);
		world.setBlock(i + 9, j, k, Blocks.air, 0, 2);
		world.setBlock(i, j, k + 1, Blocks.air, 0, 2);
		world.setBlock(i + 1, j, k + 1, PlaceDeepslateTiles, 2, 2);
		world.setBlock(i + 2, j, k + 1, Blocks.wool, 7, 2);
		world.setBlock(i + 3, j, k + 1, Blocks.wool, 7, 2);
		world.setBlock(i + 4, j, k + 1, PlaceCrackedDeepslateTiles, 3, 2);
		world.setBlock(i + 5, j, k + 1, Blocks.wool, 7, 2);
		world.setBlock(i + 6, j, k + 1, Blocks.wool, 7, 2);
		world.setBlock(i + 7, j, k + 1, PlaceCrackedDeepslateTiles, 3, 2);
		world.setBlock(i + 8, j, k + 1, Blocks.air, 0, 2);
		world.setBlock(i + 9, j, k + 1, Blocks.air, 0, 2);
		world.setBlock(i, j, k + 2, Blocks.air, 0, 2);
		world.setBlock(i + 1, j, k + 2, PlaceCrackedDeepslateTiles, 3, 2);
		world.setBlock(i + 2, j, k + 2, Blocks.wool, 7, 2);
		world.setBlock(i + 3, j, k + 2, Blocks.wool, 7, 2);
		world.setBlock(i + 4, j, k + 2, PlaceDeepslateTiles, 2, 2);
		world.setBlock(i + 5, j, k + 2, Blocks.wool, 7, 2);
		world.setBlock(i + 6, j, k + 2, Blocks.wool, 7, 2);
		world.setBlock(i + 7, j, k + 2, PlaceDeepslateTiles, 2, 2);
		world.setBlock(i + 8, j, k + 2, Blocks.air, 0, 2);
		world.setBlock(i + 9, j, k + 2, Blocks.air, 0, 2);
		world.setBlock(i, j, k + 3, Blocks.air, 0, 2);
		world.setBlock(i + 1, j, k + 3, PlaceDeepslateTiles, 2, 2);
		world.setBlock(i + 2, j, k + 3, Blocks.wool, 7, 2);
		world.setBlock(i + 3, j, k + 3, Blocks.wool, 7, 2);
		world.setBlock(i + 4, j, k + 3, PlaceDeepslateTiles, 2, 2);
		world.setBlock(i + 5, j, k + 3, Blocks.wool, 7, 2);
		world.setBlock(i + 6, j, k + 3, Blocks.air, 0, 2);
		world.setBlock(i + 7, j, k + 3, PlaceDeepslateTiles, 2, 2);
		world.setBlock(i + 8, j, k + 3, Blocks.air, 0, 2);
		world.setBlock(i + 9, j, k + 3, Blocks.air, 0, 2);
		world.setBlock(i, j, k + 4, Blocks.air, 0, 2);
		world.setBlock(i + 1, j, k + 4, PlaceCrackedDeepslateTiles, 3, 2);
		world.setBlock(i + 2, j, k + 4, Blocks.wool, 7, 2);
		world.setBlock(i + 3, j, k + 4, Blocks.wool, 7, 2);
		world.setBlock(i + 4, j, k + 4, PlaceCrackedDeepslateTiles, 3, 2);
		world.setBlock(i + 5, j, k + 4, Blocks.wool, 7, 2);
		world.setBlock(i + 6, j, k + 4, Blocks.wool, 7, 2);
		world.setBlock(i + 7, j, k + 4, PlaceCrackedDeepslateTiles, 3, 2);
		world.setBlock(i + 8, j, k + 4, Blocks.air, 0, 2);
		world.setBlock(i + 9, j, k + 4, Blocks.air, 0, 2);
		world.setBlock(i, j, k + 5, Blocks.air, 0, 2);
		world.setBlock(i + 1, j, k + 5, PlaceDeepslateTiles, 2, 2);
		world.setBlock(i + 2, j, k + 5, Blocks.wool, 7, 2);
		world.setBlock(i + 3, j, k + 5, Blocks.wool, 7, 2);
		world.setBlock(i + 4, j, k + 5, PlaceDeepslateTiles, 2, 2);
		world.setBlock(i + 5, j, k + 5, Blocks.wool, 7, 2);
		world.setBlock(i + 6, j, k + 5, Blocks.wool, 7, 2);
		world.setBlock(i + 7, j, k + 5, PlaceDeepslateTiles, 2, 2);
		world.setBlock(i + 8, j, k + 5, Blocks.air, 0, 2);
		world.setBlock(i + 9, j, k + 5, Blocks.air, 0, 2);
		world.setBlock(i, j, k + 6, Blocks.air, 0, 2);
		world.setBlock(i + 1, j, k + 6, PlaceDeepslateTiles, 2, 2);
		world.setBlock(i + 2, j, k + 6, Blocks.wool, 7, 2);
		world.setBlock(i + 3, j, k + 6, Blocks.wool, 7, 2);
		world.setBlock(i + 4, j, k + 6, PlaceDeepslateTiles, 2, 2);
		world.setBlock(i + 5, j, k + 6, Blocks.wool, 7, 2);
		world.setBlock(i + 6, j, k + 6, Blocks.wool, 7, 2);
		world.setBlock(i + 7, j, k + 6, PlaceDeepslateTiles, 2, 2);
		world.setBlock(i + 8, j, k + 6, Blocks.air, 0, 2);
		world.setBlock(i + 9, j, k + 6, Blocks.air, 0, 2);
		world.setBlock(i, j, k + 7, Blocks.air, 0, 2);
		world.setBlock(i + 1, j, k + 7, PlaceCrackedDeepslateTiles, 3, 2);
		world.setBlock(i + 2, j, k + 7, Blocks.wool, 7, 2);
		world.setBlock(i + 3, j, k + 7, Blocks.air, 0, 2);
		world.setBlock(i + 4, j, k + 7, PlaceDeepslateTiles, 2, 2);
		world.setBlock(i + 5, j, k + 7, Blocks.wool, 7, 2);
		world.setBlock(i + 6, j, k + 7, Blocks.wool, 7, 2);
		world.setBlock(i + 7, j, k + 7, PlaceDeepslateTiles, 2, 2);
		world.setBlock(i + 8, j, k + 7, Blocks.air, 0, 2);
		world.setBlock(i + 9, j, k + 7, Blocks.air, 0, 2);
		world.setBlock(i, j, k + 8, Blocks.air, 0, 2);
		world.setBlock(i + 1, j, k + 8, PlaceDeepslateTiles, 2, 2);
		world.setBlock(i + 2, j, k + 8, Blocks.wool, 7, 2);
		world.setBlock(i + 3, j, k + 8, Blocks.wool, 7, 2);
		world.setBlock(i + 4, j, k + 8, PlaceChiseledDeepslate, 4, 2);
		world.setBlock(i + 5, j, k + 8, Blocks.wool, 7, 2);
		world.setBlock(i + 6, j, k + 8, Blocks.wool, 7, 2);
		world.setBlock(i + 7, j, k + 8, PlaceDeepslateTiles, 2, 2);
		world.setBlock(i + 8, j, k + 8, Blocks.air, 0, 2);
		world.setBlock(i + 9, j, k + 8, Blocks.air, 0, 2);
		world.setBlock(i, j, k + 9, Blocks.air, 0, 2);
		world.setBlock(i + 1, j, k + 9, PlaceCrackedDeepslateTiles, 3, 2);
		world.setBlock(i + 2, j, k + 9, Blocks.wool, 7, 2);
		world.setBlock(i + 3, j, k + 9, Blocks.wool, 7, 2);
		world.setBlock(i + 4, j, k + 9, PlaceDeepslateTiles, 2, 2);
		world.setBlock(i + 5, j, k + 9, Blocks.wool, 7, 2);
		world.setBlock(i + 6, j, k + 9, Blocks.wool, 7, 2);
		world.setBlock(i + 7, j, k + 9, PlaceDeepslateTiles, 2, 2);
		world.setBlock(i + 8, j, k + 9, Blocks.air, 0, 2);
		world.setBlock(i + 9, j, k + 9, Blocks.air, 0, 2);
		world.setBlock(i, j, k + 10, Blocks.air, 0, 2);
		world.setBlock(i + 1, j, k + 10, PlaceDeepslateTiles, 2, 2);
		world.setBlock(i + 2, j, k + 10, Blocks.wool, 7, 2);
		world.setBlock(i + 3, j, k + 10, Blocks.wool, 7, 2);
		world.setBlock(i + 4, j, k + 10, PlaceCrackedDeepslateTiles, 3, 2);
		world.setBlock(i + 5, j, k + 10, Blocks.wool, 7, 2);
		world.setBlock(i + 6, j, k + 10, Blocks.wool, 7, 2);
		world.setBlock(i + 7, j, k + 10, PlaceDeepslateTiles, 2, 2);
		world.setBlock(i + 8, j, k + 10, Blocks.air, 0, 2);
		world.setBlock(i + 9, j, k + 10, Blocks.air, 0, 2);
		world.setBlock(i, j, k + 11, Blocks.air, 0, 2);
		world.setBlock(i + 1, j, k + 11, NovaCraftBlocks.sculk_block, 0, 2);
		world.setBlock(i + 2, j, k + 11, Blocks.wool, 7, 2);
		world.setBlock(i + 3, j, k + 11, Blocks.wool, 7, 2);
		world.setBlock(i + 4, j, k + 11, PlaceDeepslateTiles, 2, 2);
		world.setBlock(i + 5, j, k + 11, Blocks.wool, 7, 2);
		world.setBlock(i + 6, j, k + 11, Blocks.wool, 7, 2);
		world.setBlock(i + 7, j, k + 11, PlaceCrackedDeepslateTiles, 3, 2);
		world.setBlock(i + 8, j, k + 11, Blocks.air, 0, 2);
		world.setBlock(i + 9, j, k + 11, Blocks.air, 0, 2);
		world.setBlock(i, j, k + 12, Blocks.air, 0, 2);
		world.setBlock(i + 1, j, k + 12, PlaceCrackedDeepslateTiles, 3, 2);
		world.setBlock(i + 2, j, k + 12, Blocks.air, 0, 2);
		world.setBlock(i + 3, j, k + 12, Blocks.wool, 7, 2);
		world.setBlock(i + 4, j, k + 12, PlaceChiseledDeepslate, 4, 2);
		world.setBlock(i + 5, j, k + 12, Blocks.wool, 7, 2);
		world.setBlock(i + 6, j, k + 12, Blocks.wool, 7, 2);
		world.setBlock(i + 7, j, k + 12, PlaceDeepslateTiles, 2, 2);
		world.setBlock(i + 8, j, k + 12, Blocks.air, 0, 2);
		world.setBlock(i + 9, j, k + 12, Blocks.air, 0, 2);
		world.setBlock(i, j, k + 13, Blocks.air, 0, 2);
		world.setBlock(i + 1, j, k + 13, PlaceDeepslateTiles, 2, 2);
		world.setBlock(i + 2, j, k + 13, Blocks.wool, 7, 2);
		world.setBlock(i + 3, j, k + 13, Blocks.wool, 7, 2);
		world.setBlock(i + 4, j, k + 13, PlaceDeepslateTiles, 2, 2);
		world.setBlock(i + 5, j, k + 13, Blocks.wool, 7, 2);
		world.setBlock(i + 6, j, k + 13, Blocks.wool, 7, 2);
		world.setBlock(i + 7, j, k + 13, PlaceDeepslateTiles, 2, 2);
		world.setBlock(i + 8, j, k + 13, Blocks.air, 0, 2);
		world.setBlock(i + 9, j, k + 13, Blocks.air, 0, 2);
		world.setBlock(i, j, k + 14, Blocks.air, 0, 2);
		world.setBlock(i + 1, j, k + 14, PlaceDeepslateTiles, 2, 2);
		world.setBlock(i + 2, j, k + 14, Blocks.wool, 7, 2);
		world.setBlock(i + 3, j, k + 14, Blocks.wool, 7, 2);
		world.setBlock(i + 4, j, k + 14, PlaceDeepslateTiles, 2, 2);
		world.setBlock(i + 5, j, k + 14, Blocks.wool, 7, 2);
		world.setBlock(i + 6, j, k + 14, Blocks.wool, 7, 2);
		world.setBlock(i + 7, j, k + 14, PlaceDeepslateTiles, 2, 2);
		world.setBlock(i + 8, j, k + 14, Blocks.air, 0, 2);
		world.setBlock(i + 9, j, k + 14, Blocks.air, 0, 2);
		world.setBlock(i, j, k + 15, Blocks.air, 0, 2);
		world.setBlock(i + 1, j, k + 15, PlaceCrackedDeepslateTiles, 3, 2);
		world.setBlock(i + 2, j, k + 15, Blocks.wool, 7, 2);
		world.setBlock(i + 3, j, k + 15, Blocks.wool, 7, 2);
		world.setBlock(i + 4, j, k + 15, PlaceDeepslateTiles, 2, 2);
		world.setBlock(i + 5, j, k + 15, Blocks.wool, 7, 2);
		world.setBlock(i + 6, j, k + 15, Blocks.wool, 7, 2);
		world.setBlock(i + 7, j, k + 15, PlaceCrackedDeepslateTiles, 3, 2);
		world.setBlock(i + 8, j, k + 15, Blocks.air, 0, 2);
		world.setBlock(i + 9, j, k + 15, Blocks.air, 0, 2);
		world.setBlock(i, j, k + 16, Blocks.air, 0, 2);
		world.setBlock(i + 1, j, k + 16, Blocks.air, 0, 2);
		world.setBlock(i + 2, j, k + 16, Blocks.wool, 7, 2);
		world.setBlock(i + 3, j, k + 16, Blocks.wool, 7, 2);
		world.setBlock(i + 4, j, k + 16, PlaceCrackedDeepslateTiles, 3, 2);
		world.setBlock(i + 5, j, k + 16, Blocks.wool, 7, 2);
		world.setBlock(i + 6, j, k + 16, Blocks.wool, 7, 2);
		world.setBlock(i + 7, j, k + 16, PlaceDeepslateTiles, 2, 2);
		world.setBlock(i + 8, j, k + 16, Blocks.air, 0, 2);
		world.setBlock(i + 9, j, k + 16, Blocks.air, 0, 2);
		world.setBlock(i, j, k + 17, Blocks.air, 0, 2);
		world.setBlock(i + 1, j, k + 17, PlaceCrackedDeepslateTiles, 3, 2);
		world.setBlock(i + 2, j, k + 17, Blocks.air, 0, 2);
		world.setBlock(i + 3, j, k + 17, Blocks.wool, 7, 2);
		world.setBlock(i + 4, j, k + 17, PlaceDeepslateTiles, 2, 2);
		world.setBlock(i + 5, j, k + 17, Blocks.wool, 7, 2);
		world.setBlock(i + 6, j, k + 17, Blocks.wool, 7, 2);
		world.setBlock(i + 7, j, k + 17, Blocks.air, 0, 2);
		world.setBlock(i + 8, j, k + 17, Blocks.air, 0, 2);
		world.setBlock(i + 9, j, k + 17, Blocks.air, 0, 2);
		world.setBlock(i, j, k + 18, Blocks.air, 0, 2);
		world.setBlock(i + 1, j, k + 18, PlaceDeepslateTiles, 2, 2);
		world.setBlock(i + 2, j, k + 18, Blocks.wool, 7, 2);
		world.setBlock(i + 3, j, k + 18, Blocks.wool, 7, 2);
		world.setBlock(i + 4, j, k + 18, PlaceDeepslateTiles, 2, 2);
		world.setBlock(i + 5, j, k + 18, Blocks.wool, 7, 2);
		world.setBlock(i + 6, j, k + 18, Blocks.wool, 7, 2);
		world.setBlock(i + 7, j, k + 18, PlaceCrackedDeepslateTiles, 3, 2);
		world.setBlock(i + 8, j, k + 18, Blocks.air, 0, 2);
		world.setBlock(i + 9, j, k + 18, Blocks.air, 0, 2);
		world.setBlock(i, j, k + 19, Blocks.air, 0, 2);
		world.setBlock(i + 1, j, k + 19, PlaceDeepslateTiles, 2, 2);
		world.setBlock(i + 2, j, k + 19, Blocks.wool, 7, 2);
		world.setBlock(i + 3, j, k + 19, Blocks.wool, 7, 2);
		world.setBlock(i + 4, j, k + 19, PlaceDeepslateTiles, 2, 2);
		world.setBlock(i + 5, j, k + 19, Blocks.wool, 7, 2);
		world.setBlock(i + 6, j, k + 19, Blocks.wool, 7, 2);
		world.setBlock(i + 7, j, k + 19, PlaceCrackedDeepslateTiles, 3, 2);
		world.setBlock(i + 8, j, k + 19, Blocks.air, 0, 2);
		world.setBlock(i + 9, j, k + 19, Blocks.air, 0, 2);
		world.setBlock(i, j, k + 20, Blocks.air, 0, 2);
		world.setBlock(i + 1, j, k + 20, PlaceDeepslateTiles, 2, 2);
		world.setBlock(i + 2, j, k + 20, Blocks.wool, 7, 2);
		world.setBlock(i + 3, j, k + 20, Blocks.wool, 7, 2);
		world.setBlock(i + 4, j, k + 20, PlaceDeepslateTiles, 2, 2);
		world.setBlock(i + 5, j, k + 20, Blocks.air, 0, 2);
		world.setBlock(i + 6, j, k + 20, Blocks.wool, 7, 2);
		world.setBlock(i + 7, j, k + 20, PlaceCrackedDeepslateTiles, 3, 2);
		world.setBlock(i + 8, j, k + 20, Blocks.air, 0, 2);
		world.setBlock(i + 9, j, k + 20, Blocks.air, 0, 2);
		world.setBlock(i, j, k + 21, Blocks.air, 0, 2);
		world.setBlock(i + 1, j, k + 21, PlaceCrackedDeepslateTiles, 3, 2);
		world.setBlock(i + 2, j, k + 21, Blocks.wool, 7, 2);
		world.setBlock(i + 3, j, k + 21, Blocks.wool, 7, 2);
		world.setBlock(i + 4, j, k + 21, PlaceDeepslateTiles, 2, 2);
		world.setBlock(i + 5, j, k + 21, Blocks.wool, 7, 2);
		world.setBlock(i + 6, j, k + 21, Blocks.wool, 7, 2);
		world.setBlock(i + 7, j, k + 21, PlaceDeepslateTiles, 2, 2);
		world.setBlock(i + 8, j, k + 21, Blocks.air, 0, 2);
		world.setBlock(i + 9, j, k + 21, Blocks.air, 0, 2);
		world.setBlock(i, j, k + 22, Blocks.air, 0, 2);
		world.setBlock(i + 1, j, k + 22, PlaceDeepslateTiles, 2, 2);
		world.setBlock(i + 2, j, k + 22, Blocks.wool, 7, 2);
		world.setBlock(i + 3, j, k + 22, Blocks.wool, 7, 2);
		world.setBlock(i + 4, j, k + 22, PlaceCrackedDeepslateTiles, 3, 2);
		world.setBlock(i + 5, j, k + 22, Blocks.wool, 7, 2);
		world.setBlock(i + 6, j, k + 22, Blocks.wool, 7, 2);
		world.setBlock(i + 7, j, k + 22, PlaceCrackedDeepslateTiles, 3, 2);
		world.setBlock(i + 8, j, k + 22, Blocks.air, 0, 2);
		world.setBlock(i + 9, j, k + 22, Blocks.air, 0, 2);
		world.setBlock(i, j, k + 23, Blocks.air, 0, 2);
		world.setBlock(i + 1, j, k + 23, PlaceCrackedDeepslateTiles, 3, 2);
		world.setBlock(i + 2, j, k + 23, Blocks.wool, 7, 2);
		world.setBlock(i + 3, j, k + 23, Blocks.wool, 7, 2);
		world.setBlock(i + 4, j, k + 23, PlaceDeepslateTiles, 2, 2);
		world.setBlock(i + 5, j, k + 23, Blocks.wool, 7, 2);
		world.setBlock(i + 6, j, k + 23, Blocks.wool, 7, 2);
		world.setBlock(i + 7, j, k + 23, PlaceDeepslateTiles, 2, 2);
		world.setBlock(i + 8, j, k + 23, Blocks.air, 0, 2);
		world.setBlock(i + 9, j, k + 23, Blocks.air, 0, 2);
		world.setBlock(i, j, k + 24, Blocks.air, 0, 2);
		world.setBlock(i + 1, j, k + 24, Blocks.air, 0, 2);
		world.setBlock(i + 2, j, k + 24, Blocks.wool, 7, 2);
		world.setBlock(i + 3, j, k + 24, Blocks.wool, 7, 2);
		world.setBlock(i + 4, j, k + 24, PlaceDeepslateTiles, 2, 2);
		world.setBlock(i + 5, j, k + 24, Blocks.wool, 7, 2);
		world.setBlock(i + 6, j, k + 24, Blocks.wool, 7, 2);
		world.setBlock(i + 7, j, k + 24, PlaceCrackedDeepslateTiles, 3, 2);
		world.setBlock(i + 8, j, k + 24, Blocks.air, 0, 2);
		world.setBlock(i + 9, j, k + 24, Blocks.air, 0, 2);
		world.setBlock(i, j, k + 25, Blocks.air, 0, 2);
		world.setBlock(i + 1, j, k + 25, PlaceDeepslateTiles, 2, 2);
		world.setBlock(i + 2, j, k + 25, Blocks.air, 0, 2);
		world.setBlock(i + 3, j, k + 25, Blocks.air, 0, 2);
		world.setBlock(i + 4, j, k + 25, Blocks.air, 0, 2);
		world.setBlock(i + 5, j, k + 25, Blocks.wool, 7, 2);
		world.setBlock(i + 6, j, k + 25, Blocks.wool, 7, 2);
		world.setBlock(i + 7, j, k + 25, PlaceDeepslateTiles, 2, 2);
		world.setBlock(i + 8, j, k + 25, Blocks.air, 0, 2);
		world.setBlock(i + 9, j, k + 25, Blocks.air, 0, 2);
		world.setBlock(i, j, k + 26, Blocks.air, 0, 2);
		world.setBlock(i + 1, j, k + 26, PlaceDeepslateTiles, 2, 2);
		world.setBlock(i + 2, j, k + 26, Blocks.air, 0, 2);
		world.setBlock(i + 3, j, k + 26, Blocks.wool, 7, 2);
		world.setBlock(i + 4, j, k + 26, PlaceDeepslateTiles, 2, 2);
		world.setBlock(i + 5, j, k + 26, Blocks.wool, 7, 2);
		world.setBlock(i + 6, j, k + 26, Blocks.wool, 7, 2);
		world.setBlock(i + 7, j, k + 26, PlaceDeepslateTiles, 2, 2);
		world.setBlock(i + 8, j, k + 26, Blocks.air, 0, 2);
		world.setBlock(i + 9, j, k + 26, Blocks.air, 0, 2);
		world.setBlock(i, j, k + 27, Blocks.air, 0, 2);
		world.setBlock(i + 1, j, k + 27, PlaceCrackedDeepslateTiles, 3, 2);
		world.setBlock(i + 2, j, k + 27, Blocks.wool, 7, 2);
		world.setBlock(i + 3, j, k + 27, Blocks.wool, 7, 2);
		world.setBlock(i + 4, j, k + 27, PlaceCrackedDeepslateTiles, 3, 2);
		world.setBlock(i + 5, j, k + 27, Blocks.wool, 7, 2);
		world.setBlock(i + 6, j, k + 27, Blocks.wool, 7, 2);
		world.setBlock(i + 7, j, k + 27, PlaceDeepslateTiles, 2, 2);
		world.setBlock(i + 8, j, k + 27, Blocks.air, 0, 2);
		world.setBlock(i + 9, j, k + 27, Blocks.air, 0, 2);
		world.setBlock(i, j, k + 28, Blocks.air, 0, 2);
		world.setBlock(i + 1, j, k + 28, PlaceDeepslateTiles, 2, 2);
		world.setBlock(i + 2, j, k + 28, Blocks.wool, 7, 2);
		world.setBlock(i + 3, j, k + 28, Blocks.wool, 7, 2);
		world.setBlock(i + 4, j, k + 28, PlaceCrackedDeepslateTiles, 3, 2);
		world.setBlock(i + 5, j, k + 28, Blocks.wool, 7, 2);
		world.setBlock(i + 6, j, k + 28, Blocks.wool, 7, 2);
		world.setBlock(i + 7, j, k + 28, PlaceCrackedDeepslateTiles, 3, 2);
		world.setBlock(i + 8, j, k + 28, Blocks.air, 0, 2);
		world.setBlock(i + 9, j, k + 28, Blocks.air, 0, 2);
		world.setBlock(i, j, k + 29, Blocks.air, 0, 2);
		world.setBlock(i + 1, j, k + 29, PlaceCrackedDeepslateTiles, 3, 2);
		world.setBlock(i + 2, j, k + 29, Blocks.wool, 7, 2);
		world.setBlock(i + 3, j, k + 29, Blocks.wool, 7, 2);
		world.setBlock(i + 4, j, k + 29, Blocks.wool, 7, 2);
		world.setBlock(i + 5, j, k + 29, Blocks.wool, 7, 2);
		world.setBlock(i + 6, j, k + 29, Blocks.wool, 7, 2);
		world.setBlock(i + 7, j, k + 29, PlaceDeepslateTiles, 2, 2);
		world.setBlock(i + 8, j, k + 29, Blocks.air, 0, 2);
		world.setBlock(i + 9, j, k + 29, Blocks.air, 0, 2);
		world.setBlock(i, j, k + 30, Blocks.air, 0, 2);
		world.setBlock(i + 1, j, k + 30, PlaceDeepslateTiles, 2, 2);
		world.setBlock(i + 2, j, k + 30, Blocks.wool, 7, 2);
		world.setBlock(i + 3, j, k + 30, Blocks.wool, 7, 2);
		world.setBlock(i + 4, j, k + 30, PlaceDeepslateTiles, 2, 2);
		world.setBlock(i + 5, j, k + 30, Blocks.wool, 7, 2);
		world.setBlock(i + 6, j, k + 30, Blocks.wool, 7, 2);
		world.setBlock(i + 7, j, k + 30, PlaceDeepslateTiles, 2, 2);
		world.setBlock(i + 8, j, k + 30, PlaceCrackedDeepslateTiles, 3, 2);
		world.setBlock(i + 9, j, k + 30, PlaceDeepslateTileStairs, 1, 2);
		world.setBlock(i, j, k + 31, Blocks.air, 0, 2);
		world.setBlock(i + 1, j, k + 31, PlaceDeepslateTiles, 2, 2);
		world.setBlock(i + 2, j, k + 31, Blocks.wool, 7, 2);
		world.setBlock(i + 3, j, k + 31, NovaCraftBlocks.sculk_block, 0, 2);
		world.setBlock(i + 4, j, k + 31, PlaceDeepslateTiles, 2, 2);
		world.setBlock(i + 5, j, k + 31, Blocks.wool, 7, 2);
		world.setBlock(i + 6, j, k + 31, Blocks.wool, 7, 2);
		world.setBlock(i + 7, j, k + 31, PlaceDeepslateTiles, 2, 2);
		world.setBlock(i + 8, j, k + 31, PlaceDeepslateTiles, 2, 2);
		world.setBlock(i + 9, j, k + 31, PlaceDeepslateTileStairs, 1, 2);
		world.setBlock(i, j, k + 32, Blocks.air, 0, 2);
		world.setBlock(i + 1, j, k + 32, PlaceDeepslateTiles, 2, 2);
		world.setBlock(i + 2, j, k + 32, Blocks.wool, 7, 2);
		world.setBlock(i + 3, j, k + 32, Blocks.wool, 7, 2);
		world.setBlock(i + 4, j, k + 32, PlaceDeepslateTiles, 2, 2);
		world.setBlock(i + 5, j, k + 32, Blocks.wool, 7, 2);
		world.setBlock(i + 6, j, k + 32, Blocks.wool, 7, 2);
		world.setBlock(i + 7, j, k + 32, NovaCraftBlocks.sculk_block, 0, 2);
		world.setBlock(i + 8, j, k + 32, NovaCraftBlocks.sculk_block, 0, 2);
		world.setBlock(i + 9, j, k + 32, PlaceDeepslateTileStairs, 1, 2);
		world.setBlock(i, j, k + 33, Blocks.air, 0, 2);
		world.setBlock(i + 1, j, k + 33, NovaCraftBlocks.sculk_block, 0, 2);
		world.setBlock(i + 2, j, k + 33, Blocks.wool, 7, 2);
		world.setBlock(i + 3, j, k + 33, Blocks.wool, 7, 2);
		world.setBlock(i + 4, j, k + 33, Blocks.wool, 7, 2);
		world.setBlock(i + 5, j, k + 33, Blocks.wool, 7, 2);
		world.setBlock(i + 6, j, k + 33, Blocks.wool, 7, 2);
		world.setBlock(i + 7, j, k + 33, PlaceDeepslateTiles, 2, 2);
		world.setBlock(i + 8, j, k + 33, Blocks.air, 0, 2);
		world.setBlock(i + 9, j, k + 33, Blocks.air, 0, 2);
		world.setBlock(i, j, k + 34, Blocks.air, 0, 2);
		world.setBlock(i + 1, j, k + 34, PlaceCrackedDeepslateTiles, 3, 2);
		world.setBlock(i + 2, j, k + 34, Blocks.wool, 7, 2);
		world.setBlock(i + 3, j, k + 34, Blocks.wool, 7, 2);
		world.setBlock(i + 4, j, k + 34, PlaceDeepslateTiles, 2, 2);
		world.setBlock(i + 5, j, k + 34, Blocks.wool, 7, 2);
		world.setBlock(i + 6, j, k + 34, Blocks.wool, 7, 2);
		world.setBlock(i + 7, j, k + 34, PlaceCrackedDeepslateTiles, 3, 2);
		world.setBlock(i + 8, j, k + 34, Blocks.air, 0, 2);
		world.setBlock(i + 9, j, k + 34, Blocks.air, 0, 2);
		world.setBlock(i, j, k + 35, Blocks.air, 0, 2);
		world.setBlock(i + 1, j, k + 35, PlaceCrackedDeepslateTiles, 3, 2);
		world.setBlock(i + 2, j, k + 35, Blocks.wool, 7, 2);
		world.setBlock(i + 3, j, k + 35, Blocks.wool, 7, 2);
		world.setBlock(i + 4, j, k + 35, NovaCraftBlocks.sculk_block, 0, 2);
		world.setBlock(i + 5, j, k + 35, Blocks.wool, 7, 2);
		world.setBlock(i + 6, j, k + 35, Blocks.wool, 7, 2);
		world.setBlock(i + 7, j, k + 35, PlaceDeepslateTiles, 2, 2);
		world.setBlock(i + 8, j, k + 35, Blocks.air, 0, 2);
		world.setBlock(i + 9, j, k + 35, Blocks.air, 0, 2);
		world.setBlock(i, j, k + 36, Blocks.air, 0, 2);
		world.setBlock(i + 1, j, k + 36, PlaceDeepslateTiles, 2, 2);
		world.setBlock(i + 2, j, k + 36, NovaCraftBlocks.sculk_block, 0, 2);
		world.setBlock(i + 3, j, k + 36, Blocks.wool, 7, 2);
		world.setBlock(i + 4, j, k + 36, PlaceDeepslateTiles, 2, 2);
		world.setBlock(i + 5, j, k + 36, Blocks.wool, 7, 2);
		world.setBlock(i + 6, j, k + 36, Blocks.wool, 7, 2);
		world.setBlock(i + 7, j, k + 36, PlaceDeepslateTiles, 2, 2);
		world.setBlock(i + 8, j, k + 36, Blocks.air, 0, 2);
		world.setBlock(i + 9, j, k + 36, Blocks.air, 0, 2);
		world.setBlock(i, j, k + 37, Blocks.air, 0, 2);
		world.setBlock(i + 1, j, k + 37, PlaceCrackedDeepslateTiles, 3, 2);
		world.setBlock(i + 2, j, k + 37, Blocks.wool, 7, 2);
		world.setBlock(i + 3, j, k + 37, Blocks.wool, 7, 2);
		world.setBlock(i + 4, j, k + 37, PlaceCrackedDeepslateTiles, 3, 2);
		world.setBlock(i + 5, j, k + 37, Blocks.wool, 7, 2);
		world.setBlock(i + 6, j, k + 37, Blocks.wool, 7, 2);
		world.setBlock(i + 7, j, k + 37, PlaceDeepslateTiles, 2, 2);
		world.setBlock(i + 8, j, k + 37, Blocks.air, 0, 2);
		world.setBlock(i + 9, j, k + 37, Blocks.air, 0, 2);
		world.setBlock(i, j, k + 38, Blocks.air, 0, 2);
		world.setBlock(i + 1, j, k + 38, PlaceCrackedDeepslateTiles, 3, 2);
		world.setBlock(i + 2, j, k + 38, Blocks.wool, 7, 2);
		world.setBlock(i + 3, j, k + 38, Blocks.wool, 7, 2);
		world.setBlock(i + 4, j, k + 38, PlaceDeepslateTiles, 2, 2);
		world.setBlock(i + 5, j, k + 38, Blocks.wool, 7, 2);
		world.setBlock(i + 6, j, k + 38, Blocks.wool, 7, 2);
		world.setBlock(i + 7, j, k + 38, PlaceCrackedDeepslateTiles, 3, 2);
		world.setBlock(i + 8, j, k + 38, Blocks.air, 0, 2);
		world.setBlock(i + 9, j, k + 38, Blocks.air, 0, 2);
		world.setBlock(i, j, k + 39, Blocks.air, 0, 2);
		world.setBlock(i + 1, j, k + 39, PlaceDeepslateTiles, 2, 2);
		world.setBlock(i + 2, j, k + 39, Blocks.wool, 7, 2);
		world.setBlock(i + 3, j, k + 39, Blocks.wool, 7, 2);
		world.setBlock(i + 4, j, k + 39, PlaceChiseledDeepslate, 4, 2);
		world.setBlock(i + 5, j, k + 39, Blocks.wool, 7, 2);
		world.setBlock(i + 6, j, k + 39, Blocks.wool, 7, 2);
		world.setBlock(i + 7, j, k + 39, PlaceDeepslateTiles, 2, 2);
		world.setBlock(i + 8, j, k + 39, Blocks.air, 0, 2);
		world.setBlock(i + 9, j, k + 39, Blocks.air, 0, 2);
		world.setBlock(i, j, k + 40, Blocks.air, 0, 2);
		world.setBlock(i + 1, j, k + 40, PlaceDeepslateTiles, 2, 2);
		world.setBlock(i + 2, j, k + 40, Blocks.wool, 7, 2);
		world.setBlock(i + 3, j, k + 40, Blocks.wool, 7, 2);
		world.setBlock(i + 4, j, k + 40, Blocks.air, 0, 2);
		world.setBlock(i + 5, j, k + 40, Blocks.wool, 7, 2);
		world.setBlock(i + 6, j, k + 40, Blocks.wool, 7, 2);
		world.setBlock(i + 7, j, k + 40, Blocks.air, 0, 2);
		world.setBlock(i + 8, j, k + 40, Blocks.air, 0, 2);
		world.setBlock(i + 9, j, k + 40, Blocks.air, 0, 2);
		world.setBlock(i, j, k + 41, Blocks.air, 0, 2);
		world.setBlock(i + 1, j, k + 41, PlaceDeepslateTiles, 2, 2);
		world.setBlock(i + 2, j, k + 41, Blocks.wool, 7, 2);
		world.setBlock(i + 3, j, k + 41, Blocks.wool, 7, 2);
		world.setBlock(i + 4, j, k + 41, PlaceCrackedDeepslateTiles, 3, 2);
		world.setBlock(i + 5, j, k + 41, Blocks.wool, 7, 2);
		world.setBlock(i + 6, j, k + 41, Blocks.wool, 7, 2);
		world.setBlock(i + 7, j, k + 41, PlaceCrackedDeepslateTiles, 3, 2);
		world.setBlock(i + 8, j, k + 41, Blocks.air, 0, 2);
		world.setBlock(i + 9, j, k + 41, Blocks.air, 0, 2);
		world.setBlock(i, j + 1, k, Blocks.air, 0, 2);
		world.setBlock(i + 1, j + 1, k, PlaceDeepslateBricks, 0, 2);
		world.setBlock(i + 2, j + 1, k, Blocks.wool, 7, 2);
		world.setBlock(i + 3, j + 1, k, Blocks.wool, 7, 2);
		world.setBlock(i + 4, j + 1, k, Blocks.air, 0, 2);
		world.setBlock(i + 5, j + 1, k, Blocks.wool, 7, 2);
		world.setBlock(i + 6, j + 1, k, Blocks.wool, 7, 2);
		world.setBlock(i + 7, j + 1, k, PlaceCrackedDeepslateBricks, 1, 2);
		world.setBlock(i + 8, j + 1, k, Blocks.air, 0, 2);
		world.setBlock(i + 9, j + 1, k, Blocks.air, 0, 2);
		world.setBlock(i, j + 1, k + 1, Blocks.air, 0, 2);
		world.setBlock(i + 1, j + 1, k + 1, PlaceCrackedDeepslateBricks, 1, 2);
		world.setBlock(i + 2, j + 1, k + 1, Blocks.wool, 7, 2);
		world.setBlock(i + 3, j + 1, k + 1, Blocks.wool, 7, 2);
		world.setBlock(i + 4, j + 1, k + 1, PlaceDeepslateBricks, 0, 2);
		world.setBlock(i + 5, j + 1, k + 1, Blocks.wool, 7, 2);
		world.setBlock(i + 6, j + 1, k + 1, Blocks.wool, 7, 2);
		world.setBlock(i + 7, j + 1, k + 1, PlaceDeepslateBricks, 0, 2);
		world.setBlock(i + 8, j + 1, k + 1, Blocks.air, 0, 2);
		world.setBlock(i + 9, j + 1, k + 1, Blocks.air, 0, 2);
		world.setBlock(i, j + 1, k + 2, Blocks.air, 0, 2);
		world.setBlock(i + 1, j + 1, k + 2, PlaceCrackedDeepslateBricks, 1, 2);
		world.setBlock(i + 2, j + 1, k + 2, Blocks.wool, 7, 2);
		world.setBlock(i + 3, j + 1, k + 2, Blocks.wool, 7, 2);
		world.setBlock(i + 4, j + 1, k + 2, Blocks.air, 0, 2);
		world.setBlock(i + 5, j + 1, k + 2, Blocks.wool, 7, 2);
		world.setBlock(i + 6, j + 1, k + 2, Blocks.wool, 7, 2);
		world.setBlock(i + 7, j + 1, k + 2, NovaCraftBlocks.sculk_block, 0, 2);
		world.setBlock(i + 8, j + 1, k + 2, Blocks.air, 0, 2);
		world.setBlock(i + 9, j + 1, k + 2, Blocks.air, 0, 2);
		world.setBlock(i, j + 1, k + 3, Blocks.air, 0, 2);
		world.setBlock(i + 1, j + 1, k + 3, NovaCraftBlocks.sculk_block, 0, 2);
		world.setBlock(i + 2, j + 1, k + 3, Blocks.wool, 7, 2);
		world.setBlock(i + 3, j + 1, k + 3, Blocks.wool, 7, 2);
		world.setBlock(i + 4, j + 1, k + 3, PlaceDeepslateBricks, 0, 2);
		world.setBlock(i + 5, j + 1, k + 3, Blocks.wool, 7, 2);
		world.setBlock(i + 6, j + 1, k + 3, Blocks.wool, 7, 2);
		world.setBlock(i + 7, j + 1, k + 3, NovaCraftBlocks.sculk_block, 0, 2);
		world.setBlock(i + 8, j + 1, k + 3, Blocks.air, 0, 2);
		world.setBlock(i + 9, j + 1, k + 3, Blocks.air, 0, 2);
		world.setBlock(i, j + 1, k + 4, Blocks.air, 0, 2);
		world.setBlock(i + 1, j + 1, k + 4, PlaceCrackedDeepslateBricks, 1, 2);
		world.setBlock(i + 2, j + 1, k + 4, Blocks.wool, 7, 2);
		world.setBlock(i + 3, j + 1, k + 4, Blocks.wool, 7, 2);
		world.setBlock(i + 4, j + 1, k + 4, PlaceCrackedDeepslateBricks, 1, 2);
		world.setBlock(i + 5, j + 1, k + 4, Blocks.wool, 7, 2);
		world.setBlock(i + 6, j + 1, k + 4, Blocks.wool, 7, 2);
		world.setBlock(i + 7, j + 1, k + 4, PlaceDeepslateBricks, 0, 2);
		world.setBlock(i + 8, j + 1, k + 4, Blocks.air, 0, 2);
		world.setBlock(i + 9, j + 1, k + 4, Blocks.air, 0, 2);
		world.setBlock(i, j + 1, k + 5, Blocks.air, 0, 2);
		world.setBlock(i + 1, j + 1, k + 5, PlaceDeepslateBricks, 0, 2);
		world.setBlock(i + 2, j + 1, k + 5, Blocks.wool, 7, 2);
		world.setBlock(i + 3, j + 1, k + 5, Blocks.wool, 7, 2);
		world.setBlock(i + 4, j + 1, k + 5, PlaceCrackedDeepslateBricks, 1, 2);
		world.setBlock(i + 5, j + 1, k + 5, Blocks.wool, 7, 2);
		world.setBlock(i + 6, j + 1, k + 5, Blocks.wool, 7, 2);
		world.setBlock(i + 7, j + 1, k + 5, PlaceDeepslateBricks, 0, 2);
		world.setBlock(i + 8, j + 1, k + 5, Blocks.air, 0, 2);
		world.setBlock(i + 9, j + 1, k + 5, Blocks.air, 0, 2);
		world.setBlock(i, j + 1, k + 6, Blocks.air, 0, 2);
		world.setBlock(i + 1, j + 1, k + 6, PlaceDeepslateBricks, 0, 2);
		world.setBlock(i + 2, j + 1, k + 6, Blocks.wool, 7, 2);
		world.setBlock(i + 3, j + 1, k + 6, Blocks.wool, 7, 2);
		world.setBlock(i + 4, j + 1, k + 6, PlaceDeepslateBricks, 0, 2);
		world.setBlock(i + 5, j + 1, k + 6, Blocks.wool, 7, 2);
		world.setBlock(i + 6, j + 1, k + 6, Blocks.wool, 7, 2);
		world.setBlock(i + 7, j + 1, k + 6, PlaceDeepslateBricks, 0, 2);
		world.setBlock(i + 8, j + 1, k + 6, Blocks.air, 0, 2);
		world.setBlock(i + 9, j + 1, k + 6, Blocks.air, 0, 2);
		world.setBlock(i, j + 1, k + 7, Blocks.air, 0, 2);
		world.setBlock(i + 1, j + 1, k + 7, PlaceCrackedDeepslateBricks, 1, 2);
		world.setBlock(i + 2, j + 1, k + 7, Blocks.wool, 7, 2);
		world.setBlock(i + 3, j + 1, k + 7, Blocks.wool, 7, 2);
		world.setBlock(i + 4, j + 1, k + 7, PlaceDeepslateBricks, 0, 2);
		world.setBlock(i + 5, j + 1, k + 7, Blocks.wool, 7, 2);
		world.setBlock(i + 6, j + 1, k + 7, Blocks.wool, 7, 2);
		world.setBlock(i + 7, j + 1, k + 7, PlaceDeepslateBricks, 0, 2);
		world.setBlock(i + 8, j + 1, k + 7, Blocks.air, 0, 2);
		world.setBlock(i + 9, j + 1, k + 7, Blocks.air, 0, 2);
		world.setBlock(i, j + 1, k + 8, Blocks.air, 0, 2);
		world.setBlock(i + 1, j + 1, k + 8, PlaceDeepslateBricks, 0, 2);
		world.setBlock(i + 2, j + 1, k + 8, Blocks.wool, 7, 2);
		world.setBlock(i + 3, j + 1, k + 8, Blocks.wool, 7, 2);
		world.setBlock(i + 4, j + 1, k + 8, PlaceCrackedDeepslateBricks, 1, 2);
		world.setBlock(i + 5, j + 1, k + 8, Blocks.wool, 7, 2);
		world.setBlock(i + 6, j + 1, k + 8, NovaCraftBlocks.sculk_block, 0, 2);
		world.setBlock(i + 7, j + 1, k + 8, NovaCraftBlocks.sculk_block, 0, 2);
		world.setBlock(i + 8, j + 1, k + 8, Blocks.air, 0, 2);
		world.setBlock(i + 9, j + 1, k + 8, Blocks.air, 0, 2);
		world.setBlock(i, j + 1, k + 9, Blocks.air, 0, 2);
		world.setBlock(i + 1, j + 1, k + 9, PlaceDeepslateBricks, 0, 2);
		world.setBlock(i + 2, j + 1, k + 9, Blocks.wool, 7, 2);
		world.setBlock(i + 3, j + 1, k + 9, Blocks.wool, 7, 2);
		world.setBlock(i + 4, j + 1, k + 9, PlaceCrackedDeepslateBricks, 1, 2);
		world.setBlock(i + 5, j + 1, k + 9, Blocks.wool, 7, 2);
		world.setBlock(i + 6, j + 1, k + 9, Blocks.wool, 7, 2);
		world.setBlock(i + 7, j + 1, k + 9, PlaceCrackedDeepslateBricks, 1, 2);
		world.setBlock(i + 8, j + 1, k + 9, Blocks.air, 0, 2);
		world.setBlock(i + 9, j + 1, k + 9, Blocks.air, 0, 2);
		world.setBlock(i, j + 1, k + 10, Blocks.air, 0, 2);
		world.setBlock(i + 1, j + 1, k + 10, PlaceDeepslateBricks, 0, 2);
		world.setBlock(i + 2, j + 1, k + 10, Blocks.wool, 7, 2);
		world.setBlock(i + 3, j + 1, k + 10, Blocks.wool, 7, 2);
		world.setBlock(i + 4, j + 1, k + 10, PlaceDeepslateBricks, 0, 2);
		world.setBlock(i + 5, j + 1, k + 10, Blocks.wool, 7, 2);
		world.setBlock(i + 6, j + 1, k + 10, Blocks.wool, 7, 2);
		world.setBlock(i + 7, j + 1, k + 10, PlaceDeepslateBricks, 0, 2);
		world.setBlock(i + 8, j + 1, k + 10, Blocks.air, 0, 2);
		world.setBlock(i + 9, j + 1, k + 10, Blocks.air, 0, 2);
		world.setBlock(i, j + 1, k + 11, Blocks.air, 0, 2);
		world.setBlock(i + 1, j + 1, k + 11, PlaceDeepslateBricks, 0, 2);
		world.setBlock(i + 2, j + 1, k + 11, NovaCraftBlocks.sculk_block, 0, 2);
		world.setBlock(i + 3, j + 1, k + 11, Blocks.wool, 7, 2);
		world.setBlock(i + 4, j + 1, k + 11, PlaceDeepslateBricks, 0, 2);
		world.setBlock(i + 5, j + 1, k + 11, Blocks.wool, 7, 2);
		world.setBlock(i + 6, j + 1, k + 11, Blocks.wool, 7, 2);
		world.setBlock(i + 7, j + 1, k + 11, PlaceDeepslateBricks, 0, 2);
		world.setBlock(i + 8, j + 1, k + 11, Blocks.air, 0, 2);
		world.setBlock(i + 9, j + 1, k + 11, Blocks.air, 0, 2);
		world.setBlock(i, j + 1, k + 12, Blocks.air, 0, 2);
		world.setBlock(i + 1, j + 1, k + 12, PlaceDeepslateBricks, 0, 2);
		world.setBlock(i + 2, j + 1, k + 12, Blocks.wool, 7, 2);
		world.setBlock(i + 3, j + 1, k + 12, Blocks.wool, 7, 2);
		world.setBlock(i + 4, j + 1, k + 12, PlaceDeepslateBricks, 0, 2);
		world.setBlock(i + 5, j + 1, k + 12, Blocks.wool, 7, 2);
		world.setBlock(i + 6, j + 1, k + 12, Blocks.wool, 7, 2);
		world.setBlock(i + 7, j + 1, k + 12, PlaceDeepslateBricks, 0, 2);
		world.setBlock(i + 8, j + 1, k + 12, Blocks.air, 0, 2);
		world.setBlock(i + 9, j + 1, k + 12, Blocks.air, 0, 2);
		world.setBlock(i, j + 1, k + 13, Blocks.air, 0, 2);
		world.setBlock(i + 1, j + 1, k + 13, PlaceCrackedDeepslateBricks, 1, 2);
		world.setBlock(i + 2, j + 1, k + 13, Blocks.wool, 7, 2);
		world.setBlock(i + 3, j + 1, k + 13, Blocks.wool, 7, 2);
		world.setBlock(i + 4, j + 1, k + 13, PlaceCrackedDeepslateBricks, 1, 2);
		world.setBlock(i + 5, j + 1, k + 13, Blocks.wool, 7, 2);
		world.setBlock(i + 6, j + 1, k + 13, Blocks.wool, 7, 2);
		world.setBlock(i + 7, j + 1, k + 13, PlaceDeepslateBricks, 0, 2);
		world.setBlock(i + 8, j + 1, k + 13, Blocks.air, 0, 2);
		world.setBlock(i + 9, j + 1, k + 13, Blocks.air, 0, 2);
		world.setBlock(i, j + 1, k + 14, Blocks.air, 0, 2);
		world.setBlock(i + 1, j + 1, k + 14, PlaceDeepslateBricks, 0, 2);
		world.setBlock(i + 2, j + 1, k + 14, Blocks.wool, 7, 2);
		world.setBlock(i + 3, j + 1, k + 14, Blocks.wool, 7, 2);
		world.setBlock(i + 4, j + 1, k + 14, PlaceDeepslateBricks, 0, 2);
		world.setBlock(i + 5, j + 1, k + 14, Blocks.wool, 7, 2);
		world.setBlock(i + 6, j + 1, k + 14, Blocks.wool, 7, 2);
		world.setBlock(i + 7, j + 1, k + 14, PlaceDeepslateBricks, 0, 2);
		world.setBlock(i + 8, j + 1, k + 14, Blocks.air, 0, 2);
		world.setBlock(i + 9, j + 1, k + 14, Blocks.air, 0, 2);
		world.setBlock(i, j + 1, k + 15, Blocks.air, 0, 2);
		world.setBlock(i + 1, j + 1, k + 15, PlaceDeepslateBricks, 0, 2);
		world.setBlock(i + 2, j + 1, k + 15, Blocks.wool, 7, 2);
		world.setBlock(i + 3, j + 1, k + 15, NovaCraftBlocks.sculk_block, 0, 2);
		world.setBlock(i + 4, j + 1, k + 15, PlaceDeepslateBricks, 0, 2);
		world.setBlock(i + 5, j + 1, k + 15, Blocks.wool, 7, 2);
		world.setBlock(i + 6, j + 1, k + 15, Blocks.wool, 7, 2);
		world.setBlock(i + 7, j + 1, k + 15, PlaceDeepslateBricks, 0, 2);
		world.setBlock(i + 8, j + 1, k + 15, Blocks.air, 0, 2);
		world.setBlock(i + 9, j + 1, k + 15, Blocks.air, 0, 2);
		world.setBlock(i, j + 1, k + 16, Blocks.air, 0, 2);
		world.setBlock(i + 1, j + 1, k + 16, PlaceDeepslateBricks, 0, 2);
		world.setBlock(i + 2, j + 1, k + 16, Blocks.wool, 7, 2);
		world.setBlock(i + 3, j + 1, k + 16, Blocks.wool, 7, 2);
		world.setBlock(i + 4, j + 1, k + 16, PlaceCrackedDeepslateBricks, 1, 2);
		world.setBlock(i + 5, j + 1, k + 16, Blocks.wool, 7, 2);
		world.setBlock(i + 6, j + 1, k + 16, Blocks.wool, 7, 2);
		world.setBlock(i + 7, j + 1, k + 16, PlaceCrackedDeepslateBricks, 1, 2);
		world.setBlock(i + 8, j + 1, k + 16, Blocks.air, 0, 2);
		world.setBlock(i + 9, j + 1, k + 16, Blocks.air, 0, 2);
		world.setBlock(i, j + 1, k + 17, Blocks.air, 0, 2);
		world.setBlock(i + 1, j + 1, k + 17, PlaceDeepslateBricks, 0, 2);
		world.setBlock(i + 2, j + 1, k + 17, Blocks.wool, 7, 2);
		world.setBlock(i + 3, j + 1, k + 17, Blocks.wool, 7, 2);
		world.setBlock(i + 4, j + 1, k + 17, PlaceDeepslateBricks, 0, 2);
		world.setBlock(i + 5, j + 1, k + 17, Blocks.wool, 7, 2);
		world.setBlock(i + 6, j + 1, k + 17, Blocks.wool, 7, 2);
		world.setBlock(i + 7, j + 1, k + 17, PlaceDeepslateBricks, 0, 2);
		world.setBlock(i + 8, j + 1, k + 17, Blocks.air, 0, 2);
		world.setBlock(i + 9, j + 1, k + 17, Blocks.air, 0, 2);
		world.setBlock(i, j + 1, k + 18, Blocks.air, 0, 2);
		world.setBlock(i + 1, j + 1, k + 18, PlaceDeepslateBricks, 0, 2);
		world.setBlock(i + 2, j + 1, k + 18, Blocks.wool, 7, 2);
		world.setBlock(i + 3, j + 1, k + 18, Blocks.wool, 7, 2);
		world.setBlock(i + 4, j + 1, k + 18, PlaceDeepslateBricks, 0, 2);
		world.setBlock(i + 5, j + 1, k + 18, Blocks.wool, 7, 2);
		world.setBlock(i + 6, j + 1, k + 18, Blocks.wool, 7, 2);
		world.setBlock(i + 7, j + 1, k + 18, PlaceDeepslateBricks, 0, 2);
		world.setBlock(i + 8, j + 1, k + 18, Blocks.air, 0, 2);
		world.setBlock(i + 9, j + 1, k + 18, Blocks.air, 0, 2);
		world.setBlock(i, j + 1, k + 19, Blocks.air, 0, 2);
		world.setBlock(i + 1, j + 1, k + 19, PlaceDeepslateBricks, 0, 2);
		world.setBlock(i + 2, j + 1, k + 19, Blocks.wool, 7, 2);
		world.setBlock(i + 3, j + 1, k + 19, Blocks.wool, 7, 2);
		world.setBlock(i + 4, j + 1, k + 19, PlaceDeepslateBricks, 0, 2);
		world.setBlock(i + 5, j + 1, k + 19, NovaCraftBlocks.sculk_block, 0, 2);
		world.setBlock(i + 6, j + 1, k + 19, Blocks.wool, 7, 2);
		world.setBlock(i + 7, j + 1, k + 19, PlaceCrackedDeepslateBricks, 1, 2);
		world.setBlock(i + 8, j + 1, k + 19, Blocks.air, 0, 2);
		world.setBlock(i + 9, j + 1, k + 19, Blocks.air, 0, 2);
		world.setBlock(i, j + 1, k + 20, Blocks.air, 0, 2);
		world.setBlock(i + 1, j + 1, k + 20, PlaceCrackedDeepslateBricks, 1, 2);
		world.setBlock(i + 2, j + 1, k + 20, Blocks.wool, 7, 2);
		world.setBlock(i + 3, j + 1, k + 20, Blocks.wool, 7, 2);
		world.setBlock(i + 4, j + 1, k + 20, PlaceDeepslateBricks, 0, 2);
		world.setBlock(i + 5, j + 1, k + 20, Blocks.wool, 7, 2);
		world.setBlock(i + 6, j + 1, k + 20, Blocks.wool, 7, 2);
		world.setBlock(i + 7, j + 1, k + 20, PlaceDeepslateBricks, 0, 2);
		world.setBlock(i + 8, j + 1, k + 20, Blocks.air, 0, 2);
		world.setBlock(i + 9, j + 1, k + 20, Blocks.air, 0, 2);
		world.setBlock(i, j + 1, k + 21, Blocks.air, 0, 2);
		world.setBlock(i + 1, j + 1, k + 21, PlaceDeepslateBricks, 0, 2);
		world.setBlock(i + 2, j + 1, k + 21, Blocks.wool, 7, 2);
		world.setBlock(i + 3, j + 1, k + 21, Blocks.wool, 7, 2);
		world.setBlock(i + 4, j + 1, k + 21, PlaceDeepslateBricks, 0, 2);
		world.setBlock(i + 5, j + 1, k + 21, Blocks.wool, 7, 2);
		world.setBlock(i + 6, j + 1, k + 21, Blocks.wool, 7, 2);
		world.setBlock(i + 7, j + 1, k + 21, PlaceDeepslateBricks, 0, 2);
		world.setBlock(i + 8, j + 1, k + 21, Blocks.air, 0, 2);
		world.setBlock(i + 9, j + 1, k + 21, Blocks.air, 0, 2);
		world.setBlock(i, j + 1, k + 22, Blocks.air, 0, 2);
		world.setBlock(i + 1, j + 1, k + 22, Blocks.air, 0, 2);
		world.setBlock(i + 2, j + 1, k + 22, Blocks.wool, 7, 2);
		world.setBlock(i + 3, j + 1, k + 22, Blocks.wool, 7, 2);
		world.setBlock(i + 4, j + 1, k + 22, PlaceDeepslateBricks, 0, 2);
		world.setBlock(i + 5, j + 1, k + 22, Blocks.wool, 7, 2);
		world.setBlock(i + 6, j + 1, k + 22, NovaCraftBlocks.sculk_block, 0, 2);
		world.setBlock(i + 7, j + 1, k + 22, PlaceDeepslateBricks, 0, 2);
		world.setBlock(i + 8, j + 1, k + 22, Blocks.air, 0, 2);
		world.setBlock(i + 9, j + 1, k + 22, Blocks.air, 0, 2);
		world.setBlock(i, j + 1, k + 23, Blocks.air, 0, 2);
		world.setBlock(i + 1, j + 1, k + 23, PlaceDeepslateBricks, 0, 2);
		world.setBlock(i + 2, j + 1, k + 23, Blocks.wool, 7, 2);
		world.setBlock(i + 3, j + 1, k + 23, Blocks.wool, 7, 2);
		world.setBlock(i + 4, j + 1, k + 23, PlaceDeepslateBricks, 0, 2);
		world.setBlock(i + 5, j + 1, k + 23, Blocks.wool, 7, 2);
		world.setBlock(i + 6, j + 1, k + 23, NovaCraftBlocks.sculk_block, 0, 2);
		world.setBlock(i + 7, j + 1, k + 23, PlaceDeepslateBricks, 0, 2);
		world.setBlock(i + 8, j + 1, k + 23, Blocks.air, 0, 2);
		world.setBlock(i + 9, j + 1, k + 23, Blocks.air, 0, 2);
		world.setBlock(i, j + 1, k + 24, Blocks.air, 0, 2);
		world.setBlock(i + 1, j + 1, k + 24, PlaceCrackedDeepslateBricks, 1, 2);
		world.setBlock(i + 2, j + 1, k + 24, Blocks.wool, 7, 2);
		world.setBlock(i + 3, j + 1, k + 24, Blocks.wool, 7, 2);
		world.setBlock(i + 4, j + 1, k + 24, PlaceCrackedDeepslateBricks, 1, 2);
		world.setBlock(i + 5, j + 1, k + 24, Blocks.wool, 7, 2);
		world.setBlock(i + 6, j + 1, k + 24, Blocks.wool, 7, 2);
		world.setBlock(i + 7, j + 1, k + 24, PlaceDeepslateBricks, 0, 2);
		world.setBlock(i + 8, j + 1, k + 24, Blocks.air, 0, 2);
		world.setBlock(i + 9, j + 1, k + 24, Blocks.air, 0, 2);
		world.setBlock(i, j + 1, k + 25, Blocks.air, 0, 2);
		world.setBlock(i + 1, j + 1, k + 25, PlaceDeepslateBricks, 0, 2);
		world.setBlock(i + 2, j + 1, k + 25, Blocks.wool, 7, 2);
		world.setBlock(i + 3, j + 1, k + 25, Blocks.wool, 7, 2);
		world.setBlock(i + 4, j + 1, k + 25, PlaceDeepslateBricks, 0, 2);
		world.setBlock(i + 5, j + 1, k + 25, Blocks.wool, 7, 2);
		world.setBlock(i + 6, j + 1, k + 25, Blocks.wool, 7, 2);
		world.setBlock(i + 7, j + 1, k + 25, PlaceDeepslateBricks, 0, 2);
		world.setBlock(i + 8, j + 1, k + 25, Blocks.air, 0, 2);
		world.setBlock(i + 9, j + 1, k + 25, Blocks.air, 0, 2);
		world.setBlock(i, j + 1, k + 26, Blocks.air, 0, 2);
		world.setBlock(i + 1, j + 1, k + 26, PlaceCrackedDeepslateBricks, 1, 2);
		world.setBlock(i + 2, j + 1, k + 26, Blocks.wool, 7, 2);
		world.setBlock(i + 3, j + 1, k + 26, Blocks.wool, 7, 2);
		world.setBlock(i + 4, j + 1, k + 26, PlaceDeepslateBricks, 0, 2);
		world.setBlock(i + 5, j + 1, k + 26, Blocks.wool, 7, 2);
		world.setBlock(i + 6, j + 1, k + 26, Blocks.wool, 7, 2);
		world.setBlock(i + 7, j + 1, k + 26, PlaceCrackedDeepslateBricks, 1, 2);
		world.setBlock(i + 8, j + 1, k + 26, Blocks.air, 0, 2);
		world.setBlock(i + 9, j + 1, k + 26, Blocks.air, 0, 2);
		world.setBlock(i, j + 1, k + 27, Blocks.air, 0, 2);
		world.setBlock(i + 1, j + 1, k + 27, PlaceCrackedDeepslateBricks, 1, 2);
		world.setBlock(i + 2, j + 1, k + 27, Blocks.wool, 7, 2);
		world.setBlock(i + 3, j + 1, k + 27, Blocks.wool, 7, 2);
		world.setBlock(i + 4, j + 1, k + 27, PlaceDeepslateBricks, 0, 2);
		world.setBlock(i + 5, j + 1, k + 27, Blocks.air, 0, 2);
		world.setBlock(i + 6, j + 1, k + 27, Blocks.wool, 7, 2);
		world.setBlock(i + 7, j + 1, k + 27, Blocks.air, 0, 2);
		world.setBlock(i + 8, j + 1, k + 27, Blocks.air, 0, 2);
		world.setBlock(i + 9, j + 1, k + 27, Blocks.air, 0, 2);
		world.setBlock(i, j + 1, k + 28, Blocks.air, 0, 2);
		world.setBlock(i + 1, j + 1, k + 28, PlaceCrackedDeepslateBricks, 1, 2);
		world.setBlock(i + 2, j + 1, k + 28, Blocks.wool, 7, 2);
		world.setBlock(i + 3, j + 1, k + 28, Blocks.wool, 7, 2);
		world.setBlock(i + 4, j + 1, k + 28, Blocks.air, 0, 2);
		world.setBlock(i + 5, j + 1, k + 28, Blocks.air, 0, 2);
		world.setBlock(i + 6, j + 1, k + 28, Blocks.air, 0, 2);
		world.setBlock(i + 7, j + 1, k + 28, Blocks.air, 0, 2);
		world.setBlock(i + 8, j + 1, k + 28, Blocks.air, 0, 2);
		world.setBlock(i + 9, j + 1, k + 28, Blocks.air, 0, 2);
		world.setBlock(i, j + 1, k + 29, Blocks.air, 0, 2);
		world.setBlock(i + 1, j + 1, k + 29, PlaceDeepslateBricks, 0, 2);
		world.setBlock(i + 2, j + 1, k + 29, Blocks.wool, 7, 2);
		world.setBlock(i + 3, j + 1, k + 29, Blocks.air, 0, 2);
		world.setBlock(i + 4, j + 1, k + 29, Blocks.air, 0, 2);
		world.setBlock(i + 5, j + 1, k + 29, Blocks.air, 0, 2);
		world.setBlock(i + 6, j + 1, k + 29, Blocks.air, 0, 2);
		world.setBlock(i + 7, j + 1, k + 29, Blocks.air, 0, 2);
		world.setBlock(i + 8, j + 1, k + 29, Blocks.air, 0, 2);
		world.setBlock(i + 9, j + 1, k + 29, Blocks.air, 0, 2);
		world.setBlock(i, j + 1, k + 30, Blocks.air, 0, 2);
		world.setBlock(i + 1, j + 1, k + 30, PlaceDeepslateBricks, 0, 2);
		world.setBlock(i + 2, j + 1, k + 30, Blocks.wool, 7, 2);
		world.setBlock(i + 3, j + 1, k + 30, Blocks.air, 0, 2);
		world.setBlock(i + 4, j + 1, k + 30, Blocks.air, 0, 2);
		world.setBlock(i + 5, j + 1, k + 30, Blocks.air, 0, 2);
		world.setBlock(i + 6, j + 1, k + 30, Blocks.air, 0, 2);
		world.setBlock(i + 7, j + 1, k + 30, Blocks.air, 0, 2);
		world.setBlock(i + 8, j + 1, k + 30, Blocks.air, 0, 2);
		world.setBlock(i + 9, j + 1, k + 30, Blocks.air, 0, 2);
		world.setBlock(i, j + 1, k + 31, Blocks.air, 0, 2);
		world.setBlock(i + 1, j + 1, k + 31, Blocks.air, 0, 2);
		world.setBlock(i + 2, j + 1, k + 31, Blocks.air, 0, 2);
		world.setBlock(i + 3, j + 1, k + 31, Blocks.air, 0, 2);
		world.setBlock(i + 4, j + 1, k + 31, Blocks.air, 0, 2);
		world.setBlock(i + 5, j + 1, k + 31, Blocks.air, 0, 2);
		world.setBlock(i + 6, j + 1, k + 31, Blocks.air, 0, 2);
		world.setBlock(i + 7, j + 1, k + 31, Blocks.air, 0, 2);
		world.setBlock(i + 8, j + 1, k + 31, Blocks.air, 0, 2);
		world.setBlock(i + 9, j + 1, k + 31, Blocks.air, 0, 2);
		world.setBlock(i, j + 1, k + 32, Blocks.air, 0, 2);
		world.setBlock(i + 1, j + 1, k + 32, Blocks.air, 0, 2);
		world.setBlock(i + 2, j + 1, k + 32, Blocks.air, 0, 2);
		world.setBlock(i + 3, j + 1, k + 32, Blocks.air, 0, 2);
		world.setBlock(i + 4, j + 1, k + 32, Blocks.air, 0, 2);
		world.setBlock(i + 5, j + 1, k + 32, Blocks.air, 0, 2);
		world.setBlock(i + 6, j + 1, k + 32, Blocks.air, 0, 2);
		world.setBlock(i + 7, j + 1, k + 32, Blocks.air, 0, 2);
		world.setBlock(i + 8, j + 1, k + 32, Blocks.air, 0, 2);
		world.setBlock(i + 9, j + 1, k + 32, Blocks.air, 0, 2);
		world.setBlock(i, j + 1, k + 33, Blocks.air, 0, 2);
		world.setBlock(i + 1, j + 1, k + 33, Blocks.air, 0, 2);
		world.setBlock(i + 2, j + 1, k + 33, Blocks.air, 0, 2);
		world.setBlock(i + 3, j + 1, k + 33, Blocks.air, 0, 2);
		world.setBlock(i + 4, j + 1, k + 33, Blocks.air, 0, 2);
		world.setBlock(i + 5, j + 1, k + 33, Blocks.air, 0, 2);
		world.setBlock(i + 6, j + 1, k + 33, Blocks.air, 0, 2);
		world.setBlock(i + 7, j + 1, k + 33, PlaceCrackedDeepslateBricks, 1, 2);
		world.setBlock(i + 8, j + 1, k + 33, Blocks.air, 0, 2);
		world.setBlock(i + 9, j + 1, k + 33, Blocks.air, 0, 2);
		world.setBlock(i, j + 1, k + 34, Blocks.air, 0, 2);
		world.setBlock(i + 1, j + 1, k + 34, Blocks.air, 0, 2);
		world.setBlock(i + 2, j + 1, k + 34, Blocks.air, 0, 2);
		world.setBlock(i + 3, j + 1, k + 34, Blocks.air, 0, 2);
		world.setBlock(i + 4, j + 1, k + 34, Blocks.air, 0, 2);
		world.setBlock(i + 5, j + 1, k + 34, Blocks.air, 0, 2);
		world.setBlock(i + 6, j + 1, k + 34, Blocks.wool, 7, 2);
		world.setBlock(i + 7, j + 1, k + 34, PlaceCrackedDeepslateBricks, 1, 2);
		world.setBlock(i + 8, j + 1, k + 34, Blocks.air, 0, 2);
		world.setBlock(i + 9, j + 1, k + 34, Blocks.air, 0, 2);
		world.setBlock(i, j + 1, k + 35, Blocks.air, 0, 2);
		world.setBlock(i + 1, j + 1, k + 35, Blocks.air, 0, 2);
		world.setBlock(i + 2, j + 1, k + 35, Blocks.air, 0, 2);
		world.setBlock(i + 3, j + 1, k + 35, Blocks.air, 0, 2);
		world.setBlock(i + 4, j + 1, k + 35, Blocks.air, 0, 2);
		world.setBlock(i + 5, j + 1, k + 35, Blocks.wool, 7, 2);
		world.setBlock(i + 6, j + 1, k + 35, Blocks.wool, 7, 2);
		world.setBlock(i + 7, j + 1, k + 35, PlaceDeepslateBricks, 0, 2);
		world.setBlock(i + 8, j + 1, k + 35, Blocks.air, 0, 2);
		world.setBlock(i + 9, j + 1, k + 35, Blocks.air, 0, 2);
		world.setBlock(i, j + 1, k + 36, Blocks.air, 0, 2);
		world.setBlock(i + 1, j + 1, k + 36, Blocks.air, 0, 2);
		world.setBlock(i + 2, j + 1, k + 36, Blocks.air, 0, 2);
		world.setBlock(i + 3, j + 1, k + 36, Blocks.air, 0, 2);
		world.setBlock(i + 4, j + 1, k + 36, Blocks.air, 0, 2);
		world.setBlock(i + 5, j + 1, k + 36, Blocks.wool, 7, 2);
		world.setBlock(i + 6, j + 1, k + 36, Blocks.wool, 7, 2);
		world.setBlock(i + 7, j + 1, k + 36, PlaceCrackedDeepslateBricks, 1, 2);
		world.setBlock(i + 8, j + 1, k + 36, Blocks.air, 0, 2);
		world.setBlock(i + 9, j + 1, k + 36, Blocks.air, 0, 2);
		world.setBlock(i, j + 1, k + 37, Blocks.air, 0, 2);
		world.setBlock(i + 1, j + 1, k + 37, Blocks.air, 0, 2);
		world.setBlock(i + 2, j + 1, k + 37, Blocks.air, 0, 2);
		world.setBlock(i + 3, j + 1, k + 37, Blocks.wool, 7, 2);
		world.setBlock(i + 4, j + 1, k + 37, PlaceDeepslateBricks, 0, 2);
		world.setBlock(i + 5, j + 1, k + 37, Blocks.wool, 7, 2);
		world.setBlock(i + 6, j + 1, k + 37, Blocks.wool, 7, 2);
		world.setBlock(i + 7, j + 1, k + 37, PlaceCrackedDeepslateBricks, 1, 2);
		world.setBlock(i + 8, j + 1, k + 37, Blocks.air, 0, 2);
		world.setBlock(i + 9, j + 1, k + 37, Blocks.air, 0, 2);
		world.setBlock(i, j + 1, k + 38, Blocks.air, 0, 2);
		world.setBlock(i + 1, j + 1, k + 38, PlaceDeepslateBricks, 0, 2);
		world.setBlock(i + 2, j + 1, k + 38, Blocks.air, 0, 2);
		world.setBlock(i + 3, j + 1, k + 38, Blocks.wool, 7, 2);
		world.setBlock(i + 4, j + 1, k + 38, Blocks.air, 0, 2);
		world.setBlock(i + 5, j + 1, k + 38, Blocks.wool, 7, 2);
		world.setBlock(i + 6, j + 1, k + 38, Blocks.wool, 7, 2);
		world.setBlock(i + 7, j + 1, k + 38, PlaceDeepslateBricks, 0, 2);
		world.setBlock(i + 8, j + 1, k + 38, Blocks.air, 0, 2);
		world.setBlock(i + 9, j + 1, k + 38, Blocks.air, 0, 2);
		world.setBlock(i, j + 1, k + 39, Blocks.air, 0, 2);
		world.setBlock(i + 1, j + 1, k + 39, PlaceDeepslateBricks, 0, 2);
		world.setBlock(i + 2, j + 1, k + 39, Blocks.wool, 7, 2);
		world.setBlock(i + 3, j + 1, k + 39, Blocks.wool, 7, 2);
		world.setBlock(i + 4, j + 1, k + 39, PlaceDeepslateBricks, 0, 2);
		world.setBlock(i + 5, j + 1, k + 39, Blocks.wool, 7, 2);
		world.setBlock(i + 6, j + 1, k + 39, Blocks.wool, 7, 2);
		world.setBlock(i + 7, j + 1, k + 39, PlaceDeepslateBricks, 0, 2);
		world.setBlock(i + 8, j + 1, k + 39, Blocks.air, 0, 2);
		world.setBlock(i + 9, j + 1, k + 39, Blocks.air, 0, 2);
		world.setBlock(i, j + 1, k + 40, Blocks.air, 0, 2);
		world.setBlock(i + 1, j + 1, k + 40, PlaceDeepslateBricks, 0, 2);
		world.setBlock(i + 2, j + 1, k + 40, Blocks.wool, 7, 2);
		world.setBlock(i + 3, j + 1, k + 40, Blocks.wool, 7, 2);
		world.setBlock(i + 4, j + 1, k + 40, PlaceCrackedDeepslateBricks, 1, 2);
		world.setBlock(i + 5, j + 1, k + 40, Blocks.wool, 7, 2);
		world.setBlock(i + 6, j + 1, k + 40, Blocks.wool, 7, 2);
		world.setBlock(i + 7, j + 1, k + 40, PlaceDeepslateBricks, 0, 2);
		world.setBlock(i + 8, j + 1, k + 40, Blocks.air, 0, 2);
		world.setBlock(i + 9, j + 1, k + 40, Blocks.air, 0, 2);
		world.setBlock(i, j + 1, k + 41, Blocks.air, 0, 2);
		world.setBlock(i + 1, j + 1, k + 41, PlaceDeepslateBricks, 0, 2);
		world.setBlock(i + 2, j + 1, k + 41, Blocks.wool, 7, 2);
		world.setBlock(i + 3, j + 1, k + 41, Blocks.wool, 7, 2);
		world.setBlock(i + 4, j + 1, k + 41, PlaceDeepslateBricks, 0, 2);
		world.setBlock(i + 5, j + 1, k + 41, Blocks.wool, 7, 2);
		world.setBlock(i + 6, j + 1, k + 41, Blocks.wool, 7, 2);
		world.setBlock(i + 7, j + 1, k + 41, PlaceDeepslateBricks, 0, 2);
		world.setBlock(i + 8, j + 1, k + 41, Blocks.air, 0, 2);
		world.setBlock(i + 9, j + 1, k + 41, Blocks.air, 0, 2);
		world.setBlock(i, j + 2, k, Blocks.air, 0, 2);
		world.setBlock(i + 1, j + 2, k, Blocks.air, 0, 2);
		world.setBlock(i + 2, j + 2, k, Blocks.air, 0, 2);
		world.setBlock(i + 3, j + 2, k, Blocks.air, 0, 2);
		world.setBlock(i + 4, j + 2, k, PlaceCrackedDeepslateTiles, 3, 2);
		world.setBlock(i + 5, j + 2, k, Blocks.air, 0, 2);
		world.setBlock(i + 6, j + 2, k, Blocks.air, 0, 2);
		world.setBlock(i + 7, j + 2, k, Blocks.air, 0, 2);
		world.setBlock(i + 8, j + 2, k, Blocks.air, 0, 2);
		world.setBlock(i + 9, j + 2, k, Blocks.air, 0, 2);
		world.setBlock(i, j + 2, k + 1, Blocks.air, 0, 2);
		world.setBlock(i + 1, j + 2, k + 1, PlacePolishedDeepslate, 0, 2);
		world.setBlock(i + 2, j + 2, k + 1, Blocks.air, 0, 2);
		world.setBlock(i + 3, j + 2, k + 1, Blocks.air, 0, 2);
		world.setBlock(i + 4, j + 2, k + 1, PlaceCrackedDeepslateTiles, 3, 2);
		world.setBlock(i + 5, j + 2, k + 1, Blocks.air, 0, 2);
		world.setBlock(i + 6, j + 2, k + 1, Blocks.air, 0, 2);
		world.setBlock(i + 7, j + 2, k + 1, PlacePolishedDeepslate, 0, 2);
		world.setBlock(i + 8, j + 2, k + 1, Blocks.air, 0, 2);
		world.setBlock(i + 9, j + 2, k + 1, Blocks.air, 0, 2);
		world.setBlock(i, j + 2, k + 2, Blocks.air, 0, 2);
		world.setBlock(i + 1, j + 2, k + 2, NovaCraftBlocks.sculk_block, 0, 2);
		world.setBlock(i + 2, j + 2, k + 2, Blocks.air, 0, 2);
		world.setBlock(i + 3, j + 2, k + 2, Blocks.air, 0, 2);
		world.setBlock(i + 4, j + 2, k + 2, PlaceDeepslateTiles, 2, 2);
		world.setBlock(i + 5, j + 2, k + 2, Blocks.air, 0, 2);
		world.setBlock(i + 6, j + 2, k + 2, Blocks.air, 0, 2);
		world.setBlock(i + 7, j + 2, k + 2, Blocks.air, 0, 2);
		world.setBlock(i + 8, j + 2, k + 2, Blocks.air, 0, 2);
		world.setBlock(i + 9, j + 2, k + 2, Blocks.air, 0, 2);
		world.setBlock(i, j + 2, k + 3, Blocks.air, 0, 2);
		world.setBlock(i + 1, j + 2, k + 3, Blocks.air, 0, 2);
		world.setBlock(i + 2, j + 2, k + 3, Blocks.air, 0, 2);
		world.setBlock(i + 3, j + 2, k + 3, Blocks.air, 0, 2);
		world.setBlock(i + 4, j + 2, k + 3, PlaceDeepslateTiles, 2, 2);
		world.setBlock(i + 5, j + 2, k + 3, Blocks.air, 0, 2);
		world.setBlock(i + 6, j + 2, k + 3, Blocks.air, 0, 2);
		world.setBlock(i + 7, j + 2, k + 3, Blocks.air, 0, 2);
		world.setBlock(i + 8, j + 2, k + 3, Blocks.air, 0, 2);
		world.setBlock(i + 9, j + 2, k + 3, Blocks.air, 0, 2);
		world.setBlock(i, j + 2, k + 4, Blocks.air, 0, 2);
		world.setBlock(i + 1, j + 2, k + 4, Blocks.air, 0, 2);
		world.setBlock(i + 2, j + 2, k + 4, Blocks.air, 0, 2);
		world.setBlock(i + 3, j + 2, k + 4, Blocks.air, 0, 2);
		world.setBlock(i + 4, j + 2, k + 4, PlaceDeepslateTiles, 2, 2);
		world.setBlock(i + 5, j + 2, k + 4, Blocks.air, 0, 2);
		world.setBlock(i + 6, j + 2, k + 4, Blocks.air, 0, 2);
		world.setBlock(i + 7, j + 2, k + 4, Blocks.air, 0, 2);
		world.setBlock(i + 8, j + 2, k + 4, Blocks.air, 0, 2);
		world.setBlock(i + 9, j + 2, k + 4, Blocks.air, 0, 2);
		world.setBlock(i, j + 2, k + 5, Blocks.air, 0, 2);
		world.setBlock(i + 1, j + 2, k + 5, PlacePolishedDeepslate, 0, 2);
		world.setBlock(i + 2, j + 2, k + 5, Blocks.air, 0, 2);
		world.setBlock(i + 3, j + 2, k + 5, Blocks.air, 0, 2);
		world.setBlock(i + 4, j + 2, k + 5, PlaceDeepslateTiles, 2, 2);
		world.setBlock(i + 5, j + 2, k + 5, Blocks.air, 0, 2);
		world.setBlock(i + 6, j + 2, k + 5, Blocks.air, 0, 2);
		world.setBlock(i + 7, j + 2, k + 5, PlacePolishedDeepslate, 0, 2);
		world.setBlock(i + 8, j + 2, k + 5, Blocks.air, 0, 2);
		world.setBlock(i + 9, j + 2, k + 5, Blocks.air, 0, 2);
		world.setBlock(i, j + 2, k + 6, Blocks.air, 0, 2);
		world.setBlock(i + 1, j + 2, k + 6, Blocks.air, 0, 2);
		world.setBlock(i + 2, j + 2, k + 6, Blocks.air, 0, 2);
		world.setBlock(i + 3, j + 2, k + 6, Blocks.air, 0, 2);
		world.setBlock(i + 4, j + 2, k + 6, PlaceDeepslateTiles, 2, 2);
		world.setBlock(i + 5, j + 2, k + 6, Blocks.air, 0, 2);
		world.setBlock(i + 6, j + 2, k + 6, Blocks.air, 0, 2);
		world.setBlock(i + 7, j + 2, k + 6, Blocks.air, 0, 2);
		world.setBlock(i + 8, j + 2, k + 6, Blocks.air, 0, 2);
		world.setBlock(i + 9, j + 2, k + 6, Blocks.air, 0, 2);
		world.setBlock(i, j + 2, k + 7, Blocks.air, 0, 2);
		world.setBlock(i + 1, j + 2, k + 7, PlacePolishedDeepslate, 0, 2);
		world.setBlock(i + 2, j + 2, k + 7, Blocks.air, 0, 2);
		world.setBlock(i + 3, j + 2, k + 7, Blocks.air, 0, 2);
		world.setBlock(i + 4, j + 2, k + 7, PlaceDeepslateTiles, 2, 2);
		world.setBlock(i + 5, j + 2, k + 7, Blocks.air, 0, 2);
		world.setBlock(i + 6, j + 2, k + 7, Blocks.air, 0, 2);
		world.setBlock(i + 7, j + 2, k + 7, PlacePolishedDeepslate, 0, 2);
		world.setBlock(i + 8, j + 2, k + 7, Blocks.air, 0, 2);
		world.setBlock(i + 9, j + 2, k + 7, Blocks.air, 0, 2);
		world.setBlock(i, j + 2, k + 8, Blocks.air, 0, 2);
		world.setBlock(i + 1, j + 2, k + 8, NovaCraftBlocks.sculk_block, 0, 2);
		world.setBlock(i + 2, j + 2, k + 8, Blocks.air, 0, 2);
		world.setBlock(i + 3, j + 2, k + 8, Blocks.air, 0, 2);
		world.setBlock(i + 4, j + 2, k + 8, PlaceDeepslateTiles, 2, 2);
		world.setBlock(i + 5, j + 2, k + 8, Blocks.air, 0, 2);
		world.setBlock(i + 6, j + 2, k + 8, Blocks.air, 0, 2);
		world.setBlock(i + 7, j + 2, k + 8, Blocks.air, 0, 2);
		world.setBlock(i + 8, j + 2, k + 8, Blocks.air, 0, 2);
		world.setBlock(i + 9, j + 2, k + 8, Blocks.air, 0, 2);
		world.setBlock(i, j + 2, k + 9, Blocks.air, 0, 2);
		world.setBlock(i + 1, j + 2, k + 9, PlaceCrackedDeepslateBricks, 1, 2);
		world.setBlock(i + 2, j + 2, k + 9, Blocks.air, 0, 2);
		world.setBlock(i + 3, j + 2, k + 9, Blocks.air, 0, 2);
		world.setBlock(i + 4, j + 2, k + 9, Blocks.air, 0, 2);
		world.setBlock(i + 5, j + 2, k + 9, Blocks.air, 0, 2);
		world.setBlock(i + 6, j + 2, k + 9, Blocks.air, 0, 2);
		world.setBlock(i + 7, j + 2, k + 9, PlaceDeepslateBricks, 0, 2);
		world.setBlock(i + 8, j + 2, k + 9, Blocks.air, 0, 2);
		world.setBlock(i + 9, j + 2, k + 9, Blocks.air, 0, 2);
		world.setBlock(i, j + 2, k + 10, Blocks.air, 0, 2);
		world.setBlock(i + 1, j + 2, k + 10, Blocks.air, 0, 2);
		world.setBlock(i + 2, j + 2, k + 10, Blocks.air, 0, 2);
		world.setBlock(i + 3, j + 2, k + 10, Blocks.air, 0, 2);
		world.setBlock(i + 4, j + 2, k + 10, PlaceDeepslateTiles, 2, 2);
		world.setBlock(i + 5, j + 2, k + 10, Blocks.air, 0, 2);
		world.setBlock(i + 6, j + 2, k + 10, Blocks.air, 0, 2);
		world.setBlock(i + 7, j + 2, k + 10, NovaCraftBlocks.sculk_block, 0, 2);
		world.setBlock(i + 8, j + 2, k + 10, Blocks.air, 0, 2);
		world.setBlock(i + 9, j + 2, k + 10, Blocks.air, 0, 2);
		world.setBlock(i, j + 2, k + 11, Blocks.air, 0, 2);
		world.setBlock(i + 1, j + 2, k + 11, PlaceDeepslateBricks, 0, 2);
		world.setBlock(i + 2, j + 2, k + 11, Blocks.air, 0, 2);
		world.setBlock(i + 3, j + 2, k + 11, Blocks.air, 0, 2);
		world.setBlock(i + 4, j + 2, k + 11, PlaceChiseledDeepslate, 4, 2);
		world.setBlock(i + 5, j + 2, k + 11, Blocks.air, 0, 2);
		world.setBlock(i + 6, j + 2, k + 11, Blocks.air, 0, 2);
		world.setBlock(i + 7, j + 2, k + 11, PlaceDeepslateBricks, 0, 2);
		world.setBlock(i + 8, j + 2, k + 11, Blocks.air, 0, 2);
		world.setBlock(i + 9, j + 2, k + 11, Blocks.air, 0, 2);
		world.setBlock(i, j + 2, k + 12, Blocks.air, 0, 2);
		world.setBlock(i + 1, j + 2, k + 12, Blocks.air, 0, 2);
		world.setBlock(i + 2, j + 2, k + 12, Blocks.air, 0, 2);
		world.setBlock(i + 3, j + 2, k + 12, Blocks.air, 0, 2);
		world.setBlock(i + 4, j + 2, k + 12, PlaceCrackedDeepslateTiles, 3, 2);
		world.setBlock(i + 5, j + 2, k + 12, Blocks.air, 0, 2);
		world.setBlock(i + 6, j + 2, k + 12, Blocks.air, 0, 2);
		world.setBlock(i + 7, j + 2, k + 12, Blocks.air, 0, 2);
		world.setBlock(i + 8, j + 2, k + 12, Blocks.air, 0, 2);
		world.setBlock(i + 9, j + 2, k + 12, Blocks.air, 0, 2);
		world.setBlock(i, j + 2, k + 13, Blocks.air, 0, 2);
		world.setBlock(i + 1, j + 2, k + 13, PlacePolishedDeepslate, 0, 2);
		world.setBlock(i + 2, j + 2, k + 13, Blocks.air, 0, 2);
		world.setBlock(i + 3, j + 2, k + 13, Blocks.air, 0, 2);
		world.setBlock(i + 4, j + 2, k + 13, PlaceCrackedDeepslateTiles, 3, 2);
		world.setBlock(i + 5, j + 2, k + 13, Blocks.air, 0, 2);
		world.setBlock(i + 6, j + 2, k + 13, Blocks.air, 0, 2);
		world.setBlock(i + 7, j + 2, k + 13, PlacePolishedDeepslate, 0, 2);
		world.setBlock(i + 8, j + 2, k + 13, Blocks.air, 0, 2);
		world.setBlock(i + 9, j + 2, k + 13, Blocks.air, 0, 2);
		world.setBlock(i, j + 2, k + 14, Blocks.air, 0, 2);
		world.setBlock(i + 1, j + 2, k + 14, Blocks.air, 0, 2);
		world.setBlock(i + 2, j + 2, k + 14, Blocks.air, 0, 2);
		world.setBlock(i + 3, j + 2, k + 14, Blocks.air, 0, 2);
		world.setBlock(i + 4, j + 2, k + 14, PlaceDeepslateTiles, 2, 2);
		world.setBlock(i + 5, j + 2, k + 14, Blocks.air, 0, 2);
		world.setBlock(i + 6, j + 2, k + 14, Blocks.air, 0, 2);
		world.setBlock(i + 7, j + 2, k + 14, NovaCraftBlocks.sculk_block, 0, 2);
		world.setBlock(i + 8, j + 2, k + 14, Blocks.air, 0, 2);
		world.setBlock(i + 9, j + 2, k + 14, Blocks.air, 0, 2);
		world.setBlock(i, j + 2, k + 15, Blocks.air, 0, 2);
		world.setBlock(i + 1, j + 2, k + 15, PlaceCrackedDeepslateBricks, 1, 2);
		world.setBlock(i + 2, j + 2, k + 15, Blocks.air, 0, 2);
		world.setBlock(i + 3, j + 2, k + 15, Blocks.air, 0, 2);
		world.setBlock(i + 4, j + 2, k + 15, PlaceChiseledDeepslate, 4, 2);
		world.setBlock(i + 5, j + 2, k + 15, Blocks.air, 0, 2);
		world.setBlock(i + 6, j + 2, k + 15, Blocks.air, 0, 2);
		world.setBlock(i + 7, j + 2, k + 15, PlaceCrackedDeepslateBricks, 1, 2);
		world.setBlock(i + 8, j + 2, k + 15, Blocks.air, 0, 2);
		world.setBlock(i + 9, j + 2, k + 15, Blocks.air, 0, 2);
		world.setBlock(i, j + 2, k + 16, Blocks.air, 0, 2);
		world.setBlock(i + 1, j + 2, k + 16, NovaCraftBlocks.sculk_block, 0, 2);
		world.setBlock(i + 2, j + 2, k + 16, Blocks.air, 0, 2);
		world.setBlock(i + 3, j + 2, k + 16, Blocks.air, 0, 2);
		world.setBlock(i + 4, j + 2, k + 16, PlaceDeepslateTiles, 2, 2);
		world.setBlock(i + 5, j + 2, k + 16, Blocks.air, 0, 2);
		world.setBlock(i + 6, j + 2, k + 16, Blocks.air, 0, 2);
		world.setBlock(i + 7, j + 2, k + 16, Blocks.air, 0, 2);
		world.setBlock(i + 8, j + 2, k + 16, Blocks.air, 0, 2);
		world.setBlock(i + 9, j + 2, k + 16, Blocks.air, 0, 2);
		world.setBlock(i, j + 2, k + 17, Blocks.air, 0, 2);
		world.setBlock(i + 1, j + 2, k + 17, PlaceDeepslateBricks, 0, 2);
		world.setBlock(i + 2, j + 2, k + 17, Blocks.air, 0, 2);
		world.setBlock(i + 3, j + 2, k + 17, Blocks.air, 0, 2);
		world.setBlock(i + 4, j + 2, k + 17, PlaceChiseledDeepslate, 4, 2);
		world.setBlock(i + 5, j + 2, k + 17, Blocks.air, 0, 2);
		world.setBlock(i + 6, j + 2, k + 17, Blocks.air, 0, 2);
		world.setBlock(i + 7, j + 2, k + 17, PlaceDeepslateBricks, 0, 2);
		world.setBlock(i + 8, j + 2, k + 17, Blocks.air, 0, 2);
		world.setBlock(i + 9, j + 2, k + 17, Blocks.air, 0, 2);
		world.setBlock(i, j + 2, k + 18, Blocks.air, 0, 2);
		world.setBlock(i + 1, j + 2, k + 18, Blocks.air, 0, 2);
		world.setBlock(i + 2, j + 2, k + 18, Blocks.air, 0, 2);
		world.setBlock(i + 3, j + 2, k + 18, Blocks.air, 0, 2);
		world.setBlock(i + 4, j + 2, k + 18, NovaCraftBlocks.sculk_block, 0, 2);
		world.setBlock(i + 5, j + 2, k + 18, Blocks.air, 0, 2);
		world.setBlock(i + 6, j + 2, k + 18, Blocks.air, 0, 2);
		world.setBlock(i + 7, j + 2, k + 18, Blocks.air, 0, 2);
		world.setBlock(i + 8, j + 2, k + 18, Blocks.air, 0, 2);
		world.setBlock(i + 9, j + 2, k + 18, Blocks.air, 0, 2);
		world.setBlock(i, j + 2, k + 19, Blocks.air, 0, 2);
		world.setBlock(i + 1, j + 2, k + 19, PlacePolishedDeepslate, 0, 2);
		world.setBlock(i + 2, j + 2, k + 19, Blocks.air, 0, 2);
		world.setBlock(i + 3, j + 2, k + 19, Blocks.air, 0, 2);
		world.setBlock(i + 4, j + 2, k + 19, PlaceDeepslateTiles, 2, 2);
		world.setBlock(i + 5, j + 2, k + 19, Blocks.air, 0, 2);
		world.setBlock(i + 6, j + 2, k + 19, Blocks.air, 0, 2);
		world.setBlock(i + 7, j + 2, k + 19, PlacePolishedDeepslate, 0, 2);
		world.setBlock(i + 8, j + 2, k + 19, Blocks.air, 0, 2);
		world.setBlock(i + 9, j + 2, k + 19, Blocks.air, 0, 2);
		world.setBlock(i, j + 2, k + 20, Blocks.air, 0, 2);
		world.setBlock(i + 1, j + 2, k + 20, Blocks.air, 0, 2);
		world.setBlock(i + 2, j + 2, k + 20, Blocks.air, 0, 2);
		world.setBlock(i + 3, j + 2, k + 20, Blocks.air, 0, 2);
		world.setBlock(i + 4, j + 2, k + 20, PlaceDeepslateTiles, 2, 2);
		world.setBlock(i + 5, j + 2, k + 20, Blocks.air, 0, 2);
		world.setBlock(i + 6, j + 2, k + 20, Blocks.air, 0, 2);
		world.setBlock(i + 7, j + 2, k + 20, Blocks.air, 0, 2);
		world.setBlock(i + 8, j + 2, k + 20, Blocks.air, 0, 2);
		world.setBlock(i + 9, j + 2, k + 20, Blocks.air, 0, 2);
		world.setBlock(i, j + 2, k + 21, Blocks.air, 0, 2);
		world.setBlock(i + 1, j + 2, k + 21, PlaceCrackedDeepslateBricks, 1, 2);
		world.setBlock(i + 2, j + 2, k + 21, Blocks.air, 0, 2);
		world.setBlock(i + 3, j + 2, k + 21, Blocks.air, 0, 2);
		world.setBlock(i + 4, j + 2, k + 21, PlaceChiseledDeepslate, 4, 2);
		world.setBlock(i + 5, j + 2, k + 21, Blocks.air, 0, 2);
		world.setBlock(i + 6, j + 2, k + 21, Blocks.air, 0, 2);
		world.setBlock(i + 7, j + 2, k + 21, PlaceDeepslateBricks, 0, 2);
		world.setBlock(i + 8, j + 2, k + 21, Blocks.air, 0, 2);
		world.setBlock(i + 9, j + 2, k + 21, Blocks.air, 0, 2);
		world.setBlock(i, j + 2, k + 22, Blocks.air, 0, 2);
		world.setBlock(i + 1, j + 2, k + 22, Blocks.air, 0, 2);
		world.setBlock(i + 2, j + 2, k + 22, Blocks.air, 0, 2);
		world.setBlock(i + 3, j + 2, k + 22, Blocks.air, 0, 2);
		world.setBlock(i + 4, j + 2, k + 22, PlaceDeepslateTiles, 2, 2);
		world.setBlock(i + 5, j + 2, k + 22, Blocks.air, 0, 2);
		world.setBlock(i + 6, j + 2, k + 22, Blocks.air, 0, 2);
		world.setBlock(i + 7, j + 2, k + 22, Blocks.air, 0, 2);
		world.setBlock(i + 8, j + 2, k + 22, Blocks.air, 0, 2);
		world.setBlock(i + 9, j + 2, k + 22, Blocks.air, 0, 2);
		world.setBlock(i, j + 2, k + 23, Blocks.air, 0, 2);
		world.setBlock(i + 1, j + 2, k + 23, PlaceCrackedDeepslateBricks, 1, 2);
		world.setBlock(i + 2, j + 2, k + 23, Blocks.air, 0, 2);
		world.setBlock(i + 3, j + 2, k + 23, Blocks.air, 0, 2);
		world.setBlock(i + 4, j + 2, k + 23, PlaceChiseledDeepslate, 4, 2);
		world.setBlock(i + 5, j + 2, k + 23, Blocks.air, 0, 2);
		world.setBlock(i + 6, j + 2, k + 23, Blocks.air, 0, 2);
		world.setBlock(i + 7, j + 2, k + 23, PlaceCrackedDeepslateBricks, 1, 2);
		world.setBlock(i + 8, j + 2, k + 23, Blocks.air, 0, 2);
		world.setBlock(i + 9, j + 2, k + 23, Blocks.air, 0, 2);
		world.setBlock(i, j + 2, k + 24, Blocks.air, 0, 2);
		world.setBlock(i + 1, j + 2, k + 24, PlaceDeepslateBricks, 0, 2);
		world.setBlock(i + 2, j + 2, k + 24, Blocks.air, 0, 2);
		world.setBlock(i + 3, j + 2, k + 24, Blocks.air, 0, 2);
		world.setBlock(i + 4, j + 2, k + 24, PlaceChiseledDeepslate, 4, 2);
		world.setBlock(i + 5, j + 2, k + 24, Blocks.air, 0, 2);
		world.setBlock(i + 6, j + 2, k + 24, Blocks.air, 0, 2);
		world.setBlock(i + 7, j + 2, k + 24, PlaceCrackedDeepslateBricks, 1, 2);
		world.setBlock(i + 8, j + 2, k + 24, Blocks.air, 0, 2);
		world.setBlock(i + 9, j + 2, k + 24, Blocks.air, 0, 2);
		world.setBlock(i, j + 2, k + 25, Blocks.air, 0, 2);
		world.setBlock(i + 1, j + 2, k + 25, Blocks.air, 0, 2);
		world.setBlock(i + 2, j + 2, k + 25, Blocks.air, 0, 2);
		world.setBlock(i + 3, j + 2, k + 25, Blocks.air, 0, 2);
		world.setBlock(i + 4, j + 2, k + 25, PlaceCrackedDeepslateTiles, 3, 2);
		world.setBlock(i + 5, j + 2, k + 25, Blocks.air, 0, 2);
		world.setBlock(i + 6, j + 2, k + 25, Blocks.air, 0, 2);
		world.setBlock(i + 7, j + 2, k + 25, Blocks.air, 0, 2);
		world.setBlock(i + 8, j + 2, k + 25, Blocks.air, 0, 2);
		world.setBlock(i + 9, j + 2, k + 25, Blocks.air, 0, 2);
		world.setBlock(i, j + 2, k + 26, Blocks.air, 0, 2);
		world.setBlock(i + 1, j + 2, k + 26, PlaceDeepslateBricks, 0, 2);
		world.setBlock(i + 2, j + 2, k + 26, Blocks.air, 0, 2);
		world.setBlock(i + 3, j + 2, k + 26, Blocks.air, 0, 2);
		world.setBlock(i + 4, j + 2, k + 26, PlaceChiseledDeepslate, 4, 2);
		world.setBlock(i + 5, j + 2, k + 26, Blocks.air, 0, 2);
		world.setBlock(i + 6, j + 2, k + 26, Blocks.air, 0, 2);
		world.setBlock(i + 7, j + 2, k + 26, PlaceDeepslateBricks, 0, 2);
		world.setBlock(i + 8, j + 2, k + 26, Blocks.air, 0, 2);
		world.setBlock(i + 9, j + 2, k + 26, Blocks.air, 0, 2);
		world.setBlock(i, j + 2, k + 27, Blocks.air, 0, 2);
		world.setBlock(i + 1, j + 2, k + 27, Blocks.air, 0, 2);
		world.setBlock(i + 2, j + 2, k + 27, Blocks.air, 0, 2);
		world.setBlock(i + 3, j + 2, k + 27, Blocks.air, 0, 2);
		world.setBlock(i + 4, j + 2, k + 27, PlaceCrackedDeepslateTiles, 3, 2);
		world.setBlock(i + 5, j + 2, k + 27, Blocks.air, 0, 2);
		world.setBlock(i + 6, j + 2, k + 27, Blocks.air, 0, 2);
		world.setBlock(i + 7, j + 2, k + 27, Blocks.air, 0, 2);
		world.setBlock(i + 8, j + 2, k + 27, Blocks.air, 0, 2);
		world.setBlock(i + 9, j + 2, k + 27, Blocks.air, 0, 2);
		world.setBlock(i, j + 2, k + 28, Blocks.air, 0, 2);
		world.setBlock(i + 1, j + 2, k + 28, PlacePolishedDeepslate, 0, 2);
		world.setBlock(i + 2, j + 2, k + 28, Blocks.air, 0, 2);
		world.setBlock(i + 3, j + 2, k + 28, Blocks.air, 0, 2);
		world.setBlock(i + 4, j + 2, k + 28, Blocks.air, 0, 2);
		world.setBlock(i + 5, j + 2, k + 28, Blocks.air, 0, 2);
		world.setBlock(i + 6, j + 2, k + 28, Blocks.air, 0, 2);
		world.setBlock(i + 7, j + 2, k + 28, Blocks.air, 0, 2);
		world.setBlock(i + 8, j + 2, k + 28, Blocks.air, 0, 2);
		world.setBlock(i + 9, j + 2, k + 28, Blocks.air, 0, 2);
		world.setBlock(i, j + 2, k + 29, Blocks.air, 0, 2);
		world.setBlock(i + 1, j + 2, k + 29, Blocks.air, 0, 2);
		world.setBlock(i + 2, j + 2, k + 29, Blocks.air, 0, 2);
		world.setBlock(i + 3, j + 2, k + 29, Blocks.air, 0, 2);
		world.setBlock(i + 4, j + 2, k + 29, Blocks.air, 0, 2);
		world.setBlock(i + 5, j + 2, k + 29, Blocks.air, 0, 2);
		world.setBlock(i + 6, j + 2, k + 29, Blocks.air, 0, 2);
		world.setBlock(i + 7, j + 2, k + 29, Blocks.air, 0, 2);
		world.setBlock(i + 8, j + 2, k + 29, Blocks.air, 0, 2);
		world.setBlock(i + 9, j + 2, k + 29, Blocks.air, 0, 2);
		world.setBlock(i, j + 2, k + 30, Blocks.air, 0, 2);
		world.setBlock(i + 1, j + 2, k + 30, PlaceDeepslateBricks, 0, 2);
		world.setBlock(i + 2, j + 2, k + 30, Blocks.air, 0, 2);
		world.setBlock(i + 3, j + 2, k + 30, Blocks.air, 0, 2);
		world.setBlock(i + 4, j + 2, k + 30, Blocks.air, 0, 2);
		world.setBlock(i + 5, j + 2, k + 30, Blocks.air, 0, 2);
		world.setBlock(i + 6, j + 2, k + 30, Blocks.air, 0, 2);
		world.setBlock(i + 7, j + 2, k + 30, Blocks.air, 0, 2);
		world.setBlock(i + 8, j + 2, k + 30, Blocks.air, 0, 2);
		world.setBlock(i + 9, j + 2, k + 30, Blocks.air, 0, 2);
		world.setBlock(i, j + 2, k + 31, Blocks.air, 0, 2);
		world.setBlock(i + 1, j + 2, k + 31, Blocks.air, 0, 2);
		world.setBlock(i + 2, j + 2, k + 31, Blocks.air, 0, 2);
		world.setBlock(i + 3, j + 2, k + 31, Blocks.air, 0, 2);
		world.setBlock(i + 4, j + 2, k + 31, Blocks.air, 0, 2);
		world.setBlock(i + 5, j + 2, k + 31, Blocks.air, 0, 2);
		world.setBlock(i + 6, j + 2, k + 31, Blocks.air, 0, 2);
		world.setBlock(i + 7, j + 2, k + 31, Blocks.air, 0, 2);
		world.setBlock(i + 8, j + 2, k + 31, Blocks.air, 0, 2);
		world.setBlock(i + 9, j + 2, k + 31, Blocks.air, 0, 2);
		world.setBlock(i, j + 2, k + 32, Blocks.air, 0, 2);
		world.setBlock(i + 1, j + 2, k + 32, Blocks.air, 0, 2);
		world.setBlock(i + 2, j + 2, k + 32, Blocks.air, 0, 2);
		world.setBlock(i + 3, j + 2, k + 32, Blocks.air, 0, 2);
		world.setBlock(i + 4, j + 2, k + 32, Blocks.air, 0, 2);
		world.setBlock(i + 5, j + 2, k + 32, Blocks.air, 0, 2);
		world.setBlock(i + 6, j + 2, k + 32, Blocks.air, 0, 2);
		world.setBlock(i + 7, j + 2, k + 32, Blocks.air, 0, 2);
		world.setBlock(i + 8, j + 2, k + 32, Blocks.air, 0, 2);
		world.setBlock(i + 9, j + 2, k + 32, Blocks.air, 0, 2);
		world.setBlock(i, j + 2, k + 33, Blocks.air, 0, 2);
		world.setBlock(i + 1, j + 2, k + 33, Blocks.air, 0, 2);
		world.setBlock(i + 2, j + 2, k + 33, Blocks.air, 0, 2);
		world.setBlock(i + 3, j + 2, k + 33, Blocks.air, 0, 2);
		world.setBlock(i + 4, j + 2, k + 33, Blocks.air, 0, 2);
		world.setBlock(i + 5, j + 2, k + 33, Blocks.air, 0, 2);
		world.setBlock(i + 6, j + 2, k + 33, Blocks.air, 0, 2);
		world.setBlock(i + 7, j + 2, k + 33, Blocks.air, 0, 2);
		world.setBlock(i + 8, j + 2, k + 33, Blocks.air, 0, 2);
		world.setBlock(i + 9, j + 2, k + 33, Blocks.air, 0, 2);
		world.setBlock(i, j + 2, k + 34, Blocks.air, 0, 2);
		world.setBlock(i + 1, j + 2, k + 34, Blocks.air, 0, 2);
		world.setBlock(i + 2, j + 2, k + 34, Blocks.air, 0, 2);
		world.setBlock(i + 3, j + 2, k + 34, Blocks.air, 0, 2);
		world.setBlock(i + 4, j + 2, k + 34, Blocks.air, 0, 2);
		world.setBlock(i + 5, j + 2, k + 34, Blocks.air, 0, 2);
		world.setBlock(i + 6, j + 2, k + 34, Blocks.air, 0, 2);
		world.setBlock(i + 7, j + 2, k + 34, PlacePolishedDeepslate, 0, 2);
		world.setBlock(i + 8, j + 2, k + 34, Blocks.air, 0, 2);
		world.setBlock(i + 9, j + 2, k + 34, Blocks.air, 0, 2);
		world.setBlock(i, j + 2, k + 35, Blocks.air, 0, 2);
		world.setBlock(i + 1, j + 2, k + 35, Blocks.air, 0, 2);
		world.setBlock(i + 2, j + 2, k + 35, Blocks.air, 0, 2);
		world.setBlock(i + 3, j + 2, k + 35, Blocks.air, 0, 2);
		world.setBlock(i + 4, j + 2, k + 35, Blocks.air, 0, 2);
		world.setBlock(i + 5, j + 2, k + 35, Blocks.air, 0, 2);
		world.setBlock(i + 6, j + 2, k + 35, Blocks.air, 0, 2);
		world.setBlock(i + 7, j + 2, k + 35, Blocks.air, 0, 2);
		world.setBlock(i + 8, j + 2, k + 35, Blocks.air, 0, 2);
		world.setBlock(i + 9, j + 2, k + 35, Blocks.air, 0, 2);
		world.setBlock(i, j + 2, k + 36, Blocks.air, 0, 2);
		world.setBlock(i + 1, j + 2, k + 36, Blocks.air, 0, 2);
		world.setBlock(i + 2, j + 2, k + 36, Blocks.air, 0, 2);
		world.setBlock(i + 3, j + 2, k + 36, Blocks.air, 0, 2);
		world.setBlock(i + 4, j + 2, k + 36, Blocks.air, 0, 2);
		world.setBlock(i + 5, j + 2, k + 36, Blocks.air, 0, 2);
		world.setBlock(i + 6, j + 2, k + 36, Blocks.air, 0, 2);
		world.setBlock(i + 7, j + 2, k + 36, PlaceDeepslateBricks, 0, 2);
		world.setBlock(i + 8, j + 2, k + 36, Blocks.air, 0, 2);
		world.setBlock(i + 9, j + 2, k + 36, Blocks.air, 0, 2);
		world.setBlock(i, j + 2, k + 37, Blocks.air, 0, 2);
		world.setBlock(i + 1, j + 2, k + 37, Blocks.air, 0, 2);
		world.setBlock(i + 2, j + 2, k + 37, Blocks.air, 0, 2);
		world.setBlock(i + 3, j + 2, k + 37, Blocks.air, 0, 2);
		world.setBlock(i + 4, j + 2, k + 37, PlaceDeepslateTiles, 2, 2);
		world.setBlock(i + 5, j + 2, k + 37, Blocks.air, 0, 2);
		world.setBlock(i + 6, j + 2, k + 37, Blocks.air, 0, 2);
		world.setBlock(i + 7, j + 2, k + 37, Blocks.air, 0, 2);
		world.setBlock(i + 8, j + 2, k + 37, Blocks.air, 0, 2);
		world.setBlock(i + 9, j + 2, k + 37, Blocks.air, 0, 2);
		world.setBlock(i, j + 2, k + 38, Blocks.air, 0, 2);
		world.setBlock(i + 1, j + 2, k + 38, PlaceDeepslateBricks, 0, 2);
		world.setBlock(i + 2, j + 2, k + 38, Blocks.air, 0, 2);
		world.setBlock(i + 3, j + 2, k + 38, Blocks.air, 0, 2);
		world.setBlock(i + 4, j + 2, k + 38, PlaceChiseledDeepslate, 4, 2);
		world.setBlock(i + 5, j + 2, k + 38, Blocks.air, 0, 2);
		world.setBlock(i + 6, j + 2, k + 38, Blocks.air, 0, 2);
		world.setBlock(i + 7, j + 2, k + 38, PlaceDeepslateBricks, 0, 2);
		world.setBlock(i + 8, j + 2, k + 38, Blocks.air, 0, 2);
		world.setBlock(i + 9, j + 2, k + 38, Blocks.air, 0, 2);
		world.setBlock(i, j + 2, k + 39, Blocks.air, 0, 2);
		world.setBlock(i + 1, j + 2, k + 39, Blocks.air, 0, 2);
		world.setBlock(i + 2, j + 2, k + 39, Blocks.air, 0, 2);
		world.setBlock(i + 3, j + 2, k + 39, Blocks.air, 0, 2);
		world.setBlock(i + 4, j + 2, k + 39, PlaceCrackedDeepslateTiles, 3, 2);
		world.setBlock(i + 5, j + 2, k + 39, Blocks.air, 0, 2);
		world.setBlock(i + 6, j + 2, k + 39, Blocks.air, 0, 2);
		world.setBlock(i + 7, j + 2, k + 39, Blocks.air, 0, 2);
		world.setBlock(i + 8, j + 2, k + 39, Blocks.air, 0, 2);
		world.setBlock(i + 9, j + 2, k + 39, Blocks.air, 0, 2);
		world.setBlock(i, j + 2, k + 40, Blocks.air, 0, 2);
		world.setBlock(i + 1, j + 2, k + 40, PlacePolishedDeepslate, 0, 2);
		world.setBlock(i + 2, j + 2, k + 40, Blocks.air, 0, 2);
		world.setBlock(i + 3, j + 2, k + 40, Blocks.air, 0, 2);
		world.setBlock(i + 4, j + 2, k + 40, PlaceDeepslateTiles, 2, 2);
		world.setBlock(i + 5, j + 2, k + 40, Blocks.air, 0, 2);
		world.setBlock(i + 6, j + 2, k + 40, Blocks.air, 0, 2);
		world.setBlock(i + 7, j + 2, k + 40, PlacePolishedDeepslate, 0, 2);
		world.setBlock(i + 8, j + 2, k + 40, Blocks.air, 0, 2);
		world.setBlock(i + 9, j + 2, k + 40, Blocks.air, 0, 2);
		world.setBlock(i, j + 2, k + 41, Blocks.air, 0, 2);
		world.setBlock(i + 1, j + 2, k + 41, Blocks.air, 0, 2);
		world.setBlock(i + 2, j + 2, k + 41, Blocks.air, 0, 2);
		world.setBlock(i + 3, j + 2, k + 41, Blocks.air, 0, 2);
		world.setBlock(i + 4, j + 2, k + 41, PlaceDeepslateTiles, 2, 2);
		world.setBlock(i + 5, j + 2, k + 41, Blocks.air, 0, 2);
		world.setBlock(i + 6, j + 2, k + 41, Blocks.air, 0, 2);
		world.setBlock(i + 7, j + 2, k + 41, Blocks.air, 0, 2);
		world.setBlock(i + 8, j + 2, k + 41, Blocks.air, 0, 2);
		world.setBlock(i + 9, j + 2, k + 41, Blocks.air, 0, 2);
		world.setBlock(i, j + 3, k, Blocks.air, 0, 2);
		world.setBlock(i + 1, j + 3, k, Blocks.air, 0, 2);
		world.setBlock(i + 2, j + 3, k, Blocks.air, 0, 2);
		world.setBlock(i + 3, j + 3, k, Blocks.air, 0, 2);
		world.setBlock(i + 4, j + 3, k, PlaceCrackedDeepslateBricks, 1, 2);
		world.setBlock(i + 5, j + 3, k, Blocks.air, 0, 2);
		world.setBlock(i + 6, j + 3, k, Blocks.air, 0, 2);
		world.setBlock(i + 7, j + 3, k, Blocks.air, 0, 2);
		world.setBlock(i + 8, j + 3, k, Blocks.air, 0, 2);
		world.setBlock(i + 9, j + 3, k, Blocks.air, 0, 2);
		world.setBlock(i, j + 3, k + 1, Blocks.air, 0, 2);
		world.setBlock(i + 1, j + 3, k + 1, PlacePolishedDeepslate, 0, 2);
		world.setBlock(i + 2, j + 3, k + 1, Blocks.air, 0, 2);
		world.setBlock(i + 3, j + 3, k + 1, Blocks.air, 0, 2);
		world.setBlock(i + 4, j + 3, k + 1, PlaceDeepslateBricks, 0, 2);
		world.setBlock(i + 5, j + 3, k + 1, Blocks.air, 0, 2);
		world.setBlock(i + 6, j + 3, k + 1, Blocks.air, 0, 2);
		world.setBlock(i + 7, j + 3, k + 1, PlacePolishedDeepslate, 0, 2);
		world.setBlock(i + 8, j + 3, k + 1, Blocks.air, 0, 2);
		world.setBlock(i + 9, j + 3, k + 1, Blocks.air, 0, 2);
		world.setBlock(i, j + 3, k + 2, Blocks.air, 0, 2);
		world.setBlock(i + 1, j + 3, k + 2, Blocks.air, 0, 2);
		world.setBlock(i + 2, j + 3, k + 2, Blocks.air, 0, 2);
		world.setBlock(i + 3, j + 3, k + 2, Blocks.air, 0, 2);
		world.setBlock(i + 4, j + 3, k + 2, PlaceDeepslateBricks, 0, 2);
		world.setBlock(i + 5, j + 3, k + 2, Blocks.air, 0, 2);
		world.setBlock(i + 6, j + 3, k + 2, Blocks.air, 0, 2);
		world.setBlock(i + 7, j + 3, k + 2, Blocks.air, 0, 2);
		world.setBlock(i + 8, j + 3, k + 2, Blocks.air, 0, 2);
		world.setBlock(i + 9, j + 3, k + 2, Blocks.air, 0, 2);
		world.setBlock(i, j + 3, k + 3, Blocks.air, 0, 2);
		world.setBlock(i + 1, j + 3, k + 3, Blocks.air, 0, 2);
		world.setBlock(i + 2, j + 3, k + 3, Blocks.air, 0, 2);
		world.setBlock(i + 3, j + 3, k + 3, Blocks.air, 0, 2);
		world.setBlock(i + 4, j + 3, k + 3, PlaceCrackedDeepslateBricks, 1, 2);
		world.setBlock(i + 5, j + 3, k + 3, Blocks.air, 0, 2);
		world.setBlock(i + 6, j + 3, k + 3, Blocks.air, 0, 2);
		world.setBlock(i + 7, j + 3, k + 3, Blocks.air, 0, 2);
		world.setBlock(i + 8, j + 3, k + 3, Blocks.air, 0, 2);
		world.setBlock(i + 9, j + 3, k + 3, Blocks.air, 0, 2);
		world.setBlock(i, j + 3, k + 4, Blocks.air, 0, 2);
		world.setBlock(i + 1, j + 3, k + 4, Blocks.air, 0, 2);
		world.setBlock(i + 2, j + 3, k + 4, Blocks.air, 0, 2);
		world.setBlock(i + 3, j + 3, k + 4, Blocks.air, 0, 2);
		world.setBlock(i + 4, j + 3, k + 4, PlaceDeepslateBricks, 0, 2);
		world.setBlock(i + 5, j + 3, k + 4, Blocks.air, 0, 2);
		world.setBlock(i + 6, j + 3, k + 4, Blocks.air, 0, 2);
		world.setBlock(i + 7, j + 3, k + 4, Blocks.air, 0, 2);
		world.setBlock(i + 8, j + 3, k + 4, Blocks.air, 0, 2);
		world.setBlock(i + 9, j + 3, k + 4, Blocks.air, 0, 2);
		world.setBlock(i, j + 3, k + 5, Blocks.air, 0, 2);
		world.setBlock(i + 1, j + 3, k + 5, PlacePolishedDeepslate, 0, 2);
		world.setBlock(i + 2, j + 3, k + 5, Blocks.air, 0, 2);
		world.setBlock(i + 3, j + 3, k + 5, Blocks.air, 0, 2);
		world.setBlock(i + 4, j + 3, k + 5, Blocks.air, 0, 2);
		world.setBlock(i + 5, j + 3, k + 5, Blocks.air, 0, 2);
		world.setBlock(i + 6, j + 3, k + 5, Blocks.air, 0, 2);
		world.setBlock(i + 7, j + 3, k + 5, PlacePolishedDeepslate, 0, 2);
		world.setBlock(i + 8, j + 3, k + 5, Blocks.air, 0, 2);
		world.setBlock(i + 9, j + 3, k + 5, Blocks.air, 0, 2);
		world.setBlock(i, j + 3, k + 6, Blocks.air, 0, 2);
		world.setBlock(i + 1, j + 3, k + 6, Blocks.air, 0, 2);
		world.setBlock(i + 2, j + 3, k + 6, Blocks.air, 0, 2);
		world.setBlock(i + 3, j + 3, k + 6, Blocks.air, 0, 2);
		world.setBlock(i + 4, j + 3, k + 6, PlaceCrackedDeepslateBricks, 1, 2);
		world.setBlock(i + 5, j + 3, k + 6, Blocks.air, 0, 2);
		world.setBlock(i + 6, j + 3, k + 6, Blocks.air, 0, 2);
		world.setBlock(i + 7, j + 3, k + 6, Blocks.air, 0, 2);
		world.setBlock(i + 8, j + 3, k + 6, Blocks.air, 0, 2);
		world.setBlock(i + 9, j + 3, k + 6, Blocks.air, 0, 2);
		world.setBlock(i, j + 3, k + 7, Blocks.air, 0, 2);
		world.setBlock(i + 1, j + 3, k + 7, PlacePolishedDeepslate, 0, 2);
		world.setBlock(i + 2, j + 3, k + 7, Blocks.air, 0, 2);
		world.setBlock(i + 3, j + 3, k + 7, Blocks.air, 0, 2);
		world.setBlock(i + 4, j + 3, k + 7, PlaceCrackedDeepslateBricks, 1, 2);
		world.setBlock(i + 5, j + 3, k + 7, Blocks.air, 0, 2);
		world.setBlock(i + 6, j + 3, k + 7, Blocks.air, 0, 2);
		world.setBlock(i + 7, j + 3, k + 7, PlacePolishedDeepslate, 0, 2);
		world.setBlock(i + 8, j + 3, k + 7, Blocks.air, 0, 2);
		world.setBlock(i + 9, j + 3, k + 7, Blocks.air, 0, 2);
		world.setBlock(i, j + 3, k + 8, Blocks.air, 0, 2);
		world.setBlock(i + 1, j + 3, k + 8, Blocks.air, 0, 2);
		world.setBlock(i + 2, j + 3, k + 8, Blocks.air, 0, 2);
		world.setBlock(i + 3, j + 3, k + 8, Blocks.air, 0, 2);
		world.setBlock(i + 4, j + 3, k + 8, PlaceDeepslateBricks, 0, 2);
		world.setBlock(i + 5, j + 3, k + 8, Blocks.air, 0, 2);
		world.setBlock(i + 6, j + 3, k + 8, Blocks.air, 0, 2);
		world.setBlock(i + 7, j + 3, k + 8, Blocks.air, 0, 2);
		world.setBlock(i + 8, j + 3, k + 8, Blocks.air, 0, 2);
		world.setBlock(i + 9, j + 3, k + 8, Blocks.air, 0, 2);
		world.setBlock(i, j + 3, k + 9, Blocks.air, 0, 2);
		world.setBlock(i + 1, j + 3, k + 9, Blocks.air, 0, 2);
		world.setBlock(i + 2, j + 3, k + 9, Blocks.air, 0, 2);
		world.setBlock(i + 3, j + 3, k + 9, Blocks.air, 0, 2);
		world.setBlock(i + 4, j + 3, k + 9, Blocks.air, 0, 2);
		world.setBlock(i + 5, j + 3, k + 9, Blocks.air, 0, 2);
		world.setBlock(i + 6, j + 3, k + 9, Blocks.air, 0, 2);
		world.setBlock(i + 7, j + 3, k + 9, Blocks.air, 0, 2);
		world.setBlock(i + 8, j + 3, k + 9, Blocks.air, 0, 2);
		world.setBlock(i + 9, j + 3, k + 9, Blocks.air, 0, 2);
		world.setBlock(i, j + 3, k + 10, Blocks.air, 0, 2);
		world.setBlock(i + 1, j + 3, k + 10, Blocks.air, 0, 2);
		world.setBlock(i + 2, j + 3, k + 10, Blocks.air, 0, 2);
		world.setBlock(i + 3, j + 3, k + 10, Blocks.air, 0, 2);
		world.setBlock(i + 4, j + 3, k + 10, PlacePolishedDeepslate, 0, 2);
		world.setBlock(i + 5, j + 3, k + 10, Blocks.air, 0, 2);
		world.setBlock(i + 6, j + 3, k + 10, Blocks.air, 0, 2);
		world.setBlock(i + 7, j + 3, k + 10, Blocks.air, 0, 2);
		world.setBlock(i + 8, j + 3, k + 10, Blocks.air, 0, 2);
		world.setBlock(i + 9, j + 3, k + 10, Blocks.air, 0, 2);
		world.setBlock(i, j + 3, k + 11, Blocks.air, 0, 2);
		world.setBlock(i + 1, j + 3, k + 11, Blocks.air, 0, 2);
		world.setBlock(i + 2, j + 3, k + 11, Blocks.air, 0, 2);
		world.setBlock(i + 3, j + 3, k + 11, Blocks.air, 0, 2);
		world.setBlock(i + 4, j + 3, k + 11, PlaceCrackedDeepslateTiles, 3, 2);
		world.setBlock(i + 5, j + 3, k + 11, Blocks.air, 0, 2);
		world.setBlock(i + 6, j + 3, k + 11, Blocks.air, 0, 2);
		world.setBlock(i + 7, j + 3, k + 11, NovaCraftBlocks.sculk_block, 0, 2);
		world.setBlock(i + 8, j + 3, k + 11, Blocks.air, 0, 2);
		world.setBlock(i + 9, j + 3, k + 11, Blocks.air, 0, 2);
		world.setBlock(i, j + 3, k + 12, Blocks.air, 0, 2);
		world.setBlock(i + 1, j + 3, k + 12, Blocks.air, 0, 2);
		world.setBlock(i + 2, j + 3, k + 12, Blocks.air, 0, 2);
		world.setBlock(i + 3, j + 3, k + 12, Blocks.air, 0, 2);
		world.setBlock(i + 4, j + 3, k + 12, PlaceCrackedDeepslateBricks, 1, 2);
		world.setBlock(i + 5, j + 3, k + 12, Blocks.air, 0, 2);
		world.setBlock(i + 6, j + 3, k + 12, Blocks.air, 0, 2);
		world.setBlock(i + 7, j + 3, k + 12, Blocks.air, 0, 2);
		world.setBlock(i + 8, j + 3, k + 12, Blocks.air, 0, 2);
		world.setBlock(i + 9, j + 3, k + 12, Blocks.air, 0, 2);
		world.setBlock(i, j + 3, k + 13, Blocks.air, 0, 2);
		world.setBlock(i + 1, j + 3, k + 13, PlacePolishedDeepslate, 0, 2);
		world.setBlock(i + 2, j + 3, k + 13, Blocks.air, 0, 2);
		world.setBlock(i + 3, j + 3, k + 13, Blocks.air, 0, 2);
		world.setBlock(i + 4, j + 3, k + 13, PlaceCrackedDeepslateBricks, 1, 2);
		world.setBlock(i + 5, j + 3, k + 13, Blocks.air, 0, 2);
		world.setBlock(i + 6, j + 3, k + 13, Blocks.air, 0, 2);
		world.setBlock(i + 7, j + 3, k + 13, PlacePolishedDeepslate, 0, 2);
		world.setBlock(i + 8, j + 3, k + 13, Blocks.air, 0, 2);
		world.setBlock(i + 9, j + 3, k + 13, Blocks.air, 0, 2);
		world.setBlock(i, j + 3, k + 14, Blocks.air, 0, 2);
		world.setBlock(i + 1, j + 3, k + 14, Blocks.air, 0, 2);
		world.setBlock(i + 2, j + 3, k + 14, Blocks.air, 0, 2);
		world.setBlock(i + 3, j + 3, k + 14, Blocks.air, 0, 2);
		world.setBlock(i + 4, j + 3, k + 14, PlaceDeepslateBricks, 0, 2);
		world.setBlock(i + 5, j + 3, k + 14, Blocks.air, 0, 2);
		world.setBlock(i + 6, j + 3, k + 14, Blocks.air, 0, 2);
		world.setBlock(i + 7, j + 3, k + 14, Blocks.air, 0, 2);
		world.setBlock(i + 8, j + 3, k + 14, Blocks.air, 0, 2);
		world.setBlock(i + 9, j + 3, k + 14, Blocks.air, 0, 2);
		world.setBlock(i, j + 3, k + 15, Blocks.air, 0, 2);
		world.setBlock(i + 1, j + 3, k + 15, Blocks.air, 0, 2);
		world.setBlock(i + 2, j + 3, k + 15, Blocks.air, 0, 2);
		world.setBlock(i + 3, j + 3, k + 15, Blocks.air, 0, 2);
		world.setBlock(i + 4, j + 3, k + 15, PlaceDeepslateTiles, 2, 2);
		world.setBlock(i + 5, j + 3, k + 15, Blocks.air, 0, 2);
		world.setBlock(i + 6, j + 3, k + 15, Blocks.air, 0, 2);
		world.setBlock(i + 7, j + 3, k + 15, Blocks.air, 0, 2);
		world.setBlock(i + 8, j + 3, k + 15, Blocks.air, 0, 2);
		world.setBlock(i + 9, j + 3, k + 15, Blocks.air, 0, 2);
		world.setBlock(i, j + 3, k + 16, Blocks.air, 0, 2);
		world.setBlock(i + 1, j + 3, k + 16, Blocks.air, 0, 2);
		world.setBlock(i + 2, j + 3, k + 16, Blocks.air, 0, 2);
		world.setBlock(i + 3, j + 3, k + 16, Blocks.air, 0, 2);
		world.setBlock(i + 4, j + 3, k + 16, PlacePolishedDeepslate, 0, 2);
		world.setBlock(i + 5, j + 3, k + 16, Blocks.air, 0, 2);
		world.setBlock(i + 6, j + 3, k + 16, Blocks.air, 0, 2);
		world.setBlock(i + 7, j + 3, k + 16, Blocks.air, 0, 2);
		world.setBlock(i + 8, j + 3, k + 16, Blocks.air, 0, 2);
		world.setBlock(i + 9, j + 3, k + 16, Blocks.air, 0, 2);
		world.setBlock(i, j + 3, k + 17, Blocks.air, 0, 2);
		world.setBlock(i + 1, j + 3, k + 17, Blocks.air, 0, 2);
		world.setBlock(i + 2, j + 3, k + 17, Blocks.air, 0, 2);
		world.setBlock(i + 3, j + 3, k + 17, Blocks.air, 0, 2);
		world.setBlock(i + 4, j + 3, k + 17, PlaceDeepslateTiles, 2, 2);
		world.setBlock(i + 5, j + 3, k + 17, Blocks.air, 0, 2);
		world.setBlock(i + 6, j + 3, k + 17, Blocks.air, 0, 2);
		world.setBlock(i + 7, j + 3, k + 17, Blocks.air, 0, 2);
		world.setBlock(i + 8, j + 3, k + 17, Blocks.air, 0, 2);
		world.setBlock(i + 9, j + 3, k + 17, Blocks.air, 0, 2);
		world.setBlock(i, j + 3, k + 18, Blocks.air, 0, 2);
		world.setBlock(i + 1, j + 3, k + 18, Blocks.air, 0, 2);
		world.setBlock(i + 2, j + 3, k + 18, Blocks.air, 0, 2);
		world.setBlock(i + 3, j + 3, k + 18, Blocks.air, 0, 2);
		world.setBlock(i + 4, j + 3, k + 18, NovaCraftBlocks.sculk_block, 0, 2);
		world.setBlock(i + 5, j + 3, k + 18, Blocks.air, 0, 2);
		world.setBlock(i + 6, j + 3, k + 18, Blocks.air, 0, 2);
		world.setBlock(i + 7, j + 3, k + 18, Blocks.air, 0, 2);
		world.setBlock(i + 8, j + 3, k + 18, Blocks.air, 0, 2);
		world.setBlock(i + 9, j + 3, k + 18, Blocks.air, 0, 2);
		world.setBlock(i, j + 3, k + 19, Blocks.air, 0, 2);
		world.setBlock(i + 1, j + 3, k + 19, PlacePolishedDeepslate, 0, 2);
		world.setBlock(i + 2, j + 3, k + 19, Blocks.air, 0, 2);
		world.setBlock(i + 3, j + 3, k + 19, Blocks.air, 0, 2);
		world.setBlock(i + 4, j + 3, k + 19, PlaceDeepslateBricks, 0, 2);
		world.setBlock(i + 5, j + 3, k + 19, Blocks.air, 0, 2);
		world.setBlock(i + 6, j + 3, k + 19, Blocks.air, 0, 2);
		world.setBlock(i + 7, j + 3, k + 19, PlacePolishedDeepslate, 0, 2);
		world.setBlock(i + 8, j + 3, k + 19, Blocks.air, 0, 2);
		world.setBlock(i + 9, j + 3, k + 19, Blocks.air, 0, 2);
		world.setBlock(i, j + 3, k + 20, Blocks.air, 0, 2);
		world.setBlock(i + 1, j + 3, k + 20, Blocks.air, 0, 2);
		world.setBlock(i + 2, j + 3, k + 20, Blocks.air, 0, 2);
		world.setBlock(i + 3, j + 3, k + 20, Blocks.air, 0, 2);
		world.setBlock(i + 4, j + 3, k + 20, PlaceDeepslateBricks, 0, 2);
		world.setBlock(i + 5, j + 3, k + 20, Blocks.air, 0, 2);
		world.setBlock(i + 6, j + 3, k + 20, Blocks.air, 0, 2);
		world.setBlock(i + 7, j + 3, k + 20, Blocks.air, 0, 2);
		world.setBlock(i + 8, j + 3, k + 20, Blocks.air, 0, 2);
		world.setBlock(i + 9, j + 3, k + 20, Blocks.air, 0, 2);
		world.setBlock(i, j + 3, k + 21, Blocks.air, 0, 2);
		world.setBlock(i + 1, j + 3, k + 21, Blocks.air, 0, 2);
		world.setBlock(i + 2, j + 3, k + 21, Blocks.air, 0, 2);
		world.setBlock(i + 3, j + 3, k + 21, Blocks.air, 0, 2);
		world.setBlock(i + 4, j + 3, k + 21, PlaceDeepslateTiles, 2, 2);
		world.setBlock(i + 5, j + 3, k + 21, Blocks.air, 0, 2);
		world.setBlock(i + 6, j + 3, k + 21, Blocks.air, 0, 2);
		world.setBlock(i + 7, j + 3, k + 21, NovaCraftBlocks.sculk_block, 0, 2);
		world.setBlock(i + 8, j + 3, k + 21, Blocks.air, 0, 2);
		world.setBlock(i + 9, j + 3, k + 21, Blocks.air, 0, 2);
		world.setBlock(i, j + 3, k + 22, Blocks.air, 0, 2);
		world.setBlock(i + 1, j + 3, k + 22, Blocks.air, 0, 2);
		world.setBlock(i + 2, j + 3, k + 22, Blocks.air, 0, 2);
		world.setBlock(i + 3, j + 3, k + 22, Blocks.air, 0, 2);
		world.setBlock(i + 4, j + 3, k + 22, PlacePolishedDeepslate, 0, 2);
		world.setBlock(i + 5, j + 3, k + 22, Blocks.air, 0, 2);
		world.setBlock(i + 6, j + 3, k + 22, Blocks.air, 0, 2);
		world.setBlock(i + 7, j + 3, k + 22, Blocks.air, 0, 2);
		world.setBlock(i + 8, j + 3, k + 22, Blocks.air, 0, 2);
		world.setBlock(i + 9, j + 3, k + 22, Blocks.air, 0, 2);
		world.setBlock(i, j + 3, k + 23, Blocks.air, 0, 2);
		world.setBlock(i + 1, j + 3, k + 23, Blocks.air, 0, 2);
		world.setBlock(i + 2, j + 3, k + 23, Blocks.air, 0, 2);
		world.setBlock(i + 3, j + 3, k + 23, Blocks.air, 0, 2);
		world.setBlock(i + 4, j + 3, k + 23, PlaceDeepslateTiles, 2, 2);
		world.setBlock(i + 5, j + 3, k + 23, Blocks.air, 0, 2);
		world.setBlock(i + 6, j + 3, k + 23, Blocks.air, 0, 2);
		world.setBlock(i + 7, j + 3, k + 23, Blocks.air, 0, 2);
		world.setBlock(i + 8, j + 3, k + 23, Blocks.air, 0, 2);
		world.setBlock(i + 9, j + 3, k + 23, Blocks.air, 0, 2);
		world.setBlock(i, j + 3, k + 24, Blocks.air, 0, 2);
		world.setBlock(i + 1, j + 3, k + 24, Blocks.air, 0, 2);
		world.setBlock(i + 2, j + 3, k + 24, Blocks.air, 0, 2);
		world.setBlock(i + 3, j + 3, k + 24, Blocks.air, 0, 2);
		world.setBlock(i + 4, j + 3, k + 24, PlaceDeepslateTiles, 2, 2);
		world.setBlock(i + 5, j + 3, k + 24, Blocks.air, 0, 2);
		world.setBlock(i + 6, j + 3, k + 24, Blocks.air, 0, 2);
		world.setBlock(i + 7, j + 3, k + 24, Blocks.air, 0, 2);
		world.setBlock(i + 8, j + 3, k + 24, Blocks.air, 0, 2);
		world.setBlock(i + 9, j + 3, k + 24, Blocks.air, 0, 2);
		world.setBlock(i, j + 3, k + 25, Blocks.air, 0, 2);
		world.setBlock(i + 1, j + 3, k + 25, Blocks.air, 0, 2);
		world.setBlock(i + 2, j + 3, k + 25, Blocks.air, 0, 2);
		world.setBlock(i + 3, j + 3, k + 25, Blocks.air, 0, 2);
		world.setBlock(i + 4, j + 3, k + 25, PlacePolishedDeepslate, 0, 2);
		world.setBlock(i + 5, j + 3, k + 25, Blocks.air, 0, 2);
		world.setBlock(i + 6, j + 3, k + 25, Blocks.air, 0, 2);
		world.setBlock(i + 7, j + 3, k + 25, Blocks.air, 0, 2);
		world.setBlock(i + 8, j + 3, k + 25, Blocks.air, 0, 2);
		world.setBlock(i + 9, j + 3, k + 25, Blocks.air, 0, 2);
		world.setBlock(i, j + 3, k + 26, Blocks.air, 0, 2);
		world.setBlock(i + 1, j + 3, k + 26, Blocks.air, 0, 2);
		world.setBlock(i + 2, j + 3, k + 26, Blocks.air, 0, 2);
		world.setBlock(i + 3, j + 3, k + 26, Blocks.air, 0, 2);
		world.setBlock(i + 4, j + 3, k + 26, PlaceDeepslateTiles, 2, 2);
		world.setBlock(i + 5, j + 3, k + 26, Blocks.air, 0, 2);
		world.setBlock(i + 6, j + 3, k + 26, Blocks.air, 0, 2);
		world.setBlock(i + 7, j + 3, k + 26, Blocks.air, 0, 2);
		world.setBlock(i + 8, j + 3, k + 26, Blocks.air, 0, 2);
		world.setBlock(i + 9, j + 3, k + 26, Blocks.air, 0, 2);
		world.setBlock(i, j + 3, k + 27, Blocks.air, 0, 2);
		world.setBlock(i + 1, j + 3, k + 27, Blocks.air, 0, 2);
		world.setBlock(i + 2, j + 3, k + 27, Blocks.air, 0, 2);
		world.setBlock(i + 3, j + 3, k + 27, Blocks.air, 0, 2);
		world.setBlock(i + 4, j + 3, k + 27, Blocks.air, 0, 2);
		world.setBlock(i + 5, j + 3, k + 27, Blocks.air, 0, 2);
		world.setBlock(i + 6, j + 3, k + 27, Blocks.air, 0, 2);
		world.setBlock(i + 7, j + 3, k + 27, Blocks.air, 0, 2);
		world.setBlock(i + 8, j + 3, k + 27, Blocks.air, 0, 2);
		world.setBlock(i + 9, j + 3, k + 27, Blocks.air, 0, 2);
		world.setBlock(i, j + 3, k + 28, Blocks.air, 0, 2);
		world.setBlock(i + 1, j + 3, k + 28, PlacePolishedDeepslate, 0, 2);
		world.setBlock(i + 2, j + 3, k + 28, Blocks.air, 0, 2);
		world.setBlock(i + 3, j + 3, k + 28, Blocks.air, 0, 2);
		world.setBlock(i + 4, j + 3, k + 28, Blocks.air, 0, 2);
		world.setBlock(i + 5, j + 3, k + 28, Blocks.air, 0, 2);
		world.setBlock(i + 6, j + 3, k + 28, Blocks.air, 0, 2);
		world.setBlock(i + 7, j + 3, k + 28, PlacePolishedDeepslate, 0, 2);
		world.setBlock(i + 8, j + 3, k + 28, Blocks.air, 0, 2);
		world.setBlock(i + 9, j + 3, k + 28, Blocks.air, 0, 2);
		world.setBlock(i, j + 3, k + 29, Blocks.air, 0, 2);
		world.setBlock(i + 1, j + 3, k + 29, Blocks.air, 0, 2);
		world.setBlock(i + 2, j + 3, k + 29, Blocks.air, 0, 2);
		world.setBlock(i + 3, j + 3, k + 29, Blocks.air, 0, 2);
		world.setBlock(i + 4, j + 3, k + 29, Blocks.air, 0, 2);
		world.setBlock(i + 5, j + 3, k + 29, Blocks.air, 0, 2);
		world.setBlock(i + 6, j + 3, k + 29, Blocks.air, 0, 2);
		world.setBlock(i + 7, j + 3, k + 29, Blocks.air, 0, 2);
		world.setBlock(i + 8, j + 3, k + 29, Blocks.air, 0, 2);
		world.setBlock(i + 9, j + 3, k + 29, Blocks.air, 0, 2);
		world.setBlock(i, j + 3, k + 30, Blocks.air, 0, 2);
		world.setBlock(i + 1, j + 3, k + 30, Blocks.air, 0, 2);
		world.setBlock(i + 2, j + 3, k + 30, Blocks.air, 0, 2);
		world.setBlock(i + 3, j + 3, k + 30, Blocks.air, 0, 2);
		world.setBlock(i + 4, j + 3, k + 30, Blocks.air, 0, 2);
		world.setBlock(i + 5, j + 3, k + 30, Blocks.air, 0, 2);
		world.setBlock(i + 6, j + 3, k + 30, Blocks.air, 0, 2);
		world.setBlock(i + 7, j + 3, k + 30, Blocks.air, 0, 2);
		world.setBlock(i + 8, j + 3, k + 30, Blocks.air, 0, 2);
		world.setBlock(i + 9, j + 3, k + 30, Blocks.air, 0, 2);
		world.setBlock(i, j + 3, k + 31, Blocks.air, 0, 2);
		world.setBlock(i + 1, j + 3, k + 31, Blocks.air, 0, 2);
		world.setBlock(i + 2, j + 3, k + 31, Blocks.air, 0, 2);
		world.setBlock(i + 3, j + 3, k + 31, Blocks.air, 0, 2);
		world.setBlock(i + 4, j + 3, k + 31, Blocks.air, 0, 2);
		world.setBlock(i + 5, j + 3, k + 31, Blocks.air, 0, 2);
		world.setBlock(i + 6, j + 3, k + 31, Blocks.air, 0, 2);
		world.setBlock(i + 7, j + 3, k + 31, Blocks.air, 0, 2);
		world.setBlock(i + 8, j + 3, k + 31, Blocks.air, 0, 2);
