package com.NovaCraft.world.ancient_city;

import net.minecraft.tileentity.TileEntity;
import net.minecraft.world.gen.feature.*;
import net.minecraft.block.*;
import net.minecraft.world.*;
import java.util.*;
import com.NovaCraft.Items.NovaCraftItems;
import com.NovaCraft.config.Configs;
import com.NovaCraft.entity.EntityWardling;
import com.NovaCraftBlocks.NovaCraftBlocks;
import net.minecraft.init.*;
import net.minecraft.item.ItemStack;
import net.minecraft.tileentity.TileEntityChest;
import net.minecraft.tileentity.TileEntityMobSpawner;

public class AncientCityWardenAltarNewGen2 extends WorldGenerator {

    public AncientCityWardenAltarNewGen2() {

    }

    public boolean generate(final World world, final Random random, final int i, final int j, final int k) {

        world.setBlock(i + 31, j + 9, k + 5, placeStoneBricks(random), 0, 2);
        world.setBlock(i + 32, j + 9, k + 5, NovaCraftBlocks.nullstone_bricks, 0, 2);
        world.setBlock(i + 33, j + 9, k + 5, NovaCraftBlocks.nullstone_bricks, 0, 2);
        world.setBlock(i + 34, j + 9, k + 5, NovaCraftBlocks.nullstone_bricks, 0, 2);
        world.setBlock(i + 35, j + 9, k + 5, NovaCraftBlocks.nullstone_bricks, 0, 2);
        world.setBlock(i + 36, j + 9, k + 5, NovaCraftBlocks.nullstone_bricks, 0, 2);
        world.setBlock(i + 37, j + 9, k + 5, NovaCraftBlocks.nullstone_bricks, 0, 2);
        world.setBlock(i + 38, j + 9, k + 5, NovaCraftBlocks.nullstone_bricks, 0, 2);
        world.setBlock(i + 39, j + 9, k + 5, placeStoneBricks(random), 0, 2);
        world.setBlock(i + 40, j + 9, k + 5, NovaCraftBlocks.carved_vanite_bricks, 0, 2);
        world.setBlock(i + 30, j + 9, k + 6, NovaCraftBlocks.carved_vanite_bricks, 0, 2);
        world.setBlock(i + 31, j + 9, k + 6, placeStoneBricks(random), 0, 2);
        world.setBlock(i + 32, j + 9, k + 6, NovaCraftBlocks.sculk_block, 0, 2);
        world.setBlock(i + 33, j + 9, k + 6, NovaCraftBlocks.nullstone_bricks, 0, 2);
        world.setBlock(i + 34, j + 9, k + 6, NovaCraftBlocks.nullstone_bricks, 0, 2);
        world.setBlock(i + 35, j + 9, k + 6, NovaCraftBlocks.nullstone_bricks, 0, 2);
        world.setBlock(i + 36, j + 9, k + 6, NovaCraftBlocks.nullstone_bricks, 0, 2);
        world.setBlock(i + 37, j + 9, k + 6, NovaCraftBlocks.nullstone_bricks, 0, 2);
        world.setBlock(i + 38, j + 9, k + 6, NovaCraftBlocks.sculk_block, 0, 2);
        world.setBlock(i + 39, j + 9, k + 6, NovaCraftBlocks.sculk_block, 0, 2);
        world.setBlock(i + 40, j + 9, k + 6, NovaCraftBlocks.carved_vanite_bricks, 0, 2);
        world.setBlock(i + 30, j + 9, k + 7, NovaCraftBlocks.carved_vanite_bricks, 0, 2);
        world.setBlock(i + 31, j + 9, k + 7, NovaCraftBlocks.carved_vanite_bricks, 0, 2);
        world.setBlock(i + 32, j + 9, k + 7, placeStoneBricks(random), 0, 2);
        world.setBlock(i + 33, j + 9, k + 7, placeStoneBricks(random), 0, 2);
        world.setBlock(i + 34, j + 9, k + 7, NovaCraftBlocks.sculk_block, 0, 2);
        world.setBlock(i + 35, j + 9, k + 7, placeStoneBricks(random), 0, 2);
        world.setBlock(i + 36, j + 9, k + 7, placeStoneBricks(random), 0, 2);
        world.setBlock(i + 37, j + 9, k + 7, placeStoneBricks(random), 0, 2);
        world.setBlock(i + 38, j + 9, k + 7, placeStoneBricks(random), 0, 2);
        world.setBlock(i + 39, j + 9, k + 7, NovaCraftBlocks.carved_vanite_bricks, 0, 2);
        world.setBlock(i + 40, j + 9, k + 7, NovaCraftBlocks.carved_vanite_bricks, 0, 2);
        world.setBlock(i + 31, j + 9, k + 8, NovaCraftBlocks.carved_vanite_bricks, 0, 2);
        world.setBlock(i + 32, j + 9, k + 8, NovaCraftBlocks.carved_vanite_bricks, 0, 2);
        world.setBlock(i + 33, j + 9, k + 8, NovaCraftBlocks.carved_vanite_bricks, 0, 2);
        world.setBlock(i + 34, j + 9, k + 8, placeStoneBricks(random), 0, 2);
        world.setBlock(i + 35, j + 9, k + 8, NovaCraftBlocks.sculk_block, 0, 2);
        world.setBlock(i + 36, j + 9, k + 8, placeStoneBricks(random), 0, 2);
        world.setBlock(i + 37, j + 9, k + 8, NovaCraftBlocks.carved_vanite_bricks, 0, 2);
        world.setBlock(i + 38, j + 9, k + 8, NovaCraftBlocks.carved_vanite_bricks, 0, 2);
        world.setBlock(i + 39, j + 9, k + 8, NovaCraftBlocks.carved_vanite_bricks, 0, 2);
        world.setBlock(i + 33, j + 9, k + 9, NovaCraftBlocks.carved_vanite_bricks, 0, 2);
        world.setBlock(i + 34, j + 9, k + 9, NovaCraftBlocks.nullstone_brick_stairs, 3, 2);
        world.setBlock(i + 35, j + 9, k + 9, NovaCraftBlocks.nullstone_brick_stairs, 3, 2);
        world.setBlock(i + 36, j + 9, k + 9, NovaCraftBlocks.nullstone_brick_stairs, 3, 2);
        world.setBlock(i + 37, j + 9, k + 9, NovaCraftBlocks.carved_vanite_bricks, 0, 2);
        world.setBlock(i + 33, j + 9, k + 10, NovaCraftBlocks.nullstone_brick_wall, 0, 2);
        world.setBlock(i + 37, j + 9, k + 10, NovaCraftBlocks.nullstone_brick_wall, 0, 2);
        world.setBlock(i + 33, j + 9, k + 11, NovaCraftBlocks.nullstone_brick_wall, 0, 2);
        world.setBlock(i + 37, j + 9, k + 11, NovaCraftBlocks.nullstone_brick_wall, 0, 2);
        world.setBlock(i + 33, j + 9, k + 12, NovaCraftBlocks.nullstone_brick_wall, 0, 2);
        world.setBlock(i + 37, j + 9, k + 12, NovaCraftBlocks.nullstone_brick_wall, 0, 2);
        world.setBlock(i + 27, j + 9, k + 19, placeStoneBricks(random), 0, 2);
        world.setBlock(i + 28, j + 9, k + 19, placeStoneBricks(random), 0, 2);
        world.setBlock(i + 42, j + 9, k + 19, placeStoneBricks(random), 0, 2);
        world.setBlock(i + 43, j + 9, k + 19, NovaCraftBlocks.sculk_block, 0, 2);
        world.setBlock(i + 27, j + 9, k + 20, NovaCraftBlocks.sculk_block, 0, 2);
        world.setBlock(i + 28, j + 9, k + 20, placeStoneBricks(random), 0, 2);
        world.setBlock(i + 42, j + 9, k + 20, placeStoneBricks(random), 0, 2);
        world.setBlock(i + 43, j + 9, k + 20, placeStoneBricks(random), 0, 2);
        world.setBlock(i + 3, j + 9, k + 21, NovaCraftBlocks.carved_vanite_bricks, 0, 2);
        world.setBlock(i + 4, j + 9, k + 21, NovaCraftBlocks.carved_vanite_bricks, 0, 2);
        world.setBlock(i + 5, j + 9, k + 21, NovaCraftBlocks.carved_vanite_bricks, 0, 2);
        world.setBlock(i + 6, j + 9, k + 21, NovaCraftBlocks.carved_vanite_bricks, 0, 2);
        world.setBlock(i + 7, j + 9, k + 21, NovaCraftBlocks.carved_vanite_bricks, 0, 2);
        world.setBlock(i + 8, j + 9, k + 21, NovaCraftBlocks.carved_vanite_bricks, 0, 2);
        world.setBlock(i + 9, j + 9, k + 21, NovaCraftBlocks.carved_vanite_bricks, 0, 2);
        world.setBlock(i + 10, j + 9, k + 21, NovaCraftBlocks.carved_vanite_bricks, 0, 2);
        world.setBlock(i + 11, j + 9, k + 21, NovaCraftBlocks.carved_vanite_bricks, 0, 2);
        world.setBlock(i + 2, j + 9, k + 22, NovaCraftBlocks.carved_vanite_bricks, 0, 2);
        world.setBlock(i + 3, j + 9, k + 22, placeStoneBricks(random), 0, 2);
        world.setBlock(i + 4, j + 9, k + 22, placeStoneBricks(random), 0, 2);
        world.setBlock(i + 5, j + 9, k + 22, placeStoneBricks(random), 0, 2);
        world.setBlock(i + 6, j + 9, k + 22, NovaCraftBlocks.nullstone_bricks, 0, 2);
        world.setBlock(i + 7, j + 9, k + 22, placeStoneBricks(random), 0, 2);
        world.setBlock(i + 8, j + 9, k + 22, NovaCraftBlocks.nullstone_bricks, 0, 2);
        world.setBlock(i + 9, j + 9, k + 22, placeStoneBricks(random), 0, 2);
        world.setBlock(i + 10, j + 9, k + 22, NovaCraftBlocks.nullstone_bricks, 0, 2);
        world.setBlock(i + 11, j + 9, k + 22, placeStoneBricks(random), 0, 2);
        world.setBlock(i + 12, j + 9, k + 22, NovaCraftBlocks.carved_vanite_bricks, 0, 2);
        world.setBlock(i + 1, j + 9, k + 23, NovaCraftBlocks.carved_vanite_bricks, 0, 2);
        world.setBlock(i + 2, j + 9, k + 23, placeStoneBricks(random), 0, 2);
        world.setBlock(i + 3, j + 9, k + 23, placeStoneBricks(random), 0, 2);
        world.setBlock(i + 4, j + 9, k + 23, placeStoneBricks(random), 0, 2);
        world.setBlock(i + 5, j + 9, k + 23, placeStoneBricks(random), 0, 2);
        world.setBlock(i + 6, j + 9, k + 23, placeStoneBricks(random), 0, 2);
        world.setBlock(i + 7, j + 9, k + 23, placeStoneBricks(random), 0, 2);
        world.setBlock(i + 8, j + 9, k + 23, placeStoneBricks(random), 0, 2);
        world.setBlock(i + 9, j + 9, k + 23, placeStoneBricks(random), 0, 2);
        world.setBlock(i + 10, j + 9, k + 23, placeStoneBricks(random), 0, 2);
        world.setBlock(i + 11, j + 9, k + 23, placeStoneBricks(random), 0, 2);
        world.setBlock(i + 12, j + 9, k + 23, placeStoneBricks(random), 0, 2);
        world.setBlock(i + 13, j + 9, k + 23, NovaCraftBlocks.carved_vanite_bricks, 0, 2);
        world.setBlock(i, j + 9, k + 24, NovaCraftBlocks.carved_vanite_bricks, 0, 2);
        world.setBlock(i + 1, j + 9, k + 24, placeStoneBricks(random), 0, 2);
        world.setBlock(i + 2, j + 9, k + 24, placeStoneBricks(random), 0, 2);
        world.setBlock(i + 3, j + 9, k + 24, placeStoneBricks(random), 0, 2);
        world.setBlock(i + 4, j + 9, k + 24, placeStoneBricks(random), 0, 2);
        world.setBlock(i + 5, j + 9, k + 24, placeStoneBricks(random), 0, 2);
        world.setBlock(i + 6, j + 9, k + 24, NovaCraftBlocks.nullstone_bricks, 0, 2);
        world.setBlock(i + 7, j + 9, k + 24, placeStoneBricks(random), 0, 2);
        world.setBlock(i + 8, j + 9, k + 24, NovaCraftBlocks.nullstone_bricks, 0, 2);
        world.setBlock(i + 9, j + 9, k + 24, placeStoneBricks(random), 0, 2);
        world.setBlock(i + 10, j + 9, k + 24, NovaCraftBlocks.nullstone_bricks, 0, 2);
        world.setBlock(i + 11, j + 9, k + 24, placeStoneBricks(random), 0, 2);
        world.setBlock(i + 12, j + 9, k + 24, NovaCraftBlocks.nullstone_bricks, 0, 2);
        world.setBlock(i + 13, j + 9, k + 24, placeStoneBricks(random), 0, 2);
        world.setBlock(i + 14, j + 9, k + 24, NovaCraftBlocks.carved_vanite_bricks, 0, 2);
        world.setBlock(i + 31, j + 9, k + 24, NovaCraftBlocks.nullstone_bricks, 0, 2);
        world.setBlock(i + 39, j + 9, k + 24, NovaCraftBlocks.nullstone_bricks, 0, 2);
        world.setBlock(i, j + 9, k + 25, NovaCraftBlocks.carved_vanite_bricks, 0, 2);
        world.setBlock(i + 1, j + 9, k + 25, placeStoneBricks(random), 0, 2);
        world.setBlock(i + 2, j + 9, k + 25, placeStoneBricks(random), 0, 2);
        world.setBlock(i + 3, j + 9, k + 25, placeStoneBricks(random), 0, 2);
        world.setBlock(i + 4, j + 9, k + 25, NovaCraftBlocks.sculk_block, 0, 2);
        world.setBlock(i + 5, j + 9, k + 25, NovaCraftBlocks.sculk_block, 0, 2);
        world.setBlock(i + 6, j + 9, k + 25, NovaCraftBlocks.nullstone_bricks, 0, 2);
        world.setBlock(i + 7, j + 9, k + 25, placeStoneBricks(random), 0, 2);
        world.setBlock(i + 8, j + 9, k + 25, NovaCraftBlocks.nullstone_bricks, 0, 2);
        world.setBlock(i + 9, j + 9, k + 25, placeStoneBricks(random), 0, 2);
        world.setBlock(i + 10, j + 9, k + 25, NovaCraftBlocks.nullstone_bricks, 0, 2);
        world.setBlock(i + 11, j + 9, k + 25, placeStoneBricks(random), 0, 2);
        world.setBlock(i + 12, j + 9, k + 25, NovaCraftBlocks.nullstone_bricks, 0, 2);
        world.setBlock(i + 13, j + 9, k + 25, placeStoneBricks(random), 0, 2);
        world.setBlock(i + 14, j + 9, k + 25, NovaCraftBlocks.carved_vanite_bricks, 0, 2);
        world.setBlock(i, j + 9, k + 26, NovaCraftBlocks.carved_vanite_bricks, 0, 2);
        world.setBlock(i + 1, j + 9, k + 26, placeStoneBricks(random), 0, 2);
        world.setBlock(i + 2, j + 9, k + 26, placeStoneBricks(random), 0, 2);
        world.setBlock(i + 3, j + 9, k + 26, placeStoneBricks(random), 0, 2);
        world.setBlock(i + 4, j + 9, k + 26, placeStoneBricks(random), 0, 2);
        world.setBlock(i + 5, j + 9, k + 26, placeStoneBricks(random), 0, 2);
        world.setBlock(i + 6, j + 9, k + 26, placeStoneBricks(random), 0, 2);
        world.setBlock(i + 7, j + 9, k + 26, placeStoneBricks(random), 0, 2);
        world.setBlock(i + 8, j + 9, k + 26, placeStoneBricks(random), 0, 2);
        world.setBlock(i + 9, j + 9, k + 26, placeStoneBricks(random), 0, 2);
        world.setBlock(i + 10, j + 9, k + 26, placeStoneBricks(random), 0, 2);
        world.setBlock(i + 11, j + 9, k + 26, NovaCraftBlocks.sculk_block, 0, 2);
        world.setBlock(i + 12, j + 9, k + 26, NovaCraftBlocks.sculk_block, 0, 2);
        world.setBlock(i + 13, j + 9, k + 26, placeStoneBricks(random), 0, 2);
        world.setBlock(i + 14, j + 9, k + 26, NovaCraftBlocks.carved_vanite_bricks, 0, 2);
        world.setBlock(i + 15, j + 9, k + 26, NovaCraftBlocks.carved_vanite_bricks, 0, 2);
        world.setBlock(i + 16, j + 9, k + 26, NovaCraftBlocks.carved_vanite_bricks, 0, 2);
        world.setBlock(i + 17, j + 9, k + 26, NovaCraftBlocks.nullstone_brick_wall, 0, 2);
        world.setBlock(i + 18, j + 9, k + 26, NovaCraftBlocks.nullstone_brick_wall, 0, 2);
        world.setBlock(i + 19, j + 9, k + 26, NovaCraftBlocks.nullstone_brick_wall, 0, 2);
        world.setBlock(i + 33, j + 9, k + 26, NovaCraftBlocks.sculk_bricks, 0, 2);
        world.setBlock(i + 37, j + 9, k + 26, NovaCraftBlocks.sculk_bricks, 0, 2);
        world.setBlock(i, j + 9, k + 27, NovaCraftBlocks.carved_vanite_bricks, 0, 2);
        world.setBlock(i + 1, j + 9, k + 27, placeStoneBricks(random), 0, 2);
        world.setBlock(i + 2, j + 9, k + 27, placeStoneBricks(random), 0, 2);
        world.setBlock(i + 3, j + 9, k + 27, placeStoneBricks(random), 0, 2);
        world.setBlock(i + 4, j + 9, k + 27, NovaCraftBlocks.nullstone_bricks, 0, 2);
        world.setBlock(i + 5, j + 9, k + 27, NovaCraftBlocks.nullstone_bricks, 0, 2);
        world.setBlock(i + 6, j + 9, k + 27, NovaCraftBlocks.nullstone_bricks, 0, 2);
        world.setBlock(i + 7, j + 9, k + 27, NovaCraftBlocks.nullstone_bricks, 0, 2);
        world.setBlock(i + 8, j + 9, k + 27, NovaCraftBlocks.nullstone_bricks, 0, 2);
        world.setBlock(i + 9, j + 9, k + 27, NovaCraftBlocks.nullstone_bricks, 0, 2);
        world.setBlock(i + 10, j + 9, k + 27, NovaCraftBlocks.nullstone_bricks, 0, 2);
        world.setBlock(i + 11, j + 9, k + 27, NovaCraftBlocks.nullstone_bricks, 0, 2);
        world.setBlock(i + 12, j + 9, k + 27, NovaCraftBlocks.nullstone_bricks, 0, 2);
        world.setBlock(i + 13, j + 9, k + 27, NovaCraftBlocks.nullstone_bricks, 0, 2);
        world.setBlock(i + 14, j + 9, k + 27, NovaCraftBlocks.nullstone_bricks, 0, 2);
        world.setBlock(i + 15, j + 9, k + 27, NovaCraftBlocks.sculk_block, 0, 2);
        world.setBlock(i + 16, j + 9, k + 27, NovaCraftBlocks.nullstone_brick_stairs, 1, 2);
        world.setBlock(i, j + 9, k + 28, NovaCraftBlocks.carved_vanite_bricks, 0, 2);
        world.setBlock(i + 1, j + 9, k + 28, placeStoneBricks(random), 0, 2);
        world.setBlock(i + 2, j + 9, k + 28, placeStoneBricks(random), 0, 2);
        world.setBlock(i + 3, j + 9, k + 28, placeStoneBricks(random), 0, 2);
        world.setBlock(i + 4, j + 9, k + 28, NovaCraftBlocks.nullstone_bricks, 0, 2);
        world.setBlock(i + 5, j + 9, k + 28, NovaCraftBlocks.nullstone_bricks, 0, 2);
        world.setBlock(i + 6, j + 9, k + 28, NovaCraftBlocks.nullstone_bricks, 0, 2);
        world.setBlock(i + 7, j + 9, k + 28, NovaCraftBlocks.nullstone_bricks, 0, 2);
        world.setBlock(i + 8, j + 9, k + 28, NovaCraftBlocks.nullstone_bricks, 0, 2);
        world.setBlock(i + 9, j + 9, k + 28, NovaCraftBlocks.nullstone_bricks, 0, 2);
        world.setBlock(i + 10, j + 9, k + 28, NovaCraftBlocks.nullstone_bricks, 0, 2);
        world.setBlock(i + 11, j + 9, k + 28, NovaCraftBlocks.nullstone_bricks, 0, 2);
        world.setBlock(i + 12, j + 9, k + 28, NovaCraftBlocks.nullstone_bricks, 0, 2);
        world.setBlock(i + 13, j + 9, k + 28, NovaCraftBlocks.nullstone_bricks, 0, 2);
        world.setBlock(i + 14, j + 9, k + 28, NovaCraftBlocks.nullstone_bricks, 0, 2);
        world.setBlock(i + 15, j + 9, k + 28, placeStoneBricks(random), 0, 2);
        world.setBlock(i + 16, j + 9, k + 28, NovaCraftBlocks.nullstone_brick_stairs, 1, 2);
        world.setBlock(i, j + 9, k + 29, NovaCraftBlocks.carved_vanite_bricks, 0, 2);
        world.setBlock(i + 1, j + 9, k + 29, placeStoneBricks(random), 0, 2);
        world.setBlock(i + 2, j + 9, k + 29, placeStoneBricks(random), 0, 2);
        world.setBlock(i + 3, j + 9, k + 29, placeStoneBricks(random), 0, 2);
        world.setBlock(i + 4, j + 9, k + 29, NovaCraftBlocks.nullstone_bricks, 0, 2);
        world.setBlock(i + 5, j + 9, k + 29, NovaCraftBlocks.nullstone_bricks, 0, 2);
        world.setBlock(i + 6, j + 9, k + 29, NovaCraftBlocks.nullstone_bricks, 0, 2);
        world.setBlock(i + 7, j + 9, k + 29, NovaCraftBlocks.nullstone_bricks, 0, 2);
        world.setBlock(i + 8, j + 9, k + 29, NovaCraftBlocks.nullstone_bricks, 0, 2);
        world.setBlock(i + 9, j + 9, k + 29, NovaCraftBlocks.nullstone_bricks, 0, 2);
        world.setBlock(i + 10, j + 9, k + 29, NovaCraftBlocks.nullstone_bricks, 0, 2);
        world.setBlock(i + 11, j + 9, k + 29, NovaCraftBlocks.nullstone_bricks, 0, 2);
        world.setBlock(i + 12, j + 9, k + 29, NovaCraftBlocks.nullstone_bricks, 0, 2);
        world.setBlock(i + 13, j + 9, k + 29, NovaCraftBlocks.nullstone_bricks, 0, 2);
        world.setBlock(i + 14, j + 9, k + 29, NovaCraftBlocks.nullstone_bricks, 0, 2);
        world.setBlock(i + 15, j + 9, k + 29, placeStoneBricks(random), 0, 2);
        world.setBlock(i + 16, j + 9, k + 29, NovaCraftBlocks.nullstone_brick_stairs, 1, 2);
        world.setBlock(i, j + 9, k + 30, NovaCraftBlocks.carved_vanite_bricks, 0, 2);
        world.setBlock(i + 1, j + 9, k + 30, placeStoneBricks(random), 0, 2);
        world.setBlock(i + 2, j + 9, k + 30, placeStoneBricks(random), 0, 2);
        world.setBlock(i + 3, j + 9, k + 30, placeStoneBricks(random), 0, 2);
        world.setBlock(i + 4, j + 9, k + 30, placeStoneBricks(random), 0, 2);
        world.setBlock(i + 5, j + 9, k + 30, placeStoneBricks(random), 0, 2);
        world.setBlock(i + 6, j + 9, k + 30, placeStoneBricks(random), 0, 2);
        world.setBlock(i + 7, j + 9, k + 30, placeStoneBricks(random), 0, 2);
        world.setBlock(i + 8, j + 9, k + 30, NovaCraftBlocks.sculk_block, 0, 2);
        world.setBlock(i + 9, j + 9, k + 30, placeStoneBricks(random), 0, 2);
        world.setBlock(i + 10, j + 9, k + 30, placeStoneBricks(random), 0, 2);
        world.setBlock(i + 11, j + 9, k + 30, placeStoneBricks(random), 0, 2);
        world.setBlock(i + 12, j + 9, k + 30, placeStoneBricks(random), 0, 2);
        world.setBlock(i + 13, j + 9, k + 30, placeStoneBricks(random), 0, 2);
        world.setBlock(i + 14, j + 9, k + 30, NovaCraftBlocks.carved_vanite_bricks, 0, 2);
        world.setBlock(i + 15, j + 9, k + 30, NovaCraftBlocks.carved_vanite_bricks, 0, 2);
        world.setBlock(i + 16, j + 9, k + 30, NovaCraftBlocks.carved_vanite_bricks, 0, 2);
        world.setBlock(i + 17, j + 9, k + 30, NovaCraftBlocks.nullstone_brick_wall, 0, 2);
        world.setBlock(i + 18, j + 9, k + 30, NovaCraftBlocks.nullstone_brick_wall, 0, 2);
        world.setBlock(i + 19, j + 9, k + 30, NovaCraftBlocks.nullstone_brick_wall, 0, 2);
        world.setBlock(i + 33, j + 9, k + 30, NovaCraftBlocks.sculk_bricks, 0, 2);
        world.setBlock(i + 37, j + 9, k + 30, NovaCraftBlocks.sculk_bricks, 0, 2);
        world.setBlock(i, j + 9, k + 31, NovaCraftBlocks.carved_vanite_bricks, 0, 2);
        world.setBlock(i + 1, j + 9, k + 31, placeStoneBricks(random), 0, 2);
        world.setBlock(i + 2, j + 9, k + 31, NovaCraftBlocks.sculk_block, 0, 2);
        world.setBlock(i + 3, j + 9, k + 31, placeStoneBricks(random), 0, 2);
        world.setBlock(i + 4, j + 9, k + 31, placeStoneBricks(random), 0, 2);
        world.setBlock(i + 5, j + 9, k + 31, NovaCraftBlocks.sculk_block, 0, 2);
        world.setBlock(i + 6, j + 9, k + 31, NovaCraftBlocks.nullstone_bricks, 0, 2);
        world.setBlock(i + 7, j + 9, k + 31, placeStoneBricks(random), 0, 2);
        world.setBlock(i + 8, j + 9, k + 31, NovaCraftBlocks.nullstone_bricks, 0, 2);
        world.setBlock(i + 9, j + 9, k + 31, placeStoneBricks(random), 0, 2);
        world.setBlock(i + 10, j + 9, k + 31, NovaCraftBlocks.nullstone_bricks, 0, 2);
        world.setBlock(i + 11, j + 9, k + 31, placeStoneBricks(random), 0, 2);
        world.setBlock(i + 12, j + 9, k + 31, NovaCraftBlocks.nullstone_bricks, 0, 2);
        world.setBlock(i + 13, j + 9, k + 31, placeStoneBricks(random), 0, 2);
        world.setBlock(i + 14, j + 9, k + 31, NovaCraftBlocks.carved_vanite_bricks, 0, 2);
        world.setBlock(i, j + 9, k + 32, NovaCraftBlocks.carved_vanite_bricks, 0, 2);
        world.setBlock(i + 1, j + 9, k + 32, placeStoneBricks(random), 0, 2);
        world.setBlock(i + 2, j + 9, k + 32, placeStoneBricks(random), 0, 2);
        world.setBlock(i + 3, j + 9, k + 32, placeStoneBricks(random), 0, 2);
        world.setBlock(i + 4, j + 9, k + 32, placeStoneBricks(random), 0, 2);
        world.setBlock(i + 5, j + 9, k + 32, placeStoneBricks(random), 0, 2);
        world.setBlock(i + 6, j + 9, k + 32, NovaCraftBlocks.nullstone_bricks, 0, 2);
        world.setBlock(i + 7, j + 9, k + 32, placeStoneBricks(random), 0, 2);
        world.setBlock(i + 8, j + 9, k + 32, NovaCraftBlocks.nullstone_bricks, 0, 2);
        world.setBlock(i + 9, j + 9, k + 32, placeStoneBricks(random), 0, 2);
        world.setBlock(i + 10, j + 9, k + 32, NovaCraftBlocks.nullstone_bricks, 0, 2);
        world.setBlock(i + 11, j + 9, k + 32, placeStoneBricks(random), 0, 2);
        world.setBlock(i + 12, j + 9, k + 32, NovaCraftBlocks.nullstone_bricks, 0, 2);
        world.setBlock(i + 13, j + 9, k + 32, placeStoneBricks(random), 0, 2);
        world.setBlock(i + 14, j + 9, k + 32, NovaCraftBlocks.carved_vanite_bricks, 0, 2);
        world.setBlock(i + 31, j + 9, k + 32, NovaCraftBlocks.nullstone_bricks, 0, 2);
        world.setBlock(i + 39, j + 9, k + 32, NovaCraftBlocks.nullstone_bricks, 0, 2);
        world.setBlock(i + 1, j + 9, k + 33, NovaCraftBlocks.carved_vanite_bricks, 0, 2);
        world.setBlock(i + 2, j + 9, k + 33, placeStoneBricks(random), 0, 2);
        world.setBlock(i + 3, j + 9, k + 33, placeStoneBricks(random), 0, 2);
        world.setBlock(i + 4, j + 9, k + 33, placeStoneBricks(random), 0, 2);
        world.setBlock(i + 5, j + 9, k + 33, placeStoneBricks(random), 0, 2);
        world.setBlock(i + 6, j + 9, k + 33, placeStoneBricks(random), 0, 2);
        world.setBlock(i + 7, j + 9, k + 33, placeStoneBricks(random), 0, 2);
        world.setBlock(i + 8, j + 9, k + 33, placeStoneBricks(random), 0, 2);
        world.setBlock(i + 9, j + 9, k + 33, placeStoneBricks(random), 0, 2);
        world.setBlock(i + 10, j + 9, k + 33, NovaCraftBlocks.sculk_block, 0, 2);
        world.setBlock(i + 11, j + 9, k + 33, placeStoneBricks(random), 0, 2);
        world.setBlock(i + 12, j + 9, k + 33, placeStoneBricks(random), 0, 2);
        world.setBlock(i + 13, j + 9, k + 33, NovaCraftBlocks.carved_vanite_bricks, 0, 2);
        world.setBlock(i + 2, j + 9, k + 34, NovaCraftBlocks.carved_vanite_bricks, 0, 2);
        world.setBlock(i + 3, j + 9, k + 34, placeStoneBricks(random), 0, 2);
        world.setBlock(i + 4, j + 9, k + 34, placeStoneBricks(random), 0, 2);
        world.setBlock(i + 5, j + 9, k + 34, placeStoneBricks(random), 0, 2);
        world.setBlock(i + 6, j + 9, k + 34, NovaCraftBlocks.nullstone_bricks, 0, 2);
        world.setBlock(i + 7, j + 9, k + 34, placeStoneBricks(random), 0, 2);
        world.setBlock(i + 8, j + 9, k + 34, NovaCraftBlocks.nullstone_bricks, 0, 2);
        world.setBlock(i + 9, j + 9, k + 34, placeStoneBricks(random), 0, 2);
        world.setBlock(i + 10, j + 9, k + 34, NovaCraftBlocks.nullstone_bricks, 0, 2);
        world.setBlock(i + 11, j + 9, k + 34, placeStoneBricks(random), 0, 2);
        world.setBlock(i + 12, j + 9, k + 34, NovaCraftBlocks.carved_vanite_bricks, 0, 2);
        world.setBlock(i + 3, j + 9, k + 35, NovaCraftBlocks.carved_vanite_bricks, 0, 2);
        world.setBlock(i + 4, j + 9, k + 35, NovaCraftBlocks.carved_vanite_bricks, 0, 2);
        world.setBlock(i + 5, j + 9, k + 35, NovaCraftBlocks.carved_vanite_bricks, 0, 2);
        world.setBlock(i + 6, j + 9, k + 35, NovaCraftBlocks.carved_vanite_bricks, 0, 2);
        world.setBlock(i + 7, j + 9, k + 35, NovaCraftBlocks.carved_vanite_bricks, 0, 2);
        world.setBlock(i + 8, j + 9, k + 35, NovaCraftBlocks.carved_vanite_bricks, 0, 2);
        world.setBlock(i + 9, j + 9, k + 35, NovaCraftBlocks.carved_vanite_bricks, 0, 2);
        world.setBlock(i + 10, j + 9, k + 35, NovaCraftBlocks.carved_vanite_bricks, 0, 2);
        world.setBlock(i + 11, j + 9, k + 35, NovaCraftBlocks.carved_vanite_bricks, 0, 2);
        world.setBlock(i + 27, j + 9, k + 36, placeStoneBricks(random), 0, 2);
        world.setBlock(i + 28, j + 9, k + 36, placeStoneBricks(random), 0, 2);
        world.setBlock(i + 42, j + 9, k + 36, placeStoneBricks(random), 0, 2);
        world.setBlock(i + 43, j + 9, k + 36, NovaCraftBlocks.sculk_block, 0, 2);
        world.setBlock(i + 27, j + 9, k + 37, placeStoneBricks(random), 0, 2);
        world.setBlock(i + 28, j + 9, k + 37, NovaCraftBlocks.sculk_block, 0, 2);
        world.setBlock(i + 42, j + 9, k + 37, placeStoneBricks(random), 0, 2);
        world.setBlock(i + 43, j + 9, k + 37, placeStoneBricks(random), 0, 2);
        world.setBlock(i + 33, j + 9, k + 43, NovaCraftBlocks.nullstone_brick_wall, 0, 2);
        world.setBlock(i + 37, j + 9, k + 43, NovaCraftBlocks.nullstone_brick_wall, 0, 2);
        world.setBlock(i + 33, j + 9, k + 44, NovaCraftBlocks.nullstone_brick_wall, 0, 2);
        world.setBlock(i + 37, j + 9, k + 44, NovaCraftBlocks.nullstone_brick_wall, 0, 2);
        world.setBlock(i + 33, j + 9, k + 45, NovaCraftBlocks.nullstone_brick_wall, 0, 2);
        world.setBlock(i + 37, j + 9, k + 45, NovaCraftBlocks.nullstone_brick_wall, 0, 2);
        world.setBlock(i + 33, j + 9, k + 46, NovaCraftBlocks.nullstone_brick_wall, 0, 2);
        world.setBlock(i + 37, j + 9, k + 46, NovaCraftBlocks.nullstone_brick_wall, 0, 2);
        world.setBlock(i + 31, j + 9, k + 47, NovaCraftBlocks.carved_vanite_bricks, 0, 2);
        world.setBlock(i + 32, j + 9, k + 47, NovaCraftBlocks.carved_vanite_bricks, 0, 2);
        world.setBlock(i + 33, j + 9, k + 47, NovaCraftBlocks.carved_vanite_bricks, 0, 2);
        world.setBlock(i + 34, j + 9, k + 47, NovaCraftBlocks.nullstone_brick_stairs, 2, 2);
        world.setBlock(i + 35, j + 9, k + 47, NovaCraftBlocks.nullstone_brick_stairs, 2, 2);
        world.setBlock(i + 36, j + 9, k + 47, NovaCraftBlocks.nullstone_brick_stairs, 2, 2);
        world.setBlock(i + 37, j + 9, k + 47, NovaCraftBlocks.carved_vanite_bricks, 0, 2);
        world.setBlock(i + 38, j + 9, k + 47, NovaCraftBlocks.carved_vanite_bricks, 0, 2);
        world.setBlock(i + 39, j + 9, k + 47, NovaCraftBlocks.carved_vanite_bricks, 0, 2);
        world.setBlock(i + 30, j + 9, k + 48, NovaCraftBlocks.carved_vanite_bricks, 0, 2);
        world.setBlock(i + 31, j + 9, k + 48, NovaCraftBlocks.carved_vanite_bricks, 0, 2);
        world.setBlock(i + 32, j + 9, k + 48, placeStoneBricks(random), 0, 2);
        world.setBlock(i + 33, j + 9, k + 48, placeStoneBricks(random), 0, 2);
        world.setBlock(i + 34, j + 9, k + 48, placeStoneBricks(random), 0, 2);
        world.setBlock(i + 35, j + 9, k + 48, placeStoneBricks(random), 0, 2);
        world.setBlock(i + 36, j + 9, k + 48, placeStoneBricks(random), 0, 2);
        world.setBlock(i + 37, j + 9, k + 48, placeStoneBricks(random), 0, 2);
        world.setBlock(i + 38, j + 9, k + 48, placeStoneBricks(random), 0, 2);
        world.setBlock(i + 39, j + 9, k + 48, NovaCraftBlocks.carved_vanite_bricks, 0, 2);
        world.setBlock(i + 40, j + 9, k + 48, NovaCraftBlocks.carved_vanite_bricks, 0, 2);
        world.setBlock(i + 29, j + 9, k + 49, NovaCraftBlocks.carved_vanite_bricks, 0, 2);
        world.setBlock(i + 30, j + 9, k + 49, NovaCraftBlocks.carved_vanite_bricks, 0, 2);
        world.setBlock(i + 31, j + 9, k + 49, placeStoneBricks(random), 0, 2);
        world.setBlock(i + 32, j + 9, k + 49, placeStoneBricks(random), 0, 2);
        world.setBlock(i + 33, j + 9, k + 49, NovaCraftBlocks.nullstone_bricks, 0, 2);
        world.setBlock(i + 34, j + 9, k + 49, NovaCraftBlocks.nullstone_bricks, 0, 2);
        world.setBlock(i + 35, j + 9, k + 49, NovaCraftBlocks.nullstone_bricks, 0, 2);
        world.setBlock(i + 36, j + 9, k + 49, NovaCraftBlocks.nullstone_bricks, 0, 2);
        world.setBlock(i + 37, j + 9, k + 49, NovaCraftBlocks.nullstone_bricks, 0, 2);
        world.setBlock(i + 38, j + 9, k + 49, NovaCraftBlocks.sculk_block, 0, 2);
        world.setBlock(i + 39, j + 9, k + 49, placeStoneBricks(random), 0, 2);
        world.setBlock(i + 40, j + 9, k + 49, NovaCraftBlocks.carved_vanite_bricks, 0, 2);
        world.setBlock(i + 41, j + 9, k + 49, NovaCraftBlocks.carved_vanite_bricks, 0, 2);
        world.setBlock(i + 29, j + 9, k + 50, NovaCraftBlocks.carved_vanite_bricks, 0, 2);
        world.setBlock(i + 30, j + 9, k + 50, placeStoneBricks(random), 0, 2);
        world.setBlock(i + 31, j + 9, k + 50, NovaCraftBlocks.sculk_block, 0, 2);
        world.setBlock(i + 32, j + 9, k + 50, NovaCraftBlocks.nullstone_bricks, 0, 2);
        world.setBlock(i + 33, j + 9, k + 50, NovaCraftBlocks.nullstone_bricks, 0, 2);
        world.setBlock(i + 34, j + 9, k + 50, NovaCraftBlocks.nullstone_bricks, 0, 2);
        world.setBlock(i + 35, j + 9, k + 50, NovaCraftBlocks.nullstone_bricks, 0, 2);
        world.setBlock(i + 36, j + 9, k + 50, NovaCraftBlocks.nullstone_bricks, 0, 2);
        world.setBlock(i + 37, j + 9, k + 50, NovaCraftBlocks.nullstone_bricks, 0, 2);
        world.setBlock(i + 38, j + 9, k + 50, NovaCraftBlocks.nullstone_bricks, 0, 2);
        world.setBlock(i + 39, j + 9, k + 50, placeStoneBricks(random), 0, 2);
        world.setBlock(i + 40, j + 9, k + 50, NovaCraftBlocks.sculk_block, 0, 2);
        world.setBlock(i + 41, j + 9, k + 50, NovaCraftBlocks.carved_vanite_bricks, 0, 2);
        world.setBlock(i + 29, j + 9, k + 51, NovaCraftBlocks.carved_vanite_bricks, 0, 2);
        world.setBlock(i + 30, j + 9, k + 51, NovaCraftBlocks.sculk_block, 0, 2);
        world.setBlock(i + 31, j + 9, k + 51, NovaCraftBlocks.nullstone_bricks, 0, 2);
        world.setBlock(i + 32, j + 9, k + 51, NovaCraftBlocks.nullstone_bricks, 0, 2);
        world.setBlock(i + 33, j + 9, k + 51, NovaCraftBlocks.nullstone_bricks, 0, 2);
        world.setBlock(i + 34, j + 9, k + 51, NovaCraftBlocks.nullstone_bricks, 0, 2);
        world.setBlock(i + 35, j + 9, k + 51, NovaCraftBlocks.nullstone_bricks, 0, 2);
        world.setBlock(i + 36, j + 9, k + 51, NovaCraftBlocks.nullstone_bricks, 0, 2);
        world.setBlock(i + 37, j + 9, k + 51, NovaCraftBlocks.nullstone_bricks, 0, 2);
        world.setBlock(i + 38, j + 9, k + 51, NovaCraftBlocks.nullstone_bricks, 0, 2);
        world.setBlock(i + 39, j + 9, k + 51, NovaCraftBlocks.nullstone_bricks, 0, 2);
        world.setBlock(i + 40, j + 9, k + 51, placeStoneBricks(random), 0, 2);
        world.setBlock(i + 41, j + 9, k + 51, NovaCraftBlocks.carved_vanite_bricks, 0, 2);
        world.setBlock(i + 29, j + 9, k + 52, NovaCraftBlocks.carved_vanite_bricks, 0, 2);
        world.setBlock(i + 30, j + 9, k + 52, NovaCraftBlocks.carved_vanite_bricks, 0, 2);
        world.setBlock(i + 31, j + 9, k + 52, placeStoneBricks(random), 0, 2);
        world.setBlock(i + 32, j + 9, k + 52, NovaCraftBlocks.nullstone_bricks, 0, 2);
        world.setBlock(i + 33, j + 9, k + 52, NovaCraftBlocks.nullstone_bricks, 0, 2);
        world.setBlock(i + 34, j + 9, k + 52, NovaCraftBlocks.nullstone_bricks, 0, 2);
        world.setBlock(i + 35, j + 9, k + 52, NovaCraftBlocks.nullstone_bricks, 0, 2);
        world.setBlock(i + 36, j + 9, k + 52, NovaCraftBlocks.nullstone_bricks, 0, 2);
        world.setBlock(i + 37, j + 9, k + 52, NovaCraftBlocks.nullstone_bricks, 0, 2);
        world.setBlock(i + 38, j + 9, k + 52, NovaCraftBlocks.nullstone_bricks, 0, 2);
        world.setBlock(i + 39, j + 9, k + 52, NovaCraftBlocks.sculk_block, 0, 2);
        world.setBlock(i + 40, j + 9, k + 52, NovaCraftBlocks.carved_vanite_bricks, 0, 2);
        world.setBlock(i + 41, j + 9, k + 52, NovaCraftBlocks.carved_vanite_bricks, 0, 2);
        world.setBlock(i + 30, j + 9, k + 53, NovaCraftBlocks.carved_vanite_bricks, 0, 2);
        world.setBlock(i + 31, j + 9, k + 53, NovaCraftBlocks.carved_vanite_bricks, 0, 2);
        world.setBlock(i + 32, j + 9, k + 53, placeStoneBricks(random), 0, 2);
        world.setBlock(i + 33, j + 9, k + 53, NovaCraftBlocks.nullstone_bricks, 0, 2);
        world.setBlock(i + 34, j + 9, k + 53, NovaCraftBlocks.nullstone_bricks, 0, 2);
        world.setBlock(i + 35, j + 9, k + 53, NovaCraftBlocks.nullstone_bricks, 0, 2);
        world.setBlock(i + 36, j + 9, k + 53, NovaCraftBlocks.nullstone_bricks, 0, 2);
        world.setBlock(i + 37, j + 9, k + 53, NovaCraftBlocks.nullstone_bricks, 0, 2);
        world.setBlock(i + 38, j + 9, k + 53, NovaCraftBlocks.sculk_block, 0, 2);
        world.setBlock(i + 39, j + 9, k + 53, NovaCraftBlocks.carved_vanite_bricks, 0, 2);
        world.setBlock(i + 40, j + 9, k + 53, NovaCraftBlocks.carved_vanite_bricks, 0, 2);
        world.setBlock(i + 31, j + 9, k + 54, NovaCraftBlocks.carved_vanite_bricks, 0, 2);
        world.setBlock(i + 32, j + 9, k + 54, NovaCraftBlocks.carved_vanite_bricks, 0, 2);
        world.setBlock(i + 33, j + 9, k + 54, placeStoneBricks(random), 0, 2);
        world.setBlock(i + 34, j + 9, k + 54, NovaCraftBlocks.sculk_block, 0, 2);
        world.setBlock(i + 35, j + 9, k + 54, placeStoneBricks(random), 0, 2);
        world.setBlock(i + 36, j + 9, k + 54, placeStoneBricks(random), 0, 2);
        world.setBlock(i + 37, j + 9, k + 54, placeStoneBricks(random), 0, 2);
        world.setBlock(i + 38, j + 9, k + 54, NovaCraftBlocks.carved_vanite_bricks, 0, 2);
        world.setBlock(i + 39, j + 9, k + 54, NovaCraftBlocks.carved_vanite_bricks, 0, 2);
        world.setBlock(i + 32, j + 9, k + 55, NovaCraftBlocks.carved_vanite_bricks, 0, 2);
        world.setBlock(i + 33, j + 9, k + 55, NovaCraftBlocks.carved_vanite_bricks, 0, 2);
        world.setBlock(i + 34, j + 9, k + 55, NovaCraftBlocks.carved_vanite_bricks, 0, 2);
        world.setBlock(i + 35, j + 9, k + 55, NovaCraftBlocks.carved_vanite_bricks, 0, 2);
        world.setBlock(i + 36, j + 9, k + 55, NovaCraftBlocks.carved_vanite_bricks, 0, 2);
        world.setBlock(i + 37, j + 9, k + 55, NovaCraftBlocks.carved_vanite_bricks, 0, 2);
        world.setBlock(i + 38, j + 9, k + 55, NovaCraftBlocks.carved_vanite_bricks, 0, 2);
        world.setBlock(i + 32, j + 10, k, NovaCraftBlocks.nullstone_brick_wall, 0, 2);
        world.setBlock(i + 33, j + 10, k, NovaCraftBlocks.nullstone_brick_wall, 0, 2);
        world.setBlock(i + 34, j + 10, k, NovaCraftBlocks.nullstone_brick_wall, 0, 2);
        world.setBlock(i + 35, j + 10, k, NovaCraftBlocks.nullstone_brick_wall, 0, 2);
        world.setBlock(i + 36, j + 10, k, NovaCraftBlocks.nullstone_brick_wall, 0, 2);
        world.setBlock(i + 37, j + 10, k, NovaCraftBlocks.nullstone_brick_wall, 0, 2);
        world.setBlock(i + 38, j + 10, k, NovaCraftBlocks.nullstone_brick_wall, 0, 2);
        world.setBlock(i + 32, j + 10, k + 1, NovaCraftBlocks.nullstone_brick_wall, 0, 2);
        world.setBlock(i + 38, j + 10, k + 1, NovaCraftBlocks.nullstone_brick_wall, 0, 2);
        world.setBlock(i + 30, j + 10, k + 2, NovaCraftBlocks.nullstone_brick_wall, 0, 2);
        world.setBlock(i + 31, j + 10, k + 2, NovaCraftBlocks.nullstone_brick_wall, 0, 2);
        world.setBlock(i + 39, j + 10, k + 2, NovaCraftBlocks.nullstone_brick_wall, 0, 2);
        world.setBlock(i + 40, j + 10, k + 2, NovaCraftBlocks.nullstone_brick_wall, 0, 2);
        world.setBlock(i + 30, j + 10, k + 3, NovaCraftBlocks.nullstone_brick_wall, 0, 2);
        world.setBlock(i + 33, j + 10, k + 3, NovaCraftBlocks.sculk_tiled_slab, 0, 2);
        world.setBlock(i + 34, j + 10, k + 3, NovaCraftBlocks.sculk_bricks, 0, 2);
        world.setBlock(i + 35, j + 10, k + 3, NovaCraftBlocks.sculk_bricks, 0, 2);
        world.setBlock(i + 36, j + 10, k + 3, NovaCraftBlocks.sculk_bricks, 0, 2);
        world.setBlock(i + 37, j + 10, k + 3, NovaCraftBlocks.sculk_tiled_slab, 0, 2);
        world.setBlock(i + 40, j + 10, k + 3, NovaCraftBlocks.nullstone_brick_wall, 0, 2);
        world.setBlock(i + 30, j + 10, k + 4, NovaCraftBlocks.nullstone_brick_wall, 0, 2);
        world.setBlock(i + 32, j + 10, k + 4, NovaCraftBlocks.sculk_tiled_slab, 0, 2);
        world.setBlock(i + 33, j + 10, k + 4, NovaCraftBlocks.sculk_bricks, 0, 2);
        world.setBlock(i + 34, j + 10, k + 4, NovaCraftBlocks.sculk_bricks, 0, 2);
        world.setBlock(i + 35, j + 10, k + 4, NovaCraftBlocks.sculk_bricks, 0, 2);
        world.setBlock(i + 36, j + 10, k + 4, NovaCraftBlocks.sculk_bricks, 0, 2);
        world.setBlock(i + 37, j + 10, k + 4, NovaCraftBlocks.sculk_bricks, 0, 2);
        world.setBlock(i + 38, j + 10, k + 4, NovaCraftBlocks.sculk_tiled_slab, 0, 2);
        world.setBlock(i + 40, j + 10, k + 4, NovaCraftBlocks.nullstone_brick_wall, 0, 2);
        world.setBlock(i + 30, j + 10, k + 5, NovaCraftBlocks.nullstone_brick_wall, 0, 2);
        world.setBlock(i + 33, j + 10, k + 5, NovaCraftBlocks.sculk_tiled_slab, 0, 2);
        world.setBlock(i + 34, j + 10, k + 5, NovaCraftBlocks.sculk_bricks, 0, 2);
        world.setBlock(i + 35, j + 10, k + 5, NovaCraftBlocks.sculk_tiled_slab, 0, 2);
        world.setBlock(i + 36, j + 10, k + 5, NovaCraftBlocks.sculk_bricks, 0, 2);
        world.setBlock(i + 37, j + 10, k + 5, NovaCraftBlocks.sculk_tiled_slab, 0, 2);
        world.setBlock(i + 40, j + 10, k + 5, NovaCraftBlocks.nullstone_brick_wall, 0, 2);
        world.setBlock(i + 30, j + 10, k + 6, NovaCraftBlocks.nullstone_brick_wall, 0, 2);
        world.setBlock(i + 34, j + 10, k + 6, NovaCraftBlocks.sculk_tiled_slab, 0, 2);
        world.setBlock(i + 36, j + 10, k + 6, NovaCraftBlocks.sculk_tiled_slab, 0, 2);
        world.setBlock(i + 40, j + 10, k + 6, NovaCraftBlocks.nullstone_brick_wall, 0, 2);
        world.setBlock(i + 30, j + 10, k + 7, NovaCraftBlocks.nullstone_brick_wall, 0, 2);
        world.setBlock(i + 31, j + 10, k + 7, NovaCraftBlocks.nullstone_brick_wall, 0, 2);
        world.setBlock(i + 39, j + 10, k + 7, NovaCraftBlocks.nullstone_brick_wall, 0, 2);
        world.setBlock(i + 40, j + 10, k + 7, NovaCraftBlocks.nullstone_brick_wall, 0, 2);
        world.setBlock(i + 32, j + 10, k + 8, NovaCraftBlocks.nullstone_brick_wall, 0, 2);
        world.setBlock(i + 33, j + 10, k + 8, NovaCraftBlocks.nullstone_brick_wall, 0, 2);
        world.setBlock(i + 37, j + 10, k + 8, NovaCraftBlocks.nullstone_brick_wall, 0, 2);
        world.setBlock(i + 38, j + 10, k + 8, NovaCraftBlocks.nullstone_brick_wall, 0, 2);
        world.setBlock(i + 33, j + 10, k + 9, NovaCraftBlocks.nullstone_brick_wall, 0, 2);
        world.setBlock(i + 37, j + 10, k + 9, NovaCraftBlocks.nullstone_brick_wall, 0, 2);
        world.setBlock(i + 33, j + 10, k + 10, NovaCraftBlocks.nullstone_brick_wall, 0, 2);
        world.setBlock(i + 37, j + 10, k + 10, NovaCraftBlocks.nullstone_brick_wall, 0, 2);
        world.setBlock(i + 27, j + 10, k + 19, placeStoneBricks(random), 0, 2);
        world.setBlock(i + 28, j + 10, k + 19, placeStoneBricks(random), 0, 2);
        world.setBlock(i + 42, j + 10, k + 19, placeStoneBricks(random), 0, 2);
        world.setBlock(i + 43, j + 10, k + 19, NovaCraftBlocks.sculk_block, 0, 2);
        world.setBlock(i + 27, j + 10, k + 20, NovaCraftBlocks.sculk_block, 0, 2);
        world.setBlock(i + 28, j + 10, k + 20, NovaCraftBlocks.sculk_block, 0, 2);
        world.setBlock(i + 42, j + 10, k + 20, NovaCraftBlocks.sculk_block, 0, 2);
        world.setBlock(i + 43, j + 10, k + 20, placeStoneBricks(random), 0, 2);
        world.setBlock(i + 3, j + 10, k + 21, placeStoneBricks(random), 0, 2);
        world.setBlock(i + 4, j + 10, k + 21, placeStoneBricks(random), 0, 2);
        world.setBlock(i + 5, j + 10, k + 21, placeStoneBricks(random), 0, 2);
        world.setBlock(i + 6, j + 10, k + 21, placeStoneBricks(random), 0, 2);
        world.setBlock(i + 7, j + 10, k + 21, placeStoneBricks(random), 0, 2);
        world.setBlock(i + 8, j + 10, k + 21, placeStoneBricks(random), 0, 2);
        world.setBlock(i + 9, j + 10, k + 21, placeStoneBricks(random), 0, 2);
        world.setBlock(i + 10, j + 10, k + 21, placeStoneBricks(random), 0, 2);
        world.setBlock(i + 11, j + 10, k + 21, placeStoneBricks(random), 0, 2);
        world.setBlock(i + 2, j + 10, k + 22, placeStoneBricks(random), 0, 2);
        world.setBlock(i + 3, j + 10, k + 22, placeStoneBricks(random), 0, 2);
        world.setBlock(i + 6, j + 10, k + 22, Blocks.carpet, 9, 2);
        world.setBlock(i + 7, j + 10, k + 22, NovaCraftBlocks.nullstone_brick_stairs, 0, 2);
        world.setBlock(i + 8, j + 10, k + 22, Blocks.carpet, 9, 2);
        world.setBlock(i + 9, j + 10, k + 22, NovaCraftBlocks.nullstone_brick_stairs, 0, 2);
        world.setBlock(i + 10, j + 10, k + 22, Blocks.carpet, 9, 2);
        world.setBlock(i + 11, j + 10, k + 22, NovaCraftBlocks.nullstone_brick_stairs, 0, 2);
        world.setBlock(i + 12, j + 10, k + 22, placeStoneBricks(random), 0, 2);
        world.setBlock(i + 1, j + 10, k + 23, placeStoneBricks(random), 0, 2);
        world.setBlock(i + 3, j + 10, k + 23, Blocks.ladder, 3, 2);
        world.setBlock(i + 13, j + 10, k + 23, placeStoneBricks(random), 0, 2);
        world.setBlock(i, j + 10, k + 24, placeStoneBricks(random), 0, 2);
        world.setBlock(i + 4, j + 10, k + 24, NovaCraftBlocks.nullstone_brick_wall, 0, 2);
        world.setBlock(i + 6, j + 10, k + 24, Blocks.carpet, 9, 2);
        world.setBlock(i + 7, j + 10, k + 24, NovaCraftBlocks.nullstone_brick_stairs, 0, 2);
        world.setBlock(i + 8, j + 10, k + 24, Blocks.carpet, 9, 2);
        world.setBlock(i + 9, j + 10, k + 24, NovaCraftBlocks.nullstone_brick_stairs, 0, 2);
        world.setBlock(i + 10, j + 10, k + 24, Blocks.carpet, 9, 2);
        world.setBlock(i + 11, j + 10, k + 24, NovaCraftBlocks.nullstone_brick_stairs, 0, 2);
        world.setBlock(i + 12, j + 10, k + 24, Blocks.carpet, 9, 2);
        world.setBlock(i + 13, j + 10, k + 24, NovaCraftBlocks.nullstone_brick_stairs, 0, 2);
        world.setBlock(i + 14, j + 10, k + 24, NovaCraftBlocks.sculk_block, 0, 2);
        world.setBlock(i + 39, j + 10, k + 24, NovaCraftBlocks.nullstone_bricks, 0, 2);
        world.setBlock(i, j + 10, k + 25, NovaCraftBlocks.sculk_block, 0, 2);
        world.setBlock(i + 6, j + 10, k + 25, Blocks.carpet, 9, 2);
        world.setBlock(i + 7, j + 10, k + 25, NovaCraftBlocks.nullstone_brick_stairs, 0, 2);
        world.setBlock(i + 8, j + 10, k + 25, Blocks.carpet, 9, 2);
        world.setBlock(i + 9, j + 10, k + 25, NovaCraftBlocks.nullstone_brick_stairs, 0, 2);
        world.setBlock(i + 10, j + 10, k + 25, Blocks.carpet, 9, 2);
        world.setBlock(i + 11, j + 10, k + 25, NovaCraftBlocks.nullstone_brick_stairs, 0, 2);
        world.setBlock(i + 12, j + 10, k + 25, Blocks.carpet, 9, 2);
        world.setBlock(i + 13, j + 10, k + 25, NovaCraftBlocks.nullstone_brick_stairs, 0, 2);
        world.setBlock(i + 14, j + 10, k + 25, placeStoneBricks(random), 0, 2);
        world.setBlock(i + 37, j + 10, k + 25, NovaCraftBlocks.null_cluster_2, 2, 2);
        world.setBlock(i, j + 10, k + 26, placeStoneBricks(random), 0, 2);
        world.setBlock(i + 1, j + 10, k + 26, NovaCraftBlocks.sculk_tiled_slab, 0, 2);
        world.setBlock(i + 2, j + 10, k + 26, NovaCraftBlocks.sculk_tiled_slab, 0, 2);
        world.setBlock(i + 14, j + 10, k + 26, placeStoneBricks(random), 0, 2);
        world.setBlock(i + 15, j + 10, k + 26, NovaCraftBlocks.nullstone_brick_wall, 0, 2);
        world.setBlock(i + 16, j + 10, k + 26, NovaCraftBlocks.nullstone_brick_wall, 0, 2);
        world.setBlock(i + 17, j + 10, k + 26, NovaCraftBlocks.nullstone_brick_wall, 0, 2);
        world.setBlock(i + 32, j + 10, k + 26, NovaCraftBlocks.null_cluster_2, 4, 2);
        world.setBlock(i + 33, j + 10, k + 26, NovaCraftBlocks.budding_null_block, 0, 2);
        world.setBlock(i + 34, j + 10, k + 26, NovaCraftBlocks.null_cluster_2, 5, 2);
        world.setBlock(i + 36, j + 10, k + 26, NovaCraftBlocks.null_cluster_2, 4, 2);
        world.setBlock(i + 37, j + 10, k + 26, NovaCraftBlocks.budding_null_block, 0, 2);
        world.setBlock(i, j + 10, k + 27, placeStoneBricks(random), 0, 2);
        world.setBlock(i + 1, j + 10, k + 27, NovaCraftBlocks.sculk_bricks, 0, 2);
        world.setBlock(i + 2, j + 10, k + 27, NovaCraftBlocks.sculk_bricks, 0, 2);
        world.setBlock(i + 3, j + 10, k + 27, NovaCraftBlocks.sculk_tiled_slab, 0, 2);
        world.setBlock(i + 4, j + 10, k + 27, Blocks.carpet, 9, 2);
        world.setBlock(i + 5, j + 10, k + 27, Blocks.carpet, 9, 2);
        world.setBlock(i + 6, j + 10, k + 27, Blocks.carpet, 9, 2);
        world.setBlock(i + 7, j + 10, k + 27, Blocks.carpet, 9, 2);
        world.setBlock(i + 8, j + 10, k + 27, Blocks.carpet, 9, 2);
        world.setBlock(i + 9, j + 10, k + 27, Blocks.carpet, 9, 2);
        world.setBlock(i + 10, j + 10, k + 27, Blocks.carpet, 9, 2);
        world.setBlock(i + 11, j + 10, k + 27, Blocks.carpet, 9, 2);
        world.setBlock(i + 12, j + 10, k + 27, Blocks.carpet, 9, 2);
        world.setBlock(i + 13, j + 10, k + 27, Blocks.carpet, 9, 2);
        world.setBlock(i + 14, j + 10, k + 27, Blocks.carpet, 9, 2);
        world.setBlock(i + 33, j + 10, k + 27, NovaCraftBlocks.null_cluster_2, 3, 2);
        world.setBlock(i + 37, j + 10, k + 27, NovaCraftBlocks.null_cluster_2, 3, 2);
        world.setBlock(i, j + 10, k + 28, NovaCraftBlocks.sculk_block, 0, 2);
        world.setBlock(i + 1, j + 10, k + 28, NovaCraftBlocks.sculk_bricks, 0, 2);
        world.setBlock(i + 2, j + 10, k + 28, NovaCraftBlocks.nullstone_brick_stairs, 1, 2);
        world.setBlock(i + 4, j + 10, k + 28, Blocks.carpet, 9, 2);
        world.setBlock(i + 5, j + 10, k + 28, Blocks.carpet, 9, 2);
        world.setBlock(i + 6, j + 10, k + 28, Blocks.carpet, 9, 2);
        world.setBlock(i + 7, j + 10, k + 28, Blocks.carpet, 9, 2);
        world.setBlock(i + 8, j + 10, k + 28, Blocks.carpet, 9, 2);
        world.setBlock(i + 9, j + 10, k + 28, Blocks.carpet, 9, 2);
        world.setBlock(i + 10, j + 10, k + 28, Blocks.carpet, 9, 2);
        world.setBlock(i + 11, j + 10, k + 28, Blocks.carpet, 9, 2);
        world.setBlock(i + 12, j + 10, k + 28, Blocks.carpet, 9, 2);
        world.setBlock(i + 13, j + 10, k + 28, Blocks.carpet, 9, 2);
        world.setBlock(i + 14, j + 10, k + 28, Blocks.carpet, 9, 2);
        world.setBlock(i, j + 10, k + 29, placeStoneBricks(random), 0, 2);
        world.setBlock(i + 1, j + 10, k + 29, NovaCraftBlocks.sculk_bricks, 0, 2);
        world.setBlock(i + 2, j + 10, k + 29, NovaCraftBlocks.sculk_bricks, 0, 2);
        world.setBlock(i + 3, j + 10, k + 29, NovaCraftBlocks.sculk_tiled_slab, 0, 2);
        world.setBlock(i + 4, j + 10, k + 29, Blocks.carpet, 9, 2);
        world.setBlock(i + 5, j + 10, k + 29, Blocks.carpet, 9, 2);
        world.setBlock(i + 6, j + 10, k + 29, Blocks.carpet, 9, 2);
        world.setBlock(i + 7, j + 10, k + 29, Blocks.carpet, 9, 2);
        world.setBlock(i + 8, j + 10, k + 29, Blocks.carpet, 9, 2);
        world.setBlock(i + 9, j + 10, k + 29, Blocks.carpet, 9, 2);
        world.setBlock(i + 10, j + 10, k + 29, Blocks.carpet, 9, 2);
        world.setBlock(i + 11, j + 10, k + 29, Blocks.carpet, 9, 2);
        world.setBlock(i + 12, j + 10, k + 29, Blocks.carpet, 9, 2);
        world.setBlock(i + 13, j + 10, k + 29, Blocks.carpet, 9, 2);
        world.setBlock(i + 14, j + 10, k + 29, Blocks.carpet, 9, 2);
        world.setBlock(i + 33, j + 10, k + 29, NovaCraftBlocks.null_cluster_2, 2, 2);
        world.setBlock(i + 37, j + 10, k + 29, NovaCraftBlocks.null_cluster_2, 2, 2);
        world.setBlock(i, j + 10, k + 30, placeStoneBricks(random), 0, 2);
        world.setBlock(i + 1, j + 10, k + 30, NovaCraftBlocks.sculk_tiled_slab, 0, 2);
        world.setBlock(i + 2, j + 10, k + 30, NovaCraftBlocks.sculk_tiled_slab, 0, 2);
        world.setBlock(i + 14, j + 10, k + 30, placeStoneBricks(random), 0, 2);
        world.setBlock(i + 15, j + 10, k + 30, NovaCraftBlocks.nullstone_brick_wall, 0, 2);
        world.setBlock(i + 16, j + 10, k + 30, NovaCraftBlocks.nullstone_brick_wall, 0, 2);
        world.setBlock(i + 17, j + 10, k + 30, NovaCraftBlocks.nullstone_brick_wall, 0, 2);
        world.setBlock(i + 33, j + 10, k + 30, NovaCraftBlocks.budding_null_block, 0, 2);
        world.setBlock(i + 34, j + 10, k + 30, NovaCraftBlocks.null_cluster_2, 5, 2);
        world.setBlock(i + 37, j + 10, k + 30, NovaCraftBlocks.budding_null_block, 0, 2);
        world.setBlock(i + 38, j + 10, k + 30, NovaCraftBlocks.null_cluster_2, 5, 2);
        world.setBlock(i, j + 10, k + 31, placeStoneBricks(random), 0, 2);
        world.setBlock(i + 6, j + 10, k + 31, Blocks.carpet, 9, 2);
        world.setBlock(i + 7, j + 10, k + 31, NovaCraftBlocks.nullstone_brick_stairs, 0, 2);
        world.setBlock(i + 8, j + 10, k + 31, Blocks.carpet, 9, 2);
        world.setBlock(i + 9, j + 10, k + 31, NovaCraftBlocks.nullstone_brick_stairs, 0, 2);
        world.setBlock(i + 10, j + 10, k + 31, Blocks.carpet, 9, 2);
        world.setBlock(i + 11, j + 10, k + 31, NovaCraftBlocks.nullstone_brick_stairs, 0, 2);
        world.setBlock(i + 12, j + 10, k + 31, Blocks.carpet, 9, 2);
        world.setBlock(i + 13, j + 10, k + 31, NovaCraftBlocks.nullstone_brick_stairs, 0, 2);
        world.setBlock(i + 14, j + 10, k + 31, placeStoneBricks(random), 0, 2);
        world.setBlock(i + 37, j + 10, k + 31, NovaCraftBlocks.null_cluster_2, 3, 2);
        world.setBlock(i, j + 10, k + 32, placeStoneBricks(random), 0, 2);
        world.setBlock(i + 4, j + 10, k + 32, NovaCraftBlocks.nullstone_brick_wall, 0, 2);
        world.setBlock(i + 6, j + 10, k + 32, Blocks.carpet, 9, 2);
        world.setBlock(i + 7, j + 10, k + 32, NovaCraftBlocks.nullstone_brick_stairs, 0, 2);
        world.setBlock(i + 8, j + 10, k + 32, Blocks.carpet, 9, 2);
        world.setBlock(i + 9, j + 10, k + 32, NovaCraftBlocks.nullstone_brick_stairs, 0, 2);
        world.setBlock(i + 10, j + 10, k + 32, Blocks.carpet, 9, 2);
        world.setBlock(i + 11, j + 10, k + 32, NovaCraftBlocks.nullstone_brick_stairs, 0, 2);
        world.setBlock(i + 12, j + 10, k + 32, Blocks.carpet, 9, 2);
        world.setBlock(i + 13, j + 10, k + 32, NovaCraftBlocks.nullstone_brick_stairs, 0, 2);
        world.setBlock(i + 14, j + 10, k + 32, placeStoneBricks(random), 0, 2);
        world.setBlock(i + 1, j + 10, k + 33, NovaCraftBlocks.sculk_block, 0, 2);
        world.setBlock(i + 3, j + 10, k + 33, Blocks.ladder, 2, 2);
        world.setBlock(i + 13, j + 10, k + 33, placeStoneBricks(random), 0, 2);
        world.setBlock(i + 2, j + 10, k + 34, placeStoneBricks(random), 0, 2);
        world.setBlock(i + 3, j + 10, k + 34, placeStoneBricks(random), 0, 2);
        world.setBlock(i + 6, j + 10, k + 34, Blocks.carpet, 9, 2);
        world.setBlock(i + 7, j + 10, k + 34, NovaCraftBlocks.nullstone_brick_stairs, 0, 2);
        world.setBlock(i + 8, j + 10, k + 34, Blocks.carpet, 9, 2);
        world.setBlock(i + 9, j + 10, k + 34, NovaCraftBlocks.nullstone_brick_stairs, 0, 2);
        world.setBlock(i + 10, j + 10, k + 34, Blocks.carpet, 9, 2);
        world.setBlock(i + 11, j + 10, k + 34, NovaCraftBlocks.nullstone_brick_stairs, 0, 2);
        world.setBlock(i + 12, j + 10, k + 34, placeStoneBricks(random), 0, 2);
        world.setBlock(i + 3, j + 10, k + 35, placeStoneBricks(random), 0, 2);
        world.setBlock(i + 4, j + 10, k + 35, placeStoneBricks(random), 0, 2);
        world.setBlock(i + 5, j + 10, k + 35, placeStoneBricks(random), 0, 2);
        world.setBlock(i + 6, j + 10, k + 35, placeStoneBricks(random), 0, 2);
        world.setBlock(i + 7, j + 10, k + 35, placeStoneBricks(random), 0, 2);
        world.setBlock(i + 8, j + 10, k + 35, placeStoneBricks(random), 0, 2);
        world.setBlock(i + 9, j + 10, k + 35, placeStoneBricks(random), 0, 2);
        world.setBlock(i + 10, j + 10, k + 35, placeStoneBricks(random), 0, 2);
        world.setBlock(i + 11, j + 10, k + 35, NovaCraftBlocks.sculk_block, 0, 2);
        world.setBlock(i + 27, j + 10, k + 36, placeStoneBricks(random), 0, 2);
        world.setBlock(i + 28, j + 10, k + 36, NovaCraftBlocks.sculk_block, 0, 2);
        world.setBlock(i + 42, j + 10, k + 36, placeStoneBricks(random), 0, 2);
        world.setBlock(i + 43, j + 10, k + 36, placeStoneBricks(random), 0, 2);
        world.setBlock(i + 27, j + 10, k + 37, NovaCraftBlocks.sculk_block, 0, 2);
        world.setBlock(i + 28, j + 10, k + 37, placeStoneBricks(random), 0, 2);
        world.setBlock(i + 42, j + 10, k + 37, placeStoneBricks(random), 0, 2);
        world.setBlock(i + 43, j + 10, k + 37, NovaCraftBlocks.sculk_block, 0, 2);
        world.setBlock(i + 33, j + 10, k + 46, NovaCraftBlocks.nullstone_brick_wall, 0, 2);
        world.setBlock(i + 37, j + 10, k + 46, NovaCraftBlocks.nullstone_brick_wall, 0, 2);
        world.setBlock(i + 32, j + 10, k + 47, NovaCraftBlocks.nullstone_brick_wall, 0, 2);
        world.setBlock(i + 33, j + 10, k + 47, NovaCraftBlocks.nullstone_brick_wall, 0, 2);
        world.setBlock(i + 37, j + 10, k + 47, NovaCraftBlocks.nullstone_brick_wall, 0, 2);
        world.setBlock(i + 38, j + 10, k + 47, NovaCraftBlocks.nullstone_brick_wall, 0, 2);
        world.setBlock(i + 30, j + 10, k + 48, NovaCraftBlocks.nullstone_brick_wall, 0, 2);
        world.setBlock(i + 31, j + 10, k + 48, NovaCraftBlocks.nullstone_brick_wall, 0, 2);
        world.setBlock(i + 39, j + 10, k + 48, NovaCraftBlocks.nullstone_brick_wall, 0, 2);
        world.setBlock(i + 40, j + 10, k + 48, NovaCraftBlocks.nullstone_brick_wall, 0, 2);
        world.setBlock(i + 29, j + 10, k + 49, NovaCraftBlocks.nullstone_brick_wall, 0, 2);
        world.setBlock(i + 30, j + 10, k + 49, NovaCraftBlocks.nullstone_brick_wall, 0, 2);
        world.setBlock(i + 34, j + 10, k + 49, NovaCraftBlocks.sculk_tiled_slab, 0, 2);
        world.setBlock(i + 36, j + 10, k + 49, NovaCraftBlocks.sculk_tiled_slab, 0, 2);
        world.setBlock(i + 40, j + 10, k + 49, NovaCraftBlocks.nullstone_brick_wall, 0, 2);
        world.setBlock(i + 41, j + 10, k + 49, NovaCraftBlocks.nullstone_brick_wall, 0, 2);
        world.setBlock(i + 29, j + 10, k + 50, NovaCraftBlocks.nullstone_brick_wall, 0, 2);
        world.setBlock(i + 33, j + 10, k + 50, NovaCraftBlocks.sculk_tiled_slab, 0, 2);
        world.setBlock(i + 34, j + 10, k + 50, NovaCraftBlocks.sculk_bricks, 0, 2);
        world.setBlock(i + 35, j + 10, k + 50, NovaCraftBlocks.sculk_tiled_slab, 0, 2);
        world.setBlock(i + 36, j + 10, k + 50, NovaCraftBlocks.sculk_bricks, 0, 2);
        world.setBlock(i + 37, j + 10, k + 50, NovaCraftBlocks.sculk_tiled_slab, 0, 2);
        world.setBlock(i + 41, j + 10, k + 50, NovaCraftBlocks.nullstone_brick_wall, 0, 2);
        world.setBlock(i + 29, j + 10, k + 51, NovaCraftBlocks.nullstone_brick_wall, 0, 2);
        world.setBlock(i + 32, j + 10, k + 51, NovaCraftBlocks.sculk_tiled_slab, 0, 2);
        world.setBlock(i + 33, j + 10, k + 51, NovaCraftBlocks.sculk_bricks, 0, 2);
        world.setBlock(i + 34, j + 10, k + 51, NovaCraftBlocks.sculk_bricks, 0, 2);
        world.setBlock(i + 35, j + 10, k + 51, NovaCraftBlocks.sculk_bricks, 0, 2);
        world.setBlock(i + 36, j + 10, k + 51, NovaCraftBlocks.sculk_bricks, 0, 2);
        world.setBlock(i + 37, j + 10, k + 51, NovaCraftBlocks.sculk_bricks, 0, 2);
        world.setBlock(i + 38, j + 10, k + 51, NovaCraftBlocks.sculk_tiled_slab, 0, 2);
        world.setBlock(i + 41, j + 10, k + 51, NovaCraftBlocks.nullstone_brick_wall, 0, 2);
        world.setBlock(i + 29, j + 10, k + 52, NovaCraftBlocks.nullstone_brick_wall, 0, 2);
        world.setBlock(i + 30, j + 10, k + 52, NovaCraftBlocks.nullstone_brick_wall, 0, 2);
        world.setBlock(i + 33, j + 10, k + 52, NovaCraftBlocks.sculk_tiled_slab, 0, 2);
        world.setBlock(i + 34, j + 10, k + 52, NovaCraftBlocks.sculk_bricks, 0, 2);
        world.setBlock(i + 35, j + 10, k + 52, NovaCraftBlocks.sculk_bricks, 0, 2);
        world.setBlock(i + 36, j + 10, k + 52, NovaCraftBlocks.sculk_bricks, 0, 2);
        world.setBlock(i + 37, j + 10, k + 52, NovaCraftBlocks.sculk_tiled_slab, 0, 2);
        world.setBlock(i + 40, j + 10, k + 52, NovaCraftBlocks.nullstone_brick_wall, 0, 2);
        world.setBlock(i + 41, j + 10, k + 52, NovaCraftBlocks.nullstone_brick_wall, 0, 2);
        world.setBlock(i + 30, j + 10, k + 53, NovaCraftBlocks.nullstone_brick_wall, 0, 2);
        world.setBlock(i + 31, j + 10, k + 53, NovaCraftBlocks.nullstone_brick_wall, 0, 2);
        world.setBlock(i + 39, j + 10, k + 53, NovaCraftBlocks.nullstone_brick_wall, 0, 2);
        world.setBlock(i + 40, j + 10, k + 53, NovaCraftBlocks.nullstone_brick_wall, 0, 2);
        world.setBlock(i + 32, j + 10, k + 54, NovaCraftBlocks.nullstone_brick_wall, 0, 2);
        world.setBlock(i + 38, j + 10, k + 54, NovaCraftBlocks.nullstone_brick_wall, 0, 2);
        world.setBlock(i + 32, j + 10, k + 55, NovaCraftBlocks.nullstone_brick_wall, 0, 2);
        world.setBlock(i + 33, j + 10, k + 55, NovaCraftBlocks.nullstone_brick_wall, 0, 2);
        world.setBlock(i + 34, j + 10, k + 55, NovaCraftBlocks.nullstone_brick_wall, 0, 2);
        world.setBlock(i + 35, j + 10, k + 55, NovaCraftBlocks.nullstone_brick_wall, 0, 2);
        world.setBlock(i + 36, j + 10, k + 55, NovaCraftBlocks.nullstone_brick_wall, 0, 2);
        world.setBlock(i + 37, j + 10, k + 55, NovaCraftBlocks.nullstone_brick_wall, 0, 2);
        world.setBlock(i + 38, j + 10, k + 55, NovaCraftBlocks.nullstone_brick_wall, 0, 2);
        world.setBlock(i + 34, j + 11, k + 3, NovaCraftBlocks.sculk_tiles, 0, 2);
        world.setBlock(i + 35, j + 11, k + 3, NovaCraftBlocks.sculk_tiles, 0, 2);
        world.setBlock(i + 36, j + 11, k + 3, NovaCraftBlocks.sculk_tiles, 0, 2);
        world.setBlock(i + 33, j + 11, k + 4, NovaCraftBlocks.sculk_tiled_wall, 0, 2);
        world.setBlock(i + 37, j + 11, k + 4, NovaCraftBlocks.sculk_tiled_wall, 0, 2);
        world.setBlock(i + 34, j + 11, k + 5, NovaCraftBlocks.sculk_tiled_wall, 0, 2);
        world.setBlock(i + 36, j + 11, k + 5, NovaCraftBlocks.sculk_tiled_wall, 0, 2);
        world.setBlock(i + 27, j + 11, k + 19, placeStoneBricks(random), 0, 2);
        world.setBlock(i + 28, j + 11, k + 19, NovaCraftBlocks.sculk_block, 0, 2);
        world.setBlock(i + 42, j + 11, k + 19, placeStoneBricks(random), 0, 2);
        world.setBlock(i + 43, j + 11, k + 19, placeStoneBricks(random), 0, 2);
        world.setBlock(i + 27, j + 11, k + 20, NovaCraftBlocks.sculk_block, 0, 2);
        world.setBlock(i + 28, j + 11, k + 20, placeStoneBricks(random), 0, 2);
        world.setBlock(i + 42, j + 11, k + 20, placeStoneBricks(random), 0, 2);
        world.setBlock(i + 43, j + 11, k + 20, placeStoneBricks(random), 0, 2);
        world.setBlock(i + 3, j + 11, k + 21, NovaCraftBlocks.sculk_block, 0, 2);
        world.setBlock(i + 4, j + 11, k + 21, placeStoneBricks(random), 0, 2);
        world.setBlock(i + 5, j + 11, k + 21, placeStoneBricks(random), 0, 2);
        world.setBlock(i + 6, j + 11, k + 21, placeStoneBricks(random), 0, 2);
        world.setBlock(i + 7, j + 11, k + 21, placeStoneBricks(random), 0, 2);
        world.setBlock(i + 8, j + 11, k + 21, NovaCraftBlocks.sculk_block, 0, 2);
        world.setBlock(i + 9, j + 11, k + 21, NovaCraftBlocks.sculk_block, 0, 2);
        world.setBlock(i + 10, j + 11, k + 21, placeStoneBricks(random), 0, 2);
        world.setBlock(i + 11, j + 11, k + 21, placeStoneBricks(random), 0, 2);
        world.setBlock(i + 2, j + 11, k + 22, placeStoneBricks(random), 0, 2);
        world.setBlock(i + 3, j + 11, k + 22, placeStoneBricks(random), 0, 2);
        world.setBlock(i + 12, j + 11, k + 22, placeStoneBricks(random), 0, 2);
        world.setBlock(i + 1, j + 11, k + 23, placeStoneBricks(random), 0, 2);
        world.setBlock(i + 3, j + 11, k + 23, Blocks.ladder, 3, 2);
        world.setBlock(i + 13, j + 11, k + 23, placeStoneBricks(random), 0, 2);
        world.setBlock(i, j + 11, k + 24, placeStoneBricks(random), 0, 2);
        world.setBlock(i + 4, j + 11, k + 24, NovaCraftBlocks.dim_vanite_torch, 5, 2);
        world.setBlock(i + 14, j + 11, k + 24, NovaCraftBlocks.sculk_block, 0, 2);

        if (Configs.enableTreasureCratesDropDiamonds) {
            world.setBlock(i + 39, j + 11, k + 24, Blocks.diamond_block, 0, 2);
        } else {
            world.setBlock(i + 39, j + 11, k + 24, Blocks.air, 0, 2);
        }

        world.setBlock(i, j + 11, k + 25, NovaCraftBlocks.sculk_block, 0, 2);
        world.setBlock(i + 1, j + 11, k + 25, NovaCraftBlocks.nullstone_brick_wall, 0, 2);
        world.setBlock(i + 14, j + 11, k + 25, placeStoneBricks(random), 0, 2);
        world.setBlock(i, j + 11, k + 26, placeStoneBricks(random), 0, 2);
        world.setBlock(i + 14, j + 11, k + 26, placeStoneBricks(random), 0, 2);
        world.setBlock(i + 33, j + 11, k + 26, NovaCraftBlocks.null_cluster_2, 1, 2);
        world.setBlock(i, j + 11, k + 27, placeStoneBricks(random), 0, 2);
        world.setBlock(i + 1, j + 11, k + 27, NovaCraftBlocks.sculk_tiles, 0, 2);
        world.setBlock(i, j + 11, k + 28, placeStoneBricks(random), 0, 2);
        world.setBlock(i + 1, j + 11, k + 28, NovaCraftBlocks.sculk_tiles, 0, 2);
        world.setBlock(i, j + 11, k + 29, placeStoneBricks(random), 0, 2);
        world.setBlock(i + 1, j + 11, k + 29, NovaCraftBlocks.sculk_tiles, 0, 2);
        world.setBlock(i, j + 11, k + 30, placeStoneBricks(random), 0, 2);
        world.setBlock(i + 14, j + 11, k + 30, NovaCraftBlocks.sculk_block, 0, 2);
        world.setBlock(i + 33, j + 11, k + 30, NovaCraftBlocks.null_cluster_2, 1, 2);
        world.setBlock(i + 37, j + 11, k + 30, NovaCraftBlocks.null_cluster_2, 1, 2);
        world.setBlock(i, j + 11, k + 31, placeStoneBricks(random), 0, 2);
        world.setBlock(i + 1, j + 11, k + 31, NovaCraftBlocks.nullstone_brick_wall, 0, 2);
        world.setBlock(i + 14, j + 11, k + 31, placeStoneBricks(random), 0, 2);
        world.setBlock(i, j + 11, k + 32, placeStoneBricks(random), 0, 2);
        world.setBlock(i + 4, j + 11, k + 32, NovaCraftBlocks.dim_vanite_torch, 5, 2);
        world.setBlock(i + 14, j + 11, k + 32, placeStoneBricks(random), 0, 2);
        world.setBlock(i + 1, j + 11, k + 33, placeStoneBricks(random), 0, 2);
        world.setBlock(i + 3, j + 11, k + 33, Blocks.ladder, 2, 2);
        world.setBlock(i + 13, j + 11, k + 33, placeStoneBricks(random), 0, 2);
        world.setBlock(i + 2, j + 11, k + 34, placeStoneBricks(random), 0, 2);
        world.setBlock(i + 3, j + 11, k + 34, placeStoneBricks(random), 0, 2);
        world.setBlock(i + 12, j + 11, k + 34, NovaCraftBlocks.sculk_block, 0, 2);
        world.setBlock(i + 3, j + 11, k + 35, placeStoneBricks(random), 0, 2);
        world.setBlock(i + 4, j + 11, k + 35, placeStoneBricks(random), 0, 2);
        world.setBlock(i + 5, j + 11, k + 35, placeStoneBricks(random), 0, 2);
        world.setBlock(i + 6, j + 11, k + 35, NovaCraftBlocks.sculk_block, 0, 2);
        world.setBlock(i + 7, j + 11, k + 35, placeStoneBricks(random), 0, 2);
        world.setBlock(i + 8, j + 11, k + 35, placeStoneBricks(random), 0, 2);
        world.setBlock(i + 9, j + 11, k + 35, placeStoneBricks(random), 0, 2);
        world.setBlock(i + 10, j + 11, k + 35, placeStoneBricks(random), 0, 2);
        world.setBlock(i + 11, j + 11, k + 35, placeStoneBricks(random), 0, 2);
        world.setBlock(i + 27, j + 11, k + 36, placeStoneBricks(random), 0, 2);
        world.setBlock(i + 28, j + 11, k + 36, placeStoneBricks(random), 0, 2);
        world.setBlock(i + 42, j + 11, k + 36, placeStoneBricks(random), 0, 2);
        world.setBlock(i + 43, j + 11, k + 36, NovaCraftBlocks.sculk_block, 0, 2);
        world.setBlock(i + 27, j + 11, k + 37, NovaCraftBlocks.sculk_block, 0, 2);
        world.setBlock(i + 28, j + 11, k + 37, placeStoneBricks(random), 0, 2);
        world.setBlock(i + 42, j + 11, k + 37, placeStoneBricks(random), 0, 2);
        world.setBlock(i + 43, j + 11, k + 37, placeStoneBricks(random), 0, 2);
        world.setBlock(i + 34, j + 11, k + 50, NovaCraftBlocks.sculk_tiled_wall, 0, 2);
        world.setBlock(i + 36, j + 11, k + 50, NovaCraftBlocks.sculk_tiled_wall, 0, 2);
        world.setBlock(i + 33, j + 11, k + 51, NovaCraftBlocks.sculk_tiled_wall, 0, 2);
        world.setBlock(i + 37, j + 11, k + 51, NovaCraftBlocks.sculk_tiled_wall, 0, 2);
        world.setBlock(i + 34, j + 11, k + 52, NovaCraftBlocks.sculk_tiles, 0, 2);
        world.setBlock(i + 35, j + 11, k + 52, NovaCraftBlocks.sculk_tiles, 0, 2);
        world.setBlock(i + 36, j + 11, k + 52, NovaCraftBlocks.sculk_tiles, 0, 2);
        world.setBlock(i + 35, j + 12, k + 3, NovaCraftBlocks.chiseled_sculk, 0, 2);
        world.setBlock(i + 33, j + 12, k + 4, NovaCraftBlocks.sculk_tiled_wall, 0, 2);
        world.setBlock(i + 37, j + 12, k + 4, NovaCraftBlocks.sculk_tiled_wall, 0, 2);
        world.setBlock(i + 34, j + 12, k + 5, NovaCraftBlocks.dim_vanite_torch, 5, 2);
        world.setBlock(i + 36, j + 12, k + 5, NovaCraftBlocks.dim_vanite_torch, 5, 2);
        world.setBlock(i + 27, j + 12, k + 19, placeStoneBricks(random), 0, 2);
        world.setBlock(i + 28, j + 12, k + 19, placeStoneBricks(random), 0, 2);
        world.setBlock(i + 42, j + 12, k + 19, placeStoneBricks(random), 0, 2);
        world.setBlock(i + 43, j + 12, k + 19, placeStoneBricks(random), 0, 2);
        world.setBlock(i + 27, j + 12, k + 20, placeStoneBricks(random), 0, 2);
        world.setBlock(i + 28, j + 12, k + 20, placeStoneBricks(random), 0, 2);
        world.setBlock(i + 42, j + 12, k + 20, placeStoneBricks(random), 0, 2);
        world.setBlock(i + 43, j + 12, k + 20, NovaCraftBlocks.sculk_block, 0, 2);
        world.setBlock(i + 3, j + 12, k + 21, placeStoneBricks(random), 0, 2);
        world.setBlock(i + 4, j + 12, k + 21, placeStoneBricks(random), 0, 2);
        world.setBlock(i + 5, j + 12, k + 21, placeStoneBricks(random), 0, 2);
        world.setBlock(i + 6, j + 12, k + 21, placeStoneBricks(random), 0, 2);
        world.setBlock(i + 7, j + 12, k + 21, placeStoneBricks(random), 0, 2);
        world.setBlock(i + 8, j + 12, k + 21, placeStoneBricks(random), 0, 2);
        world.setBlock(i + 9, j + 12, k + 21, placeStoneBricks(random), 0, 2);
        world.setBlock(i + 10, j + 12, k + 21, placeStoneBricks(random), 0, 2);
        world.setBlock(i + 11, j + 12, k + 21, placeStoneBricks(random), 0, 2);
        world.setBlock(i + 2, j + 12, k + 22, placeStoneBricks(random), 0, 2);
        world.setBlock(i + 3, j + 12, k + 22, placeStoneBricks(random), 0, 2);
        world.setBlock(i + 4, j + 12, k + 22, placeStoneBricks(random), 0, 2);
        world.setBlock(i + 5, j + 12, k + 22, placeStoneBricks(random), 0, 2);
        world.setBlock(i + 6, j + 12, k + 22, placeStoneBricks(random), 0, 2);
        world.setBlock(i + 7, j + 12, k + 22, placeStoneBricks(random), 0, 2);
        world.setBlock(i + 8, j + 12, k + 22, placeStoneBricks(random), 0, 2);
        world.setBlock(i + 9, j + 12, k + 22, placeStoneBricks(random), 0, 2);
        world.setBlock(i + 10, j + 12, k + 22, placeStoneBricks(random), 0, 2);
        world.setBlock(i + 11, j + 12, k + 22, placeStoneBricks(random), 0, 2);
        world.setBlock(i + 12, j + 12, k + 22, NovaCraftBlocks.sculk_block, 0, 2);
        world.setBlock(i + 1, j + 12, k + 23, placeStoneBricks(random), 0, 2);
        world.setBlock(i + 3, j + 12, k + 23, Blocks.ladder, 3, 2);
        world.setBlock(i + 7, j + 12, k + 23, NovaCraftBlocks.nullstone_brick_wall, 0, 2);
        world.setBlock(i + 9, j + 12, k + 23, NovaCraftBlocks.nullstone_brick_wall, 0, 2);
        world.setBlock(i + 13, j + 12, k + 23, placeStoneBricks(random), 0, 2);
        world.setBlock(i, j + 12, k + 24, NovaCraftBlocks.sculk_block, 0, 2);
        world.setBlock(i + 14, j + 12, k + 24, placeStoneBricks(random), 0, 2);
        world.setBlock(i, j + 12, k + 25, placeStoneBricks(random), 0, 2);
        world.setBlock(i + 1, j + 12, k + 25, NovaCraftBlocks.dim_vanite_torch, 5, 2);
        world.setBlock(i + 14, j + 12, k + 25, placeStoneBricks(random), 0, 2);
        world.setBlock(i, j + 12, k + 26, placeStoneBricks(random), 0, 2);
        world.setBlock(i + 14, j + 12, k + 26, NovaCraftBlocks.sculk_block, 0, 2);
        world.setBlock(i, j + 12, k + 27, placeStoneBricks(random), 0, 2);
        world.setBlock(i, j + 12, k + 28, placeStoneBricks(random), 0, 2);
        world.setBlock(i + 1, j + 12, k + 28, NovaCraftBlocks.chiseled_sculk, 0, 2);
        world.setBlock(i, j + 12, k + 29, NovaCraftBlocks.sculk_block, 0, 2);
        world.setBlock(i, j + 12, k + 30, placeStoneBricks(random), 0, 2);
        world.setBlock(i + 14, j + 12, k + 30, NovaCraftBlocks.sculk_block, 0, 2);
        world.setBlock(i, j + 12, k + 31, placeStoneBricks(random), 0, 2);
        world.setBlock(i + 1, j + 12, k + 31, NovaCraftBlocks.dim_vanite_torch, 5, 2);
        world.setBlock(i + 14, j + 12, k + 31, NovaCraftBlocks.sculk_block, 0, 2);
        world.setBlock(i, j + 12, k + 32, NovaCraftBlocks.sculk_block, 0, 2);
        world.setBlock(i + 14, j + 12, k + 32, placeStoneBricks(random), 0, 2);
        world.setBlock(i + 1, j + 12, k + 33, placeStoneBricks(random), 0, 2);
        world.setBlock(i + 3, j + 12, k + 33, Blocks.ladder, 2, 2);
        world.setBlock(i + 7, j + 12, k + 33, NovaCraftBlocks.nullstone_brick_wall, 0, 2);
        world.setBlock(i + 9, j + 12, k + 33, NovaCraftBlocks.nullstone_brick_wall, 0, 2);
        world.setBlock(i + 13, j + 12, k + 33, placeStoneBricks(random), 0, 2);
        world.setBlock(i + 2, j + 12, k + 34, placeStoneBricks(random), 0, 2);
        world.setBlock(i + 3, j + 12, k + 34, placeStoneBricks(random), 0, 2);
        world.setBlock(i + 4, j + 12, k + 34, placeStoneBricks(random), 0, 2);
        world.setBlock(i + 5, j + 12, k + 34, placeStoneBricks(random), 0, 2);
        world.setBlock(i + 6, j + 12, k + 34, placeStoneBricks(random), 0, 2);
        world.setBlock(i + 7, j + 12, k + 34, placeStoneBricks(random), 0, 2);
        world.setBlock(i + 8, j + 12, k + 34, placeStoneBricks(random), 0, 2);
        world.setBlock(i + 9, j + 12, k + 34, placeStoneBricks(random), 0, 2);
        world.setBlock(i + 10, j + 12, k + 34, placeStoneBricks(random), 0, 2);
        world.setBlock(i + 11, j + 12, k + 34, placeStoneBricks(random), 0, 2);
        world.setBlock(i + 12, j + 12, k + 34, placeStoneBricks(random), 0, 2);
        world.setBlock(i + 3, j + 12, k + 35, placeStoneBricks(random), 0, 2);
        world.setBlock(i + 4, j + 12, k + 35, placeStoneBricks(random), 0, 2);
        world.setBlock(i + 5, j + 12, k + 35, placeStoneBricks(random), 0, 2);
        world.setBlock(i + 6, j + 12, k + 35, placeStoneBricks(random), 0, 2);
        world.setBlock(i + 7, j + 12, k + 35, placeStoneBricks(random), 0, 2);
        world.setBlock(i + 8, j + 12, k + 35, placeStoneBricks(random), 0, 2);
        world.setBlock(i + 9, j + 12, k + 35, placeStoneBricks(random), 0, 2);
        world.setBlock(i + 10, j + 12, k + 35, NovaCraftBlocks.sculk_block, 0, 2);
        world.setBlock(i + 11, j + 12, k + 35, placeStoneBricks(random), 0, 2);
        world.setBlock(i + 27, j + 12, k + 36, placeStoneBricks(random), 0, 2);
        world.setBlock(i + 28, j + 12, k + 36, NovaCraftBlocks.sculk_block, 0, 2);
        world.setBlock(i + 42, j + 12, k + 36, placeStoneBricks(random), 0, 2);
        world.setBlock(i + 43, j + 12, k + 36, NovaCraftBlocks.sculk_block, 0, 2);
        world.setBlock(i + 27, j + 12, k + 37, NovaCraftBlocks.sculk_block, 0, 2);
        world.setBlock(i + 28, j + 12, k + 37, placeStoneBricks(random), 0, 2);
        world.setBlock(i + 42, j + 12, k + 37, NovaCraftBlocks.sculk_block, 0, 2);
        world.setBlock(i + 43, j + 12, k + 37, placeStoneBricks(random), 0, 2);
        world.setBlock(i + 34, j + 12, k + 50, NovaCraftBlocks.dim_vanite_torch, 5, 2);
        world.setBlock(i + 36, j + 12, k + 50, NovaCraftBlocks.dim_vanite_torch, 5, 2);
        world.setBlock(i + 33, j + 12, k + 51, NovaCraftBlocks.sculk_tiled_wall, 0, 2);
        world.setBlock(i + 37, j + 12, k + 51, NovaCraftBlocks.sculk_tiled_wall, 0, 2);
        world.setBlock(i + 35, j + 12, k + 52, NovaCraftBlocks.chiseled_sculk, 0, 2);
        world.setBlock(i + 27, j + 13, k + 19, placeStoneBricks(random), 0, 2);
        world.setBlock(i + 28, j + 13, k + 19, NovaCraftBlocks.sculk_block, 0, 2);
        world.setBlock(i + 42, j + 13, k + 19, NovaCraftBlocks.sculk_block, 0, 2);
        world.setBlock(i + 43, j + 13, k + 19, placeStoneBricks(random), 0, 2);
        world.setBlock(i + 27, j + 13, k + 20, placeStoneBricks(random), 0, 2);
        world.setBlock(i + 28, j + 13, k + 20, NovaCraftBlocks.sculk_block, 0, 2);
        world.setBlock(i + 42, j + 13, k + 20, NovaCraftBlocks.sculk_block, 0, 2);
        world.setBlock(i + 43, j + 13, k + 20, NovaCraftBlocks.sculk_block, 0, 2);
        world.setBlock(i + 3, j + 13, k + 21, placeStoneBricks(random), 0, 2);
        world.setBlock(i + 4, j + 13, k + 21, placeStoneBricks(random), 0, 2);
        world.setBlock(i + 5, j + 13, k + 21, placeStoneBricks(random), 0, 2);
        world.setBlock(i + 6, j + 13, k + 21, placeStoneBricks(random), 0, 2);
        world.setBlock(i + 7, j + 13, k + 21, placeStoneBricks(random), 0, 2);
        world.setBlock(i + 8, j + 13, k + 21, NovaCraftBlocks.sculk_block, 0, 2);
        world.setBlock(i + 9, j + 13, k + 21, placeStoneBricks(random), 0, 2);
        world.setBlock(i + 10, j + 13, k + 21, placeStoneBricks(random), 0, 2);
        world.setBlock(i + 11, j + 13, k + 21, NovaCraftBlocks.sculk_block, 0, 2);
        world.setBlock(i + 2, j + 13, k + 22, placeStoneBricks(random), 0, 2);
        world.setBlock(i + 12, j + 13, k + 22, placeStoneBricks(random), 0, 2);
        world.setBlock(i + 1, j + 13, k + 23, NovaCraftBlocks.sculk_block, 0, 2);
        world.setBlock(i + 7, j + 13, k + 23, NovaCraftBlocks.dim_vanite_torch, 5, 2);
        world.setBlock(i + 9, j + 13, k + 23, NovaCraftBlocks.dim_vanite_torch, 5, 2);
        world.setBlock(i + 13, j + 13, k + 23, placeStoneBricks(random), 0, 2);
        world.setBlock(i, j + 13, k + 24, placeStoneBricks(random), 0, 2);
        world.setBlock(i + 14, j + 13, k + 24, placeStoneBricks(random), 0, 2);
        world.setBlock(i, j + 13, k + 25, placeStoneBricks(random), 0, 2);
        world.setBlock(i + 14, j + 13, k + 25, placeStoneBricks(random), 0, 2);
        world.setBlock(i, j + 13, k + 26, placeStoneBricks(random), 0, 2);
        world.setBlock(i + 14, j + 13, k + 26, placeStoneBricks(random), 0, 2);
        world.setBlock(i, j + 13, k + 27, placeStoneBricks(random), 0, 2);
        world.setBlock(i + 14, j + 13, k + 27, placeStoneBricks(random), 0, 2);
        world.setBlock(i, j + 13, k + 28, placeStoneBricks(random), 0, 2);
        world.setBlock(i + 14, j + 13, k + 28, placeStoneBricks(random), 0, 2);
        world.setBlock(i, j + 13, k + 29, placeStoneBricks(random), 0, 2);
        world.setBlock(i + 14, j + 13, k + 29, placeStoneBricks(random), 0, 2);
        world.setBlock(i, j + 13, k + 30, placeStoneBricks(random), 0, 2);
        world.setBlock(i + 14, j + 13, k + 30, placeStoneBricks(random), 0, 2);
        world.setBlock(i, j + 13, k + 31, NovaCraftBlocks.sculk_block, 0, 2);
        world.setBlock(i + 14, j + 13, k + 31, NovaCraftBlocks.sculk_block, 0, 2);
        world.setBlock(i, j + 13, k + 32, placeStoneBricks(random), 0, 2);
        world.setBlock(i + 14, j + 13, k + 32, placeStoneBricks(random), 0, 2);
        world.setBlock(i + 1, j + 13, k + 33, placeStoneBricks(random), 0, 2);
        world.setBlock(i + 7, j + 13, k + 33, NovaCraftBlocks.dim_vanite_torch, 5, 2);
        world.setBlock(i + 9, j + 13, k + 33, NovaCraftBlocks.dim_vanite_torch, 5, 2);
        world.setBlock(i + 13, j + 13, k + 33, placeStoneBricks(random), 0, 2);
        world.setBlock(i + 2, j + 13, k + 34, placeStoneBricks(random), 0, 2);
        world.setBlock(i + 12, j + 13, k + 34, placeStoneBricks(random), 0, 2);
        world.setBlock(i + 3, j + 13, k + 35, placeStoneBricks(random), 0, 2);
        world.setBlock(i + 4, j + 13, k + 35, placeStoneBricks(random), 0, 2);
        world.setBlock(i + 5, j + 13, k + 35, placeStoneBricks(random), 0, 2);
        world.setBlock(i + 6, j + 13, k + 35, placeStoneBricks(random), 0, 2);
        world.setBlock(i + 7, j + 13, k + 35, placeStoneBricks(random), 0, 2);
        world.setBlock(i + 8, j + 13, k + 35, placeStoneBricks(random), 0, 2);
        world.setBlock(i + 9, j + 13, k + 35, placeStoneBricks(random), 0, 2);
        world.setBlock(i + 10, j + 13, k + 35, placeStoneBricks(random), 0, 2);
        world.setBlock(i + 11, j + 13, k + 35, placeStoneBricks(random), 0, 2);
        world.setBlock(i + 27, j + 13, k + 36, NovaCraftBlocks.sculk_block, 0, 2);
        world.setBlock(i + 28, j + 13, k + 36, placeStoneBricks(random), 0, 2);
        world.setBlock(i + 42, j + 13, k + 36, placeStoneBricks(random), 0, 2);
        world.setBlock(i + 43, j + 13, k + 36, placeStoneBricks(random), 0, 2);
        world.setBlock(i + 27, j + 13, k + 37, placeStoneBricks(random), 0, 2);
        world.setBlock(i + 28, j + 13, k + 37, NovaCraftBlocks.sculk_block, 0, 2);
        world.setBlock(i + 42, j + 13, k + 37, placeStoneBricks(random), 0, 2);
        world.setBlock(i + 43, j + 13, k + 37, NovaCraftBlocks.sculk_block, 0, 2);
        world.setBlock(i + 27, j + 14, k + 19, placeStoneBricks(random), 0, 2);
        world.setBlock(i + 28, j + 14, k + 19, NovaCraftBlocks.sculk_block, 0, 2);
        world.setBlock(i + 42, j + 14, k + 19, NovaCraftBlocks.sculk_block, 0, 2);
        world.setBlock(i + 43, j + 14, k + 19, NovaCraftBlocks.sculk_block, 0, 2);
        world.setBlock(i + 27, j + 14, k + 20, placeStoneBricks(random), 0, 2);
        world.setBlock(i + 28, j + 14, k + 20, NovaCraftBlocks.sculk_block, 0, 2);
        world.setBlock(i + 42, j + 14, k + 20, placeStoneBricks(random), 0, 2);
        world.setBlock(i + 43, j + 14, k + 20, placeStoneBricks(random), 0, 2);
        world.setBlock(i + 3, j + 14, k + 22, placeStoneBricks(random), 0, 2);
        world.setBlock(i + 4, j + 14, k + 22, placeStoneBricks(random), 0, 2);
        world.setBlock(i + 5, j + 14, k + 22, placeStoneBricks(random), 0, 2);
        world.setBlock(i + 6, j + 14, k + 22, placeStoneBricks(random), 0, 2);
        world.setBlock(i + 7, j + 14, k + 22, placeStoneBricks(random), 0, 2);
        world.setBlock(i + 8, j + 14, k + 22, placeStoneBricks(random), 0, 2);
        world.setBlock(i + 9, j + 14, k + 22, placeStoneBricks(random), 0, 2);
        world.setBlock(i + 10, j + 14, k + 22, placeStoneBricks(random), 0, 2);
        world.setBlock(i + 11, j + 14, k + 22, placeStoneBricks(random), 0, 2);
        world.setBlock(i + 2, j + 14, k + 23, placeStoneBricks(random), 0, 2);
        world.setBlock(i + 3, j + 14, k + 23, placeStoneBricks(random), 0, 2);
        world.setBlock(i + 12, j + 14, k + 23, placeStoneBricks(random), 0, 2);
        world.setBlock(i + 1, j + 14, k + 24, placeStoneBricks(random), 0, 2);
        world.setBlock(i + 2, j + 14, k + 24, placeStoneBricks(random), 0, 2);
        world.setBlock(i + 12, j + 14, k + 24, placeStoneBricks(random), 0, 2);
        world.setBlock(i + 13, j + 14, k + 24, placeStoneBricks(random), 0, 2);
        world.setBlock(i + 1, j + 14, k + 25, placeStoneBricks(random), 0, 2);
        world.setBlock(i + 13, j + 14, k + 25, placeStoneBricks(random), 0, 2);
        world.setBlock(i + 1, j + 14, k + 26, placeStoneBricks(random), 0, 2);
        world.setBlock(i + 13, j + 14, k + 26, NovaCraftBlocks.sculk_block, 0, 2);
        world.setBlock(i + 1, j + 14, k + 27, placeStoneBricks(random), 0, 2);
        world.setBlock(i + 13, j + 14, k + 27, placeStoneBricks(random), 0, 2);
        world.setBlock(i + 1, j + 14, k + 28, placeStoneBricks(random), 0, 2);
        world.setBlock(i + 13, j + 14, k + 28, placeStoneBricks(random), 0, 2);
        world.setBlock(i + 1, j + 14, k + 29, placeStoneBricks(random), 0, 2);
        world.setBlock(i + 13, j + 14, k + 29, placeStoneBricks(random), 0, 2);
        world.setBlock(i + 1, j + 14, k + 30, placeStoneBricks(random), 0, 2);
        world.setBlock(i + 6, j + 14, k + 30, NovaCraftBlocks.nullstone_brick_wall, 0, 2);
        world.setBlock(i + 13, j + 14, k + 30, placeStoneBricks(random), 0, 2);
        world.setBlock(i + 1, j + 14, k + 31, placeStoneBricks(random), 0, 2);
        world.setBlock(i + 13, j + 14, k + 31, placeStoneBricks(random), 0, 2);
        world.setBlock(i + 1, j + 14, k + 32, placeStoneBricks(random), 0, 2);
        world.setBlock(i + 2, j + 14, k + 32, placeStoneBricks(random), 0, 2);
        world.setBlock(i + 12, j + 14, k + 32, placeStoneBricks(random), 0, 2);
        world.setBlock(i + 13, j + 14, k + 32, NovaCraftBlocks.sculk_block, 0, 2);
        world.setBlock(i + 2, j + 14, k + 33, placeStoneBricks(random), 0, 2);
        world.setBlock(i + 3, j + 14, k + 33, placeStoneBricks(random), 0, 2);
        world.setBlock(i + 11, j + 14, k + 33, placeStoneBricks(random), 0, 2);
        world.setBlock(i + 12, j + 14, k + 33, placeStoneBricks(random), 0, 2);
        world.setBlock(i + 3, j + 14, k + 34, placeStoneBricks(random), 0, 2);
        world.setBlock(i + 4, j + 14, k + 34, placeStoneBricks(random), 0, 2);
        world.setBlock(i + 5, j + 14, k + 34, NovaCraftBlocks.sculk_block, 0, 2);
        world.setBlock(i + 6, j + 14, k + 34, NovaCraftBlocks.sculk_block, 0, 2);
        world.setBlock(i + 7, j + 14, k + 34, placeStoneBricks(random), 0, 2);
        world.setBlock(i + 8, j + 14, k + 34, placeStoneBricks(random), 0, 2);
        world.setBlock(i + 9, j + 14, k + 34, placeStoneBricks(random), 0, 2);
        world.setBlock(i + 10, j + 14, k + 34, placeStoneBricks(random), 0, 2);
        world.setBlock(i + 11, j + 14, k + 34, placeStoneBricks(random), 0, 2);
        world.setBlock(i + 27, j + 14, k + 36, placeStoneBricks(random), 0, 2);
        world.setBlock(i + 28, j + 14, k + 36, placeStoneBricks(random), 0, 2);
        world.setBlock(i + 42, j + 14, k + 36, placeStoneBricks(random), 0, 2);
        world.setBlock(i + 43, j + 14, k + 36, placeStoneBricks(random), 0, 2);
        world.setBlock(i + 27, j + 14, k + 37, placeStoneBricks(random), 0, 2);
        world.setBlock(i + 28, j + 14, k + 37, NovaCraftBlocks.sculk_block, 0, 2);
        world.setBlock(i + 42, j + 14, k + 37, NovaCraftBlocks.sculk_block, 0, 2);
        world.setBlock(i + 43, j + 14, k + 37, placeStoneBricks(random), 0, 2);
        world.setBlock(i + 27, j + 15, k + 19, placeStoneBricks(random), 0, 2);
        world.setBlock(i + 28, j + 15, k + 19, NovaCraftBlocks.sculk_block, 0, 2);
        world.setBlock(i + 42, j + 15, k + 19, placeStoneBricks(random), 0, 2);
        world.setBlock(i + 43, j + 15, k + 19, NovaCraftBlocks.sculk_block, 0, 2);
        world.setBlock(i + 27, j + 15, k + 20, placeStoneBricks(random), 0, 2);
        world.setBlock(i + 28, j + 15, k + 20, placeStoneBricks(random), 0, 2);
        world.setBlock(i + 42, j + 15, k + 20, NovaCraftBlocks.sculk_block, 0, 2);
        world.setBlock(i + 43, j + 15, k + 20, placeStoneBricks(random), 0, 2);
        world.setBlock(i + 4, j + 15, k + 23, placeStoneBricks(random), 0, 2);
        world.setBlock(i + 5, j + 15, k + 23, placeStoneBricks(random), 0, 2);
        world.setBlock(i + 6, j + 15, k + 23, placeStoneBricks(random), 0, 2);
        world.setBlock(i + 7, j + 15, k + 23, placeStoneBricks(random), 0, 2);
        world.setBlock(i + 8, j + 15, k + 23, placeStoneBricks(random), 0, 2);
        world.setBlock(i + 9, j + 15, k + 23, placeStoneBricks(random), 0, 2);
        world.setBlock(i + 10, j + 15, k + 23, placeStoneBricks(random), 0, 2);
        world.setBlock(i + 11, j + 15, k + 23, placeStoneBricks(random), 0, 2);
        world.setBlock(i + 3, j + 15, k + 24, placeStoneBricks(random), 0, 2);
        world.setBlock(i + 11, j + 15, k + 24, placeStoneBricks(random), 0, 2);
        world.setBlock(i + 2, j + 15, k + 25, placeStoneBricks(random), 0, 2);
        world.setBlock(i + 12, j + 15, k + 25, NovaCraftBlocks.sculk_block, 0, 2);
        world.setBlock(i + 2, j + 15, k + 26, NovaCraftBlocks.sculk_block, 0, 2);
        world.setBlock(i + 9, j + 15, k + 26, NovaCraftBlocks.nullstone_brick_wall, 0, 2);
        world.setBlock(i + 12, j + 15, k + 26, placeStoneBricks(random), 0, 2);
        world.setBlock(i + 2, j + 15, k + 27, placeStoneBricks(random), 0, 2);
        world.setBlock(i + 12, j + 15, k + 27, placeStoneBricks(random), 0, 2);
        world.setBlock(i + 2, j + 15, k + 28, placeStoneBricks(random), 0, 2);
        world.setBlock(i + 12, j + 15, k + 28, NovaCraftBlocks.sculk_block, 0, 2);
        world.setBlock(i + 2, j + 15, k + 29, placeStoneBricks(random), 0, 2);
        world.setBlock(i + 12, j + 15, k + 29, placeStoneBricks(random), 0, 2);
        world.setBlock(i + 2, j + 15, k + 30, placeStoneBricks(random), 0, 2);
        world.setBlock(i + 6, j + 15, k + 30, NovaCraftBlocks.nullstone_brick_wall, 0, 2);
        world.setBlock(i + 12, j + 15, k + 30, placeStoneBricks(random), 0, 2);
        world.setBlock(i + 2, j + 15, k + 31, placeStoneBricks(random), 0, 2);
        world.setBlock(i + 12, j + 15, k + 31, placeStoneBricks(random), 0, 2);
        world.setBlock(i + 3, j + 15, k + 32, NovaCraftBlocks.sculk_block, 0, 2);
        world.setBlock(i + 11, j + 15, k + 32, placeStoneBricks(random), 0, 2);
        world.setBlock(i + 4, j + 15, k + 33, placeStoneBricks(random), 0, 2);
        world.setBlock(i + 5, j + 15, k + 33, placeStoneBricks(random), 0, 2);
        world.setBlock(i + 6, j + 15, k + 33, placeStoneBricks(random), 0, 2);
        world.setBlock(i + 7, j + 15, k + 33, placeStoneBricks(random), 0, 2);
        world.setBlock(i + 8, j + 15, k + 33, placeStoneBricks(random), 0, 2);
        world.setBlock(i + 9, j + 15, k + 33, placeStoneBricks(random), 0, 2);
        world.setBlock(i + 10, j + 15, k + 33, placeStoneBricks(random), 0, 2);
        world.setBlock(i + 27, j + 15, k + 36, placeStoneBricks(random), 0, 2);
        world.setBlock(i + 28, j + 15, k + 36, placeStoneBricks(random), 0, 2);
        world.setBlock(i + 42, j + 15, k + 36, placeStoneBricks(random), 0, 2);
        world.setBlock(i + 43, j + 15, k + 36, placeStoneBricks(random), 0, 2);
        world.setBlock(i + 27, j + 15, k + 37, placeStoneBricks(random), 0, 2);
        world.setBlock(i + 28, j + 15, k + 37, placeStoneBricks(random), 0, 2);
        world.setBlock(i + 42, j + 15, k + 37, NovaCraftBlocks.sculk_block, 0, 2);
        world.setBlock(i + 43, j + 15, k + 37, placeStoneBricks(random), 0, 2);
        world.setBlock(i + 27, j + 16, k + 19, placeStoneBricks(random), 0, 2);
        world.setBlock(i + 28, j + 16, k + 19, placeStoneBricks(random), 0, 2);
        world.setBlock(i + 42, j + 16, k + 19, NovaCraftBlocks.sculk_block, 0, 2);
        world.setBlock(i + 43, j + 16, k + 19, NovaCraftBlocks.sculk_block, 0, 2);
        world.setBlock(i + 27, j + 16, k + 20, NovaCraftBlocks.sculk_block, 0, 2);
        world.setBlock(i + 28, j + 16, k + 20, placeStoneBricks(random), 0, 2);
        world.setBlock(i + 42, j + 16, k + 20, placeStoneBricks(random), 0, 2);
        world.setBlock(i + 43, j + 16, k + 20, NovaCraftBlocks.sculk_block, 0, 2);
        world.setBlock(i + 4, j + 16, k + 24, placeStoneBricks(random), 0, 2);
        world.setBlock(i + 5, j + 16, k + 24, placeStoneBricks(random), 0, 2);
        world.setBlock(i + 6, j + 16, k + 24, NovaCraftBlocks.sculk_block, 0, 2);
        world.setBlock(i + 7, j + 16, k + 24, NovaCraftBlocks.sculk_block, 0, 2);
        world.setBlock(i + 8, j + 16, k + 24, placeStoneBricks(random), 0, 2);
        world.setBlock(i + 9, j + 16, k + 24, placeStoneBricks(random), 0, 2);
        world.setBlock(i + 10, j + 16, k + 24, placeStoneBricks(random), 0, 2);
        world.setBlock(i + 3, j + 16, k + 25, placeStoneBricks(random), 0, 2);
        world.setBlock(i + 11, j + 16, k + 25, placeStoneBricks(random), 0, 2);
        world.setBlock(i + 3, j + 16, k + 26, placeStoneBricks(random), 0, 2);
        world.setBlock(i + 9, j + 16, k + 26, NovaCraftBlocks.nullstone_brick_wall, 0, 2);
        world.setBlock(i + 11, j + 16, k + 26, placeStoneBricks(random), 0, 2);
        world.setBlock(i + 3, j + 16, k + 27, placeStoneBricks(random), 0, 2);
        world.setBlock(i + 11, j + 16, k + 27, placeStoneBricks(random), 0, 2);
        world.setBlock(i + 3, j + 16, k + 28, placeStoneBricks(random), 0, 2);
        world.setBlock(i + 11, j + 16, k + 28, placeStoneBricks(random), 0, 2);
        world.setBlock(i + 3, j + 16, k + 29, placeStoneBricks(random), 0, 2);
        world.setBlock(i + 11, j + 16, k + 29, placeStoneBricks(random), 0, 2);
        world.setBlock(i + 3, j + 16, k + 30, placeStoneBricks(random), 0, 2);
        world.setBlock(i + 6, j + 16, k + 30, NovaCraftBlocks.nullstone_brick_wall, 0, 2);
        world.setBlock(i + 11, j + 16, k + 30, placeStoneBricks(random), 0, 2);
        world.setBlock(i + 3, j + 16, k + 31, placeStoneBricks(random), 0, 2);
        world.setBlock(i + 11, j + 16, k + 31, placeStoneBricks(random), 0, 2);
        world.setBlock(i + 4, j + 16, k + 32, placeStoneBricks(random), 0, 2);
        world.setBlock(i + 5, j + 16, k + 32, placeStoneBricks(random), 0, 2);
        world.setBlock(i + 6, j + 16, k + 32, placeStoneBricks(random), 0, 2);
        world.setBlock(i + 7, j + 16, k + 32, placeStoneBricks(random), 0, 2);
        world.setBlock(i + 8, j + 16, k + 32, placeStoneBricks(random), 0, 2);
        world.setBlock(i + 9, j + 16, k + 32, placeStoneBricks(random), 0, 2);
        world.setBlock(i + 10, j + 16, k + 32, placeStoneBricks(random), 0, 2);
        world.setBlock(i + 27, j + 16, k + 36, NovaCraftBlocks.sculk_block, 0, 2);
        world.setBlock(i + 28, j + 16, k + 36, NovaCraftBlocks.sculk_block, 0, 2);
        world.setBlock(i + 42, j + 16, k + 36, NovaCraftBlocks.sculk_block, 0, 2);
        world.setBlock(i + 43, j + 16, k + 36, placeStoneBricks(random), 0, 2);
        world.setBlock(i + 27, j + 16, k + 37, placeStoneBricks(random), 0, 2);
        world.setBlock(i + 28, j + 16, k + 37, placeStoneBricks(random), 0, 2);
        world.setBlock(i + 42, j + 16, k + 37, placeStoneBricks(random), 0, 2);
        world.setBlock(i + 43, j + 16, k + 37, placeStoneBricks(random), 0, 2);
        world.setBlock(i + 6, j + 17, k, NovaCraftBlocks.nullstone, 0, 2);
        world.setBlock(i + 7, j + 17, k, NovaCraftBlocks.nullstone, 0, 2);
        world.setBlock(i + 8, j + 17, k, NovaCraftBlocks.nullstone, 0, 2);
        world.setBlock(i + 9, j + 17, k, NovaCraftBlocks.nullstone, 0, 2);
        world.setBlock(i + 12, j + 17, k, NovaCraftBlocks.nullstone, 0, 2);
        world.setBlock(i + 13, j + 17, k, NovaCraftBlocks.nullstone, 0, 2);
        world.setBlock(i + 14, j + 17, k, NovaCraftBlocks.nullstone, 0, 2);
        world.setBlock(i + 13, j + 17, k + 1, NovaCraftBlocks.nullstone, 0, 2);
        world.setBlock(i + 14, j + 17, k + 1, NovaCraftBlocks.nullstone, 0, 2);
        world.setBlock(i + 27, j + 17, k + 18, NovaCraftBlocks.sculk_block, 0, 2);
        world.setBlock(i + 28, j + 17, k + 18, placeStoneBricks(random), 0, 2);
        world.setBlock(i + 42, j + 17, k + 18, NovaCraftBlocks.sculk_block, 0, 2);
        world.setBlock(i + 43, j + 17, k + 18, placeStoneBricks(random), 0, 2);
        world.setBlock(i + 26, j + 17, k + 19, placeStoneBricks(random), 0, 2);
        world.setBlock(i + 27, j + 17, k + 19, placeStoneBricks(random), 0, 2);
        world.setBlock(i + 28, j + 17, k + 19, placeStoneBricks(random), 0, 2);
        world.setBlock(i + 29, j + 17, k + 19, NovaCraftBlocks.sculk_block, 0, 2);
        world.setBlock(i + 41, j + 17, k + 19, NovaCraftBlocks.sculk_block, 0, 2);
        world.setBlock(i + 42, j + 17, k + 19, NovaCraftBlocks.sculk_block, 0, 2);
        world.setBlock(i + 43, j + 17, k + 19, placeStoneBricks(random), 0, 2);
        world.setBlock(i + 44, j + 17, k + 19, placeStoneBricks(random), 0, 2);
        world.setBlock(i + 26, j + 17, k + 20, NovaCraftBlocks.sculk_block, 0, 2);
        world.setBlock(i + 27, j + 17, k + 20, NovaCraftBlocks.sculk_block, 0, 2);
        world.setBlock(i + 28, j + 17, k + 20, placeStoneBricks(random), 0, 2);
        world.setBlock(i + 29, j + 17, k + 20, placeStoneBricks(random), 0, 2);
        world.setBlock(i + 41, j + 17, k + 20, placeStoneBricks(random), 0, 2);
        world.setBlock(i + 42, j + 17, k + 20, placeStoneBricks(random), 0, 2);
        world.setBlock(i + 43, j + 17, k + 20, placeStoneBricks(random), 0, 2);
        world.setBlock(i + 44, j + 17, k + 20, placeStoneBricks(random), 0, 2);
        world.setBlock(i + 27, j + 17, k + 21, NovaCraftBlocks.sculk_block, 0, 2);
        world.setBlock(i + 28, j + 17, k + 21, NovaCraftBlocks.sculk_block, 0, 2);
        world.setBlock(i + 42, j + 17, k + 21, NovaCraftBlocks.sculk_block, 0, 2);
        world.setBlock(i + 43, j + 17, k + 21, NovaCraftBlocks.sculk_block, 0, 2);
        world.setBlock(i + 4, j + 17, k + 24, NovaCraftBlocks.sculk_block, 0, 2);
        world.setBlock(i + 5, j + 17, k + 24, placeStoneBricks(random), 0, 2);
        world.setBlock(i + 6, j + 17, k + 24, placeStoneBricks(random), 0, 2);
        world.setBlock(i + 7, j + 17, k + 24, placeStoneBricks(random), 0, 2);
        world.setBlock(i + 8, j + 17, k + 24, placeStoneBricks(random), 0, 2);
        world.setBlock(i + 9, j + 17, k + 24, NovaCraftBlocks.sculk_block, 0, 2);
        world.setBlock(i + 10, j + 17, k + 24, NovaCraftBlocks.sculk_block, 0, 2);
        world.setBlock(i + 3, j + 17, k + 25, placeStoneBricks(random), 0, 2);
        world.setBlock(i + 4, j + 17, k + 25, placeStoneBricks(random), 0, 2);
        world.setBlock(i + 5, j + 17, k + 25, placeStoneBricks(random), 0, 2);
        world.setBlock(i + 6, j + 17, k + 25, placeStoneBricks(random), 0, 2);
        world.setBlock(i + 7, j + 17, k + 25, placeStoneBricks(random), 0, 2);
        world.setBlock(i + 8, j + 17, k + 25, placeStoneBricks(random), 0, 2);
        world.setBlock(i + 9, j + 17, k + 25, placeStoneBricks(random), 0, 2);
        world.setBlock(i + 10, j + 17, k + 25, placeStoneBricks(random), 0, 2);
        world.setBlock(i + 11, j + 17, k + 25, placeStoneBricks(random), 0, 2);
        world.setBlock(i + 3, j + 17, k + 26, placeStoneBricks(random), 0, 2);
        world.setBlock(i + 4, j + 17, k + 26, placeStoneBricks(random), 0, 2);
        world.setBlock(i + 5, j + 17, k + 26, placeStoneBricks(random), 0, 2);
        world.setBlock(i + 6, j + 17, k + 26, NovaCraftBlocks.sculk_block, 0, 2);
        world.setBlock(i + 7, j + 17, k + 26, placeStoneBricks(random), 0, 2);
        world.setBlock(i + 8, j + 17, k + 26, placeStoneBricks(random), 0, 2);
        world.setBlock(i + 9, j + 17, k + 26, placeStoneBricks(random), 0, 2);
        world.setBlock(i + 10, j + 17, k + 26, placeStoneBricks(random), 0, 2);
        world.setBlock(i + 11, j + 17, k + 26, placeStoneBricks(random), 0, 2);
        world.setBlock(i + 3, j + 17, k + 27, placeStoneBricks(random), 0, 2);
        world.setBlock(i + 4, j + 17, k + 27, placeStoneBricks(random), 0, 2);
        world.setBlock(i + 5, j + 17, k + 27, placeStoneBricks(random), 0, 2);
        world.setBlock(i + 6, j + 17, k + 27, placeStoneBricks(random), 0, 2);
        world.setBlock(i + 7, j + 17, k + 27, NovaCraftBlocks.sculk_block, 0, 2);
        world.setBlock(i + 8, j + 17, k + 27, NovaCraftBlocks.sculk_block, 0, 2);
        world.setBlock(i + 9, j + 17, k + 27, placeStoneBricks(random), 0, 2);
        world.setBlock(i + 10, j + 17, k + 27, placeStoneBricks(random), 0, 2);
        world.setBlock(i + 11, j + 17, k + 27, NovaCraftBlocks.sculk_block, 0, 2);
        world.setBlock(i + 3, j + 17, k + 28, placeStoneBricks(random), 0, 2);
        world.setBlock(i + 4, j + 17, k + 28, placeStoneBricks(random), 0, 2);
        world.setBlock(i + 5, j + 17, k + 28, placeStoneBricks(random), 0, 2);
        world.setBlock(i + 6, j + 17, k + 28, placeStoneBricks(random), 0, 2);
        world.setBlock(i + 7, j + 17, k + 28, placeStoneBricks(random), 0, 2);
        world.setBlock(i + 8, j + 17, k + 28, placeStoneBricks(random), 0, 2);
        world.setBlock(i + 9, j + 17, k + 28, placeStoneBricks(random), 0, 2);
        world.setBlock(i + 10, j + 17, k + 28, placeStoneBricks(random), 0, 2);
        world.setBlock(i + 11, j + 17, k + 28, placeStoneBricks(random), 0, 2);
        world.setBlock(i + 3, j + 17, k + 29, placeStoneBricks(random), 0, 2);
        world.setBlock(i + 4, j + 17, k + 29, placeStoneBricks(random), 0, 2);
        world.setBlock(i + 5, j + 17, k + 29, placeStoneBricks(random), 0, 2);
        world.setBlock(i + 6, j + 17, k + 29, placeStoneBricks(random), 0, 2);
        world.setBlock(i + 7, j + 17, k + 29, placeStoneBricks(random), 0, 2);
        world.setBlock(i + 8, j + 17, k + 29, placeStoneBricks(random), 0, 2);
        world.setBlock(i + 9, j + 17, k + 29, placeStoneBricks(random), 0, 2);
        world.setBlock(i + 10, j + 17, k + 29, NovaCraftBlocks.sculk_block, 0, 2);
        world.setBlock(i + 11, j + 17, k + 29, placeStoneBricks(random), 0, 2);
        world.setBlock(i + 3, j + 17, k + 30, placeStoneBricks(random), 0, 2);
        world.setBlock(i + 4, j + 17, k + 30, placeStoneBricks(random), 0, 2);
        world.setBlock(i + 5, j + 17, k + 30, NovaCraftBlocks.sculk_block, 0, 2);
        world.setBlock(i + 6, j + 17, k + 30, placeStoneBricks(random), 0, 2);
        world.setBlock(i + 7, j + 17, k + 30, placeStoneBricks(random), 0, 2);
        world.setBlock(i + 8, j + 17, k + 30, placeStoneBricks(random), 0, 2);
        world.setBlock(i + 9, j + 17, k + 30, NovaCraftBlocks.sculk_block, 0, 2);
        world.setBlock(i + 10, j + 17, k + 30, placeStoneBricks(random), 0, 2);
        world.setBlock(i + 11, j + 17, k + 30, placeStoneBricks(random), 0, 2);
        world.setBlock(i + 3, j + 17, k + 31, placeStoneBricks(random), 0, 2);
        world.setBlock(i + 4, j + 17, k + 31, placeStoneBricks(random), 0, 2);
        world.setBlock(i + 5, j + 17, k + 31, placeStoneBricks(random), 0, 2);
        world.setBlock(i + 6, j + 17, k + 31, NovaCraftBlocks.sculk_block, 0, 2);
        world.setBlock(i + 7, j + 17, k + 31, placeStoneBricks(random), 0, 2);
        world.setBlock(i + 8, j + 17, k + 31, placeStoneBricks(random), 0, 2);
        world.setBlock(i + 9, j + 17, k + 31, placeStoneBricks(random), 0, 2);
        world.setBlock(i + 10, j + 17, k + 31, placeStoneBricks(random), 0, 2);
        world.setBlock(i + 11, j + 17, k + 31, placeStoneBricks(random), 0, 2);
        world.setBlock(i + 4, j + 17, k + 32, placeStoneBricks(random), 0, 2);
        world.setBlock(i + 5, j + 17, k + 32, placeStoneBricks(random), 0, 2);
        world.setBlock(i + 6, j + 17, k + 32, placeStoneBricks(random), 0, 2);
        world.setBlock(i + 7, j + 17, k + 32, placeStoneBricks(random), 0, 2);
        world.setBlock(i + 8, j + 17, k + 32, placeStoneBricks(random), 0, 2);
        world.setBlock(i + 9, j + 17, k + 32, placeStoneBricks(random), 0, 2);
        world.setBlock(i + 10, j + 17, k + 32, placeStoneBricks(random), 0, 2);
        world.setBlock(i + 27, j + 17, k + 35, NovaCraftBlocks.sculk_block, 0, 2);
        world.setBlock(i + 28, j + 17, k + 35, placeStoneBricks(random), 0, 2);
        world.setBlock(i + 42, j + 17, k + 35, placeStoneBricks(random), 0, 2);
        world.setBlock(i + 43, j + 17, k + 35, placeStoneBricks(random), 0, 2);
        world.setBlock(i + 26, j + 17, k + 36, placeStoneBricks(random), 0, 2);
        world.setBlock(i + 27, j + 17, k + 36, placeStoneBricks(random), 0, 2);
        world.setBlock(i + 28, j + 17, k + 36, placeStoneBricks(random), 0, 2);
